Workbook

Sheet ENTETES_MASSENA_0
A1: nomfichier | B1: E_NUM_INTERNE | C1: E_NUM_TICKET | D1: E_DATE_TICKET | E1: E_HEURE_TICKET | F1: E_HT1 | G1: E_HT2 | H1: E_HT3 | I1: E_HT4 | J1: E_TVA1 | K1: E_TVA2 | L1: E_TVA3 | M1: E_TVA4 | N1: E_HT_NON_TAXABLE | O1: E_TTC | P1: E_MDP_CB | Q1: E_MDP_ESPECES | R1: E_MDP_CHEQUES
A2: EJ310123.TXT | B2: 004517 | C2: 003562 | D2: 44928 | E2: 11:25 | F2: 249.17 | J2: 49.83 | O2: 299 | P2: 299
A3: EJ310123.TXT | B3: 004518 | C3: 003563 | D3: 44928 | E3: 12:34 | F3: 208.33 | J3: 41.67 | O3: 250 | Q3: 250
A4: EJ310123.TXT | B4: 004519 | C4: 003564 | D4: 44928 | E4: 16:36 | F4: 483.33 | J4: 96.67 | O4: 580 | Q4: 580
A5: EJ310123.TXT | B5: 004520 | C5: 003565 | D5: 44929 | E5: 15:02 | F5: 720.83 | J5: 144.17 | O5: 865 | Q5: 865
A6: EJ310123.TXT | B6: 004521 | C6: 003566 | D6: 44929 | E6: 15:03 | F6: 144.17 | J6: 28.83 | O6: 173 | Q6: 173
A7: EJ310123.TXT | B7: 004522 | C7: 003567 | D7: 44929 | E7: 15:19 | F7: 823.33 | J7: 164.67 | O7: 988 | Q7: 988
A8: EJ310123.TXT | B8: 004523 | C8: 003568 | D8: 44929 | E8: 15:19 | F8: 823.33 | J8: 164.67 | O8: 988 | Q8: 988
A9: EJ310123.TXT | B9: 004524 | C9: 003569 | D9: 44929 | E9: 15:45 | F9: 1450 | J9: 290 | O9: 1740 | P9: 1740
A10: EJ310123.TXT | B10: 004525 | C10: 003570 | D10: 44929 | E10: 16:16 | F10: 498.33 | J10: 99.67 | O10: 598 | P10: 598
A11: EJ310123.TXT | B11: 004526 | C11: 003571 | D11: 44930 | E11: 10:54 | F11: 725 | J11: 145 | O11: 870 | Q11: 870
A12: EJ310123.TXT | B12: 004527 | C12: 003572 | D12: 44932 | E12: 11:36 | F12: 37.5 | J12: 7.5 | O12: 45 | Q12: 45
A13: EJ310123.TXT | B13: 004528 | C13: 003573 | D13: 44932 | E13: 13:56 | F13: 498.33 | J13: 99.67 | O13: 598 | Q13: 598
A14: EJ310123.TXT | B14: 004529 | C14: 003574 | D14: 44932 | E14: 17:29 | F14: 5035 | J14: 1007 | O14: 6042 | R14: 6042
A15: EJ310123.TXT | B15: 004530 | C15: 003575 | D15: 44933 | E15: 15:33 | F15: 581.67 | J15: 116.33 | O15: 698 | P15: 698
A16: EJ310123.TXT | B16: 004531 | C16: 003576 | D16: 44933 | E16: 16:22 | F16: 540 | J16: 108 | O16: 648 | P16: 648
A17: EJ310123.TXT | B17: 004532 | C17: 003577 | D17: 44935 | E17: 15:13 | F17: 648.33 | J17: 129.67 | O17: 778 | Q17: 778
A18: EJ310123.TXT | B18: 004533 | C18: 003578 | D18: 44935 | E18: 15:42 | F18: 288.33 | J18: 57.67 | O18: 346 | Q18: 346
A19: EJ310123.TXT | B19: 004534 | C19: 003579 | D19: 44936 | E19: 15:49 | F19: 483.33 | J19: 96.67 | O19: 580 | Q19: 580
A20: EJ310123.TXT | B20: 004535 | C20: 003580 | D20: 44936 | E20: 15:49 | F20: 483.33 | J20: 96.67 | O20: 580 | Q20: 580
A21: EJ310123.TXT | B21: 004536 | C21: 003581 | D21: 44938 | E21: 15:51 | F21: 522.5 | J21: 104.5 | O21: 627 | Q21: 627
A22: EJ310123.TXT | B22: 004537 | C22: 003582 | D22: 44938 | E22: 18:15 | F22: 747.5 | J22: 149.5 | O22: 897 | Q22: 897
A23: EJ310123.TXT | B23: 004538 | C23: 003583 | D23: 44938 | E23: 18:15 | F23: 249.17 | J23: 49.83 | O23: 299 | Q23: 299
A24: EJ310123.TXT | B24: 004539 | C24: 003584 | D24: 44938 | E24: 18:52 | F24: 725 | J24: 145 | O24: 870 | Q24: 870
A25: EJ310123.TXT | B25: 004540 | C25: 003585 | D25: 44939 | E25: 10:29 | F25: 582.5 | J25: 116.5 | O25: 699 | Q25: 699
A26: EJ310123.TXT | B26: 004541 | C26: 003586 | D26: 44939 | E26: 10:29 | F26: 582.5 | J26: 116.5 | O26: 699 | Q26: 699
A27: EJ310123.TXT | B27: 004542 | C27: 003587 | D27: 44939 | E27: 14:36 | F27: 747.5 | J27: 149.5 | O27: 897 | Q27: 897
A28: EJ310123.TXT | B28: 004543 | C28: 003588 | D28: 44939 | E28: 15:42 | F28: 181.67 | J28: 36.33 | O28: 218 | Q28: 218
... A39: EJ310123.TXT | B39: 004554 | C39: 003599 | D39: 44942 | E39: 11:45 | F39: 581.67 | J39: 116.33 | O39: 698 | Q39: 698
A40: EJ310123.TXT | B40: 004555 | C40: 003600 | D40: 44942 | E40: 12:07 | F40: 350 | J40: 70 | O40: 420 | P40: 420
A41: EJ310123.TXT | B41: 004556 | C41: 003601 | D41: 44942 | E41: 16:10 | F41: 288.33 | J41: 57.67 | O41: 346 | Q41: 346
A42: EJ310123.TXT | B42: 004557 | C42: 003602 | D42: 44942 | E42: 18:23 | F42: 299.17 | J42: 59.83 | O42: 359 | Q42: 359
A43: EJ310123.TXT | B43: 004558 | C43: 003603 | D43: 44942 | E43: 18:25 | F43: 299.17 | J43: 59.83 | O43: 359 | P43: 359
A44: EJ310123.TXT | B44: 004559 | C44: 003604 | D44: 44943 | E44: 12:25 | F44: 581.67 | J44: 116.33 | O44: 698 | Q44: 698
A45: EJ310123.TXT | B45: 004560 | C45: 003605 | D45: 44943 | E45: 12:25 | F45: 581.67 | J45: 116.33 | O45: 698 | Q45: 698
A46: EJ310123.TXT | B46: 004561 | C46: 003606 | D46: 44943 | E46: 12:25 | F46: 581.67 | J46: 116.33 | O46: 698 | Q46: 698
A47: EJ310123.TXT | B47: 004562 | C47: 003607 | D47: 44943 | E47: 15:31 | F47: 37.5 | J47: 7.5 | O47: 45 | Q47: 45
A48: EJ310123.TXT | B48: 004563 | C48: 003608 | D48: 44944 | E48: 11:13 | F48: 166.67 | J48: 33.33 | O48: 200 | Q48: 200
A49: EJ310123.TXT | B49: 004564 | C49: 003609 | D49: 44944 | E49: 12:09 | F49: 581.67 | J49: 116.33 | O49: 698 | Q49: 698
A50: EJ310123.TXT | B50: 004565 | C50: 003610 | D50: 44944 | E50: 12:10 | F50: 299.17 | J50: 59.83 | O50: 359 | Q50: 359
...

Sheet Entetes_TriNumInterne
A1: nomfichier | B1: E_NUM_INTERNE | C1: E_NUM_TICKET | D1: E_DATE_TICKET | E1: E_HEURE_TICKET | F1: E_HT1 | G1: E_HT2 | H1: E_HT3 | I1: E_HT4 | J1: E_TVA1 | K1: E_TVA2 | L1: E_TVA3 | M1: E_TVA4 | N1: E_HT_NON_TAXABLE | O1: E_TTC | P1: E_MDP_CB | Q1: E_MDP_ESPECES | R1: E_MDP_CHEQUES
A2: EJ310123.TXT | B2: 004517 | C2: 003562 | D2: 44928 | E2: 11:25 | F2: 249.17 | J2: 49.83 | O2: 299 | P2: 299
A3: EJ310123.TXT | B3: 004518 | C3: 003563 | D3: 44928 | E3: 12:34 | F3: 208.33 | J3: 41.67 | O3: 250 | Q3: 250
A4: EJ310123.TXT | B4: 004519 | C4: 003564 | D4: 44928 | E4: 16:36 | F4: 483.33 | J4: 96.67 | O4: 580 | Q4: 580
A5: EJ310123.TXT | B5: 004520 | C5: 003565 | D5: 44929 | E5: 15:02 | F5: 720.83 | J5: 144.17 | O5: 865 | Q5: 865
A6: EJ310123.TXT | B6: 004521 | C6: 003566 | D6: 44929 | E6: 15:03 | F6: 144.17 | J6: 28.83 | O6: 173 | Q6: 173
A7: EJ310123.TXT | B7: 004522 | C7: 003567 | D7: 44929 | E7: 15:19 | F7: 823.33 | J7: 164.67 | O7: 988 | Q7: 988
A8: EJ310123.TXT | B8: 004523 | C8: 003568 | D8: 44929 | E8: 15:19 | F8: 823.33 | J8: 164.67 | O8: 988 | Q8: 988
A9: EJ310123.TXT | B9: 004524 | C9: 003569 | D9: 44929 | E9: 15:45 | F9: 1450 | J9: 290 | O9: 1740 | P9: 1740
A10: EJ310123.TXT | B10: 004525 | C10: 003570 | D10: 44929 | E10: 16:16 | F10: 498.33 | J10: 99.67 | O10: 598 | P10: 598
A11: EJ310123.TXT | B11: 004526 | C11: 003571 | D11: 44930 | E11: 10:54 | F11: 725 | J11: 145 | O11: 870 | Q11: 870
A12: EJ310123.TXT | B12: 004527 | C12: 003572 | D12: 44932 | E12: 11:36 | F12: 37.5 | J12: 7.5 | O12: 45 | Q12: 45
A13: EJ310123.TXT | B13: 004528 | C13: 003573 | D13: 44932 | E13: 13:56 | F13: 498.33 | J13: 99.67 | O13: 598 | Q13: 598
A14: EJ310123.TXT | B14: 004529 | C14: 003574 | D14: 44932 | E14: 17:29 | F14: 5035 | J14: 1007 | O14: 6042 | R14: 6042
A15: EJ310123.TXT | B15: 004530 | C15: 003575 | D15: 44933 | E15: 15:33 | F15: 581.67 | J15: 116.33 | O15: 698 | P15: 698
A16: EJ310123.TXT | B16: 004531 | C16: 003576 | D16: 44933 | E16: 16:22 | F16: 540 | J16: 108 | O16: 648 | P16: 648
A17: EJ310123.TXT | B17: 004532 | C17: 003577 | D17: 44935 | E17: 15:13 | F17: 648.33 | J17: 129.67 | O17: 778 | Q17: 778
A18: EJ310123.TXT | B18: 004533 | C18: 003578 | D18: 44935 | E18: 15:42 | F18: 288.33 | J18: 57.67 | O18: 346 | Q18: 346
A19: EJ310123.TXT | B19: 004534 | C19: 003579 | D19: 44936 | E19: 15:49 | F19: 483.33 | J19: 96.67 | O19: 580 | Q19: 580
A20: EJ310123.TXT | B20: 004535 | C20: 003580 | D20: 44936 | E20: 15:49 | F20: 483.33 | J20: 96.67 | O20: 580 | Q20: 580
A21: EJ310123.TXT | B21: 004536 | C21: 003581 | D21: 44938 | E21: 15:51 | F21: 522.5 | J21: 104.5 | O21: 627 | Q21: 627
A22: EJ310123.TXT | B22: 004537 | C22: 003582 | D22: 44938 | E22: 18:15 | F22: 747.5 | J22: 149.5 | O22: 897 | Q22: 897
A23: EJ310123.TXT | B23: 004538 | C23: 003583 | D23: 44938 | E23: 18:15 | F23: 249.17 | J23: 49.83 | O23: 299 | Q23: 299
A24: EJ310123.TXT | B24: 004539 | C24: 003584 | D24: 44938 | E24: 18:52 | F24: 725 | J24: 145 | O24: 870 | Q24: 870
A25: EJ310123.TXT | B25: 004540 | C25: 003585 | D25: 44939 | E25: 10:29 | F25: 582.5 | J25: 116.5 | O25: 699 | Q25: 699
A26: EJ310123.TXT | B26: 004541 | C26: 003586 | D26: 44939 | E26: 10:29 | F26: 582.5 | J26: 116.5 | O26: 699 | Q26: 699
A27: EJ310123.TXT | B27: 004542 | C27: 003587 | D27: 44939 | E27: 14:36 | F27: 747.5 | J27: 149.5 | O27: 897 | Q27: 897
A28: EJ310123.TXT | B28: 004543 | C28: 003588 | D28: 44939 | E28: 15:42 | F28: 181.67 | J28: 36.33 | O28: 218 | Q28: 218
... A39: EJ310123.TXT | B39: 004554 | C39: 003599 | D39: 44942 | E39: 11:45 | F39: 581.67 | J39: 116.33 | O39: 698 | Q39: 698
A40: EJ310123.TXT | B40: 004555 | C40: 003600 | D40: 44942 | E40: 12:07 | F40: 350 | J40: 70 | O40: 420 | P40: 420
A41: EJ310123.TXT | B41: 004556 | C41: 003601 | D41: 44942 | E41: 16:10 | F41: 288.33 | J41: 57.67 | O41: 346 | Q41: 346
A42: EJ310123.TXT | B42: 004557 | C42: 003602 | D42: 44942 | E42: 18:23 | F42: 299.17 | J42: 59.83 | O42: 359 | Q42: 359
A43: EJ310123.TXT | B43: 004558 | C43: 003603 | D43: 44942 | E43: 18:25 | F43: 299.17 | J43: 59.83 | O43: 359 | P43: 359
A44: EJ310123.TXT | B44: 004559 | C44: 003604 | D44: 44943 | E44: 12:25 | F44: 581.67 | J44: 116.33 | O44: 698 | Q44: 698
A45: EJ310123.TXT | B45: 004560 | C45: 003605 | D45: 44943 | E45: 12:25 | F45: 581.67 | J45: 116.33 | O45: 698 | Q45: 698
A46: EJ310123.TXT | B46: 004561 | C46: 003606 | D46: 44943 | E46: 12:25 | F46: 581.67 | J46: 116.33 | O46: 698 | Q46: 698
A47: EJ310123.TXT | B47: 004562 | C47: 003607 | D47: 44943 | E47: 15:31 | F47: 37.5 | J47: 7.5 | O47: 45 | Q47: 45
A48: EJ310123.TXT | B48: 004563 | C48: 003608 | D48: 44944 | E48: 11:13 | F48: 166.67 | J48: 33.33 | O48: 200 | Q48: 200
A49: EJ310123.TXT | B49: 004564 | C49: 003609 | D49: 44944 | E49: 12:09 | F49: 581.67 | J49: 116.33 | O49: 698 | Q49: 698
A50: EJ310123.TXT | B50: 004565 | C50: 003610 | D50: 44944 | E50: 12:10 | F50: 299.17 | J50: 59.83 | O50: 359 | Q50: 359
...

Sheet Entetes_CtrlCoherence
A1: nomfichier | B1: E_NUM_INTERNE | C1: E_NUM_TICKET | D1: E_DATE_TICKET | E1: E_HEURE_TICKET | F1: E_HT1 | G1: E_HT2 | H1: E_HT3 | I1: E_HT4 | J1: E_TVA1 | K1: E_TVA2 | L1: E_TVA3 | M1: E_TVA4 | N1: E_HT_NON_TAXABLE | O1: E_TTC | P1: E_MDP_CB | Q1: E_MDP_ESPECES | R1: E_MDP_CHEQUES | S1: AJ_TVA1_CALCULE | T1: AJ_ECART_TVA1 | U1: AJ_TTC_CALCULE | V1: AJ_ECART_TTC | W1: AJ_SOLDE_DU | X1: AJ_SOLDE_TOUS_MDP
A2: EJ310123.TXT | B2: 004517 | C2: 003562 | D2: 44928 | E2: 11:25 | F2: 249.17 | J2: 49.83 | O2: 299 | P2: 299 | S2: =F2*20% | T2: =J2-S2 | U2: =F2+J2 | V2: =O2-U2 | W2: =O2-(P2+R2) | X2: =O2-(P2+Q2+R2)
A3: EJ310123.TXT | B3: 004518 | C3: 003563 | D3: 44928 | E3: 12:34 | F3: 208.33 | J3: 41.67 | O3: 250 | Q3: 250 | S3: =F3*20% | T3: =J3-S3 | U3: =F3+J3 | V3: =O3-U3 | W3: =O3-(P3+R3) | X3: =O3-(P3+Q3+R3)
A4: EJ310123.TXT | B4: 004519 | C4: 003564 | D4: 44928 | E4: 16:36 | F4: 483.33 | J4: 96.67 | O4: 580 | Q4: 580 | S4: =F4*20% | T4: =J4-S4 | U4: =F4+J4 | V4: =O4-U4 | W4: =O4-(P4+R4) | X4: =O4-(P4+Q4+R4)
A5: EJ310123.TXT | B5: 004520 | C5: 003565 | D5: 44929 | E5: 15:02 | F5: 720.83 | J5: 144.17 | O5: 865 | Q5: 865 | S5: =F5*20% | T5: =J5-S5 | U5: =F5+J5 | V5: =O5-U5 | W5: =O5-(P5+R5) | X5: =O5-(P5+Q5+R5)
A6: EJ310123.TXT | B6: 004521 | C6: 003566 | D6: 44929 | E6: 15:03 | F6: 144.17 | J6: 28.83 | O6: 173 | Q6: 173 | S6: =F6*20% | T6: =J6-S6 | U6: =F6+J6 | V6: =O6-U6 | W6: =O6-(P6+R6) | X6: =O6-(P6+Q6+R6)
A7: EJ310123.TXT | B7: 004522 | C7: 003567 | D7: 44929 | E7: 15:19 | F7: 823.33 | J7: 164.67 | O7: 988 | Q7: 988 | S7: =F7*20% | T7: =J7-S7 | U7: =F7+J7 | V7: =O7-U7 | W7: =O7-(P7+R7) | X7: =O7-(P7+Q7+R7)
A8: EJ310123.TXT | B8: 004523 | C8: 003568 | D8: 44929 | E8: 15:19 | F8: 823.33 | J8: 164.67 | O8: 988 | Q8: 988 | S8: =F8*20% | T8: =J8-S8 | U8: =F8+J8 | V8: =O8-U8 | W8: =O8-(P8+R8) | X8: =O8-(P8+Q8+R8)
A9: EJ310123.TXT | B9: 004524 | C9: 003569 | D9: 44929 | E9: 15:45 | F9: 1450 | J9: 290 | O9: 1740 | P9: 1740 | S9: =F9*20% | T9: =J9-S9 | U9: =F9+J9 | V9: =O9-U9 | W9: =O9-(P9+R9) | X9: =O9-(P9+Q9+R9)
A10: EJ310123.TXT | B10: 004525 | C10: 003570 | D10: 44929 | E10: 16:16 | F10: 498.33 | J10: 99.67 | O10: 598 | P10: 598 | S10: =F10*20% | T10: =J10-S10 | U10: =F10+J10 | V10: =O10-U10 | W10: =O10-(P10+R10) | X10: =O10-(P10+Q10+R10)
A11: EJ310123.TXT | B11: 004526 | C11: 003571 | D11: 44930 | E11: 10:54 | F11: 725 | J11: 145 | O11: 870 | Q11: 870 | S11: =F11*20% | T11: =J11-S11 | U11: =F11+J11 | V11: =O11-U11 | W11: =O11-(P11+R11) | X11: =O11-(P11+Q11+R11)
A12: EJ310123.TXT | B12: 004527 | C12: 003572 | D12: 44932 | E12: 11:36 | F12: 37.5 | J12: 7.5 | O12: 45 | Q12: 45 | S12: =F12*20% | T12: =J12-S12 | U12: =F12+J12 | V12: =O12-U12 | W12: =O12-(P12+R12) | X12: =O12-(P12+Q12+R12)
A13: EJ310123.TXT | B13: 004528 | C13: 003573 | D13: 44932 | E13: 13:56 | F13: 498.33 | J13: 99.67 | O13: 598 | Q13: 598 | S13: =F13*20% | T13: =J13-S13 | U13: =F13+J13 | V13: =O13-U13 | W13: =O13-(P13+R13) | X13: =O13-(P13+Q13+R13)
A14: EJ310123.TXT | B14: 004529 | C14: 003574 | D14: 44932 | E14: 17:29 | F14: 5035 | J14: 1007 | O14: 6042 | R14: 6042 | S14: =F14*20% | T14: =J14-S14 | U14: =F14+J14 | V14: =O14-U14 | W14: =O14-(P14+R14) | X14: =O14-(P14+Q14+R14)
A15: EJ310123.TXT | B15: 004530 | C15: 003575 | D15: 44933 | E15: 15:33 | F15: 581.67 | J15: 116.33 | O15: 698 | P15: 698 | S15: =F15*20% | T15: =J15-S15 | U15: =F15+J15 | V15: =O15-U15 | W15: =O15-(P15+R15) | X15: =O15-(P15+Q15+R15)
A16: EJ310123.TXT | B16: 004531 | C16: 003576 | D16: 44933 | E16: 16:22 | F16: 540 | J16: 108 | O16: 648 | P16: 648 | S16: =F16*20% | T16: =J16-S16 | U16: =F16+J16 | V16: =O16-U16 | W16: =O16-(P16+R16) | X16: =O16-(P16+Q16+R16)
A17: EJ310123.TXT | B17: 004532 | C17: 003577 | D17: 44935 | E17: 15:13 | F17: 648.33 | J17: 129.67 | O17: 778 | Q17: 778 | S17: =F17*20% | T17: =J17-S17 | U17: =F17+J17 | V17: =O17-U17 | W17: =O17-(P17+R17) | X17: =O17-(P17+Q17+R17)
A18: EJ310123.TXT | B18: 004533 | C18: 003578 | D18: 44935 | E18: 15:42 | F18: 288.33 | J18: 57.67 | O18: 346 | Q18: 346 | S18: =F18*20% | T18: =J18-S18 | U18: =F18+J18 | V18: =O18-U18 | W18: =O18-(P18+R18) | X18: =O18-(P18+Q18+R18)
A19: EJ310123.TXT | B19: 004534 | C19: 003579 | D19: 44936 | E19: 15:49 | F19: 483.33 | J19: 96.67 | O19: 580 | Q19: 580 | S19: =F19*20% | T19: =J19-S19 | U19: =F19+J19 | V19: =O19-U19 | W19: =O19-(P19+R19) | X19: =O19-(P19+Q19+R19)
A20: EJ310123.TXT | B20: 004535 | C20: 003580 | D20: 44936 | E20: 15:49 | F20: 483.33 | J20: 96.67 | O20: 580 | Q20: 580 | S20: =F20*20% | T20: =J20-S20 | U20: =F20+J20 | V20: =O20-U20 | W20: =O20-(P20+R20) | X20: =O20-(P20+Q20+R20)
A21: EJ310123.TXT | B21: 004536 | C21: 003581 | D21: 44938 | E21: 15:51 | F21: 522.5 | J21: 104.5 | O21: 627 | Q21: 627 | S21: =F21*20% | T21: =J21-S21 | U21: =F21+J21 | V21: =O21-U21 | W21: =O21-(P21+R21) | X21: =O21-(P21+Q21+R21)
A22: EJ310123.TXT | B22: 004537 | C22: 003582 | D22: 44938 | E22: 18:15 | F22: 747.5 | J22: 149.5 | O22: 897 | Q22: 897 | S22: =F22*20% | T22: =J22-S22 | U22: =F22+J22 | V22: =O22-U22 | W22: =O22-(P22+R22) | X22: =O22-(P22+Q22+R22)
A23: EJ310123.TXT | B23: 004538 | C23: 003583 | D23: 44938 | E23: 18:15 | F23: 249.17 | J23: 49.83 | O23: 299 | Q23: 299 | S23: =F23*20% | T23: =J23-S23 | U23: =F23+J23 | V23: =O23-U23 | W23: =O23-(P23+R23) | X23: =O23-(P23+Q23+R23)
A24: EJ310123.TXT | B24: 004539 | C24: 003584 | D24: 44938 | E24: 18:52 | F24: 725 | J24: 145 | O24: 870 | Q24: 870 | S24: =F24*20% | T24: =J24-S24 | U24: =F24+J24 | V24: =O24-U24 | W24: =O24-(P24+R24) | X24: =O24-(P24+Q24+R24)
A25: EJ310123.TXT | B25: 004540 | C25: 003585 | D25: 44939 | E25: 10:29 | F25: 582.5 | J25: 116.5 | O25: 699 | Q25: 699 | S25: =F25*20% | T25: =J25-S25 | U25: =F25+J25 | V25: =O25-U25 | W25: =O25-(P25+R25) | X25: =O25-(P25+Q25+R25)
A26: EJ310123.TXT | B26: 004541 | C26: 003586 | D26: 44939 | E26: 10:29 | F26: 582.5 | J26: 116.5 | O26: 699 | Q26: 699 | S26: =F26*20% | T26: =J26-S26 | U26: =F26+J26 | V26: =O26-U26 | W26: =O26-(P26+R26) | X26: =O26-(P26+Q26+R26)
A27: EJ310123.TXT | B27: 004542 | C27: 003587 | D27: 44939 | E27: 14:36 | F27: 747.5 | J27: 149.5 | O27: 897 | Q27: 897 | S27: =F27*20% | T27: =J27-S27 | U27: =F27+J27 | V27: =O27-U27 | W27: =O27-(P27+R27) | X27: =O27-(P27+Q27+R27)
A28: EJ310123.TXT | B28: 004543 | C28: 003588 | D28: 44939 | E28: 15:42 | F28: 181.67 | J28: 36.33 | O28: 218 | Q28: 218 | S28: =F28*20% | T28: =J28-S28 | U28: =F28+J28 | V28: =O28-U28 | W28: =O28-(P28+R28) | X28: =O28-(P28+Q28+R28)
... A39: EJ310123.TXT | B39: 004554 | C39: 003599 | D39: 44942 | E39: 11:45 | F39: 581.67 | J39: 116.33 | O39: 698 | Q39: 698 | S39: =F39*20% | T39: =J39-S39 | U39: =F39+J39 | V39: =O39-U39 | W39: =O39-(P39+R39) | X39: =O39-(P39+Q39+R39)
A40: EJ310123.TXT | B40: 004555 | C40: 003600 | D40: 44942 | E40: 12:07 | F40: 350 | J40: 70 | O40: 420 | P40: 420 | S40: =F40*20% | T40: =J40-S40 | U40: =F40+J40 | V40: =O40-U40 | W40: =O40-(P40+R40) | X40: =O40-(P40+Q40+R40)
A41: EJ310123.TXT | B41: 004556 | C41: 003601 | D41: 44942 | E41: 16:10 | F41: 288.33 | J41: 57.67 | O41: 346 | Q41: 346 | S41: =F41*20% | T41: =J41-S41 | U41: =F41+J41 | V41: =O41-U41 | W41: =O41-(P41+R41) | X41: =O41-(P41+Q41+R41)
A42: EJ310123.TXT | B42: 004557 | C42: 003602 | D42: 44942 | E42: 18:23 | F42: 299.17 | J42: 59.83 | O42: 359 | Q42: 359 | S42: =F42*20% | T42: =J42-S42 | U42: =F42+J42 | V42: =O42-U42 | W42: =O42-(P42+R42) | X42: =O42-(P42+Q42+R42)
A43: EJ310123.TXT | B43: 004558 | C43: 003603 | D43: 44942 | E43: 18:25 | F43: 299.17 | J43: 59.83 | O43: 359 | P43: 359 | S43: =F43*20% | T43: =J43-S43 | U43: =F43+J43 | V43: =O43-U43 | W43: =O43-(P43+R43) | X43: =O43-(P43+Q43+R43)
A44: EJ310123.TXT | B44: 004559 | C44: 003604 | D44: 44943 | E44: 12:25 | F44: 581.67 | J44: 116.33 | O44: 698 | Q44: 698 | S44: =F44*20% | T44: =J44-S44 | U44: =F44+J44 | V44: =O44-U44 | W44: =O44-(P44+R44) | X44: =O44-(P44+Q44+R44)
A45: EJ310123.TXT | B45: 004560 | C45: 003605 | D45: 44943 | E45: 12:25 | F45: 581.67 | J45: 116.33 | O45: 698 | Q45: 698 | S45: =F45*20% | T45: =J45-S45 | U45: =F45+J45 | V45: =O45-U45 | W45: =O45-(P45+R45) | X45: =O45-(P45+Q45+R45)
A46: EJ310123.TXT | B46: 004561 | C46: 003606 | D46: 44943 | E46: 12:25 | F46: 581.67 | J46: 116.33 | O46: 698 | Q46: 698 | S46: =F46*20% | T46: =J46-S46 | U46: =F46+J46 | V46: =O46-U46 | W46: =O46-(P46+R46) | X46: =O46-(P46+Q46+R46)
A47: EJ310123.TXT | B47: 004562 | C47: 003607 | D47: 44943 | E47: 15:31 | F47: 37.5 | J47: 7.5 | O47: 45 | Q47: 45 | S47: =F47*20% | T47: =J47-S47 | U47: =F47+J47 | V47: =O47-U47 | W47: =O47-(P47+R47) | X47: =O47-(P47+Q47+R47)
A48: EJ310123.TXT | B48: 004563 | C48: 003608 | D48: 44944 | E48: 11:13 | F48: 166.67 | J48: 33.33 | O48: 200 | Q48: 200 | S48: =F48*20% | T48: =J48-S48 | U48: =F48+J48 | V48: =O48-U48 | W48: =O48-(P48+R48) | X48: =O48-(P48+Q48+R48)
A49: EJ310123.TXT | B49: 004564 | C49: 003609 | D49: 44944 | E49: 12:09 | F49: 581.67 | J49: 116.33 | O49: 698 | Q49: 698 | S49: =F49*20% | T49: =J49-S49 | U49: =F49+J49 | V49: =O49-U49 | W49: =O49-(P49+R49) | X49: =O49-(P49+Q49+R49)
A50: EJ310123.TXT | B50: 004565 | C50: 003610 | D50: 44944 | E50: 12:10 | F50: 299.17 | J50: 59.83 | O50: 359 | Q50: 359 | S50: =F50*20% | T50: =J50-S50 | U50: =F50+J50 | V50: =O50-U50 | W50: =O50-(P50+R50) | X50: =O50-(P50+Q50+R50)
...

Sheet Entetes_sequentialite
A1: nomfichier | B1: E_NUM_INTERNE | C1: E_NUM_TICKET | D1: E_DATE_TICKET | E1: E_HEURE_TICKET | F1: AJ_TROU_NUM_TICKET | G1: AJ_TROU_NUM_INTERNE | H1: OBSERVATION
A2: EJ310123.TXT | B2: 004517 | C2: 003562 | D2: 44928 | E2: 11:25 | F2: ="" | G2: ="" | H2: ="Premier enregistrement"
A3: EJ310123.TXT | B3: 004518 | C3: 003563 | D3: 44928 | E3: 12:34 | F3: =C3-C2 | G3: =B3-B2 | H3: =IF(AND(F3=1,G3=1),"OK","À JUSTIFIER")
A4: EJ310123.TXT | B4: 004519 | C4: 003564 | D4: 44928 | E4: 16:36 | F4: =C4-C3 | G4: =B4-B3 | H4: =IF(AND(F4=1,G4=1),"OK","À JUSTIFIER")
A5: EJ310123.TXT | B5: 004520 | C5: 003565 | D5: 44929 | E5: 15:02 | F5: =C5-C4 | G5: =B5-B4 | H5: =IF(AND(F5=1,G5=1),"OK","À JUSTIFIER")
A6: EJ310123.TXT | B6: 004521 | C6: 003566 | D6: 44929 | E6: 15:03 | F6: =C6-C5 | G6: =B6-B5 | H6: =IF(AND(F6=1,G6=1),"OK","À JUSTIFIER")
A7: EJ310123.TXT | B7: 004522 | C7: 003567 | D7: 44929 | E7: 15:19 | F7: =C7-C6 | G7: =B7-B6 | H7: =IF(AND(F7=1,G7=1),"OK","À JUSTIFIER")
A8: EJ310123.TXT | B8: 004523 | C8: 003568 | D8: 44929 | E8: 15:19 | F8: =C8-C7 | G8: =B8-B7 | H8: =IF(AND(F8=1,G8=1),"OK","À JUSTIFIER")
A9: EJ310123.TXT | B9: 004524 | C9: 003569 | D9: 44929 | E9: 15:45 | F9: =C9-C8 | G9: =B9-B8 | H9: =IF(AND(F9=1,G9=1),"OK","À JUSTIFIER")
A10: EJ310123.TXT | B10: 004525 | C10: 003570 | D10: 44929 | E10: 16:16 | F10: =C10-C9 | G10: =B10-B9 | H10: =IF(AND(F10=1,G10=1),"OK","À JUSTIFIER")
A11: EJ310123.TXT | B11: 004526 | C11: 003571 | D11: 44930 | E11: 10:54 | F11: =C11-C10 | G11: =B11-B10 | H11: =IF(AND(F11=1,G11=1),"OK","À JUSTIFIER")
A12: EJ310123.TXT | B12: 004527 | C12: 003572 | D12: 44932 | E12: 11:36 | F12: =C12-C11 | G12: =B12-B11 | H12: =IF(AND(F12=1,G12=1),"OK","À JUSTIFIER")
A13: EJ310123.TXT | B13: 004528 | C13: 003573 | D13: 44932 | E13: 13:56 | F13: =C13-C12 | G13: =B13-B12 | H13: =IF(AND(F13=1,G13=1),"OK","À JUSTIFIER")
A14: EJ310123.TXT | B14: 004529 | C14: 003574 | D14: 44932 | E14: 17:29 | F14: =C14-C13 | G14: =B14-B13 | H14: =IF(AND(F14=1,G14=1),"OK","À JUSTIFIER")
... A1154: EJ020925.TXT | B1154: 005878 | C1154: 004714 | D1154: 45896 | E1154: 15:37 | F1154: =C1154-C1153 | G1154: =B1154-B1153 | H1154: =IF(AND(F1154=1,G1154=1),"OK","À JUSTIFIER")

Sheet TD_OccurenceNumInterne
A1: E_NUM_INTERNE | B1: COMPTER_E_NUM_INTERNE
A2: 004517 | B2: =COUNTIF('Entetes_TriNumInterne'!$B$2:$B$1154,A2)
A3: 004518 | B3: =COUNTIF('Entetes_TriNumInterne'!$B$2:$B$1154,A3)
A4: 004519 | B4: =COUNTIF('Entetes_TriNumInterne'!$B$2:$B$1154,A4)
A5: 004520 | B5: =COUNTIF('Entetes_TriNumInterne'!$B$2:$B$1154,A5)
A6: 004521 | B6: =COUNTIF('Entetes_TriNumInterne'!$B$2:$B$1154,A6)
A7: 004522 | B7: =COUNTIF('Entetes_TriNumInterne'!$B$2:$B$1154,A7)
A8: 004523 | B8: =COUNTIF('Entetes_TriNumInterne'!$B$2:$B$1154,A8)
A9: 004524 | B9: =COUNTIF('Entetes_TriNumInterne'!$B$2:$B$1154,A9)
A10: 004525 | B10: =COUNTIF('Entetes_TriNumInterne'!$B$2:$B$1154,A10)
A11: 004526 | B11: =COUNTIF('Entetes_TriNumInterne'!$B$2:$B$1154,A11)
A12: 004527 | B12: =COUNTIF('Entetes_TriNumInterne'!$B$2:$B$1154,A12)
A13: 004528 | B13: =COUNTIF('Entetes_TriNumInterne'!$B$2:$B$1154,A13)
... A1154: 005878 | B1154: =COUNTIF('Entetes_TriNumInterne'!$B$2:$B$1154,A1154)

Sheet DoublonNumInterne
A1: E_NUM_INTERNE | B1: COMPTER_E_NUM_INTERNE
A2: AUCUN | B2: 0

Sheet TD_OccurenceNumTicket
A1: E_NUM_TICKET | B1: COMPTER_E_NUM_TICKET
A2: 003562 | B2: =COUNTIF('Entetes_TriNumInterne'!$C$2:$C$1154,A2)
A3: 003563 | B3: =COUNTIF('Entetes_TriNumInterne'!$C$2:$C$1154,A3)
A4: 003564 | B4: =COUNTIF('Entetes_TriNumInterne'!$C$2:$C$1154,A4)
A5: 003565 | B5: =COUNTIF('Entetes_TriNumInterne'!$C$2:$C$1154,A5)
A6: 003566 | B6: =COUNTIF('Entetes_TriNumInterne'!$C$2:$C$1154,A6)
A7: 003567 | B7: =COUNTIF('Entetes_TriNumInterne'!$C$2:$C$1154,A7)
A8: 003568 | B8: =COUNTIF('Entetes_TriNumInterne'!$C$2:$C$1154,A8)
A9: 003569 | B9: =COUNTIF('Entetes_TriNumInterne'!$C$2:$C$1154,A9)
A10: 003570 | B10: =COUNTIF('Entetes_TriNumInterne'!$C$2:$C$1154,A10)
A11: 003571 | B11: =COUNTIF('Entetes_TriNumInterne'!$C$2:$C$1154,A11)
A12: 003572 | B12: =COUNTIF('Entetes_TriNumInterne'!$C$2:$C$1154,A12)
A13: 003573 | B13: =COUNTIF('Entetes_TriNumInterne'!$C$2:$C$1154,A13)
... A1154: 004714 | B1154: =COUNTIF('Entetes_TriNumInterne'!$C$2:$C$1154,A1154)

Sheet DoublonNumTicket
A1: E_NUM_TICKET | B1: COMPTER_E_NUM_TICKET
A2: AUCUN | B2: 0

Sheet Entetes_CplteAnneeMois
A1: nomfichier | B1: E_NUM_INTERNE | C1: E_NUM_TICKET | D1: E_DATE_TICKET | E1: E_HEURE_TICKET | F1: E_HT1 | G1: E_HT2 | H1: E_HT3 | I1: E_HT4 | J1: E_TVA1 | K1: E_TVA2 | L1: E_TVA3 | M1: E_TVA4 | N1: E_HT_NON_TAXABLE | O1: E_TTC | P1: E_MDP_CB | Q1: E_MDP_ESPECES | R1: E_MDP_CHEQUES | S1: AJ_TOTAL_HT | T1: AJ_TOTAL_TVA_20 | U1: AJ_ANNEE | V1: AJ_MOIS
A2: EJ310123.TXT | B2: 004517 | C2: 003562 | D2: 44928 | E2: 11:25 | F2: 249.17 | J2: 49.83 | O2: 299 | P2: 299 | S2: =SUM(F2:I2)+N2 | T2: =J2 | U2: =YEAR(D2) | V2: =TEXT(D2,"yyyy-mm")
A3: EJ310123.TXT | B3: 004518 | C3: 003563 | D3: 44928 | E3: 12:34 | F3: 208.33 | J3: 41.67 | O3: 250 | Q3: 250 | S3: =SUM(F3:I3)+N3 | T3: =J3 | U3: =YEAR(D3) | V3: =TEXT(D3,"yyyy-mm")
A4: EJ310123.TXT | B4: 004519 | C4: 003564 | D4: 44928 | E4: 16:36 | F4: 483.33 | J4: 96.67 | O4: 580 | Q4: 580 | S4: =SUM(F4:I4)+N4 | T4: =J4 | U4: =YEAR(D4) | V4: =TEXT(D4,"yyyy-mm")
A5: EJ310123.TXT | B5: 004520 | C5: 003565 | D5: 44929 | E5: 15:02 | F5: 720.83 | J5: 144.17 | O5: 865 | Q5: 865 | S5: =SUM(F5:I5)+N5 | T5: =J5 | U5: =YEAR(D5) | V5: =TEXT(D5,"yyyy-mm")
A6: EJ310123.TXT | B6: 004521 | C6: 003566 | D6: 44929 | E6: 15:03 | F6: 144.17 | J6: 28.83 | O6: 173 | Q6: 173 | S6: =SUM(F6:I6)+N6 | T6: =J6 | U6: =YEAR(D6) | V6: =TEXT(D6,"yyyy-mm")
A7: EJ310123.TXT | B7: 004522 | C7: 003567 | D7: 44929 | E7: 15:19 | F7: 823.33 | J7: 164.67 | O7: 988 | Q7: 988 | S7: =SUM(F7:I7)+N7 | T7: =J7 | U7: =YEAR(D7) | V7: =TEXT(D7,"yyyy-mm")
A8: EJ310123.TXT | B8: 004523 | C8: 003568 | D8: 44929 | E8: 15:19 | F8: 823.33 | J8: 164.67 | O8: 988 | Q8: 988 | S8: =SUM(F8:I8)+N8 | T8: =J8 | U8: =YEAR(D8) | V8: =TEXT(D8,"yyyy-mm")
A9: EJ310123.TXT | B9: 004524 | C9: 003569 | D9: 44929 | E9: 15:45 | F9: 1450 | J9: 290 | O9: 1740 | P9: 1740 | S9: =SUM(F9:I9)+N9 | T9: =J9 | U9: =YEAR(D9) | V9: =TEXT(D9,"yyyy-mm")
A10: EJ310123.TXT | B10: 004525 | C10: 003570 | D10: 44929 | E10: 16:16 | F10: 498.33 | J10: 99.67 | O10: 598 | P10: 598 | S10: =SUM(F10:I10)+N10 | T10: =J10 | U10: =YEAR(D10) | V10: =TEXT(D10,"yyyy-mm")
A11: EJ310123.TXT | B11: 004526 | C11: 003571 | D11: 44930 | E11: 10:54 | F11: 725 | J11: 145 | O11: 870 | Q11: 870 | S11: =SUM(F11:I11)+N11 | T11: =J11 | U11: =YEAR(D11) | V11: =TEXT(D11,"yyyy-mm")
A12: EJ310123.TXT | B12: 004527 | C12: 003572 | D12: 44932 | E12: 11:36 | F12: 37.5 | J12: 7.5 | O12: 45 | Q12: 45 | S12: =SUM(F12:I12)+N12 | T12: =J12 | U12: =YEAR(D12) | V12: =TEXT(D12,"yyyy-mm")
A13: EJ310123.TXT | B13: 004528 | C13: 003573 | D13: 44932 | E13: 13:56 | F13: 498.33 | J13: 99.67 | O13: 598 | Q13: 598 | S13: =SUM(F13:I13)+N13 | T13: =J13 | U13: =YEAR(D13) | V13: =TEXT(D13,"yyyy-mm")
A14: EJ310123.TXT | B14: 004529 | C14: 003574 | D14: 44932 | E14: 17:29 | F14: 5035 | J14: 1007 | O14: 6042 | R14: 6042 | S14: =SUM(F14:I14)+N14 | T14: =J14 | U14: =YEAR(D14) | V14: =TEXT(D14,"yyyy-mm")
A15: EJ310123.TXT | B15: 004530 | C15: 003575 | D15: 44933 | E15: 15:33 | F15: 581.67 | J15: 116.33 | O15: 698 | P15: 698 | S15: =SUM(F15:I15)+N15 | T15: =J15 | U15: =YEAR(D15) | V15: =TEXT(D15,"yyyy-mm")
A16: EJ310123.TXT | B16: 004531 | C16: 003576 | D16: 44933 | E16: 16:22 | F16: 540 | J16: 108 | O16: 648 | P16: 648 | S16: =SUM(F16:I16)+N16 | T16: =J16 | U16: =YEAR(D16) | V16: =TEXT(D16,"yyyy-mm")
A17: EJ310123.TXT | B17: 004532 | C17: 003577 | D17: 44935 | E17: 15:13 | F17: 648.33 | J17: 129.67 | O17: 778 | Q17: 778 | S17: =SUM(F17:I17)+N17 | T17: =J17 | U17: =YEAR(D17) | V17: =TEXT(D17,"yyyy-mm")
A18: EJ310123.TXT | B18: 004533 | C18: 003578 | D18: 44935 | E18: 15:42 | F18: 288.33 | J18: 57.67 | O18: 346 | Q18: 346 | S18: =SUM(F18:I18)+N18 | T18: =J18 | U18: =YEAR(D18) | V18: =TEXT(D18,"yyyy-mm")
A19: EJ310123.TXT | B19: 004534 | C19: 003579 | D19: 44936 | E19: 15:49 | F19: 483.33 | J19: 96.67 | O19: 580 | Q19: 580 | S19: =SUM(F19:I19)+N19 | T19: =J19 | U19: =YEAR(D19) | V19: =TEXT(D19,"yyyy-mm")
A20: EJ310123.TXT | B20: 004535 | C20: 003580 | D20: 44936 | E20: 15:49 | F20: 483.33 | J20: 96.67 | O20: 580 | Q20: 580 | S20: =SUM(F20:I20)+N20 | T20: =J20 | U20: =YEAR(D20) | V20: =TEXT(D20,"yyyy-mm")
A21: EJ310123.TXT | B21: 004536 | C21: 003581 | D21: 44938 | E21: 15:51 | F21: 522.5 | J21: 104.5 | O21: 627 | Q21: 627 | S21: =SUM(F21:I21)+N21 | T21: =J21 | U21: =YEAR(D21) | V21: =TEXT(D21,"yyyy-mm")
A22: EJ310123.TXT | B22: 004537 | C22: 003582 | D22: 44938 | E22: 18:15 | F22: 747.5 | J22: 149.5 | O22: 897 | Q22: 897 | S22: =SUM(F22:I22)+N22 | T22: =J22 | U22: =YEAR(D22) | V22: =TEXT(D22,"yyyy-mm")
A23: EJ310123.TXT | B23: 004538 | C23: 003583 | D23: 44938 | E23: 18:15 | F23: 249.17 | J23: 49.83 | O23: 299 | Q23: 299 | S23: =SUM(F23:I23)+N23 | T23: =J23 | U23: =YEAR(D23) | V23: =TEXT(D23,"yyyy-mm")
A24: EJ310123.TXT | B24: 004539 | C24: 003584 | D24: 44938 | E24: 18:52 | F24: 725 | J24: 145 | O24: 870 | Q24: 870 | S24: =SUM(F24:I24)+N24 | T24: =J24 | U24: =YEAR(D24) | V24: =TEXT(D24,"yyyy-mm")
A25: EJ310123.TXT | B25: 004540 | C25: 003585 | D25: 44939 | E25: 10:29 | F25: 582.5 | J25: 116.5 | O25: 699 | Q25: 699 | S25: =SUM(F25:I25)+N25 | T25: =J25 | U25: =YEAR(D25) | V25: =TEXT(D25,"yyyy-mm")
A26: EJ310123.TXT | B26: 004541 | C26: 003586 | D26: 44939 | E26: 10:29 | F26: 582.5 | J26: 116.5 | O26: 699 | Q26: 699 | S26: =SUM(F26:I26)+N26 | T26: =J26 | U26: =YEAR(D26) | V26: =TEXT(D26,"yyyy-mm")
A27: EJ310123.TXT | B27: 004542 | C27: 003587 | D27: 44939 | E27: 14:36 | F27: 747.5 | J27: 149.5 | O27: 897 | Q27: 897 | S27: =SUM(F27:I27)+N27 | T27: =J27 | U27: =YEAR(D27) | V27: =TEXT(D27,"yyyy-mm")
A28: EJ310123.TXT | B28: 004543 | C28: 003588 | D28: 44939 | E28: 15:42 | F28: 181.67 | J28: 36.33 | O28: 218 | Q28: 218 | S28: =SUM(F28:I28)+N28 | T28: =J28 | U28: =YEAR(D28) | V28: =TEXT(D28,"yyyy-mm")
... A39: EJ310123.TXT | B39: 004554 | C39: 003599 | D39: 44942 | E39: 11:45 | F39: 581.67 | J39: 116.33 | O39: 698 | Q39: 698 | S39: =SUM(F39:I39)+N39 | T39: =J39 | U39: =YEAR(D39) | V39: =TEXT(D39,"yyyy-mm")
A40: EJ310123.TXT | B40: 004555 | C40: 003600 | D40: 44942 | E40: 12:07 | F40: 350 | J40: 70 | O40: 420 | P40: 420 | S40: =SUM(F40:I40)+N40 | T40: =J40 | U40: =YEAR(D40) | V40: =TEXT(D40,"yyyy-mm")
A41: EJ310123.TXT | B41: 004556 | C41: 003601 | D41: 44942 | E41: 16:10 | F41: 288.33 | J41: 57.67 | O41: 346 | Q41: 346 | S41: =SUM(F41:I41)+N41 | T41: =J41 | U41: =YEAR(D41) | V41: =TEXT(D41,"yyyy-mm")
A42: EJ310123.TXT | B42: 004557 | C42: 003602 | D42: 44942 | E42: 18:23 | F42: 299.17 | J42: 59.83 | O42: 359 | Q42: 359 | S42: =SUM(F42:I42)+N42 | T42: =J42 | U42: =YEAR(D42) | V42: =TEXT(D42,"yyyy-mm")
A43: EJ310123.TXT | B43: 004558 | C43: 003603 | D43: 44942 | E43: 18:25 | F43: 299.17 | J43: 59.83 | O43: 359 | P43: 359 | S43: =SUM(F43:I43)+N43 | T43: =J43 | U43: =YEAR(D43) | V43: =TEXT(D43,"yyyy-mm")
A44: EJ310123.TXT | B44: 004559 | C44: 003604 | D44: 44943 | E44: 12:25 | F44: 581.67 | J44: 116.33 | O44: 698 | Q44: 698 | S44: =SUM(F44:I44)+N44 | T44: =J44 | U44: =YEAR(D44) | V44: =TEXT(D44,"yyyy-mm")
A45: EJ310123.TXT | B45: 004560 | C45: 003605 | D45: 44943 | E45: 12:25 | F45: 581.67 | J45: 116.33 | O45: 698 | Q45: 698 | S45: =SUM(F45:I45)+N45 | T45: =J45 | U45: =YEAR(D45) | V45: =TEXT(D45,"yyyy-mm")
A46: EJ310123.TXT | B46: 004561 | C46: 003606 | D46: 44943 | E46: 12:25 | F46: 581.67 | J46: 116.33 | O46: 698 | Q46: 698 | S46: =SUM(F46:I46)+N46 | T46: =J46 | U46: =YEAR(D46) | V46: =TEXT(D46,"yyyy-mm")
A47: EJ310123.TXT | B47: 004562 | C47: 003607 | D47: 44943 | E47: 15:31 | F47: 37.5 | J47: 7.5 | O47: 45 | Q47: 45 | S47: =SUM(F47:I47)+N47 | T47: =J47 | U47: =YEAR(D47) | V47: =TEXT(D47,"yyyy-mm")
A48: EJ310123.TXT | B48: 004563 | C48: 003608 | D48: 44944 | E48: 11:13 | F48: 166.67 | J48: 33.33 | O48: 200 | Q48: 200 | S48: =SUM(F48:I48)+N48 | T48: =J48 | U48: =YEAR(D48) | V48: =TEXT(D48,"yyyy-mm")
A49: EJ310123.TXT | B49: 004564 | C49: 003609 | D49: 44944 | E49: 12:09 | F49: 581.67 | J49: 116.33 | O49: 698 | Q49: 698 | S49: =SUM(F49:I49)+N49 | T49: =J49 | U49: =YEAR(D49) | V49: =TEXT(D49,"yyyy-mm")
A50: EJ310123.TXT | B50: 004565 | C50: 003610 | D50: 44944 | E50: 12:10 | F50: 299.17 | J50: 59.83 | O50: 359 | Q50: 359 | S50: =SUM(F50:I50)+N50 | T50: =J50 | U50: =YEAR(D50) | V50: =TEXT(D50,"yyyy-mm")
...

Sheet TD_TotalEnctTTC
A1: AJ_ANNEE | B1: AJ_MOIS | C1: SOMME_E_TTC | D1: SOMME_E_MDP_CB | E1: SOMME_E_MDP_CHEQUES | F1: SOMME_E_MDP_ESPECES
A2: 2023 | B2: 2023-01 | C2: =SUMIFS('Entetes_CplteAnneeMois'!$O$2:$O$1154,'Entetes_CplteAnneeMois'!$V$2:$V$1154,B2) | D2: =SUMIFS('Entetes_CplteAnneeMois'!$P$2:$P$1154,'Entetes_CplteAnneeMois'!$V$2:$V$1154,B2) | E2: =SUMIFS('Entetes_CplteAnneeMois'!$R$2:$R$1154,'Entetes_CplteAnneeMois'!$V$2:$V$1154,B2) | F2: =SUMIFS('Entetes_CplteAnneeMois'!$Q$2:$Q$1154,'Entetes_CplteAnneeMois'!$V$2:$V$1154,B2)
A3: 2023 | B3: 2023-02 | C3: =SUMIFS('Entetes_CplteAnneeMois'!$O$2:$O$1154,'Entetes_CplteAnneeMois'!$V$2:$V$1154,B3) | D3: =SUMIFS('Entetes_CplteAnneeMois'!$P$2:$P$1154,'Entetes_CplteAnneeMois'!$V$2:$V$1154,B3) | E3: =SUMIFS('Entetes_CplteAnneeMois'!$R$2:$R$1154,'Entetes_CplteAnneeMois'!$V$2:$V$1154,B3) | F3: =SUMIFS('Entetes_CplteAnneeMois'!$Q$2:$Q$1154,'Entetes_CplteAnneeMois'!$V$2:$V$1154,B3)
A4: 2023 | B4: 2023-03 | C4: =SUMIFS('Entetes_CplteAnneeMois'!$O$2:$O$1154,'Entetes_CplteAnneeMois'!$V$2:$V$1154,B4) | D4: =SUMIFS('Entetes_CplteAnneeMois'!$P$2:$P$1154,'Entetes_CplteAnneeMois'!$V$2:$V$1154,B4) | E4: =SUMIFS('Entetes_CplteAnneeMois'!$R$2:$R$1154,'Entetes_CplteAnneeMois'!$V$2:$V$1154,B4) | F4: =SUMIFS('Entetes_CplteAnneeMois'!$Q$2:$Q$1154,'Entetes_CplteAnneeMois'!$V$2:$V$1154,B4)
A5: 2023 | B5: 2023-04 | C5: =SUMIFS('Entetes_CplteAnneeMois'!$O$2:$O$1154,'Entetes_CplteAnneeMois'!$V$2:$V$1154,B5) | D5: =SUMIFS('Entetes_CplteAnneeMois'!$P$2:$P$1154,'Entetes_CplteAnneeMois'!$V$2:$V$1154,B5) | E5: =SUMIFS('Entetes_CplteAnneeMois'!$R$2:$R$1154,'Entetes_CplteAnneeMois'!$V$2:$V$1154,B5) | F5: =SUMIFS('Entetes_CplteAnneeMois'!$Q$2:$Q$1154,'Entetes_CplteAnneeMois'!$V$2:$V$1154,B5)
A6: 2023 | B6: 2023-05 | C6: =SUMIFS('Entetes_CplteAnneeMois'!$O$2:$O$1154,'Entetes_CplteAnneeMois'!$V$2:$V$1154,B6) | D6: =SUMIFS('Entetes_CplteAnneeMois'!$P$2:$P$1154,'Entetes_CplteAnneeMois'!$V$2:$V$1154,B6) | E6: =SUMIFS('Entetes_CplteAnneeMois'!$R$2:$R$1154,'Entetes_CplteAnneeMois'!$V$2:$V$1154,B6) | F6: =SUMIFS('Entetes_CplteAnneeMois'!$Q$2:$Q$1154,'Entetes_CplteAnneeMois'!$V$2:$V$1154,B6)
A7: 2023 | B7: 2023-06 | C7: =SUMIFS('Entetes_CplteAnneeMois'!$O$2:$O$1154,'Entetes_CplteAnneeMois'!$V$2:$V$1154,B7) | D7: =SUMIFS('Entetes_CplteAnneeMois'!$P$2:$P$1154,'Entetes_CplteAnneeMois'!$V$2:$V$1154,B7) | E7: =SUMIFS('Entetes_CplteAnneeMois'!$R$2:$R$1154,'Entetes_CplteAnneeMois'!$V$2:$V$1154,B7) | F7: =SUMIFS('Entetes_CplteAnneeMois'!$Q$2:$Q$1154,'Entetes_CplteAnneeMois'!$V$2:$V$1154,B7)
A8: 2023 | B8: 2023-07 | C8: =SUMIFS('Entetes_CplteAnneeMois'!$O$2:$O$1154,'Entetes_CplteAnneeMois'!$V$2:$V$1154,B8) | D8: =SUMIFS('Entetes_CplteAnneeMois'!$P$2:$P$1154,'Entetes_CplteAnneeMois'!$V$2:$V$1154,B8) | E8: =SUMIFS('Entetes_CplteAnneeMois'!$R$2:$R$1154,'Entetes_CplteAnneeMois'!$V$2:$V$1154,B8) | F8: =SUMIFS('Entetes_CplteAnneeMois'!$Q$2:$Q$1154,'Entetes_CplteAnneeMois'!$V$2:$V$1154,B8)
A9: 2023 | B9: 2023-08 | C9: =SUMIFS('Entetes_CplteAnneeMois'!$O$2:$O$1154,'Entetes_CplteAnneeMois'!$V$2:$V$1154,B9) | D9: =SUMIFS('Entetes_CplteAnneeMois'!$P$2:$P$1154,'Entetes_CplteAnneeMois'!$V$2:$V$1154,B9) | E9: =SUMIFS('Entetes_CplteAnneeMois'!$R$2:$R$1154,'Entetes_CplteAnneeMois'!$V$2:$V$1154,B9) | F9: =SUMIFS('Entetes_CplteAnneeMois'!$Q$2:$Q$1154,'Entetes_CplteAnneeMois'!$V$2:$V$1154,B9)
A10: 2023 | B10: 2023-09 | C10: =SUMIFS('Entetes_CplteAnneeMois'!$O$2:$O$1154,'Entetes_CplteAnneeMois'!$V$2:$V$1154,B10) | D10: =SUMIFS('Entetes_CplteAnneeMois'!$P$2:$P$1154,'Entetes_CplteAnneeMois'!$V$2:$V$1154,B10) | E10: =SUMIFS('Entetes_CplteAnneeMois'!$R$2:$R$1154,'Entetes_CplteAnneeMois'!$V$2:$V$1154,B10) | F10: =SUMIFS('Entetes_CplteAnneeMois'!$Q$2:$Q$1154,'Entetes_CplteAnneeMois'!$V$2:$V$1154,B10)
A11: 2023 | B11: 2023-10 | C11: =SUMIFS('Entetes_CplteAnneeMois'!$O$2:$O$1154,'Entetes_CplteAnneeMois'!$V$2:$V$1154,B11) | D11: =SUMIFS('Entetes_CplteAnneeMois'!$P$2:$P$1154,'Entetes_CplteAnneeMois'!$V$2:$V$1154,B11) | E11: =SUMIFS('Entetes_CplteAnneeMois'!$R$2:$R$1154,'Entetes_CplteAnneeMois'!$V$2:$V$1154,B11) | F11: =SUMIFS('Entetes_CplteAnneeMois'!$Q$2:$Q$1154,'Entetes_CplteAnneeMois'!$V$2:$V$1154,B11)
A12: 2023 | B12: 2023-11 | C12: =SUMIFS('Entetes_CplteAnneeMois'!$O$2:$O$1154,'Entetes_CplteAnneeMois'!$V$2:$V$1154,B12) | D12: =SUMIFS('Entetes_CplteAnneeMois'!$P$2:$P$1154,'Entetes_CplteAnneeMois'!$V$2:$V$1154,B12) | E12: =SUMIFS('Entetes_CplteAnneeMois'!$R$2:$R$1154,'Entetes_CplteAnneeMois'!$V$2:$V$1154,B12) | F12: =SUMIFS('Entetes_CplteAnneeMois'!$Q$2:$Q$1154,'Entetes_CplteAnneeMois'!$V$2:$V$1154,B12)
A13: 2023 | B13: 2023-12 | C13: =SUMIFS('Entetes_CplteAnneeMois'!$O$2:$O$1154,'Entetes_CplteAnneeMois'!$V$2:$V$1154,B13) | D13: =SUMIFS('Entetes_CplteAnneeMois'!$P$2:$P$1154,'Entetes_CplteAnneeMois'!$V$2:$V$1154,B13) | E13: =SUMIFS('Entetes_CplteAnneeMois'!$R$2:$R$1154,'Entetes_CplteAnneeMois'!$V$2:$V$1154,B13) | F13: =SUMIFS('Entetes_CplteAnneeMois'!$Q$2:$Q$1154,'Entetes_CplteAnneeMois'!$V$2:$V$1154,B13)
... A33: 2025 | B33: 2025-08 | C33: =SUMIFS('Entetes_CplteAnneeMois'!$O$2:$O$1154,'Entetes_CplteAnneeMois'!$V$2:$V$1154,B33) | D33: =SUMIFS('Entetes_CplteAnneeMois'!$P$2:$P$1154,'Entetes_CplteAnneeMois'!$V$2:$V$1154,B33) | E33: =SUMIFS('Entetes_CplteAnneeMois'!$R$2:$R$1154,'Entetes_CplteAnneeMois'!$V$2:$V$1154,B33) | F33: =SUMIFS('Entetes_CplteAnneeMois'!$Q$2:$Q$1154,'Entetes_CplteAnneeMois'!$V$2:$V$1154,B33)

Sheet enct_mensuels_MASSENA
A1: AJ_ANNEE | B1: AJ_MOIS | C1: SOMME_E_TTC | D1: SOMME_E_MDP_CB | E1: SOMME_E_MDP_CHEQUES | F1: SOMME_E_MDP_ESPECES
A2: ='TD_TotalEnctTTC'!A2 | B2: ='TD_TotalEnctTTC'!B2 | C2: ='TD_TotalEnctTTC'!C2 | D2: ='TD_TotalEnctTTC'!D2 | E2: ='TD_TotalEnctTTC'!E2 | F2: ='TD_TotalEnctTTC'!F2
A3: ='TD_TotalEnctTTC'!A3 | B3: ='TD_TotalEnctTTC'!B3 | C3: ='TD_TotalEnctTTC'!C3 | D3: ='TD_TotalEnctTTC'!D3 | E3: ='TD_TotalEnctTTC'!E3 | F3: ='TD_TotalEnctTTC'!F3
A4: ='TD_TotalEnctTTC'!A4 | B4: ='TD_TotalEnctTTC'!B4 | C4: ='TD_TotalEnctTTC'!C4 | D4: ='TD_TotalEnctTTC'!D4 | E4: ='TD_TotalEnctTTC'!E4 | F4: ='TD_TotalEnctTTC'!F4
A5: ='TD_TotalEnctTTC'!A5 | B5: ='TD_TotalEnctTTC'!B5 | C5: ='TD_TotalEnctTTC'!C5 | D5: ='TD_TotalEnctTTC'!D5 | E5: ='TD_TotalEnctTTC'!E5 | F5: ='TD_TotalEnctTTC'!F5
A6: ='TD_TotalEnctTTC'!A6 | B6: ='TD_TotalEnctTTC'!B6 | C6: ='TD_TotalEnctTTC'!C6 | D6: ='TD_TotalEnctTTC'!D6 | E6: ='TD_TotalEnctTTC'!E6 | F6: ='TD_TotalEnctTTC'!F6
A7: ='TD_TotalEnctTTC'!A7 | B7: ='TD_TotalEnctTTC'!B7 | C7: ='TD_TotalEnctTTC'!C7 | D7: ='TD_TotalEnctTTC'!D7 | E7: ='TD_TotalEnctTTC'!E7 | F7: ='TD_TotalEnctTTC'!F7
A8: ='TD_TotalEnctTTC'!A8 | B8: ='TD_TotalEnctTTC'!B8 | C8: ='TD_TotalEnctTTC'!C8 | D8: ='TD_TotalEnctTTC'!D8 | E8: ='TD_TotalEnctTTC'!E8 | F8: ='TD_TotalEnctTTC'!F8
A9: ='TD_TotalEnctTTC'!A9 | B9: ='TD_TotalEnctTTC'!B9 | C9: ='TD_TotalEnctTTC'!C9 | D9: ='TD_TotalEnctTTC'!D9 | E9: ='TD_TotalEnctTTC'!E9 | F9: ='TD_TotalEnctTTC'!F9
A10: ='TD_TotalEnctTTC'!A10 | B10: ='TD_TotalEnctTTC'!B10 | C10: ='TD_TotalEnctTTC'!C10 | D10: ='TD_TotalEnctTTC'!D10 | E10: ='TD_TotalEnctTTC'!E10 | F10: ='TD_TotalEnctTTC'!F10
A11: ='TD_TotalEnctTTC'!A11 | B11: ='TD_TotalEnctTTC'!B11 | C11: ='TD_TotalEnctTTC'!C11 | D11: ='TD_TotalEnctTTC'!D11 | E11: ='TD_TotalEnctTTC'!E11 | F11: ='TD_TotalEnctTTC'!F11
A12: ='TD_TotalEnctTTC'!A12 | B12: ='TD_TotalEnctTTC'!B12 | C12: ='TD_TotalEnctTTC'!C12 | D12: ='TD_TotalEnctTTC'!D12 | E12: ='TD_TotalEnctTTC'!E12 | F12: ='TD_TotalEnctTTC'!F12
A13: ='TD_TotalEnctTTC'!A13 | B13: ='TD_TotalEnctTTC'!B13 | C13: ='TD_TotalEnctTTC'!C13 | D13: ='TD_TotalEnctTTC'!D13 | E13: ='TD_TotalEnctTTC'!E13 | F13: ='TD_TotalEnctTTC'!F13
... A33: ='TD_TotalEnctTTC'!A33 | B33: ='TD_TotalEnctTTC'!B33 | C33: ='TD_TotalEnctTTC'!C33 | D33: ='TD_TotalEnctTTC'!D33 | E33: ='TD_TotalEnctTTC'!E33 | F33: ='TD_TotalEnctTTC'!F33

Sheet TD_TotalHtTvaTtc
A1: AJ_ANNEE | B1: AJ_MOIS | C1: SOMME_AJ_TOTAL_HT | D1: SOMME_AJ_TOTAL_TVA_20 | E1: SOMME_E_TTC
A2: 2023 | B2: 2023-01 | C2: =SUMIFS('Entetes_CplteAnneeMois'!$S$2:$S$1154,'Entetes_CplteAnneeMois'!$V$2:$V$1154,B2) | D2: =SUMIFS('Entetes_CplteAnneeMois'!$T$2:$T$1154,'Entetes_CplteAnneeMois'!$V$2:$V$1154,B2) | E2: =SUMIFS('Entetes_CplteAnneeMois'!$O$2:$O$1154,'Entetes_CplteAnneeMois'!$V$2:$V$1154,B2)
A3: 2023 | B3: 2023-02 | C3: =SUMIFS('Entetes_CplteAnneeMois'!$S$2:$S$1154,'Entetes_CplteAnneeMois'!$V$2:$V$1154,B3) | D3: =SUMIFS('Entetes_CplteAnneeMois'!$T$2:$T$1154,'Entetes_CplteAnneeMois'!$V$2:$V$1154,B3) | E3: =SUMIFS('Entetes_CplteAnneeMois'!$O$2:$O$1154,'Entetes_CplteAnneeMois'!$V$2:$V$1154,B3)
A4: 2023 | B4: 2023-03 | C4: =SUMIFS('Entetes_CplteAnneeMois'!$S$2:$S$1154,'Entetes_CplteAnneeMois'!$V$2:$V$1154,B4) | D4: =SUMIFS('Entetes_CplteAnneeMois'!$T$2:$T$1154,'Entetes_CplteAnneeMois'!$V$2:$V$1154,B4) | E4: =SUMIFS('Entetes_CplteAnneeMois'!$O$2:$O$1154,'Entetes_CplteAnneeMois'!$V$2:$V$1154,B4)
A5: 2023 | B5: 2023-04 | C5: =SUMIFS('Entetes_CplteAnneeMois'!$S$2:$S$1154,'Entetes_CplteAnneeMois'!$V$2:$V$1154,B5) | D5: =SUMIFS('Entetes_CplteAnneeMois'!$T$2:$T$1154,'Entetes_CplteAnneeMois'!$V$2:$V$1154,B5) | E5: =SUMIFS('Entetes_CplteAnneeMois'!$O$2:$O$1154,'Entetes_CplteAnneeMois'!$V$2:$V$1154,B5)
A6: 2023 | B6: 2023-05 | C6: =SUMIFS('Entetes_CplteAnneeMois'!$S$2:$S$1154,'Entetes_CplteAnneeMois'!$V$2:$V$1154,B6) | D6: =SUMIFS('Entetes_CplteAnneeMois'!$T$2:$T$1154,'Entetes_CplteAnneeMois'!$V$2:$V$1154,B6) | E6: =SUMIFS('Entetes_CplteAnneeMois'!$O$2:$O$1154,'Entetes_CplteAnneeMois'!$V$2:$V$1154,B6)
A7: 2023 | B7: 2023-06 | C7: =SUMIFS('Entetes_CplteAnneeMois'!$S$2:$S$1154,'Entetes_CplteAnneeMois'!$V$2:$V$1154,B7) | D7: =SUMIFS('Entetes_CplteAnneeMois'!$T$2:$T$1154,'Entetes_CplteAnneeMois'!$V$2:$V$1154,B7) | E7: =SUMIFS('Entetes_CplteAnneeMois'!$O$2:$O$1154,'Entetes_CplteAnneeMois'!$V$2:$V$1154,B7)
A8: 2023 | B8: 2023-07 | C8: =SUMIFS('Entetes_CplteAnneeMois'!$S$2:$S$1154,'Entetes_CplteAnneeMois'!$V$2:$V$1154,B8) | D8: =SUMIFS('Entetes_CplteAnneeMois'!$T$2:$T$1154,'Entetes_CplteAnneeMois'!$V$2:$V$1154,B8) | E8: =SUMIFS('Entetes_CplteAnneeMois'!$O$2:$O$1154,'Entetes_CplteAnneeMois'!$V$2:$V$1154,B8)
A9: 2023 | B9: 2023-08 | C9: =SUMIFS('Entetes_CplteAnneeMois'!$S$2:$S$1154,'Entetes_CplteAnneeMois'!$V$2:$V$1154,B9) | D9: =SUMIFS('Entetes_CplteAnneeMois'!$T$2:$T$1154,'Entetes_CplteAnneeMois'!$V$2:$V$1154,B9) | E9: =SUMIFS('Entetes_CplteAnneeMois'!$O$2:$O$1154,'Entetes_CplteAnneeMois'!$V$2:$V$1154,B9)
A10: 2023 | B10: 2023-09 | C10: =SUMIFS('Entetes_CplteAnneeMois'!$S$2:$S$1154,'Entetes_CplteAnneeMois'!$V$2:$V$1154,B10) | D10: =SUMIFS('Entetes_CplteAnneeMois'!$T$2:$T$1154,'Entetes_CplteAnneeMois'!$V$2:$V$1154,B10) | E10: =SUMIFS('Entetes_CplteAnneeMois'!$O$2:$O$1154,'Entetes_CplteAnneeMois'!$V$2:$V$1154,B10)
A11: 2023 | B11: 2023-10 | C11: =SUMIFS('Entetes_CplteAnneeMois'!$S$2:$S$1154,'Entetes_CplteAnneeMois'!$V$2:$V$1154,B11) | D11: =SUMIFS('Entetes_CplteAnneeMois'!$T$2:$T$1154,'Entetes_CplteAnneeMois'!$V$2:$V$1154,B11) | E11: =SUMIFS('Entetes_CplteAnneeMois'!$O$2:$O$1154,'Entetes_CplteAnneeMois'!$V$2:$V$1154,B11)
A12: 2023 | B12: 2023-11 | C12: =SUMIFS('Entetes_CplteAnneeMois'!$S$2:$S$1154,'Entetes_CplteAnneeMois'!$V$2:$V$1154,B12) | D12: =SUMIFS('Entetes_CplteAnneeMois'!$T$2:$T$1154,'Entetes_CplteAnneeMois'!$V$2:$V$1154,B12) | E12: =SUMIFS('Entetes_CplteAnneeMois'!$O$2:$O$1154,'Entetes_CplteAnneeMois'!$V$2:$V$1154,B12)
A13: 2023 | B13: 2023-12 | C13: =SUMIFS('Entetes_CplteAnneeMois'!$S$2:$S$1154,'Entetes_CplteAnneeMois'!$V$2:$V$1154,B13) | D13: =SUMIFS('Entetes_CplteAnneeMois'!$T$2:$T$1154,'Entetes_CplteAnneeMois'!$V$2:$V$1154,B13) | E13: =SUMIFS('Entetes_CplteAnneeMois'!$O$2:$O$1154,'Entetes_CplteAnneeMois'!$V$2:$V$1154,B13)
... A33: 2025 | B33: 2025-08 | C33: =SUMIFS('Entetes_CplteAnneeMois'!$S$2:$S$1154,'Entetes_CplteAnneeMois'!$V$2:$V$1154,B33) | D33: =SUMIFS('Entetes_CplteAnneeMois'!$T$2:$T$1154,'Entetes_CplteAnneeMois'!$V$2:$V$1154,B33) | E33: =SUMIFS('Entetes_CplteAnneeMois'!$O$2:$O$1154,'Entetes_CplteAnneeMois'!$V$2:$V$1154,B33)

Sheet recettes_mensuelles_MASSENA
A1: AJ_ANNEE | B1: AJ_MOIS | C1: SOMME_AJ_TOTAL_HT | D1: SOMME_AJ_TOTAL_TVA_20 | E1: SOMME_E_TTC
A2: ='TD_TotalHtTvaTtc'!A2 | B2: ='TD_TotalHtTvaTtc'!B2 | C2: ='TD_TotalHtTvaTtc'!C2 | D2: ='TD_TotalHtTvaTtc'!D2 | E2: ='TD_TotalHtTvaTtc'!E2
A3: ='TD_TotalHtTvaTtc'!A3 | B3: ='TD_TotalHtTvaTtc'!B3 | C3: ='TD_TotalHtTvaTtc'!C3 | D3: ='TD_TotalHtTvaTtc'!D3 | E3: ='TD_TotalHtTvaTtc'!E3
A4: ='TD_TotalHtTvaTtc'!A4 | B4: ='TD_TotalHtTvaTtc'!B4 | C4: ='TD_TotalHtTvaTtc'!C4 | D4: ='TD_TotalHtTvaTtc'!D4 | E4: ='TD_TotalHtTvaTtc'!E4
A5: ='TD_TotalHtTvaTtc'!A5 | B5: ='TD_TotalHtTvaTtc'!B5 | C5: ='TD_TotalHtTvaTtc'!C5 | D5: ='TD_TotalHtTvaTtc'!D5 | E5: ='TD_TotalHtTvaTtc'!E5
A6: ='TD_TotalHtTvaTtc'!A6 | B6: ='TD_TotalHtTvaTtc'!B6 | C6: ='TD_TotalHtTvaTtc'!C6 | D6: ='TD_TotalHtTvaTtc'!D6 | E6: ='TD_TotalHtTvaTtc'!E6
A7: ='TD_TotalHtTvaTtc'!A7 | B7: ='TD_TotalHtTvaTtc'!B7 | C7: ='TD_TotalHtTvaTtc'!C7 | D7: ='TD_TotalHtTvaTtc'!D7 | E7: ='TD_TotalHtTvaTtc'!E7
A8: ='TD_TotalHtTvaTtc'!A8 | B8: ='TD_TotalHtTvaTtc'!B8 | C8: ='TD_TotalHtTvaTtc'!C8 | D8: ='TD_TotalHtTvaTtc'!D8 | E8: ='TD_TotalHtTvaTtc'!E8
A9: ='TD_TotalHtTvaTtc'!A9 | B9: ='TD_TotalHtTvaTtc'!B9 | C9: ='TD_TotalHtTvaTtc'!C9 | D9: ='TD_TotalHtTvaTtc'!D9 | E9: ='TD_TotalHtTvaTtc'!E9
A10: ='TD_TotalHtTvaTtc'!A10 | B10: ='TD_TotalHtTvaTtc'!B10 | C10: ='TD_TotalHtTvaTtc'!C10 | D10: ='TD_TotalHtTvaTtc'!D10 | E10: ='TD_TotalHtTvaTtc'!E10
A11: ='TD_TotalHtTvaTtc'!A11 | B11: ='TD_TotalHtTvaTtc'!B11 | C11: ='TD_TotalHtTvaTtc'!C11 | D11: ='TD_TotalHtTvaTtc'!D11 | E11: ='TD_TotalHtTvaTtc'!E11
A12: ='TD_TotalHtTvaTtc'!A12 | B12: ='TD_TotalHtTvaTtc'!B12 | C12: ='TD_TotalHtTvaTtc'!C12 | D12: ='TD_TotalHtTvaTtc'!D12 | E12: ='TD_TotalHtTvaTtc'!E12
A13: ='TD_TotalHtTvaTtc'!A13 | B13: ='TD_TotalHtTvaTtc'!B13 | C13: ='TD_TotalHtTvaTtc'!C13 | D13: ='TD_TotalHtTvaTtc'!D13 | E13: ='TD_TotalHtTvaTtc'!E13
... A33: ='TD_TotalHtTvaTtc'!A33 | B33: ='TD_TotalHtTvaTtc'!B33 | C33: ='TD_TotalHtTvaTtc'!C33 | D33: ='TD_TotalHtTvaTtc'!D33 | E33: ='TD_TotalHtTvaTtc'!E33
