Workbook

Sheet Z2_2023_MATURIN_0
A1: nomfichier | B1: E_MODELE | C1: E_MACHINE | D1: E_RAPPORT | E1: E_FICHIER | F1: E_MODE | G1: E_COMPTEUR_Z | H1: E_DATE | I1: E_HEURE | J1: D_ENREGISTREMENT | K1: D_DESIGNATION | L1: D_QUANTITE | M1: D_MONTANT
A2: Z002_01_012023_MATURIN.CSV | C2: MC#01 | D2: TRANSACTION | E2: FILE002 | F2: Z | G2: 0019 | H2: 44958 | I2: 10:06 | J2: 0001 | K2: ESPECES | L2: 10 | M2: 5248
A3: Z002_01_012023_MATURIN.CSV | C3: MC#01 | D3: TRANSACTION | E3: FILE002 | F3: Z | G3: 0019 | H3: 44958 | I3: 10:06 | J3: 0002 | K3: SOUS-TOTAL | L3: 0 | M3: 0
A4: Z002_01_012023_MATURIN.CSV | C4: MC#01 | D4: TRANSACTION | E4: FILE002 | F4: Z | G4: 0019 | H4: 44958 | I4: 10:06 | J4: 0003 | K4: CARTES | L4: 22 | M4: 17964.6
A5: Z002_01_012023_MATURIN.CSV | C5: MC#01 | D5: TRANSACTION | E5: FILE002 | F5: Z | G5: 0019 | H5: 44958 | I5: 10:06 | J5: 0004 | K5: CHEQUES | L5: 0 | M5: 0
A6: Z002_01_012023_MATURIN.CSV | C6: MC#01 | D6: TRANSACTION | E6: FILE002 | F6: Z | G6: 0019 | H6: 44958 | I6: 10:06 | J6: 0005 | K6: AIDE | L6: 0 | M6: 0
A7: Z002_01_012023_MATURIN.CSV | C7: MC#01 | D7: TRANSACTION | E7: FILE002 | F7: Z | G7: 0019 | H7: 44958 | I7: 10:06 | J7: 0006 | K7: TAX PGM | L7: 0 | M7: 0
A8: Z002_01_012023_MATURIN.CSV | C8: MC#01 | D8: TRANSACTION | E8: FILE002 | F8: Z | G8: 0019 | H8: 44958 | I8: 10:06 | J8: 0007 | K8: SORTIECAISSE | L8: 0 | M8: 0
A9: Z002_01_012023_MATURIN.CSV | C9: MC#01 | D9: TRANSACTION | E9: FILE002 | F9: Z | G9: 0019 | H9: 44958 | I9: 10:06 | J9: 0008 | K9: REC&ACCOMPTE | L9: 0 | M9: 0
A10: Z002_01_012023_MATURIN.CSV | C10: MC#01 | D10: TRANSACTION | E10: FILE002 | F10: Z | G10: 0019 | H10: 44958 | I10: 10:06 | J10: 0009 | K10: SIGN-OFF | L10: 0 | M10: 0
A11: Z002_01_012023_MATURIN.CSV | C11: MC#01 | D11: TRANSACTION | E11: FILE002 | F11: Z | G11: 0019 | H11: 44958 | I11: 10:06 | J11: 0010 | K11: NUM CAISSIER | L11: 0 | M11: 0
A12: Z002_01_012023_MATURIN.CSV | C12: MC#01 | D12: TRANSACTION | E12: FILE002 | F12: Z | G12: 0019 | H12: 44958 | I12: 10:06 | J12: 0011 | K12: SHIFT/No | L12: 0 | M12: 0
A13: Z002_01_012023_MATURIN.CSV | C13: MC#01 | D13: TRANSACTION | E13: FILE002 | F13: Z | G13: 0019 | H13: 44958 | I13: 10:06 | J13: 0012 | K13: DWN | L13: 0 | M13: 0
... A33: Z002_01_012023_MATURIN.CSV | C33: MC#01 | D33: TRANSACTION | E33: FILE002 | F33: Z | G33: 0019 | H33: 44958 | I33: 10:06 | J33: 0032 | K33: ANNULATION | L33: 0 | M33: 0
A34: Z002_01_012023_MATURIN.CSV | C34: MC#01 | D34: TRANSACTION | E34: FILE002 | F34: Z | G34: 0019 | H34: 44958 | I34: 10:06 | J34: 0033 | L34: 0 | M34: 0
A35: Z002_01_012023_MATURIN.CSV | C35: MC#01 | D35: TRANSACTION | E35: FILE002 | F35: Z | G35: 0019 | H35: 44958 | I35: 10:06 | J35: 0034 | L35: 0 | M35: 0
A36: Z002_01_012023_MATURIN.CSV | C36: MC#01 | D36: TRANSACTION | E36: FILE002 | F36: Z | G36: 0019 | H36: 44958 | I36: 10:06 | J36: 0035 | L36: 0 | M36: 0
A37: Z002_01_012023_MATURIN.CSV | C37: MC#01 | D37: TRANSACTION | E37: FILE002 | F37: Z | G37: 0019 | H37: 44958 | I37: 10:06 | J37: 0036 | L37: 0 | M37: 0
A38: Z002_01_012023_MATURIN.CSV | C38: MC#01 | D38: TRANSACTION | E38: FILE002 | F38: Z | G38: 0019 | H38: 44958 | I38: 10:06 | J38: 0037 | L38: 0 | M38: 0
A39: Z002_01_012023_MATURIN.CSV | C39: MC#01 | D39: TRANSACTION | E39: FILE002 | F39: Z | G39: 0019 | H39: 44958 | I39: 10:06 | J39: 0038 | L39: 0 | M39: 0
A40: Z002_01_012023_MATURIN.CSV | C40: MC#01 | D40: TRANSACTION | E40: FILE002 | F40: Z | G40: 0019 | H40: 44958 | I40: 10:06 | J40: 0039 | L40: 0 | M40: 0
A41: Z002_01_012023_MATURIN.CSV | C41: MC#01 | D41: TRANSACTION | E41: FILE002 | F41: Z | G41: 0019 | H41: 44958 | I41: 10:06 | J41: 0040 | L41: 0 | M41: 0
A42: Z002_01_012023_MATURIN.CSV | C42: MC#01 | D42: TRANSACTION | E42: FILE002 | F42: Z | G42: 0019 | H42: 44958 | I42: 10:06 | J42: 0041 | L42: 0 | M42: 0
A43: Z002_01_012023_MATURIN.CSV | C43: MC#01 | D43: TRANSACTION | E43: FILE002 | F43: Z | G43: 0019 | H43: 44958 | I43: 10:06 | J43: 0042 | L43: 0 | M43: 0
A44: Z002_01_012023_MATURIN.CSV | C44: MC#01 | D44: TRANSACTION | E44: FILE002 | F44: Z | G44: 0019 | H44: 44958 | I44: 10:06 | J44: 0043 | L44: 0 | M44: 0
A45: Z002_01_012023_MATURIN.CSV | C45: MC#01 | D45: TRANSACTION | E45: FILE002 | F45: Z | G45: 0019 | H45: 44958 | I45: 10:06 | J45: 0044 | L45: 0 | M45: 0
... A51: Z002_01_012023_MATURIN.CSV | C51: MC#01 | D51: TRANSACTION | E51: FILE002 | F51: Z | G51: 0019 | H51: 44958 | I51: 10:06 | J51: 0050 | L51: 0 | M51: 0
A52: Z002_01_022023_MATURIN.CSV | C52: MC#01 | D52: TRANSACTION | E52: FILE002 | F52: Z | G52: 0020 | H52: 44986 | I52: 10:42 | J52: 0001 | K52: ESPECES | L52: 14 | M52: 8570.8
A53: Z002_01_022023_MATURIN.CSV | C53: MC#01 | D53: TRANSACTION | E53: FILE002 | F53: Z | G53: 0020 | H53: 44986 | I53: 10:42 | J53: 0002 | K53: SOUS-TOTAL | L53: 0 | M53: 0
A54: Z002_01_022023_MATURIN.CSV | C54: MC#01 | D54: TRANSACTION | E54: FILE002 | F54: Z | G54: 0020 | H54: 44986 | I54: 10:42 | J54: 0003 | K54: CARTES | L54: 13 | M54: 11477
A55: Z002_01_022023_MATURIN.CSV | C55: MC#01 | D55: TRANSACTION | E55: FILE002 | F55: Z | G55: 0020 | H55: 44986 | I55: 10:42 | J55: 0004 | K55: CHEQUES | L55: 1 | M55: 329
A56: Z002_01_022023_MATURIN.CSV | C56: MC#01 | D56: TRANSACTION | E56: FILE002 | F56: Z | G56: 0020 | H56: 44986 | I56: 10:42 | J56: 0005 | K56: AIDE | L56: 0 | M56: 0
A57: Z002_01_022023_MATURIN.CSV | C57: MC#01 | D57: TRANSACTION | E57: FILE002 | F57: Z | G57: 0020 | H57: 44986 | I57: 10:42 | J57: 0006 | K57: TAX PGM | L57: 0 | M57: 0
A58: Z002_01_022023_MATURIN.CSV | C58: MC#01 | D58: TRANSACTION | E58: FILE002 | F58: Z | G58: 0020 | H58: 44986 | I58: 10:42 | J58: 0007 | K58: SORTIECAISSE | L58: 0 | M58: 0
A59: Z002_01_022023_MATURIN.CSV | C59: MC#01 | D59: TRANSACTION | E59: FILE002 | F59: Z | G59: 0020 | H59: 44986 | I59: 10:42 | J59: 0008 | K59: REC&ACCOMPTE | L59: 0 | M59: 0
A60: Z002_01_022023_MATURIN.CSV | C60: MC#01 | D60: TRANSACTION | E60: FILE002 | F60: Z | G60: 0020 | H60: 44986 | I60: 10:42 | J60: 0009 | K60: SIGN-OFF | L60: 0 | M60: 0
A61: Z002_01_022023_MATURIN.CSV | C61: MC#01 | D61: TRANSACTION | E61: FILE002 | F61: Z | G61: 0020 | H61: 44986 | I61: 10:42 | J61: 0010 | K61: NUM CAISSIER | L61: 0 | M61: 0
A62: Z002_01_022023_MATURIN.CSV | C62: MC#01 | D62: TRANSACTION | E62: FILE002 | F62: Z | G62: 0020 | H62: 44986 | I62: 10:42 | J62: 0011 | K62: SHIFT/No | L62: 0 | M62: 0
A63: Z002_01_022023_MATURIN.CSV | C63: MC#01 | D63: TRANSACTION | E63: FILE002 | F63: Z | G63: 0020 | H63: 44986 | I63: 10:42 | J63: 0012 | K63: DWN | L63: 0 | M63: 0
... A83: Z002_01_022023_MATURIN.CSV | C83: MC#01 | D83: TRANSACTION | E83: FILE002 | F83: Z | G83: 0020 | H83: 44986 | I83: 10:42 | J83: 0032 | K83: ANNULATION | L83: 0 | M83: 0
...

Sheet Z2_CplteAnneeMois
A1: nomfichier | B1: E_MODELE | C1: E_MACHINE | D1: E_RAPPORT | E1: E_FICHIER | F1: E_MODE | G1: E_COMPTEUR_Z | H1: E_DATE | I1: E_HEURE | J1: D_ENREGISTREMENT | K1: D_DESIGNATION | L1: D_QUANTITE | M1: D_MONTANT | N1: AJ_ANNEE_Z | O1: AJ_MOIS_Z
A2: Z002_01_012023_MATURIN.CSV | C2: MC#01 | D2: TRANSACTION | E2: FILE002 | F2: Z | G2: 0019 | H2: 44958 | I2: 10:06 | J2: 0001 | K2: ESPECES | L2: 10 | M2: 5248 | N2: 2023 | O2: 2023-01
A3: Z002_01_012023_MATURIN.CSV | C3: MC#01 | D3: TRANSACTION | E3: FILE002 | F3: Z | G3: 0019 | H3: 44958 | I3: 10:06 | J3: 0002 | K3: SOUS-TOTAL | L3: 0 | M3: 0 | N3: 2023 | O3: 2023-01
A4: Z002_01_012023_MATURIN.CSV | C4: MC#01 | D4: TRANSACTION | E4: FILE002 | F4: Z | G4: 0019 | H4: 44958 | I4: 10:06 | J4: 0003 | K4: CARTES | L4: 22 | M4: 17964.6 | N4: 2023 | O4: 2023-01
A5: Z002_01_012023_MATURIN.CSV | C5: MC#01 | D5: TRANSACTION | E5: FILE002 | F5: Z | G5: 0019 | H5: 44958 | I5: 10:06 | J5: 0004 | K5: CHEQUES | L5: 0 | M5: 0 | N5: 2023 | O5: 2023-01
A6: Z002_01_012023_MATURIN.CSV | C6: MC#01 | D6: TRANSACTION | E6: FILE002 | F6: Z | G6: 0019 | H6: 44958 | I6: 10:06 | J6: 0005 | K6: AIDE | L6: 0 | M6: 0 | N6: 2023 | O6: 2023-01
A7: Z002_01_012023_MATURIN.CSV | C7: MC#01 | D7: TRANSACTION | E7: FILE002 | F7: Z | G7: 0019 | H7: 44958 | I7: 10:06 | J7: 0006 | K7: TAX PGM | L7: 0 | M7: 0 | N7: 2023 | O7: 2023-01
A8: Z002_01_012023_MATURIN.CSV | C8: MC#01 | D8: TRANSACTION | E8: FILE002 | F8: Z | G8: 0019 | H8: 44958 | I8: 10:06 | J8: 0007 | K8: SORTIECAISSE | L8: 0 | M8: 0 | N8: 2023 | O8: 2023-01
A9: Z002_01_012023_MATURIN.CSV | C9: MC#01 | D9: TRANSACTION | E9: FILE002 | F9: Z | G9: 0019 | H9: 44958 | I9: 10:06 | J9: 0008 | K9: REC&ACCOMPTE | L9: 0 | M9: 0 | N9: 2023 | O9: 2023-01
A10: Z002_01_012023_MATURIN.CSV | C10: MC#01 | D10: TRANSACTION | E10: FILE002 | F10: Z | G10: 0019 | H10: 44958 | I10: 10:06 | J10: 0009 | K10: SIGN-OFF | L10: 0 | M10: 0 | N10: 2023 | O10: 2023-01
A11: Z002_01_012023_MATURIN.CSV | C11: MC#01 | D11: TRANSACTION | E11: FILE002 | F11: Z | G11: 0019 | H11: 44958 | I11: 10:06 | J11: 0010 | K11: NUM CAISSIER | L11: 0 | M11: 0 | N11: 2023 | O11: 2023-01
A12: Z002_01_012023_MATURIN.CSV | C12: MC#01 | D12: TRANSACTION | E12: FILE002 | F12: Z | G12: 0019 | H12: 44958 | I12: 10:06 | J12: 0011 | K12: SHIFT/No | L12: 0 | M12: 0 | N12: 2023 | O12: 2023-01
A13: Z002_01_012023_MATURIN.CSV | C13: MC#01 | D13: TRANSACTION | E13: FILE002 | F13: Z | G13: 0019 | H13: 44958 | I13: 10:06 | J13: 0012 | K13: DWN | L13: 0 | M13: 0 | N13: 2023 | O13: 2023-01
... A33: Z002_01_012023_MATURIN.CSV | C33: MC#01 | D33: TRANSACTION | E33: FILE002 | F33: Z | G33: 0019 | H33: 44958 | I33: 10:06 | J33: 0032 | K33: ANNULATION | L33: 0 | M33: 0 | N33: 2023 | O33: 2023-01
A34: Z002_01_012023_MATURIN.CSV | C34: MC#01 | D34: TRANSACTION | E34: FILE002 | F34: Z | G34: 0019 | H34: 44958 | I34: 10:06 | J34: 0033 | L34: 0 | M34: 0 | N34: 2023 | O34: 2023-01
A35: Z002_01_012023_MATURIN.CSV | C35: MC#01 | D35: TRANSACTION | E35: FILE002 | F35: Z | G35: 0019 | H35: 44958 | I35: 10:06 | J35: 0034 | L35: 0 | M35: 0 | N35: 2023 | O35: 2023-01
A36: Z002_01_012023_MATURIN.CSV | C36: MC#01 | D36: TRANSACTION | E36: FILE002 | F36: Z | G36: 0019 | H36: 44958 | I36: 10:06 | J36: 0035 | L36: 0 | M36: 0 | N36: 2023 | O36: 2023-01
A37: Z002_01_012023_MATURIN.CSV | C37: MC#01 | D37: TRANSACTION | E37: FILE002 | F37: Z | G37: 0019 | H37: 44958 | I37: 10:06 | J37: 0036 | L37: 0 | M37: 0 | N37: 2023 | O37: 2023-01
A38: Z002_01_012023_MATURIN.CSV | C38: MC#01 | D38: TRANSACTION | E38: FILE002 | F38: Z | G38: 0019 | H38: 44958 | I38: 10:06 | J38: 0037 | L38: 0 | M38: 0 | N38: 2023 | O38: 2023-01
A39: Z002_01_012023_MATURIN.CSV | C39: MC#01 | D39: TRANSACTION | E39: FILE002 | F39: Z | G39: 0019 | H39: 44958 | I39: 10:06 | J39: 0038 | L39: 0 | M39: 0 | N39: 2023 | O39: 2023-01
A40: Z002_01_012023_MATURIN.CSV | C40: MC#01 | D40: TRANSACTION | E40: FILE002 | F40: Z | G40: 0019 | H40: 44958 | I40: 10:06 | J40: 0039 | L40: 0 | M40: 0 | N40: 2023 | O40: 2023-01
A41: Z002_01_012023_MATURIN.CSV | C41: MC#01 | D41: TRANSACTION | E41: FILE002 | F41: Z | G41: 0019 | H41: 44958 | I41: 10:06 | J41: 0040 | L41: 0 | M41: 0 | N41: 2023 | O41: 2023-01
A42: Z002_01_012023_MATURIN.CSV | C42: MC#01 | D42: TRANSACTION | E42: FILE002 | F42: Z | G42: 0019 | H42: 44958 | I42: 10:06 | J42: 0041 | L42: 0 | M42: 0 | N42: 2023 | O42: 2023-01
A43: Z002_01_012023_MATURIN.CSV | C43: MC#01 | D43: TRANSACTION | E43: FILE002 | F43: Z | G43: 0019 | H43: 44958 | I43: 10:06 | J43: 0042 | L43: 0 | M43: 0 | N43: 2023 | O43: 2023-01
A44: Z002_01_012023_MATURIN.CSV | C44: MC#01 | D44: TRANSACTION | E44: FILE002 | F44: Z | G44: 0019 | H44: 44958 | I44: 10:06 | J44: 0043 | L44: 0 | M44: 0 | N44: 2023 | O44: 2023-01
A45: Z002_01_012023_MATURIN.CSV | C45: MC#01 | D45: TRANSACTION | E45: FILE002 | F45: Z | G45: 0019 | H45: 44958 | I45: 10:06 | J45: 0044 | L45: 0 | M45: 0 | N45: 2023 | O45: 2023-01
... A51: Z002_01_012023_MATURIN.CSV | C51: MC#01 | D51: TRANSACTION | E51: FILE002 | F51: Z | G51: 0019 | H51: 44958 | I51: 10:06 | J51: 0050 | L51: 0 | M51: 0 | N51: 2023 | O51: 2023-01
A52: Z002_01_022023_MATURIN.CSV | C52: MC#01 | D52: TRANSACTION | E52: FILE002 | F52: Z | G52: 0020 | H52: 44986 | I52: 10:42 | J52: 0001 | K52: ESPECES | L52: 14 | M52: 8570.8 | N52: 2023 | O52: 2023-02
A53: Z002_01_022023_MATURIN.CSV | C53: MC#01 | D53: TRANSACTION | E53: FILE002 | F53: Z | G53: 0020 | H53: 44986 | I53: 10:42 | J53: 0002 | K53: SOUS-TOTAL | L53: 0 | M53: 0 | N53: 2023 | O53: 2023-02
A54: Z002_01_022023_MATURIN.CSV | C54: MC#01 | D54: TRANSACTION | E54: FILE002 | F54: Z | G54: 0020 | H54: 44986 | I54: 10:42 | J54: 0003 | K54: CARTES | L54: 13 | M54: 11477 | N54: 2023 | O54: 2023-02
A55: Z002_01_022023_MATURIN.CSV | C55: MC#01 | D55: TRANSACTION | E55: FILE002 | F55: Z | G55: 0020 | H55: 44986 | I55: 10:42 | J55: 0004 | K55: CHEQUES | L55: 1 | M55: 329 | N55: 2023 | O55: 2023-02
A56: Z002_01_022023_MATURIN.CSV | C56: MC#01 | D56: TRANSACTION | E56: FILE002 | F56: Z | G56: 0020 | H56: 44986 | I56: 10:42 | J56: 0005 | K56: AIDE | L56: 0 | M56: 0 | N56: 2023 | O56: 2023-02
A57: Z002_01_022023_MATURIN.CSV | C57: MC#01 | D57: TRANSACTION | E57: FILE002 | F57: Z | G57: 0020 | H57: 44986 | I57: 10:42 | J57: 0006 | K57: TAX PGM | L57: 0 | M57: 0 | N57: 2023 | O57: 2023-02
A58: Z002_01_022023_MATURIN.CSV | C58: MC#01 | D58: TRANSACTION | E58: FILE002 | F58: Z | G58: 0020 | H58: 44986 | I58: 10:42 | J58: 0007 | K58: SORTIECAISSE | L58: 0 | M58: 0 | N58: 2023 | O58: 2023-02
A59: Z002_01_022023_MATURIN.CSV | C59: MC#01 | D59: TRANSACTION | E59: FILE002 | F59: Z | G59: 0020 | H59: 44986 | I59: 10:42 | J59: 0008 | K59: REC&ACCOMPTE | L59: 0 | M59: 0 | N59: 2023 | O59: 2023-02
A60: Z002_01_022023_MATURIN.CSV | C60: MC#01 | D60: TRANSACTION | E60: FILE002 | F60: Z | G60: 0020 | H60: 44986 | I60: 10:42 | J60: 0009 | K60: SIGN-OFF | L60: 0 | M60: 0 | N60: 2023 | O60: 2023-02
A61: Z002_01_022023_MATURIN.CSV | C61: MC#01 | D61: TRANSACTION | E61: FILE002 | F61: Z | G61: 0020 | H61: 44986 | I61: 10:42 | J61: 0010 | K61: NUM CAISSIER | L61: 0 | M61: 0 | N61: 2023 | O61: 2023-02
A62: Z002_01_022023_MATURIN.CSV | C62: MC#01 | D62: TRANSACTION | E62: FILE002 | F62: Z | G62: 0020 | H62: 44986 | I62: 10:42 | J62: 0011 | K62: SHIFT/No | L62: 0 | M62: 0 | N62: 2023 | O62: 2023-02
A63: Z002_01_022023_MATURIN.CSV | C63: MC#01 | D63: TRANSACTION | E63: FILE002 | F63: Z | G63: 0020 | H63: 44986 | I63: 10:42 | J63: 0012 | K63: DWN | L63: 0 | M63: 0 | N63: 2023 | O63: 2023-02
... A83: Z002_01_022023_MATURIN.CSV | C83: MC#01 | D83: TRANSACTION | E83: FILE002 | F83: Z | G83: 0020 | H83: 44986 | I83: 10:42 | J83: 0032 | K83: ANNULATION | L83: 0 | M83: 0 | N83: 2023 | O83: 2023-02
...

Sheet TD_TotalNatureTransac
A1: AJ_ANNEE_Z | B1: AJ_MOIS_Z | C1: E_MODE | D1: D_DESIGNATION | E1: D_QUANTITE | F1: D_MONTANT
A2: 2023 | B2: 2023-01 | C2: Z | D2: CARTES | E2: =SUMIFS('Z2_CplteAnneeMois'!$L$2:$L$751,'Z2_CplteAnneeMois'!$O$2:$O$751,B2,'Z2_CplteAnneeMois'!$F$2:$F$751,C2,'Z2_CplteAnneeMois'!$K$2:$K$751,D2) | F2: =SUMIFS('Z2_CplteAnneeMois'!$M$2:$M$751,'Z2_CplteAnneeMois'!$O$2:$O$751,B2,'Z2_CplteAnneeMois'!$F$2:$F$751,C2,'Z2_CplteAnneeMois'!$K$2:$K$751,D2)
A3: 2023 | B3: 2023-01 | C3: Z | D3: CHEQUES | E3: =SUMIFS('Z2_CplteAnneeMois'!$L$2:$L$751,'Z2_CplteAnneeMois'!$O$2:$O$751,B3,'Z2_CplteAnneeMois'!$F$2:$F$751,C3,'Z2_CplteAnneeMois'!$K$2:$K$751,D3) | F3: =SUMIFS('Z2_CplteAnneeMois'!$M$2:$M$751,'Z2_CplteAnneeMois'!$O$2:$O$751,B3,'Z2_CplteAnneeMois'!$F$2:$F$751,C3,'Z2_CplteAnneeMois'!$K$2:$K$751,D3)
A4: 2023 | B4: 2023-01 | C4: Z | D4: CORRECTION | E4: =SUMIFS('Z2_CplteAnneeMois'!$L$2:$L$751,'Z2_CplteAnneeMois'!$O$2:$O$751,B4,'Z2_CplteAnneeMois'!$F$2:$F$751,C4,'Z2_CplteAnneeMois'!$K$2:$K$751,D4) | F4: =SUMIFS('Z2_CplteAnneeMois'!$M$2:$M$751,'Z2_CplteAnneeMois'!$O$2:$O$751,B4,'Z2_CplteAnneeMois'!$F$2:$F$751,C4,'Z2_CplteAnneeMois'!$K$2:$K$751,D4)
A5: 2023 | B5: 2023-01 | C5: Z | D5: ESPECES | E5: =SUMIFS('Z2_CplteAnneeMois'!$L$2:$L$751,'Z2_CplteAnneeMois'!$O$2:$O$751,B5,'Z2_CplteAnneeMois'!$F$2:$F$751,C5,'Z2_CplteAnneeMois'!$K$2:$K$751,D5) | F5: =SUMIFS('Z2_CplteAnneeMois'!$M$2:$M$751,'Z2_CplteAnneeMois'!$O$2:$O$751,B5,'Z2_CplteAnneeMois'!$F$2:$F$751,C5,'Z2_CplteAnneeMois'!$K$2:$K$751,D5)
A6: 2023 | B6: 2023-01 | C6: Z | D6: REF./TIROIR | E6: =SUMIFS('Z2_CplteAnneeMois'!$L$2:$L$751,'Z2_CplteAnneeMois'!$O$2:$O$751,B6,'Z2_CplteAnneeMois'!$F$2:$F$751,C6,'Z2_CplteAnneeMois'!$K$2:$K$751,D6) | F6: =SUMIFS('Z2_CplteAnneeMois'!$M$2:$M$751,'Z2_CplteAnneeMois'!$O$2:$O$751,B6,'Z2_CplteAnneeMois'!$F$2:$F$751,C6,'Z2_CplteAnneeMois'!$K$2:$K$751,D6)
A7: 2023 | B7: 2023-01 | C7: ZZ1 | D7: CARTES | E7: =SUMIFS('Z2_CplteAnneeMois'!$L$2:$L$751,'Z2_CplteAnneeMois'!$O$2:$O$751,B7,'Z2_CplteAnneeMois'!$F$2:$F$751,C7,'Z2_CplteAnneeMois'!$K$2:$K$751,D7) | F7: =SUMIFS('Z2_CplteAnneeMois'!$M$2:$M$751,'Z2_CplteAnneeMois'!$O$2:$O$751,B7,'Z2_CplteAnneeMois'!$F$2:$F$751,C7,'Z2_CplteAnneeMois'!$K$2:$K$751,D7)
A8: 2023 | B8: 2023-01 | C8: ZZ1 | D8: CHEQUES | E8: =SUMIFS('Z2_CplteAnneeMois'!$L$2:$L$751,'Z2_CplteAnneeMois'!$O$2:$O$751,B8,'Z2_CplteAnneeMois'!$F$2:$F$751,C8,'Z2_CplteAnneeMois'!$K$2:$K$751,D8) | F8: =SUMIFS('Z2_CplteAnneeMois'!$M$2:$M$751,'Z2_CplteAnneeMois'!$O$2:$O$751,B8,'Z2_CplteAnneeMois'!$F$2:$F$751,C8,'Z2_CplteAnneeMois'!$K$2:$K$751,D8)
A9: 2023 | B9: 2023-01 | C9: ZZ1 | D9: CORRECTION | E9: =SUMIFS('Z2_CplteAnneeMois'!$L$2:$L$751,'Z2_CplteAnneeMois'!$O$2:$O$751,B9,'Z2_CplteAnneeMois'!$F$2:$F$751,C9,'Z2_CplteAnneeMois'!$K$2:$K$751,D9) | F9: =SUMIFS('Z2_CplteAnneeMois'!$M$2:$M$751,'Z2_CplteAnneeMois'!$O$2:$O$751,B9,'Z2_CplteAnneeMois'!$F$2:$F$751,C9,'Z2_CplteAnneeMois'!$K$2:$K$751,D9)
A10: 2023 | B10: 2023-01 | C10: ZZ1 | D10: ESPECES | E10: =SUMIFS('Z2_CplteAnneeMois'!$L$2:$L$751,'Z2_CplteAnneeMois'!$O$2:$O$751,B10,'Z2_CplteAnneeMois'!$F$2:$F$751,C10,'Z2_CplteAnneeMois'!$K$2:$K$751,D10) | F10: =SUMIFS('Z2_CplteAnneeMois'!$M$2:$M$751,'Z2_CplteAnneeMois'!$O$2:$O$751,B10,'Z2_CplteAnneeMois'!$F$2:$F$751,C10,'Z2_CplteAnneeMois'!$K$2:$K$751,D10)
A11: 2023 | B11: 2023-01 | C11: ZZ1 | D11: REF./TIROIR | E11: =SUMIFS('Z2_CplteAnneeMois'!$L$2:$L$751,'Z2_CplteAnneeMois'!$O$2:$O$751,B11,'Z2_CplteAnneeMois'!$F$2:$F$751,C11,'Z2_CplteAnneeMois'!$K$2:$K$751,D11) | F11: =SUMIFS('Z2_CplteAnneeMois'!$M$2:$M$751,'Z2_CplteAnneeMois'!$O$2:$O$751,B11,'Z2_CplteAnneeMois'!$F$2:$F$751,C11,'Z2_CplteAnneeMois'!$K$2:$K$751,D11)
A12: 2023 | B12: 2023-01 | C12: ZZ2 | D12: CARTES | E12: =SUMIFS('Z2_CplteAnneeMois'!$L$2:$L$751,'Z2_CplteAnneeMois'!$O$2:$O$751,B12,'Z2_CplteAnneeMois'!$F$2:$F$751,C12,'Z2_CplteAnneeMois'!$K$2:$K$751,D12) | F12: =SUMIFS('Z2_CplteAnneeMois'!$M$2:$M$751,'Z2_CplteAnneeMois'!$O$2:$O$751,B12,'Z2_CplteAnneeMois'!$F$2:$F$751,C12,'Z2_CplteAnneeMois'!$K$2:$K$751,D12)
A13: 2023 | B13: 2023-01 | C13: ZZ2 | D13: CHEQUES | E13: =SUMIFS('Z2_CplteAnneeMois'!$L$2:$L$751,'Z2_CplteAnneeMois'!$O$2:$O$751,B13,'Z2_CplteAnneeMois'!$F$2:$F$751,C13,'Z2_CplteAnneeMois'!$K$2:$K$751,D13) | F13: =SUMIFS('Z2_CplteAnneeMois'!$M$2:$M$751,'Z2_CplteAnneeMois'!$O$2:$O$751,B13,'Z2_CplteAnneeMois'!$F$2:$F$751,C13,'Z2_CplteAnneeMois'!$K$2:$K$751,D13)
... A181: 2023 | B181: 2023-12 | C181: ZZ2 | D181: REF./TIROIR | E181: =SUMIFS('Z2_CplteAnneeMois'!$L$2:$L$751,'Z2_CplteAnneeMois'!$O$2:$O$751,B181,'Z2_CplteAnneeMois'!$F$2:$F$751,C181,'Z2_CplteAnneeMois'!$K$2:$K$751,D181) | F181: =SUMIFS('Z2_CplteAnneeMois'!$M$2:$M$751,'Z2_CplteAnneeMois'!$O$2:$O$751,B181,'Z2_CplteAnneeMois'!$F$2:$F$751,C181,'Z2_CplteAnneeMois'!$K$2:$K$751,D181)

Sheet Z2_Total_ModeZZ1
A1: AJ_ANNEE_Z | B1: AJ_MOIS_Z | C1: CARTES_D_QUANTITE | D1: CARTES_D_MONTANT | E1: CHEQUES_D_QUANTITE | F1: CHEQUES_D_MONTANT | G1: CORRECTION_D_QUANTITE | H1: CORRECTION_D_MONTANT | I1: ESPECES_D_QUANTITE | J1: ESPECES_D_MONTANT | K1: REF__TIROIR_D_QUANTITE | L1: REF__TIROIR_D_MONTANT
A2: 2023 | B2: 2023-01 | C2: =SUMIFS('TD_TotalNatureTransac'!$E$2:$E$181,'TD_TotalNatureTransac'!$B$2:$B$181,B2,'TD_TotalNatureTransac'!$C$2:$C$181,"ZZ1",'TD_TotalNatureTransac'!$D$2:$D$181,"CARTES") | D2: =SUMIFS('TD_TotalNatureTransac'!$F$2:$F$181,'TD_TotalNatureTransac'!$B$2:$B$181,B2,'TD_TotalNatureTransac'!$C$2:$C$181,"ZZ1",'TD_TotalNatureTransac'!$D$2:$D$181,"CARTES") | E2: =SUMIFS('TD_TotalNatureTransac'!$E$2:$E$181,'TD_TotalNatureTransac'!$B$2:$B$181,B2,'TD_TotalNatureTransac'!$C$2:$C$181,"ZZ1",'TD_TotalNatureTransac'!$D$2:$D$181,"CHEQUES") | F2: =SUMIFS('TD_TotalNatureTransac'!$F$2:$F$181,'TD_TotalNatureTransac'!$B$2:$B$181,B2,'TD_TotalNatureTransac'!$C$2:$C$181,"ZZ1",'TD_TotalNatureTransac'!$D$2:$D$181,"CHEQUES") | G2: =SUMIFS('TD_TotalNatureTransac'!$E$2:$E$181,'TD_TotalNatureTransac'!$B$2:$B$181,B2,'TD_TotalNatureTransac'!$C$2:$C$181,"ZZ1",'TD_TotalNatureTransac'!$D$2:$D$181,"CORRECTION") | H2: =SUMIFS('TD_TotalNatureTransac'!$F$2:$F$181,'TD_TotalNatureTransac'!$B$2:$B$181,B2,'TD_TotalNatureTransac'!$C$2:$C$181,"ZZ1",'TD_TotalNatureTransac'!$D$2:$D$181,"CORRECTION") | I2: =SUMIFS('TD_TotalNatureTransac'!$E$2:$E$181,'TD_TotalNatureTransac'!$B$2:$B$181,B2,'TD_TotalNatureTransac'!$C$2:$C$181,"ZZ1",'TD_TotalNatureTransac'!$D$2:$D$181,"ESPECES") | J2: =SUMIFS('TD_TotalNatureTransac'!$F$2:$F$181,'TD_TotalNatureTransac'!$B$2:$B$181,B2,'TD_TotalNatureTransac'!$C$2:$C$181,"ZZ1",'TD_TotalNatureTransac'!$D$2:$D$181,"ESPECES") | K2: =SUMIFS('TD_TotalNatureTransac'!$E$2:$E$181,'TD_TotalNatureTransac'!$B$2:$B$181,B2,'TD_TotalNatureTransac'!$C$2:$C$181,"ZZ1",'TD_TotalNatureTransac'!$D$2:$D$181,"REF./TIROIR") | L2: =SUMIFS('TD_TotalNatureTransac'!$F$2:$F$181,'TD_TotalNatureTransac'!$B$2:$B$181,B2,'TD_TotalNatureTransac'!$C$2:$C$181,"ZZ1",'TD_TotalNatureTransac'!$D$2:$D$181,"REF./TIROIR")
A3: 2023 | B3: 2023-02 | C3: =SUMIFS('TD_TotalNatureTransac'!$E$2:$E$181,'TD_TotalNatureTransac'!$B$2:$B$181,B3,'TD_TotalNatureTransac'!$C$2:$C$181,"ZZ1",'TD_TotalNatureTransac'!$D$2:$D$181,"CARTES") | D3: =SUMIFS('TD_TotalNatureTransac'!$F$2:$F$181,'TD_TotalNatureTransac'!$B$2:$B$181,B3,'TD_TotalNatureTransac'!$C$2:$C$181,"ZZ1",'TD_TotalNatureTransac'!$D$2:$D$181,"CARTES") | E3: =SUMIFS('TD_TotalNatureTransac'!$E$2:$E$181,'TD_TotalNatureTransac'!$B$2:$B$181,B3,'TD_TotalNatureTransac'!$C$2:$C$181,"ZZ1",'TD_TotalNatureTransac'!$D$2:$D$181,"CHEQUES") | F3: =SUMIFS('TD_TotalNatureTransac'!$F$2:$F$181,'TD_TotalNatureTransac'!$B$2:$B$181,B3,'TD_TotalNatureTransac'!$C$2:$C$181,"ZZ1",'TD_TotalNatureTransac'!$D$2:$D$181,"CHEQUES") | G3: =SUMIFS('TD_TotalNatureTransac'!$E$2:$E$181,'TD_TotalNatureTransac'!$B$2:$B$181,B3,'TD_TotalNatureTransac'!$C$2:$C$181,"ZZ1",'TD_TotalNatureTransac'!$D$2:$D$181,"CORRECTION") | H3: =SUMIFS('TD_TotalNatureTransac'!$F$2:$F$181,'TD_TotalNatureTransac'!$B$2:$B$181,B3,'TD_TotalNatureTransac'!$C$2:$C$181,"ZZ1",'TD_TotalNatureTransac'!$D$2:$D$181,"CORRECTION") | I3: =SUMIFS('TD_TotalNatureTransac'!$E$2:$E$181,'TD_TotalNatureTransac'!$B$2:$B$181,B3,'TD_TotalNatureTransac'!$C$2:$C$181,"ZZ1",'TD_TotalNatureTransac'!$D$2:$D$181,"ESPECES") | J3: =SUMIFS('TD_TotalNatureTransac'!$F$2:$F$181,'TD_TotalNatureTransac'!$B$2:$B$181,B3,'TD_TotalNatureTransac'!$C$2:$C$181,"ZZ1",'TD_TotalNatureTransac'!$D$2:$D$181,"ESPECES") | K3: =SUMIFS('TD_TotalNatureTransac'!$E$2:$E$181,'TD_TotalNatureTransac'!$B$2:$B$181,B3,'TD_TotalNatureTransac'!$C$2:$C$181,"ZZ1",'TD_TotalNatureTransac'!$D$2:$D$181,"REF./TIROIR") | L3: =SUMIFS('TD_TotalNatureTransac'!$F$2:$F$181,'TD_TotalNatureTransac'!$B$2:$B$181,B3,'TD_TotalNatureTransac'!$C$2:$C$181,"ZZ1",'TD_TotalNatureTransac'!$D$2:$D$181,"REF./TIROIR")
A4: 2023 | B4: 2023-03 | C4: =SUMIFS('TD_TotalNatureTransac'!$E$2:$E$181,'TD_TotalNatureTransac'!$B$2:$B$181,B4,'TD_TotalNatureTransac'!$C$2:$C$181,"ZZ1",'TD_TotalNatureTransac'!$D$2:$D$181,"CARTES") | D4: =SUMIFS('TD_TotalNatureTransac'!$F$2:$F$181,'TD_TotalNatureTransac'!$B$2:$B$181,B4,'TD_TotalNatureTransac'!$C$2:$C$181,"ZZ1",'TD_TotalNatureTransac'!$D$2:$D$181,"CARTES") | E4: =SUMIFS('TD_TotalNatureTransac'!$E$2:$E$181,'TD_TotalNatureTransac'!$B$2:$B$181,B4,'TD_TotalNatureTransac'!$C$2:$C$181,"ZZ1",'TD_TotalNatureTransac'!$D$2:$D$181,"CHEQUES") | F4: =SUMIFS('TD_TotalNatureTransac'!$F$2:$F$181,'TD_TotalNatureTransac'!$B$2:$B$181,B4,'TD_TotalNatureTransac'!$C$2:$C$181,"ZZ1",'TD_TotalNatureTransac'!$D$2:$D$181,"CHEQUES") | G4: =SUMIFS('TD_TotalNatureTransac'!$E$2:$E$181,'TD_TotalNatureTransac'!$B$2:$B$181,B4,'TD_TotalNatureTransac'!$C$2:$C$181,"ZZ1",'TD_TotalNatureTransac'!$D$2:$D$181,"CORRECTION") | H4: =SUMIFS('TD_TotalNatureTransac'!$F$2:$F$181,'TD_TotalNatureTransac'!$B$2:$B$181,B4,'TD_TotalNatureTransac'!$C$2:$C$181,"ZZ1",'TD_TotalNatureTransac'!$D$2:$D$181,"CORRECTION") | I4: =SUMIFS('TD_TotalNatureTransac'!$E$2:$E$181,'TD_TotalNatureTransac'!$B$2:$B$181,B4,'TD_TotalNatureTransac'!$C$2:$C$181,"ZZ1",'TD_TotalNatureTransac'!$D$2:$D$181,"ESPECES") | J4: =SUMIFS('TD_TotalNatureTransac'!$F$2:$F$181,'TD_TotalNatureTransac'!$B$2:$B$181,B4,'TD_TotalNatureTransac'!$C$2:$C$181,"ZZ1",'TD_TotalNatureTransac'!$D$2:$D$181,"ESPECES") | K4: =SUMIFS('TD_TotalNatureTransac'!$E$2:$E$181,'TD_TotalNatureTransac'!$B$2:$B$181,B4,'TD_TotalNatureTransac'!$C$2:$C$181,"ZZ1",'TD_TotalNatureTransac'!$D$2:$D$181,"REF./TIROIR") | L4: =SUMIFS('TD_TotalNatureTransac'!$F$2:$F$181,'TD_TotalNatureTransac'!$B$2:$B$181,B4,'TD_TotalNatureTransac'!$C$2:$C$181,"ZZ1",'TD_TotalNatureTransac'!$D$2:$D$181,"REF./TIROIR")
A5: 2023 | B5: 2023-04 | C5: =SUMIFS('TD_TotalNatureTransac'!$E$2:$E$181,'TD_TotalNatureTransac'!$B$2:$B$181,B5,'TD_TotalNatureTransac'!$C$2:$C$181,"ZZ1",'TD_TotalNatureTransac'!$D$2:$D$181,"CARTES") | D5: =SUMIFS('TD_TotalNatureTransac'!$F$2:$F$181,'TD_TotalNatureTransac'!$B$2:$B$181,B5,'TD_TotalNatureTransac'!$C$2:$C$181,"ZZ1",'TD_TotalNatureTransac'!$D$2:$D$181,"CARTES") | E5: =SUMIFS('TD_TotalNatureTransac'!$E$2:$E$181,'TD_TotalNatureTransac'!$B$2:$B$181,B5,'TD_TotalNatureTransac'!$C$2:$C$181,"ZZ1",'TD_TotalNatureTransac'!$D$2:$D$181,"CHEQUES") | F5: =SUMIFS('TD_TotalNatureTransac'!$F$2:$F$181,'TD_TotalNatureTransac'!$B$2:$B$181,B5,'TD_TotalNatureTransac'!$C$2:$C$181,"ZZ1",'TD_TotalNatureTransac'!$D$2:$D$181,"CHEQUES") | G5: =SUMIFS('TD_TotalNatureTransac'!$E$2:$E$181,'TD_TotalNatureTransac'!$B$2:$B$181,B5,'TD_TotalNatureTransac'!$C$2:$C$181,"ZZ1",'TD_TotalNatureTransac'!$D$2:$D$181,"CORRECTION") | H5: =SUMIFS('TD_TotalNatureTransac'!$F$2:$F$181,'TD_TotalNatureTransac'!$B$2:$B$181,B5,'TD_TotalNatureTransac'!$C$2:$C$181,"ZZ1",'TD_TotalNatureTransac'!$D$2:$D$181,"CORRECTION") | I5: =SUMIFS('TD_TotalNatureTransac'!$E$2:$E$181,'TD_TotalNatureTransac'!$B$2:$B$181,B5,'TD_TotalNatureTransac'!$C$2:$C$181,"ZZ1",'TD_TotalNatureTransac'!$D$2:$D$181,"ESPECES") | J5: =SUMIFS('TD_TotalNatureTransac'!$F$2:$F$181,'TD_TotalNatureTransac'!$B$2:$B$181,B5,'TD_TotalNatureTransac'!$C$2:$C$181,"ZZ1",'TD_TotalNatureTransac'!$D$2:$D$181,"ESPECES") | K5: =SUMIFS('TD_TotalNatureTransac'!$E$2:$E$181,'TD_TotalNatureTransac'!$B$2:$B$181,B5,'TD_TotalNatureTransac'!$C$2:$C$181,"ZZ1",'TD_TotalNatureTransac'!$D$2:$D$181,"REF./TIROIR") | L5: =SUMIFS('TD_TotalNatureTransac'!$F$2:$F$181,'TD_TotalNatureTransac'!$B$2:$B$181,B5,'TD_TotalNatureTransac'!$C$2:$C$181,"ZZ1",'TD_TotalNatureTransac'!$D$2:$D$181,"REF./TIROIR")
A6: 2023 | B6: 2023-05 | C6: =SUMIFS('TD_TotalNatureTransac'!$E$2:$E$181,'TD_TotalNatureTransac'!$B$2:$B$181,B6,'TD_TotalNatureTransac'!$C$2:$C$181,"ZZ1",'TD_TotalNatureTransac'!$D$2:$D$181,"CARTES") | D6: =SUMIFS('TD_TotalNatureTransac'!$F$2:$F$181,'TD_TotalNatureTransac'!$B$2:$B$181,B6,'TD_TotalNatureTransac'!$C$2:$C$181,"ZZ1",'TD_TotalNatureTransac'!$D$2:$D$181,"CARTES") | E6: =SUMIFS('TD_TotalNatureTransac'!$E$2:$E$181,'TD_TotalNatureTransac'!$B$2:$B$181,B6,'TD_TotalNatureTransac'!$C$2:$C$181,"ZZ1",'TD_TotalNatureTransac'!$D$2:$D$181,"CHEQUES") | F6: =SUMIFS('TD_TotalNatureTransac'!$F$2:$F$181,'TD_TotalNatureTransac'!$B$2:$B$181,B6,'TD_TotalNatureTransac'!$C$2:$C$181,"ZZ1",'TD_TotalNatureTransac'!$D$2:$D$181,"CHEQUES") | G6: =SUMIFS('TD_TotalNatureTransac'!$E$2:$E$181,'TD_TotalNatureTransac'!$B$2:$B$181,B6,'TD_TotalNatureTransac'!$C$2:$C$181,"ZZ1",'TD_TotalNatureTransac'!$D$2:$D$181,"CORRECTION") | H6: =SUMIFS('TD_TotalNatureTransac'!$F$2:$F$181,'TD_TotalNatureTransac'!$B$2:$B$181,B6,'TD_TotalNatureTransac'!$C$2:$C$181,"ZZ1",'TD_TotalNatureTransac'!$D$2:$D$181,"CORRECTION") | I6: =SUMIFS('TD_TotalNatureTransac'!$E$2:$E$181,'TD_TotalNatureTransac'!$B$2:$B$181,B6,'TD_TotalNatureTransac'!$C$2:$C$181,"ZZ1",'TD_TotalNatureTransac'!$D$2:$D$181,"ESPECES") | J6: =SUMIFS('TD_TotalNatureTransac'!$F$2:$F$181,'TD_TotalNatureTransac'!$B$2:$B$181,B6,'TD_TotalNatureTransac'!$C$2:$C$181,"ZZ1",'TD_TotalNatureTransac'!$D$2:$D$181,"ESPECES") | K6: =SUMIFS('TD_TotalNatureTransac'!$E$2:$E$181,'TD_TotalNatureTransac'!$B$2:$B$181,B6,'TD_TotalNatureTransac'!$C$2:$C$181,"ZZ1",'TD_TotalNatureTransac'!$D$2:$D$181,"REF./TIROIR") | L6: =SUMIFS('TD_TotalNatureTransac'!$F$2:$F$181,'TD_TotalNatureTransac'!$B$2:$B$181,B6,'TD_TotalNatureTransac'!$C$2:$C$181,"ZZ1",'TD_TotalNatureTransac'!$D$2:$D$181,"REF./TIROIR")
A7: 2023 | B7: 2023-06 | C7: =SUMIFS('TD_TotalNatureTransac'!$E$2:$E$181,'TD_TotalNatureTransac'!$B$2:$B$181,B7,'TD_TotalNatureTransac'!$C$2:$C$181,"ZZ1",'TD_TotalNatureTransac'!$D$2:$D$181,"CARTES") | D7: =SUMIFS('TD_TotalNatureTransac'!$F$2:$F$181,'TD_TotalNatureTransac'!$B$2:$B$181,B7,'TD_TotalNatureTransac'!$C$2:$C$181,"ZZ1",'TD_TotalNatureTransac'!$D$2:$D$181,"CARTES") | E7: =SUMIFS('TD_TotalNatureTransac'!$E$2:$E$181,'TD_TotalNatureTransac'!$B$2:$B$181,B7,'TD_TotalNatureTransac'!$C$2:$C$181,"ZZ1",'TD_TotalNatureTransac'!$D$2:$D$181,"CHEQUES") | F7: =SUMIFS('TD_TotalNatureTransac'!$F$2:$F$181,'TD_TotalNatureTransac'!$B$2:$B$181,B7,'TD_TotalNatureTransac'!$C$2:$C$181,"ZZ1",'TD_TotalNatureTransac'!$D$2:$D$181,"CHEQUES") | G7: =SUMIFS('TD_TotalNatureTransac'!$E$2:$E$181,'TD_TotalNatureTransac'!$B$2:$B$181,B7,'TD_TotalNatureTransac'!$C$2:$C$181,"ZZ1",'TD_TotalNatureTransac'!$D$2:$D$181,"CORRECTION") | H7: =SUMIFS('TD_TotalNatureTransac'!$F$2:$F$181,'TD_TotalNatureTransac'!$B$2:$B$181,B7,'TD_TotalNatureTransac'!$C$2:$C$181,"ZZ1",'TD_TotalNatureTransac'!$D$2:$D$181,"CORRECTION") | I7: =SUMIFS('TD_TotalNatureTransac'!$E$2:$E$181,'TD_TotalNatureTransac'!$B$2:$B$181,B7,'TD_TotalNatureTransac'!$C$2:$C$181,"ZZ1",'TD_TotalNatureTransac'!$D$2:$D$181,"ESPECES") | J7: =SUMIFS('TD_TotalNatureTransac'!$F$2:$F$181,'TD_TotalNatureTransac'!$B$2:$B$181,B7,'TD_TotalNatureTransac'!$C$2:$C$181,"ZZ1",'TD_TotalNatureTransac'!$D$2:$D$181,"ESPECES") | K7: =SUMIFS('TD_TotalNatureTransac'!$E$2:$E$181,'TD_TotalNatureTransac'!$B$2:$B$181,B7,'TD_TotalNatureTransac'!$C$2:$C$181,"ZZ1",'TD_TotalNatureTransac'!$D$2:$D$181,"REF./TIROIR") | L7: =SUMIFS('TD_TotalNatureTransac'!$F$2:$F$181,'TD_TotalNatureTransac'!$B$2:$B$181,B7,'TD_TotalNatureTransac'!$C$2:$C$181,"ZZ1",'TD_TotalNatureTransac'!$D$2:$D$181,"REF./TIROIR")
A8: 2023 | B8: 2023-07 | C8: =SUMIFS('TD_TotalNatureTransac'!$E$2:$E$181,'TD_TotalNatureTransac'!$B$2:$B$181,B8,'TD_TotalNatureTransac'!$C$2:$C$181,"ZZ1",'TD_TotalNatureTransac'!$D$2:$D$181,"CARTES") | D8: =SUMIFS('TD_TotalNatureTransac'!$F$2:$F$181,'TD_TotalNatureTransac'!$B$2:$B$181,B8,'TD_TotalNatureTransac'!$C$2:$C$181,"ZZ1",'TD_TotalNatureTransac'!$D$2:$D$181,"CARTES") | E8: =SUMIFS('TD_TotalNatureTransac'!$E$2:$E$181,'TD_TotalNatureTransac'!$B$2:$B$181,B8,'TD_TotalNatureTransac'!$C$2:$C$181,"ZZ1",'TD_TotalNatureTransac'!$D$2:$D$181,"CHEQUES") | F8: =SUMIFS('TD_TotalNatureTransac'!$F$2:$F$181,'TD_TotalNatureTransac'!$B$2:$B$181,B8,'TD_TotalNatureTransac'!$C$2:$C$181,"ZZ1",'TD_TotalNatureTransac'!$D$2:$D$181,"CHEQUES") | G8: =SUMIFS('TD_TotalNatureTransac'!$E$2:$E$181,'TD_TotalNatureTransac'!$B$2:$B$181,B8,'TD_TotalNatureTransac'!$C$2:$C$181,"ZZ1",'TD_TotalNatureTransac'!$D$2:$D$181,"CORRECTION") | H8: =SUMIFS('TD_TotalNatureTransac'!$F$2:$F$181,'TD_TotalNatureTransac'!$B$2:$B$181,B8,'TD_TotalNatureTransac'!$C$2:$C$181,"ZZ1",'TD_TotalNatureTransac'!$D$2:$D$181,"CORRECTION") | I8: =SUMIFS('TD_TotalNatureTransac'!$E$2:$E$181,'TD_TotalNatureTransac'!$B$2:$B$181,B8,'TD_TotalNatureTransac'!$C$2:$C$181,"ZZ1",'TD_TotalNatureTransac'!$D$2:$D$181,"ESPECES") | J8: =SUMIFS('TD_TotalNatureTransac'!$F$2:$F$181,'TD_TotalNatureTransac'!$B$2:$B$181,B8,'TD_TotalNatureTransac'!$C$2:$C$181,"ZZ1",'TD_TotalNatureTransac'!$D$2:$D$181,"ESPECES") | K8: =SUMIFS('TD_TotalNatureTransac'!$E$2:$E$181,'TD_TotalNatureTransac'!$B$2:$B$181,B8,'TD_TotalNatureTransac'!$C$2:$C$181,"ZZ1",'TD_TotalNatureTransac'!$D$2:$D$181,"REF./TIROIR") | L8: =SUMIFS('TD_TotalNatureTransac'!$F$2:$F$181,'TD_TotalNatureTransac'!$B$2:$B$181,B8,'TD_TotalNatureTransac'!$C$2:$C$181,"ZZ1",'TD_TotalNatureTransac'!$D$2:$D$181,"REF./TIROIR")
A9: 2023 | B9: 2023-08 | C9: =SUMIFS('TD_TotalNatureTransac'!$E$2:$E$181,'TD_TotalNatureTransac'!$B$2:$B$181,B9,'TD_TotalNatureTransac'!$C$2:$C$181,"ZZ1",'TD_TotalNatureTransac'!$D$2:$D$181,"CARTES") | D9: =SUMIFS('TD_TotalNatureTransac'!$F$2:$F$181,'TD_TotalNatureTransac'!$B$2:$B$181,B9,'TD_TotalNatureTransac'!$C$2:$C$181,"ZZ1",'TD_TotalNatureTransac'!$D$2:$D$181,"CARTES") | E9: =SUMIFS('TD_TotalNatureTransac'!$E$2:$E$181,'TD_TotalNatureTransac'!$B$2:$B$181,B9,'TD_TotalNatureTransac'!$C$2:$C$181,"ZZ1",'TD_TotalNatureTransac'!$D$2:$D$181,"CHEQUES") | F9: =SUMIFS('TD_TotalNatureTransac'!$F$2:$F$181,'TD_TotalNatureTransac'!$B$2:$B$181,B9,'TD_TotalNatureTransac'!$C$2:$C$181,"ZZ1",'TD_TotalNatureTransac'!$D$2:$D$181,"CHEQUES") | G9: =SUMIFS('TD_TotalNatureTransac'!$E$2:$E$181,'TD_TotalNatureTransac'!$B$2:$B$181,B9,'TD_TotalNatureTransac'!$C$2:$C$181,"ZZ1",'TD_TotalNatureTransac'!$D$2:$D$181,"CORRECTION") | H9: =SUMIFS('TD_TotalNatureTransac'!$F$2:$F$181,'TD_TotalNatureTransac'!$B$2:$B$181,B9,'TD_TotalNatureTransac'!$C$2:$C$181,"ZZ1",'TD_TotalNatureTransac'!$D$2:$D$181,"CORRECTION") | I9: =SUMIFS('TD_TotalNatureTransac'!$E$2:$E$181,'TD_TotalNatureTransac'!$B$2:$B$181,B9,'TD_TotalNatureTransac'!$C$2:$C$181,"ZZ1",'TD_TotalNatureTransac'!$D$2:$D$181,"ESPECES") | J9: =SUMIFS('TD_TotalNatureTransac'!$F$2:$F$181,'TD_TotalNatureTransac'!$B$2:$B$181,B9,'TD_TotalNatureTransac'!$C$2:$C$181,"ZZ1",'TD_TotalNatureTransac'!$D$2:$D$181,"ESPECES") | K9: =SUMIFS('TD_TotalNatureTransac'!$E$2:$E$181,'TD_TotalNatureTransac'!$B$2:$B$181,B9,'TD_TotalNatureTransac'!$C$2:$C$181,"ZZ1",'TD_TotalNatureTransac'!$D$2:$D$181,"REF./TIROIR") | L9: =SUMIFS('TD_TotalNatureTransac'!$F$2:$F$181,'TD_TotalNatureTransac'!$B$2:$B$181,B9,'TD_TotalNatureTransac'!$C$2:$C$181,"ZZ1",'TD_TotalNatureTransac'!$D$2:$D$181,"REF./TIROIR")
A10: 2023 | B10: 2023-09 | C10: =SUMIFS('TD_TotalNatureTransac'!$E$2:$E$181,'TD_TotalNatureTransac'!$B$2:$B$181,B10,'TD_TotalNatureTransac'!$C$2:$C$181,"ZZ1",'TD_TotalNatureTransac'!$D$2:$D$181,"CARTES") | D10: =SUMIFS('TD_TotalNatureTransac'!$F$2:$F$181,'TD_TotalNatureTransac'!$B$2:$B$181,B10,'TD_TotalNatureTransac'!$C$2:$C$181,"ZZ1",'TD_TotalNatureTransac'!$D$2:$D$181,"CARTES") | E10: =SUMIFS('TD_TotalNatureTransac'!$E$2:$E$181,'TD_TotalNatureTransac'!$B$2:$B$181,B10,'TD_TotalNatureTransac'!$C$2:$C$181,"ZZ1",'TD_TotalNatureTransac'!$D$2:$D$181,"CHEQUES") | F10: =SUMIFS('TD_TotalNatureTransac'!$F$2:$F$181,'TD_TotalNatureTransac'!$B$2:$B$181,B10,'TD_TotalNatureTransac'!$C$2:$C$181,"ZZ1",'TD_TotalNatureTransac'!$D$2:$D$181,"CHEQUES") | G10: =SUMIFS('TD_TotalNatureTransac'!$E$2:$E$181,'TD_TotalNatureTransac'!$B$2:$B$181,B10,'TD_TotalNatureTransac'!$C$2:$C$181,"ZZ1",'TD_TotalNatureTransac'!$D$2:$D$181,"CORRECTION") | H10: =SUMIFS('TD_TotalNatureTransac'!$F$2:$F$181,'TD_TotalNatureTransac'!$B$2:$B$181,B10,'TD_TotalNatureTransac'!$C$2:$C$181,"ZZ1",'TD_TotalNatureTransac'!$D$2:$D$181,"CORRECTION") | I10: =SUMIFS('TD_TotalNatureTransac'!$E$2:$E$181,'TD_TotalNatureTransac'!$B$2:$B$181,B10,'TD_TotalNatureTransac'!$C$2:$C$181,"ZZ1",'TD_TotalNatureTransac'!$D$2:$D$181,"ESPECES") | J10: =SUMIFS('TD_TotalNatureTransac'!$F$2:$F$181,'TD_TotalNatureTransac'!$B$2:$B$181,B10,'TD_TotalNatureTransac'!$C$2:$C$181,"ZZ1",'TD_TotalNatureTransac'!$D$2:$D$181,"ESPECES") | K10: =SUMIFS('TD_TotalNatureTransac'!$E$2:$E$181,'TD_TotalNatureTransac'!$B$2:$B$181,B10,'TD_TotalNatureTransac'!$C$2:$C$181,"ZZ1",'TD_TotalNatureTransac'!$D$2:$D$181,"REF./TIROIR") | L10: =SUMIFS('TD_TotalNatureTransac'!$F$2:$F$181,'TD_TotalNatureTransac'!$B$2:$B$181,B10,'TD_TotalNatureTransac'!$C$2:$C$181,"ZZ1",'TD_TotalNatureTransac'!$D$2:$D$181,"REF./TIROIR")
A11: 2023 | B11: 2023-10 | C11: =SUMIFS('TD_TotalNatureTransac'!$E$2:$E$181,'TD_TotalNatureTransac'!$B$2:$B$181,B11,'TD_TotalNatureTransac'!$C$2:$C$181,"ZZ1",'TD_TotalNatureTransac'!$D$2:$D$181,"CARTES") | D11: =SUMIFS('TD_TotalNatureTransac'!$F$2:$F$181,'TD_TotalNatureTransac'!$B$2:$B$181,B11,'TD_TotalNatureTransac'!$C$2:$C$181,"ZZ1",'TD_TotalNatureTransac'!$D$2:$D$181,"CARTES") | E11: =SUMIFS('TD_TotalNatureTransac'!$E$2:$E$181,'TD_TotalNatureTransac'!$B$2:$B$181,B11,'TD_TotalNatureTransac'!$C$2:$C$181,"ZZ1",'TD_TotalNatureTransac'!$D$2:$D$181,"CHEQUES") | F11: =SUMIFS('TD_TotalNatureTransac'!$F$2:$F$181,'TD_TotalNatureTransac'!$B$2:$B$181,B11,'TD_TotalNatureTransac'!$C$2:$C$181,"ZZ1",'TD_TotalNatureTransac'!$D$2:$D$181,"CHEQUES") | G11: =SUMIFS('TD_TotalNatureTransac'!$E$2:$E$181,'TD_TotalNatureTransac'!$B$2:$B$181,B11,'TD_TotalNatureTransac'!$C$2:$C$181,"ZZ1",'TD_TotalNatureTransac'!$D$2:$D$181,"CORRECTION") | H11: =SUMIFS('TD_TotalNatureTransac'!$F$2:$F$181,'TD_TotalNatureTransac'!$B$2:$B$181,B11,'TD_TotalNatureTransac'!$C$2:$C$181,"ZZ1",'TD_TotalNatureTransac'!$D$2:$D$181,"CORRECTION") | I11: =SUMIFS('TD_TotalNatureTransac'!$E$2:$E$181,'TD_TotalNatureTransac'!$B$2:$B$181,B11,'TD_TotalNatureTransac'!$C$2:$C$181,"ZZ1",'TD_TotalNatureTransac'!$D$2:$D$181,"ESPECES") | J11: =SUMIFS('TD_TotalNatureTransac'!$F$2:$F$181,'TD_TotalNatureTransac'!$B$2:$B$181,B11,'TD_TotalNatureTransac'!$C$2:$C$181,"ZZ1",'TD_TotalNatureTransac'!$D$2:$D$181,"ESPECES") | K11: =SUMIFS('TD_TotalNatureTransac'!$E$2:$E$181,'TD_TotalNatureTransac'!$B$2:$B$181,B11,'TD_TotalNatureTransac'!$C$2:$C$181,"ZZ1",'TD_TotalNatureTransac'!$D$2:$D$181,"REF./TIROIR") | L11: =SUMIFS('TD_TotalNatureTransac'!$F$2:$F$181,'TD_TotalNatureTransac'!$B$2:$B$181,B11,'TD_TotalNatureTransac'!$C$2:$C$181,"ZZ1",'TD_TotalNatureTransac'!$D$2:$D$181,"REF./TIROIR")
A12: 2023 | B12: 2023-11 | C12: =SUMIFS('TD_TotalNatureTransac'!$E$2:$E$181,'TD_TotalNatureTransac'!$B$2:$B$181,B12,'TD_TotalNatureTransac'!$C$2:$C$181,"ZZ1",'TD_TotalNatureTransac'!$D$2:$D$181,"CARTES") | D12: =SUMIFS('TD_TotalNatureTransac'!$F$2:$F$181,'TD_TotalNatureTransac'!$B$2:$B$181,B12,'TD_TotalNatureTransac'!$C$2:$C$181,"ZZ1",'TD_TotalNatureTransac'!$D$2:$D$181,"CARTES") | E12: =SUMIFS('TD_TotalNatureTransac'!$E$2:$E$181,'TD_TotalNatureTransac'!$B$2:$B$181,B12,'TD_TotalNatureTransac'!$C$2:$C$181,"ZZ1",'TD_TotalNatureTransac'!$D$2:$D$181,"CHEQUES") | F12: =SUMIFS('TD_TotalNatureTransac'!$F$2:$F$181,'TD_TotalNatureTransac'!$B$2:$B$181,B12,'TD_TotalNatureTransac'!$C$2:$C$181,"ZZ1",'TD_TotalNatureTransac'!$D$2:$D$181,"CHEQUES") | G12: =SUMIFS('TD_TotalNatureTransac'!$E$2:$E$181,'TD_TotalNatureTransac'!$B$2:$B$181,B12,'TD_TotalNatureTransac'!$C$2:$C$181,"ZZ1",'TD_TotalNatureTransac'!$D$2:$D$181,"CORRECTION") | H12: =SUMIFS('TD_TotalNatureTransac'!$F$2:$F$181,'TD_TotalNatureTransac'!$B$2:$B$181,B12,'TD_TotalNatureTransac'!$C$2:$C$181,"ZZ1",'TD_TotalNatureTransac'!$D$2:$D$181,"CORRECTION") | I12: =SUMIFS('TD_TotalNatureTransac'!$E$2:$E$181,'TD_TotalNatureTransac'!$B$2:$B$181,B12,'TD_TotalNatureTransac'!$C$2:$C$181,"ZZ1",'TD_TotalNatureTransac'!$D$2:$D$181,"ESPECES") | J12: =SUMIFS('TD_TotalNatureTransac'!$F$2:$F$181,'TD_TotalNatureTransac'!$B$2:$B$181,B12,'TD_TotalNatureTransac'!$C$2:$C$181,"ZZ1",'TD_TotalNatureTransac'!$D$2:$D$181,"ESPECES") | K12: =SUMIFS('TD_TotalNatureTransac'!$E$2:$E$181,'TD_TotalNatureTransac'!$B$2:$B$181,B12,'TD_TotalNatureTransac'!$C$2:$C$181,"ZZ1",'TD_TotalNatureTransac'!$D$2:$D$181,"REF./TIROIR") | L12: =SUMIFS('TD_TotalNatureTransac'!$F$2:$F$181,'TD_TotalNatureTransac'!$B$2:$B$181,B12,'TD_TotalNatureTransac'!$C$2:$C$181,"ZZ1",'TD_TotalNatureTransac'!$D$2:$D$181,"REF./TIROIR")
A13: 2023 | B13: 2023-12 | C13: =SUMIFS('TD_TotalNatureTransac'!$E$2:$E$181,'TD_TotalNatureTransac'!$B$2:$B$181,B13,'TD_TotalNatureTransac'!$C$2:$C$181,"ZZ1",'TD_TotalNatureTransac'!$D$2:$D$181,"CARTES") | D13: =SUMIFS('TD_TotalNatureTransac'!$F$2:$F$181,'TD_TotalNatureTransac'!$B$2:$B$181,B13,'TD_TotalNatureTransac'!$C$2:$C$181,"ZZ1",'TD_TotalNatureTransac'!$D$2:$D$181,"CARTES") | E13: =SUMIFS('TD_TotalNatureTransac'!$E$2:$E$181,'TD_TotalNatureTransac'!$B$2:$B$181,B13,'TD_TotalNatureTransac'!$C$2:$C$181,"ZZ1",'TD_TotalNatureTransac'!$D$2:$D$181,"CHEQUES") | F13: =SUMIFS('TD_TotalNatureTransac'!$F$2:$F$181,'TD_TotalNatureTransac'!$B$2:$B$181,B13,'TD_TotalNatureTransac'!$C$2:$C$181,"ZZ1",'TD_TotalNatureTransac'!$D$2:$D$181,"CHEQUES") | G13: =SUMIFS('TD_TotalNatureTransac'!$E$2:$E$181,'TD_TotalNatureTransac'!$B$2:$B$181,B13,'TD_TotalNatureTransac'!$C$2:$C$181,"ZZ1",'TD_TotalNatureTransac'!$D$2:$D$181,"CORRECTION") | H13: =SUMIFS('TD_TotalNatureTransac'!$F$2:$F$181,'TD_TotalNatureTransac'!$B$2:$B$181,B13,'TD_TotalNatureTransac'!$C$2:$C$181,"ZZ1",'TD_TotalNatureTransac'!$D$2:$D$181,"CORRECTION") | I13: =SUMIFS('TD_TotalNatureTransac'!$E$2:$E$181,'TD_TotalNatureTransac'!$B$2:$B$181,B13,'TD_TotalNatureTransac'!$C$2:$C$181,"ZZ1",'TD_TotalNatureTransac'!$D$2:$D$181,"ESPECES") | J13: =SUMIFS('TD_TotalNatureTransac'!$F$2:$F$181,'TD_TotalNatureTransac'!$B$2:$B$181,B13,'TD_TotalNatureTransac'!$C$2:$C$181,"ZZ1",'TD_TotalNatureTransac'!$D$2:$D$181,"ESPECES") | K13: =SUMIFS('TD_TotalNatureTransac'!$E$2:$E$181,'TD_TotalNatureTransac'!$B$2:$B$181,B13,'TD_TotalNatureTransac'!$C$2:$C$181,"ZZ1",'TD_TotalNatureTransac'!$D$2:$D$181,"REF./TIROIR") | L13: =SUMIFS('TD_TotalNatureTransac'!$F$2:$F$181,'TD_TotalNatureTransac'!$B$2:$B$181,B13,'TD_TotalNatureTransac'!$C$2:$C$181,"ZZ1",'TD_TotalNatureTransac'!$D$2:$D$181,"REF./TIROIR")

Sheet Z2_Total_ModeZZ2
A1: AJ_ANNEE_Z | B1: AJ_MOIS_Z | C1: CARTES_D_QUANTITE | D1: CARTES_D_MONTANT | E1: CHEQUES_D_QUANTITE | F1: CHEQUES_D_MONTANT | G1: CORRECTION_D_QUANTITE | H1: CORRECTION_D_MONTANT | I1: ESPECES_D_QUANTITE | J1: ESPECES_D_MONTANT | K1: REF__TIROIR_D_QUANTITE | L1: REF__TIROIR_D_MONTANT
A2: 2023 | B2: 2023-01 | C2: =SUMIFS('TD_TotalNatureTransac'!$E$2:$E$181,'TD_TotalNatureTransac'!$B$2:$B$181,B2,'TD_TotalNatureTransac'!$C$2:$C$181,"ZZ2",'TD_TotalNatureTransac'!$D$2:$D$181,"CARTES") | D2: =SUMIFS('TD_TotalNatureTransac'!$F$2:$F$181,'TD_TotalNatureTransac'!$B$2:$B$181,B2,'TD_TotalNatureTransac'!$C$2:$C$181,"ZZ2",'TD_TotalNatureTransac'!$D$2:$D$181,"CARTES") | E2: =SUMIFS('TD_TotalNatureTransac'!$E$2:$E$181,'TD_TotalNatureTransac'!$B$2:$B$181,B2,'TD_TotalNatureTransac'!$C$2:$C$181,"ZZ2",'TD_TotalNatureTransac'!$D$2:$D$181,"CHEQUES") | F2: =SUMIFS('TD_TotalNatureTransac'!$F$2:$F$181,'TD_TotalNatureTransac'!$B$2:$B$181,B2,'TD_TotalNatureTransac'!$C$2:$C$181,"ZZ2",'TD_TotalNatureTransac'!$D$2:$D$181,"CHEQUES") | G2: =SUMIFS('TD_TotalNatureTransac'!$E$2:$E$181,'TD_TotalNatureTransac'!$B$2:$B$181,B2,'TD_TotalNatureTransac'!$C$2:$C$181,"ZZ2",'TD_TotalNatureTransac'!$D$2:$D$181,"CORRECTION") | H2: =SUMIFS('TD_TotalNatureTransac'!$F$2:$F$181,'TD_TotalNatureTransac'!$B$2:$B$181,B2,'TD_TotalNatureTransac'!$C$2:$C$181,"ZZ2",'TD_TotalNatureTransac'!$D$2:$D$181,"CORRECTION") | I2: =SUMIFS('TD_TotalNatureTransac'!$E$2:$E$181,'TD_TotalNatureTransac'!$B$2:$B$181,B2,'TD_TotalNatureTransac'!$C$2:$C$181,"ZZ2",'TD_TotalNatureTransac'!$D$2:$D$181,"ESPECES") | J2: =SUMIFS('TD_TotalNatureTransac'!$F$2:$F$181,'TD_TotalNatureTransac'!$B$2:$B$181,B2,'TD_TotalNatureTransac'!$C$2:$C$181,"ZZ2",'TD_TotalNatureTransac'!$D$2:$D$181,"ESPECES") | K2: =SUMIFS('TD_TotalNatureTransac'!$E$2:$E$181,'TD_TotalNatureTransac'!$B$2:$B$181,B2,'TD_TotalNatureTransac'!$C$2:$C$181,"ZZ2",'TD_TotalNatureTransac'!$D$2:$D$181,"REF./TIROIR") | L2: =SUMIFS('TD_TotalNatureTransac'!$F$2:$F$181,'TD_TotalNatureTransac'!$B$2:$B$181,B2,'TD_TotalNatureTransac'!$C$2:$C$181,"ZZ2",'TD_TotalNatureTransac'!$D$2:$D$181,"REF./TIROIR")
A3: 2023 | B3: 2023-02 | C3: =SUMIFS('TD_TotalNatureTransac'!$E$2:$E$181,'TD_TotalNatureTransac'!$B$2:$B$181,B3,'TD_TotalNatureTransac'!$C$2:$C$181,"ZZ2",'TD_TotalNatureTransac'!$D$2:$D$181,"CARTES") | D3: =SUMIFS('TD_TotalNatureTransac'!$F$2:$F$181,'TD_TotalNatureTransac'!$B$2:$B$181,B3,'TD_TotalNatureTransac'!$C$2:$C$181,"ZZ2",'TD_TotalNatureTransac'!$D$2:$D$181,"CARTES") | E3: =SUMIFS('TD_TotalNatureTransac'!$E$2:$E$181,'TD_TotalNatureTransac'!$B$2:$B$181,B3,'TD_TotalNatureTransac'!$C$2:$C$181,"ZZ2",'TD_TotalNatureTransac'!$D$2:$D$181,"CHEQUES") | F3: =SUMIFS('TD_TotalNatureTransac'!$F$2:$F$181,'TD_TotalNatureTransac'!$B$2:$B$181,B3,'TD_TotalNatureTransac'!$C$2:$C$181,"ZZ2",'TD_TotalNatureTransac'!$D$2:$D$181,"CHEQUES") | G3: =SUMIFS('TD_TotalNatureTransac'!$E$2:$E$181,'TD_TotalNatureTransac'!$B$2:$B$181,B3,'TD_TotalNatureTransac'!$C$2:$C$181,"ZZ2",'TD_TotalNatureTransac'!$D$2:$D$181,"CORRECTION") | H3: =SUMIFS('TD_TotalNatureTransac'!$F$2:$F$181,'TD_TotalNatureTransac'!$B$2:$B$181,B3,'TD_TotalNatureTransac'!$C$2:$C$181,"ZZ2",'TD_TotalNatureTransac'!$D$2:$D$181,"CORRECTION") | I3: =SUMIFS('TD_TotalNatureTransac'!$E$2:$E$181,'TD_TotalNatureTransac'!$B$2:$B$181,B3,'TD_TotalNatureTransac'!$C$2:$C$181,"ZZ2",'TD_TotalNatureTransac'!$D$2:$D$181,"ESPECES") | J3: =SUMIFS('TD_TotalNatureTransac'!$F$2:$F$181,'TD_TotalNatureTransac'!$B$2:$B$181,B3,'TD_TotalNatureTransac'!$C$2:$C$181,"ZZ2",'TD_TotalNatureTransac'!$D$2:$D$181,"ESPECES") | K3: =SUMIFS('TD_TotalNatureTransac'!$E$2:$E$181,'TD_TotalNatureTransac'!$B$2:$B$181,B3,'TD_TotalNatureTransac'!$C$2:$C$181,"ZZ2",'TD_TotalNatureTransac'!$D$2:$D$181,"REF./TIROIR") | L3: =SUMIFS('TD_TotalNatureTransac'!$F$2:$F$181,'TD_TotalNatureTransac'!$B$2:$B$181,B3,'TD_TotalNatureTransac'!$C$2:$C$181,"ZZ2",'TD_TotalNatureTransac'!$D$2:$D$181,"REF./TIROIR")
A4: 2023 | B4: 2023-03 | C4: =SUMIFS('TD_TotalNatureTransac'!$E$2:$E$181,'TD_TotalNatureTransac'!$B$2:$B$181,B4,'TD_TotalNatureTransac'!$C$2:$C$181,"ZZ2",'TD_TotalNatureTransac'!$D$2:$D$181,"CARTES") | D4: =SUMIFS('TD_TotalNatureTransac'!$F$2:$F$181,'TD_TotalNatureTransac'!$B$2:$B$181,B4,'TD_TotalNatureTransac'!$C$2:$C$181,"ZZ2",'TD_TotalNatureTransac'!$D$2:$D$181,"CARTES") | E4: =SUMIFS('TD_TotalNatureTransac'!$E$2:$E$181,'TD_TotalNatureTransac'!$B$2:$B$181,B4,'TD_TotalNatureTransac'!$C$2:$C$181,"ZZ2",'TD_TotalNatureTransac'!$D$2:$D$181,"CHEQUES") | F4: =SUMIFS('TD_TotalNatureTransac'!$F$2:$F$181,'TD_TotalNatureTransac'!$B$2:$B$181,B4,'TD_TotalNatureTransac'!$C$2:$C$181,"ZZ2",'TD_TotalNatureTransac'!$D$2:$D$181,"CHEQUES") | G4: =SUMIFS('TD_TotalNatureTransac'!$E$2:$E$181,'TD_TotalNatureTransac'!$B$2:$B$181,B4,'TD_TotalNatureTransac'!$C$2:$C$181,"ZZ2",'TD_TotalNatureTransac'!$D$2:$D$181,"CORRECTION") | H4: =SUMIFS('TD_TotalNatureTransac'!$F$2:$F$181,'TD_TotalNatureTransac'!$B$2:$B$181,B4,'TD_TotalNatureTransac'!$C$2:$C$181,"ZZ2",'TD_TotalNatureTransac'!$D$2:$D$181,"CORRECTION") | I4: =SUMIFS('TD_TotalNatureTransac'!$E$2:$E$181,'TD_TotalNatureTransac'!$B$2:$B$181,B4,'TD_TotalNatureTransac'!$C$2:$C$181,"ZZ2",'TD_TotalNatureTransac'!$D$2:$D$181,"ESPECES") | J4: =SUMIFS('TD_TotalNatureTransac'!$F$2:$F$181,'TD_TotalNatureTransac'!$B$2:$B$181,B4,'TD_TotalNatureTransac'!$C$2:$C$181,"ZZ2",'TD_TotalNatureTransac'!$D$2:$D$181,"ESPECES") | K4: =SUMIFS('TD_TotalNatureTransac'!$E$2:$E$181,'TD_TotalNatureTransac'!$B$2:$B$181,B4,'TD_TotalNatureTransac'!$C$2:$C$181,"ZZ2",'TD_TotalNatureTransac'!$D$2:$D$181,"REF./TIROIR") | L4: =SUMIFS('TD_TotalNatureTransac'!$F$2:$F$181,'TD_TotalNatureTransac'!$B$2:$B$181,B4,'TD_TotalNatureTransac'!$C$2:$C$181,"ZZ2",'TD_TotalNatureTransac'!$D$2:$D$181,"REF./TIROIR")
A5: 2023 | B5: 2023-04 | C5: =SUMIFS('TD_TotalNatureTransac'!$E$2:$E$181,'TD_TotalNatureTransac'!$B$2:$B$181,B5,'TD_TotalNatureTransac'!$C$2:$C$181,"ZZ2",'TD_TotalNatureTransac'!$D$2:$D$181,"CARTES") | D5: =SUMIFS('TD_TotalNatureTransac'!$F$2:$F$181,'TD_TotalNatureTransac'!$B$2:$B$181,B5,'TD_TotalNatureTransac'!$C$2:$C$181,"ZZ2",'TD_TotalNatureTransac'!$D$2:$D$181,"CARTES") | E5: =SUMIFS('TD_TotalNatureTransac'!$E$2:$E$181,'TD_TotalNatureTransac'!$B$2:$B$181,B5,'TD_TotalNatureTransac'!$C$2:$C$181,"ZZ2",'TD_TotalNatureTransac'!$D$2:$D$181,"CHEQUES") | F5: =SUMIFS('TD_TotalNatureTransac'!$F$2:$F$181,'TD_TotalNatureTransac'!$B$2:$B$181,B5,'TD_TotalNatureTransac'!$C$2:$C$181,"ZZ2",'TD_TotalNatureTransac'!$D$2:$D$181,"CHEQUES") | G5: =SUMIFS('TD_TotalNatureTransac'!$E$2:$E$181,'TD_TotalNatureTransac'!$B$2:$B$181,B5,'TD_TotalNatureTransac'!$C$2:$C$181,"ZZ2",'TD_TotalNatureTransac'!$D$2:$D$181,"CORRECTION") | H5: =SUMIFS('TD_TotalNatureTransac'!$F$2:$F$181,'TD_TotalNatureTransac'!$B$2:$B$181,B5,'TD_TotalNatureTransac'!$C$2:$C$181,"ZZ2",'TD_TotalNatureTransac'!$D$2:$D$181,"CORRECTION") | I5: =SUMIFS('TD_TotalNatureTransac'!$E$2:$E$181,'TD_TotalNatureTransac'!$B$2:$B$181,B5,'TD_TotalNatureTransac'!$C$2:$C$181,"ZZ2",'TD_TotalNatureTransac'!$D$2:$D$181,"ESPECES") | J5: =SUMIFS('TD_TotalNatureTransac'!$F$2:$F$181,'TD_TotalNatureTransac'!$B$2:$B$181,B5,'TD_TotalNatureTransac'!$C$2:$C$181,"ZZ2",'TD_TotalNatureTransac'!$D$2:$D$181,"ESPECES") | K5: =SUMIFS('TD_TotalNatureTransac'!$E$2:$E$181,'TD_TotalNatureTransac'!$B$2:$B$181,B5,'TD_TotalNatureTransac'!$C$2:$C$181,"ZZ2",'TD_TotalNatureTransac'!$D$2:$D$181,"REF./TIROIR") | L5: =SUMIFS('TD_TotalNatureTransac'!$F$2:$F$181,'TD_TotalNatureTransac'!$B$2:$B$181,B5,'TD_TotalNatureTransac'!$C$2:$C$181,"ZZ2",'TD_TotalNatureTransac'!$D$2:$D$181,"REF./TIROIR")
A6: 2023 | B6: 2023-05 | C6: =SUMIFS('TD_TotalNatureTransac'!$E$2:$E$181,'TD_TotalNatureTransac'!$B$2:$B$181,B6,'TD_TotalNatureTransac'!$C$2:$C$181,"ZZ2",'TD_TotalNatureTransac'!$D$2:$D$181,"CARTES") | D6: =SUMIFS('TD_TotalNatureTransac'!$F$2:$F$181,'TD_TotalNatureTransac'!$B$2:$B$181,B6,'TD_TotalNatureTransac'!$C$2:$C$181,"ZZ2",'TD_TotalNatureTransac'!$D$2:$D$181,"CARTES") | E6: =SUMIFS('TD_TotalNatureTransac'!$E$2:$E$181,'TD_TotalNatureTransac'!$B$2:$B$181,B6,'TD_TotalNatureTransac'!$C$2:$C$181,"ZZ2",'TD_TotalNatureTransac'!$D$2:$D$181,"CHEQUES") | F6: =SUMIFS('TD_TotalNatureTransac'!$F$2:$F$181,'TD_TotalNatureTransac'!$B$2:$B$181,B6,'TD_TotalNatureTransac'!$C$2:$C$181,"ZZ2",'TD_TotalNatureTransac'!$D$2:$D$181,"CHEQUES") | G6: =SUMIFS('TD_TotalNatureTransac'!$E$2:$E$181,'TD_TotalNatureTransac'!$B$2:$B$181,B6,'TD_TotalNatureTransac'!$C$2:$C$181,"ZZ2",'TD_TotalNatureTransac'!$D$2:$D$181,"CORRECTION") | H6: =SUMIFS('TD_TotalNatureTransac'!$F$2:$F$181,'TD_TotalNatureTransac'!$B$2:$B$181,B6,'TD_TotalNatureTransac'!$C$2:$C$181,"ZZ2",'TD_TotalNatureTransac'!$D$2:$D$181,"CORRECTION") | I6: =SUMIFS('TD_TotalNatureTransac'!$E$2:$E$181,'TD_TotalNatureTransac'!$B$2:$B$181,B6,'TD_TotalNatureTransac'!$C$2:$C$181,"ZZ2",'TD_TotalNatureTransac'!$D$2:$D$181,"ESPECES") | J6: =SUMIFS('TD_TotalNatureTransac'!$F$2:$F$181,'TD_TotalNatureTransac'!$B$2:$B$181,B6,'TD_TotalNatureTransac'!$C$2:$C$181,"ZZ2",'TD_TotalNatureTransac'!$D$2:$D$181,"ESPECES") | K6: =SUMIFS('TD_TotalNatureTransac'!$E$2:$E$181,'TD_TotalNatureTransac'!$B$2:$B$181,B6,'TD_TotalNatureTransac'!$C$2:$C$181,"ZZ2",'TD_TotalNatureTransac'!$D$2:$D$181,"REF./TIROIR") | L6: =SUMIFS('TD_TotalNatureTransac'!$F$2:$F$181,'TD_TotalNatureTransac'!$B$2:$B$181,B6,'TD_TotalNatureTransac'!$C$2:$C$181,"ZZ2",'TD_TotalNatureTransac'!$D$2:$D$181,"REF./TIROIR")
A7: 2023 | B7: 2023-06 | C7: =SUMIFS('TD_TotalNatureTransac'!$E$2:$E$181,'TD_TotalNatureTransac'!$B$2:$B$181,B7,'TD_TotalNatureTransac'!$C$2:$C$181,"ZZ2",'TD_TotalNatureTransac'!$D$2:$D$181,"CARTES") | D7: =SUMIFS('TD_TotalNatureTransac'!$F$2:$F$181,'TD_TotalNatureTransac'!$B$2:$B$181,B7,'TD_TotalNatureTransac'!$C$2:$C$181,"ZZ2",'TD_TotalNatureTransac'!$D$2:$D$181,"CARTES") | E7: =SUMIFS('TD_TotalNatureTransac'!$E$2:$E$181,'TD_TotalNatureTransac'!$B$2:$B$181,B7,'TD_TotalNatureTransac'!$C$2:$C$181,"ZZ2",'TD_TotalNatureTransac'!$D$2:$D$181,"CHEQUES") | F7: =SUMIFS('TD_TotalNatureTransac'!$F$2:$F$181,'TD_TotalNatureTransac'!$B$2:$B$181,B7,'TD_TotalNatureTransac'!$C$2:$C$181,"ZZ2",'TD_TotalNatureTransac'!$D$2:$D$181,"CHEQUES") | G7: =SUMIFS('TD_TotalNatureTransac'!$E$2:$E$181,'TD_TotalNatureTransac'!$B$2:$B$181,B7,'TD_TotalNatureTransac'!$C$2:$C$181,"ZZ2",'TD_TotalNatureTransac'!$D$2:$D$181,"CORRECTION") | H7: =SUMIFS('TD_TotalNatureTransac'!$F$2:$F$181,'TD_TotalNatureTransac'!$B$2:$B$181,B7,'TD_TotalNatureTransac'!$C$2:$C$181,"ZZ2",'TD_TotalNatureTransac'!$D$2:$D$181,"CORRECTION") | I7: =SUMIFS('TD_TotalNatureTransac'!$E$2:$E$181,'TD_TotalNatureTransac'!$B$2:$B$181,B7,'TD_TotalNatureTransac'!$C$2:$C$181,"ZZ2",'TD_TotalNatureTransac'!$D$2:$D$181,"ESPECES") | J7: =SUMIFS('TD_TotalNatureTransac'!$F$2:$F$181,'TD_TotalNatureTransac'!$B$2:$B$181,B7,'TD_TotalNatureTransac'!$C$2:$C$181,"ZZ2",'TD_TotalNatureTransac'!$D$2:$D$181,"ESPECES") | K7: =SUMIFS('TD_TotalNatureTransac'!$E$2:$E$181,'TD_TotalNatureTransac'!$B$2:$B$181,B7,'TD_TotalNatureTransac'!$C$2:$C$181,"ZZ2",'TD_TotalNatureTransac'!$D$2:$D$181,"REF./TIROIR") | L7: =SUMIFS('TD_TotalNatureTransac'!$F$2:$F$181,'TD_TotalNatureTransac'!$B$2:$B$181,B7,'TD_TotalNatureTransac'!$C$2:$C$181,"ZZ2",'TD_TotalNatureTransac'!$D$2:$D$181,"REF./TIROIR")
A8: 2023 | B8: 2023-07 | C8: =SUMIFS('TD_TotalNatureTransac'!$E$2:$E$181,'TD_TotalNatureTransac'!$B$2:$B$181,B8,'TD_TotalNatureTransac'!$C$2:$C$181,"ZZ2",'TD_TotalNatureTransac'!$D$2:$D$181,"CARTES") | D8: =SUMIFS('TD_TotalNatureTransac'!$F$2:$F$181,'TD_TotalNatureTransac'!$B$2:$B$181,B8,'TD_TotalNatureTransac'!$C$2:$C$181,"ZZ2",'TD_TotalNatureTransac'!$D$2:$D$181,"CARTES") | E8: =SUMIFS('TD_TotalNatureTransac'!$E$2:$E$181,'TD_TotalNatureTransac'!$B$2:$B$181,B8,'TD_TotalNatureTransac'!$C$2:$C$181,"ZZ2",'TD_TotalNatureTransac'!$D$2:$D$181,"CHEQUES") | F8: =SUMIFS('TD_TotalNatureTransac'!$F$2:$F$181,'TD_TotalNatureTransac'!$B$2:$B$181,B8,'TD_TotalNatureTransac'!$C$2:$C$181,"ZZ2",'TD_TotalNatureTransac'!$D$2:$D$181,"CHEQUES") | G8: =SUMIFS('TD_TotalNatureTransac'!$E$2:$E$181,'TD_TotalNatureTransac'!$B$2:$B$181,B8,'TD_TotalNatureTransac'!$C$2:$C$181,"ZZ2",'TD_TotalNatureTransac'!$D$2:$D$181,"CORRECTION") | H8: =SUMIFS('TD_TotalNatureTransac'!$F$2:$F$181,'TD_TotalNatureTransac'!$B$2:$B$181,B8,'TD_TotalNatureTransac'!$C$2:$C$181,"ZZ2",'TD_TotalNatureTransac'!$D$2:$D$181,"CORRECTION") | I8: =SUMIFS('TD_TotalNatureTransac'!$E$2:$E$181,'TD_TotalNatureTransac'!$B$2:$B$181,B8,'TD_TotalNatureTransac'!$C$2:$C$181,"ZZ2",'TD_TotalNatureTransac'!$D$2:$D$181,"ESPECES") | J8: =SUMIFS('TD_TotalNatureTransac'!$F$2:$F$181,'TD_TotalNatureTransac'!$B$2:$B$181,B8,'TD_TotalNatureTransac'!$C$2:$C$181,"ZZ2",'TD_TotalNatureTransac'!$D$2:$D$181,"ESPECES") | K8: =SUMIFS('TD_TotalNatureTransac'!$E$2:$E$181,'TD_TotalNatureTransac'!$B$2:$B$181,B8,'TD_TotalNatureTransac'!$C$2:$C$181,"ZZ2",'TD_TotalNatureTransac'!$D$2:$D$181,"REF./TIROIR") | L8: =SUMIFS('TD_TotalNatureTransac'!$F$2:$F$181,'TD_TotalNatureTransac'!$B$2:$B$181,B8,'TD_TotalNatureTransac'!$C$2:$C$181,"ZZ2",'TD_TotalNatureTransac'!$D$2:$D$181,"REF./TIROIR")
A9: 2023 | B9: 2023-08 | C9: =SUMIFS('TD_TotalNatureTransac'!$E$2:$E$181,'TD_TotalNatureTransac'!$B$2:$B$181,B9,'TD_TotalNatureTransac'!$C$2:$C$181,"ZZ2",'TD_TotalNatureTransac'!$D$2:$D$181,"CARTES") | D9: =SUMIFS('TD_TotalNatureTransac'!$F$2:$F$181,'TD_TotalNatureTransac'!$B$2:$B$181,B9,'TD_TotalNatureTransac'!$C$2:$C$181,"ZZ2",'TD_TotalNatureTransac'!$D$2:$D$181,"CARTES") | E9: =SUMIFS('TD_TotalNatureTransac'!$E$2:$E$181,'TD_TotalNatureTransac'!$B$2:$B$181,B9,'TD_TotalNatureTransac'!$C$2:$C$181,"ZZ2",'TD_TotalNatureTransac'!$D$2:$D$181,"CHEQUES") | F9: =SUMIFS('TD_TotalNatureTransac'!$F$2:$F$181,'TD_TotalNatureTransac'!$B$2:$B$181,B9,'TD_TotalNatureTransac'!$C$2:$C$181,"ZZ2",'TD_TotalNatureTransac'!$D$2:$D$181,"CHEQUES") | G9: =SUMIFS('TD_TotalNatureTransac'!$E$2:$E$181,'TD_TotalNatureTransac'!$B$2:$B$181,B9,'TD_TotalNatureTransac'!$C$2:$C$181,"ZZ2",'TD_TotalNatureTransac'!$D$2:$D$181,"CORRECTION") | H9: =SUMIFS('TD_TotalNatureTransac'!$F$2:$F$181,'TD_TotalNatureTransac'!$B$2:$B$181,B9,'TD_TotalNatureTransac'!$C$2:$C$181,"ZZ2",'TD_TotalNatureTransac'!$D$2:$D$181,"CORRECTION") | I9: =SUMIFS('TD_TotalNatureTransac'!$E$2:$E$181,'TD_TotalNatureTransac'!$B$2:$B$181,B9,'TD_TotalNatureTransac'!$C$2:$C$181,"ZZ2",'TD_TotalNatureTransac'!$D$2:$D$181,"ESPECES") | J9: =SUMIFS('TD_TotalNatureTransac'!$F$2:$F$181,'TD_TotalNatureTransac'!$B$2:$B$181,B9,'TD_TotalNatureTransac'!$C$2:$C$181,"ZZ2",'TD_TotalNatureTransac'!$D$2:$D$181,"ESPECES") | K9: =SUMIFS('TD_TotalNatureTransac'!$E$2:$E$181,'TD_TotalNatureTransac'!$B$2:$B$181,B9,'TD_TotalNatureTransac'!$C$2:$C$181,"ZZ2",'TD_TotalNatureTransac'!$D$2:$D$181,"REF./TIROIR") | L9: =SUMIFS('TD_TotalNatureTransac'!$F$2:$F$181,'TD_TotalNatureTransac'!$B$2:$B$181,B9,'TD_TotalNatureTransac'!$C$2:$C$181,"ZZ2",'TD_TotalNatureTransac'!$D$2:$D$181,"REF./TIROIR")
A10: 2023 | B10: 2023-09 | C10: =SUMIFS('TD_TotalNatureTransac'!$E$2:$E$181,'TD_TotalNatureTransac'!$B$2:$B$181,B10,'TD_TotalNatureTransac'!$C$2:$C$181,"ZZ2",'TD_TotalNatureTransac'!$D$2:$D$181,"CARTES") | D10: =SUMIFS('TD_TotalNatureTransac'!$F$2:$F$181,'TD_TotalNatureTransac'!$B$2:$B$181,B10,'TD_TotalNatureTransac'!$C$2:$C$181,"ZZ2",'TD_TotalNatureTransac'!$D$2:$D$181,"CARTES") | E10: =SUMIFS('TD_TotalNatureTransac'!$E$2:$E$181,'TD_TotalNatureTransac'!$B$2:$B$181,B10,'TD_TotalNatureTransac'!$C$2:$C$181,"ZZ2",'TD_TotalNatureTransac'!$D$2:$D$181,"CHEQUES") | F10: =SUMIFS('TD_TotalNatureTransac'!$F$2:$F$181,'TD_TotalNatureTransac'!$B$2:$B$181,B10,'TD_TotalNatureTransac'!$C$2:$C$181,"ZZ2",'TD_TotalNatureTransac'!$D$2:$D$181,"CHEQUES") | G10: =SUMIFS('TD_TotalNatureTransac'!$E$2:$E$181,'TD_TotalNatureTransac'!$B$2:$B$181,B10,'TD_TotalNatureTransac'!$C$2:$C$181,"ZZ2",'TD_TotalNatureTransac'!$D$2:$D$181,"CORRECTION") | H10: =SUMIFS('TD_TotalNatureTransac'!$F$2:$F$181,'TD_TotalNatureTransac'!$B$2:$B$181,B10,'TD_TotalNatureTransac'!$C$2:$C$181,"ZZ2",'TD_TotalNatureTransac'!$D$2:$D$181,"CORRECTION") | I10: =SUMIFS('TD_TotalNatureTransac'!$E$2:$E$181,'TD_TotalNatureTransac'!$B$2:$B$181,B10,'TD_TotalNatureTransac'!$C$2:$C$181,"ZZ2",'TD_TotalNatureTransac'!$D$2:$D$181,"ESPECES") | J10: =SUMIFS('TD_TotalNatureTransac'!$F$2:$F$181,'TD_TotalNatureTransac'!$B$2:$B$181,B10,'TD_TotalNatureTransac'!$C$2:$C$181,"ZZ2",'TD_TotalNatureTransac'!$D$2:$D$181,"ESPECES") | K10: =SUMIFS('TD_TotalNatureTransac'!$E$2:$E$181,'TD_TotalNatureTransac'!$B$2:$B$181,B10,'TD_TotalNatureTransac'!$C$2:$C$181,"ZZ2",'TD_TotalNatureTransac'!$D$2:$D$181,"REF./TIROIR") | L10: =SUMIFS('TD_TotalNatureTransac'!$F$2:$F$181,'TD_TotalNatureTransac'!$B$2:$B$181,B10,'TD_TotalNatureTransac'!$C$2:$C$181,"ZZ2",'TD_TotalNatureTransac'!$D$2:$D$181,"REF./TIROIR")
A11: 2023 | B11: 2023-10 | C11: =SUMIFS('TD_TotalNatureTransac'!$E$2:$E$181,'TD_TotalNatureTransac'!$B$2:$B$181,B11,'TD_TotalNatureTransac'!$C$2:$C$181,"ZZ2",'TD_TotalNatureTransac'!$D$2:$D$181,"CARTES") | D11: =SUMIFS('TD_TotalNatureTransac'!$F$2:$F$181,'TD_TotalNatureTransac'!$B$2:$B$181,B11,'TD_TotalNatureTransac'!$C$2:$C$181,"ZZ2",'TD_TotalNatureTransac'!$D$2:$D$181,"CARTES") | E11: =SUMIFS('TD_TotalNatureTransac'!$E$2:$E$181,'TD_TotalNatureTransac'!$B$2:$B$181,B11,'TD_TotalNatureTransac'!$C$2:$C$181,"ZZ2",'TD_TotalNatureTransac'!$D$2:$D$181,"CHEQUES") | F11: =SUMIFS('TD_TotalNatureTransac'!$F$2:$F$181,'TD_TotalNatureTransac'!$B$2:$B$181,B11,'TD_TotalNatureTransac'!$C$2:$C$181,"ZZ2",'TD_TotalNatureTransac'!$D$2:$D$181,"CHEQUES") | G11: =SUMIFS('TD_TotalNatureTransac'!$E$2:$E$181,'TD_TotalNatureTransac'!$B$2:$B$181,B11,'TD_TotalNatureTransac'!$C$2:$C$181,"ZZ2",'TD_TotalNatureTransac'!$D$2:$D$181,"CORRECTION") | H11: =SUMIFS('TD_TotalNatureTransac'!$F$2:$F$181,'TD_TotalNatureTransac'!$B$2:$B$181,B11,'TD_TotalNatureTransac'!$C$2:$C$181,"ZZ2",'TD_TotalNatureTransac'!$D$2:$D$181,"CORRECTION") | I11: =SUMIFS('TD_TotalNatureTransac'!$E$2:$E$181,'TD_TotalNatureTransac'!$B$2:$B$181,B11,'TD_TotalNatureTransac'!$C$2:$C$181,"ZZ2",'TD_TotalNatureTransac'!$D$2:$D$181,"ESPECES") | J11: =SUMIFS('TD_TotalNatureTransac'!$F$2:$F$181,'TD_TotalNatureTransac'!$B$2:$B$181,B11,'TD_TotalNatureTransac'!$C$2:$C$181,"ZZ2",'TD_TotalNatureTransac'!$D$2:$D$181,"ESPECES") | K11: =SUMIFS('TD_TotalNatureTransac'!$E$2:$E$181,'TD_TotalNatureTransac'!$B$2:$B$181,B11,'TD_TotalNatureTransac'!$C$2:$C$181,"ZZ2",'TD_TotalNatureTransac'!$D$2:$D$181,"REF./TIROIR") | L11: =SUMIFS('TD_TotalNatureTransac'!$F$2:$F$181,'TD_TotalNatureTransac'!$B$2:$B$181,B11,'TD_TotalNatureTransac'!$C$2:$C$181,"ZZ2",'TD_TotalNatureTransac'!$D$2:$D$181,"REF./TIROIR")
