Workbook

Sheet ENTETES_MATURIN_0
A1: nomfichier | B1: E_NUM_INTERNE | C1: E_NUM_TICKET | D1: E_DATE_TICKET | E1: E_HEURE_TICKET | F1: E_HT1 | G1: E_HT2 | H1: E_HT3 | I1: E_HT4 | J1: E_TVA1 | K1: E_TVA2 | L1: E_TVA3 | M1: E_TVA4 | N1: E_HT_NON_TAXABLE | O1: E_TTC | P1: E_MDP_CB | Q1: E_MDP_ESPECES | R1: E_MDP_CHEQUES
A2: EJ010223.TXT | B2: 000977 | C2: 000609 | D2: 44930 | E2: 12:01 | F2: 747.5 | J2: 149.5 | O2: 897 | Q2: 897
A3: EJ010223.TXT | B3: 000978 | C3: 000610 | D3: 44932 | E3: 11:30 | F3: 498.33 | J3: 99.67 | O3: 598 | P3: 598
A4: EJ010223.TXT | B4: 000979 | C4: 000611 | D4: 44932 | E4: 13:38 | F4: 483.33 | J4: 96.67 | O4: 580 | P4: 580
A5: EJ010223.TXT | B5: 000980 | C5: 000612 | D5: 44932 | E5: 13:38 | F5: 1450 | J5: 290 | O5: 1740 | P5: 1740
A6: EJ010223.TXT | B6: 000981 | C6: 000613 | D6: 44932 | E6: 13:58 | F6: 1450 | J6: 290 | O6: 1740 | P6: 1740
A7: EJ010223.TXT | B7: 000982 | C7: 000614 | D7: 44932 | E7: 13:59 | F7: 2900 | J7: 580 | O7: 3480 | P7: 3480
A8: EJ010223.TXT | B8: 000983 | C8: 000615 | D8: 44937 | E8: 12:38 | F8: 73.33 | J8: 14.67 | O8: 88 | P8: 88
A9: EJ010223.TXT | B9: 000984 | C9: 000616 | D9: 44937 | E9: 14:46 | F9: 311.5 | J9: 62.3 | O9: 373.8 | P9: 373.8
A10: EJ010223.TXT | B10: 000985 | C10: 000617 | D10: 44939 | E10: 10:27 | F10: 249.17 | J10: 49.83 | O10: 299 | P10: 299
A11: EJ010223.TXT | B11: 000986 | C11: 000618 | D11: 44939 | E11: 10:48 | F11: 146.67 | J11: 29.33 | O11: 176 | P11: 176
A12: EJ010223.TXT | B12: 000987 | C12: 000619 | D12: 44939 | E12: 13:05 | F12: 498.33 | J12: 99.67 | O12: 598 | P12: 598
A13: EJ010223.TXT | B13: 000988 | C13: 000620 | D13: 44940 | E13: 16:39 | F13: 498.33 | J13: 99.67 | O13: 598 | P13: 598
A14: EJ010223.TXT | B14: 000989 | C14: 000621 | D14: 44940 | E14: 16:53 | F14: 288.33 | J14: 57.67 | O14: 346 | P14: 346
A15: EJ010223.TXT | B15: 000990 | C15: 000622 | D15: 44942 | E15: 17:36 | F15: 658.33 | J15: 131.67 | O15: 790 | Q15: 790
A16: EJ010223.TXT | B16: 000991 | C16: 000623 | D16: 44942 | E16: 17:44 | F16: 241.67 | J16: 48.33 | O16: 290 | Q16: 290
A17: EJ010223.TXT | B17: 000992 | C17: 000624 | D17: 44942 | E17: 17:44 | F17: 241.67 | J17: 48.33 | O17: 290 | Q17: 290
A18: EJ010223.TXT | B18: 000993 | C18: 000625 | D18: 44942 | E18: 17:44 | F18: 241.67 | J18: 48.33 | O18: 290 | Q18: 290
A19: EJ010223.TXT | B19: 000994 | C19: 000626 | D19: 44943 | E19: 10:05 | F19: 747.5 | J19: 149.5 | O19: 897 | P19: 897
A20: EJ010223.TXT | B20: 000995 | C20: 000627 | D20: 44943 | E20: 11:17 | F20: 115.83 | J20: 23.17 | O20: 139 | P20: 139
A21: EJ010223.TXT | B21: 000996 | C21: 000628 | D21: 44943 | E21: 11:23 | F21: 2900 | J21: 580 | O21: 3480 | P21: 3480
A22: EJ010223.TXT | B22: 000997 | C22: 000629 | D22: 44943 | E22: 12:30 | F22: 144.17 | J22: 28.83 | O22: 173 | P22: 173
A23: EJ010223.TXT | B23: 000998 | C23: 000630 | D23: 44943 | E23: 13:47 | F23: 498.33 | J23: 99.67 | O23: 598 | Q23: 598
A24: EJ010223.TXT | B24: 000999 | C24: 000631 | D24: 44944 | E24: 12:59 | F24: 149 | J24: 29.8 | O24: 178.8 | P24: 178.8
A25: EJ010223.TXT | B25: 001000 | C25: 000632 | D25: 44944 | E25: 17:24 | F25: 73.33 | J25: 14.67 | O25: 88 | P25: 88
A26: EJ010223.TXT | B26: 001001 | C26: 000633 | D26: 44945 | E26: 12:34 | F26: 498.33 | J26: 99.67 | O26: 598 | Q26: 598
A27: EJ010223.TXT | B27: 001002 | C27: 000634 | D27: 44947 | E27: 14:43 | F27: 498.33 | J27: 99.67 | O27: 598 | P27: 598
A28: EJ010223.TXT | B28: 001003 | C28: 000635 | D28: 44951 | E28: 09:58 | F28: 249.17 | J28: 49.83 | O28: 299 | Q28: 299
A29: EJ010223.TXT | B29: 001004 | C29: 000636 | D29: 44951 | E29: 16:08 | F29: 498.33 | J29: 99.67 | O29: 598 | P29: 598
A30: EJ010223.TXT | B30: 001005 | C30: 000637 | D30: 44951 | E30: 16:46 | F30: 498.33 | J30: 99.67 | O30: 598 | Q30: 598
A31: EJ010223.TXT | B31: 001006 | C31: 000638 | D31: 44952 | E31: 16:05 | F31: 498.33 | J31: 99.67 | O31: 598 | Q31: 598
A32: EJ010223.TXT | B32: 001007 | C32: 000639 | D32: 44953 | E32: 13:19 | F32: 498.33 | J32: 99.67 | O32: 598 | P32: 598
A33: EJ010223.TXT | B33: 001008 | C33: 000640 | D33: 44953 | E33: 17:19 | F33: 498.33 | J33: 99.67 | O33: 598 | P33: 598
A34: EJ010323.TXT | B34: 001015 | C34: 000641 | D34: 44958 | E34: 15:26 | F34: 24.83 | J34: 4.97 | O34: 29.8 | Q34: 29.8
A35: EJ010323.TXT | B35: 001017 | C35: 000642 | D35: 44959 | E35: 12:55 | F35: 274.17 | J35: 54.83 | O35: 329 | P35: 329
A36: EJ010323.TXT | B36: 001020 | C36: 000643 | D36: 44959 | E36: 14:04 | F36: 274.17 | J36: 54.83 | O36: 329 | Q36: 329
A37: EJ010323.TXT | B37: 001021 | C37: 000644 | D37: 44961 | E37: 15:31 | F37: 548.33 | J37: 109.67 | O37: 658 | Q37: 658
A38: EJ010323.TXT | B38: 001022 | C38: 000645 | D38: 44961 | E38: 15:34 | F38: 548.33 | J38: 109.67 | O38: 658 | P38: 658
A39: EJ010323.TXT | B39: 001023 | C39: 000646 | D39: 44961 | E39: 16:26 | F39: 822.5 | J39: 164.5 | O39: 987 | Q39: 987
A40: EJ010323.TXT | B40: 001024 | C40: 000647 | D40: 44961 | E40: 16:35 | F40: 548.33 | J40: 109.67 | O40: 658 | P40: 658
...

Sheet Entetes_TriNumInterne
A1: nomfichier | B1: E_NUM_INTERNE | C1: E_NUM_TICKET | D1: E_DATE_TICKET | E1: E_HEURE_TICKET | F1: E_HT1 | G1: E_HT2 | H1: E_HT3 | I1: E_HT4 | J1: E_TVA1 | K1: E_TVA2 | L1: E_TVA3 | M1: E_TVA4 | N1: E_HT_NON_TAXABLE | O1: E_TTC | P1: E_MDP_CB | Q1: E_MDP_ESPECES | R1: E_MDP_CHEQUES
A2: EJ010223.TXT | B2: 000977 | C2: 000609 | D2: 44930 | E2: 12:01 | F2: 747.5 | J2: 149.5 | O2: 897 | Q2: 897
A3: EJ010223.TXT | B3: 000978 | C3: 000610 | D3: 44932 | E3: 11:30 | F3: 498.33 | J3: 99.67 | O3: 598 | P3: 598
A4: EJ010223.TXT | B4: 000979 | C4: 000611 | D4: 44932 | E4: 13:38 | F4: 483.33 | J4: 96.67 | O4: 580 | P4: 580
A5: EJ010223.TXT | B5: 000980 | C5: 000612 | D5: 44932 | E5: 13:38 | F5: 1450 | J5: 290 | O5: 1740 | P5: 1740
A6: EJ010223.TXT | B6: 000981 | C6: 000613 | D6: 44932 | E6: 13:58 | F6: 1450 | J6: 290 | O6: 1740 | P6: 1740
A7: EJ010223.TXT | B7: 000982 | C7: 000614 | D7: 44932 | E7: 13:59 | F7: 2900 | J7: 580 | O7: 3480 | P7: 3480
A8: EJ010223.TXT | B8: 000983 | C8: 000615 | D8: 44937 | E8: 12:38 | F8: 73.33 | J8: 14.67 | O8: 88 | P8: 88
A9: EJ010223.TXT | B9: 000984 | C9: 000616 | D9: 44937 | E9: 14:46 | F9: 311.5 | J9: 62.3 | O9: 373.8 | P9: 373.8
A10: EJ010223.TXT | B10: 000985 | C10: 000617 | D10: 44939 | E10: 10:27 | F10: 249.17 | J10: 49.83 | O10: 299 | P10: 299
A11: EJ010223.TXT | B11: 000986 | C11: 000618 | D11: 44939 | E11: 10:48 | F11: 146.67 | J11: 29.33 | O11: 176 | P11: 176
A12: EJ010223.TXT | B12: 000987 | C12: 000619 | D12: 44939 | E12: 13:05 | F12: 498.33 | J12: 99.67 | O12: 598 | P12: 598
A13: EJ010223.TXT | B13: 000988 | C13: 000620 | D13: 44940 | E13: 16:39 | F13: 498.33 | J13: 99.67 | O13: 598 | P13: 598
A14: EJ010223.TXT | B14: 000989 | C14: 000621 | D14: 44940 | E14: 16:53 | F14: 288.33 | J14: 57.67 | O14: 346 | P14: 346
A15: EJ010223.TXT | B15: 000990 | C15: 000622 | D15: 44942 | E15: 17:36 | F15: 658.33 | J15: 131.67 | O15: 790 | Q15: 790
A16: EJ010223.TXT | B16: 000991 | C16: 000623 | D16: 44942 | E16: 17:44 | F16: 241.67 | J16: 48.33 | O16: 290 | Q16: 290
A17: EJ010223.TXT | B17: 000992 | C17: 000624 | D17: 44942 | E17: 17:44 | F17: 241.67 | J17: 48.33 | O17: 290 | Q17: 290
A18: EJ010223.TXT | B18: 000993 | C18: 000625 | D18: 44942 | E18: 17:44 | F18: 241.67 | J18: 48.33 | O18: 290 | Q18: 290
A19: EJ010223.TXT | B19: 000994 | C19: 000626 | D19: 44943 | E19: 10:05 | F19: 747.5 | J19: 149.5 | O19: 897 | P19: 897
A20: EJ010223.TXT | B20: 000995 | C20: 000627 | D20: 44943 | E20: 11:17 | F20: 115.83 | J20: 23.17 | O20: 139 | P20: 139
A21: EJ010223.TXT | B21: 000996 | C21: 000628 | D21: 44943 | E21: 11:23 | F21: 2900 | J21: 580 | O21: 3480 | P21: 3480
A22: EJ010223.TXT | B22: 000997 | C22: 000629 | D22: 44943 | E22: 12:30 | F22: 144.17 | J22: 28.83 | O22: 173 | P22: 173
A23: EJ010223.TXT | B23: 000998 | C23: 000630 | D23: 44943 | E23: 13:47 | F23: 498.33 | J23: 99.67 | O23: 598 | Q23: 598
A24: EJ010223.TXT | B24: 000999 | C24: 000631 | D24: 44944 | E24: 12:59 | F24: 149 | J24: 29.8 | O24: 178.8 | P24: 178.8
A25: EJ010223.TXT | B25: 001000 | C25: 000632 | D25: 44944 | E25: 17:24 | F25: 73.33 | J25: 14.67 | O25: 88 | P25: 88
A26: EJ010223.TXT | B26: 001001 | C26: 000633 | D26: 44945 | E26: 12:34 | F26: 498.33 | J26: 99.67 | O26: 598 | Q26: 598
A27: EJ010223.TXT | B27: 001002 | C27: 000634 | D27: 44947 | E27: 14:43 | F27: 498.33 | J27: 99.67 | O27: 598 | P27: 598
A28: EJ010223.TXT | B28: 001003 | C28: 000635 | D28: 44951 | E28: 09:58 | F28: 249.17 | J28: 49.83 | O28: 299 | Q28: 299
A29: EJ010223.TXT | B29: 001004 | C29: 000636 | D29: 44951 | E29: 16:08 | F29: 498.33 | J29: 99.67 | O29: 598 | P29: 598
A30: EJ010223.TXT | B30: 001005 | C30: 000637 | D30: 44951 | E30: 16:46 | F30: 498.33 | J30: 99.67 | O30: 598 | Q30: 598
A31: EJ010223.TXT | B31: 001006 | C31: 000638 | D31: 44952 | E31: 16:05 | F31: 498.33 | J31: 99.67 | O31: 598 | Q31: 598
A32: EJ010223.TXT | B32: 001007 | C32: 000639 | D32: 44953 | E32: 13:19 | F32: 498.33 | J32: 99.67 | O32: 598 | P32: 598
A33: EJ010223.TXT | B33: 001008 | C33: 000640 | D33: 44953 | E33: 17:19 | F33: 498.33 | J33: 99.67 | O33: 598 | P33: 598
A34: EJ010323.TXT | B34: 001015 | C34: 000641 | D34: 44958 | E34: 15:26 | F34: 24.83 | J34: 4.97 | O34: 29.8 | Q34: 29.8
A35: EJ010323.TXT | B35: 001017 | C35: 000642 | D35: 44959 | E35: 12:55 | F35: 274.17 | J35: 54.83 | O35: 329 | P35: 329
A36: EJ010323.TXT | B36: 001020 | C36: 000643 | D36: 44959 | E36: 14:04 | F36: 274.17 | J36: 54.83 | O36: 329 | Q36: 329
A37: EJ010323.TXT | B37: 001021 | C37: 000644 | D37: 44961 | E37: 15:31 | F37: 548.33 | J37: 109.67 | O37: 658 | Q37: 658
A38: EJ010323.TXT | B38: 001022 | C38: 000645 | D38: 44961 | E38: 15:34 | F38: 548.33 | J38: 109.67 | O38: 658 | P38: 658
A39: EJ010323.TXT | B39: 001023 | C39: 000646 | D39: 44961 | E39: 16:26 | F39: 822.5 | J39: 164.5 | O39: 987 | Q39: 987
A40: EJ010323.TXT | B40: 001024 | C40: 000647 | D40: 44961 | E40: 16:35 | F40: 548.33 | J40: 109.67 | O40: 658 | P40: 658
...

Sheet Entetes_CtrlCoherence
A1: nomfichier | B1: E_NUM_INTERNE | C1: E_NUM_TICKET | D1: E_DATE_TICKET | E1: E_HEURE_TICKET | F1: E_HT1 | G1: E_HT2 | H1: E_HT3 | I1: E_HT4 | J1: E_TVA1 | K1: E_TVA2 | L1: E_TVA3 | M1: E_TVA4 | N1: E_HT_NON_TAXABLE | O1: E_TTC | P1: E_MDP_CB | Q1: E_MDP_ESPECES | R1: E_MDP_CHEQUES | S1: AJ_TVA1_CALCULE | T1: AJ_ECART_TVA1 | U1: AJ_TTC_CALCULE | V1: AJ_ECART_TTC | W1: AJ_SOLDE_DU | X1: AJ_SOLDE_TOUS_MDP
A2: EJ010223.TXT | B2: 000977 | C2: 000609 | D2: 44930 | E2: 12:01 | F2: 747.5 | J2: 149.5 | O2: 897 | Q2: 897 | S2: =F2*20% | T2: =J2-S2 | U2: =F2+J2 | V2: =O2-U2 | W2: =O2-(P2+R2) | X2: =O2-(P2+Q2+R2)
A3: EJ010223.TXT | B3: 000978 | C3: 000610 | D3: 44932 | E3: 11:30 | F3: 498.33 | J3: 99.67 | O3: 598 | P3: 598 | S3: =F3*20% | T3: =J3-S3 | U3: =F3+J3 | V3: =O3-U3 | W3: =O3-(P3+R3) | X3: =O3-(P3+Q3+R3)
A4: EJ010223.TXT | B4: 000979 | C4: 000611 | D4: 44932 | E4: 13:38 | F4: 483.33 | J4: 96.67 | O4: 580 | P4: 580 | S4: =F4*20% | T4: =J4-S4 | U4: =F4+J4 | V4: =O4-U4 | W4: =O4-(P4+R4) | X4: =O4-(P4+Q4+R4)
A5: EJ010223.TXT | B5: 000980 | C5: 000612 | D5: 44932 | E5: 13:38 | F5: 1450 | J5: 290 | O5: 1740 | P5: 1740 | S5: =F5*20% | T5: =J5-S5 | U5: =F5+J5 | V5: =O5-U5 | W5: =O5-(P5+R5) | X5: =O5-(P5+Q5+R5)
A6: EJ010223.TXT | B6: 000981 | C6: 000613 | D6: 44932 | E6: 13:58 | F6: 1450 | J6: 290 | O6: 1740 | P6: 1740 | S6: =F6*20% | T6: =J6-S6 | U6: =F6+J6 | V6: =O6-U6 | W6: =O6-(P6+R6) | X6: =O6-(P6+Q6+R6)
A7: EJ010223.TXT | B7: 000982 | C7: 000614 | D7: 44932 | E7: 13:59 | F7: 2900 | J7: 580 | O7: 3480 | P7: 3480 | S7: =F7*20% | T7: =J7-S7 | U7: =F7+J7 | V7: =O7-U7 | W7: =O7-(P7+R7) | X7: =O7-(P7+Q7+R7)
A8: EJ010223.TXT | B8: 000983 | C8: 000615 | D8: 44937 | E8: 12:38 | F8: 73.33 | J8: 14.67 | O8: 88 | P8: 88 | S8: =F8*20% | T8: =J8-S8 | U8: =F8+J8 | V8: =O8-U8 | W8: =O8-(P8+R8) | X8: =O8-(P8+Q8+R8)
A9: EJ010223.TXT | B9: 000984 | C9: 000616 | D9: 44937 | E9: 14:46 | F9: 311.5 | J9: 62.3 | O9: 373.8 | P9: 373.8 | S9: =F9*20% | T9: =J9-S9 | U9: =F9+J9 | V9: =O9-U9 | W9: =O9-(P9+R9) | X9: =O9-(P9+Q9+R9)
A10: EJ010223.TXT | B10: 000985 | C10: 000617 | D10: 44939 | E10: 10:27 | F10: 249.17 | J10: 49.83 | O10: 299 | P10: 299 | S10: =F10*20% | T10: =J10-S10 | U10: =F10+J10 | V10: =O10-U10 | W10: =O10-(P10+R10) | X10: =O10-(P10+Q10+R10)
A11: EJ010223.TXT | B11: 000986 | C11: 000618 | D11: 44939 | E11: 10:48 | F11: 146.67 | J11: 29.33 | O11: 176 | P11: 176 | S11: =F11*20% | T11: =J11-S11 | U11: =F11+J11 | V11: =O11-U11 | W11: =O11-(P11+R11) | X11: =O11-(P11+Q11+R11)
A12: EJ010223.TXT | B12: 000987 | C12: 000619 | D12: 44939 | E12: 13:05 | F12: 498.33 | J12: 99.67 | O12: 598 | P12: 598 | S12: =F12*20% | T12: =J12-S12 | U12: =F12+J12 | V12: =O12-U12 | W12: =O12-(P12+R12) | X12: =O12-(P12+Q12+R12)
A13: EJ010223.TXT | B13: 000988 | C13: 000620 | D13: 44940 | E13: 16:39 | F13: 498.33 | J13: 99.67 | O13: 598 | P13: 598 | S13: =F13*20% | T13: =J13-S13 | U13: =F13+J13 | V13: =O13-U13 | W13: =O13-(P13+R13) | X13: =O13-(P13+Q13+R13)
A14: EJ010223.TXT | B14: 000989 | C14: 000621 | D14: 44940 | E14: 16:53 | F14: 288.33 | J14: 57.67 | O14: 346 | P14: 346 | S14: =F14*20% | T14: =J14-S14 | U14: =F14+J14 | V14: =O14-U14 | W14: =O14-(P14+R14) | X14: =O14-(P14+Q14+R14)
A15: EJ010223.TXT | B15: 000990 | C15: 000622 | D15: 44942 | E15: 17:36 | F15: 658.33 | J15: 131.67 | O15: 790 | Q15: 790 | S15: =F15*20% | T15: =J15-S15 | U15: =F15+J15 | V15: =O15-U15 | W15: =O15-(P15+R15) | X15: =O15-(P15+Q15+R15)
A16: EJ010223.TXT | B16: 000991 | C16: 000623 | D16: 44942 | E16: 17:44 | F16: 241.67 | J16: 48.33 | O16: 290 | Q16: 290 | S16: =F16*20% | T16: =J16-S16 | U16: =F16+J16 | V16: =O16-U16 | W16: =O16-(P16+R16) | X16: =O16-(P16+Q16+R16)
A17: EJ010223.TXT | B17: 000992 | C17: 000624 | D17: 44942 | E17: 17:44 | F17: 241.67 | J17: 48.33 | O17: 290 | Q17: 290 | S17: =F17*20% | T17: =J17-S17 | U17: =F17+J17 | V17: =O17-U17 | W17: =O17-(P17+R17) | X17: =O17-(P17+Q17+R17)
A18: EJ010223.TXT | B18: 000993 | C18: 000625 | D18: 44942 | E18: 17:44 | F18: 241.67 | J18: 48.33 | O18: 290 | Q18: 290 | S18: =F18*20% | T18: =J18-S18 | U18: =F18+J18 | V18: =O18-U18 | W18: =O18-(P18+R18) | X18: =O18-(P18+Q18+R18)
A19: EJ010223.TXT | B19: 000994 | C19: 000626 | D19: 44943 | E19: 10:05 | F19: 747.5 | J19: 149.5 | O19: 897 | P19: 897 | S19: =F19*20% | T19: =J19-S19 | U19: =F19+J19 | V19: =O19-U19 | W19: =O19-(P19+R19) | X19: =O19-(P19+Q19+R19)
A20: EJ010223.TXT | B20: 000995 | C20: 000627 | D20: 44943 | E20: 11:17 | F20: 115.83 | J20: 23.17 | O20: 139 | P20: 139 | S20: =F20*20% | T20: =J20-S20 | U20: =F20+J20 | V20: =O20-U20 | W20: =O20-(P20+R20) | X20: =O20-(P20+Q20+R20)
A21: EJ010223.TXT | B21: 000996 | C21: 000628 | D21: 44943 | E21: 11:23 | F21: 2900 | J21: 580 | O21: 3480 | P21: 3480 | S21: =F21*20% | T21: =J21-S21 | U21: =F21+J21 | V21: =O21-U21 | W21: =O21-(P21+R21) | X21: =O21-(P21+Q21+R21)
A22: EJ010223.TXT | B22: 000997 | C22: 000629 | D22: 44943 | E22: 12:30 | F22: 144.17 | J22: 28.83 | O22: 173 | P22: 173 | S22: =F22*20% | T22: =J22-S22 | U22: =F22+J22 | V22: =O22-U22 | W22: =O22-(P22+R22) | X22: =O22-(P22+Q22+R22)
A23: EJ010223.TXT | B23: 000998 | C23: 000630 | D23: 44943 | E23: 13:47 | F23: 498.33 | J23: 99.67 | O23: 598 | Q23: 598 | S23: =F23*20% | T23: =J23-S23 | U23: =F23+J23 | V23: =O23-U23 | W23: =O23-(P23+R23) | X23: =O23-(P23+Q23+R23)
A24: EJ010223.TXT | B24: 000999 | C24: 000631 | D24: 44944 | E24: 12:59 | F24: 149 | J24: 29.8 | O24: 178.8 | P24: 178.8 | S24: =F24*20% | T24: =J24-S24 | U24: =F24+J24 | V24: =O24-U24 | W24: =O24-(P24+R24) | X24: =O24-(P24+Q24+R24)
A25: EJ010223.TXT | B25: 001000 | C25: 000632 | D25: 44944 | E25: 17:24 | F25: 73.33 | J25: 14.67 | O25: 88 | P25: 88 | S25: =F25*20% | T25: =J25-S25 | U25: =F25+J25 | V25: =O25-U25 | W25: =O25-(P25+R25) | X25: =O25-(P25+Q25+R25)
A26: EJ010223.TXT | B26: 001001 | C26: 000633 | D26: 44945 | E26: 12:34 | F26: 498.33 | J26: 99.67 | O26: 598 | Q26: 598 | S26: =F26*20% | T26: =J26-S26 | U26: =F26+J26 | V26: =O26-U26 | W26: =O26-(P26+R26) | X26: =O26-(P26+Q26+R26)
A27: EJ010223.TXT | B27: 001002 | C27: 000634 | D27: 44947 | E27: 14:43 | F27: 498.33 | J27: 99.67 | O27: 598 | P27: 598 | S27: =F27*20% | T27: =J27-S27 | U27: =F27+J27 | V27: =O27-U27 | W27: =O27-(P27+R27) | X27: =O27-(P27+Q27+R27)
A28: EJ010223.TXT | B28: 001003 | C28: 000635 | D28: 44951 | E28: 09:58 | F28: 249.17 | J28: 49.83 | O28: 299 | Q28: 299 | S28: =F28*20% | T28: =J28-S28 | U28: =F28+J28 | V28: =O28-U28 | W28: =O28-(P28+R28) | X28: =O28-(P28+Q28+R28)
A29: EJ010223.TXT | B29: 001004 | C29: 000636 | D29: 44951 | E29: 16:08 | F29: 498.33 | J29: 99.67 | O29: 598 | P29: 598 | S29: =F29*20% | T29: =J29-S29 | U29: =F29+J29 | V29: =O29-U29 | W29: =O29-(P29+R29) | X29: =O29-(P29+Q29+R29)
A30: EJ010223.TXT | B30: 001005 | C30: 000637 | D30: 44951 | E30: 16:46 | F30: 498.33 | J30: 99.67 | O30: 598 | Q30: 598 | S30: =F30*20% | T30: =J30-S30 | U30: =F30+J30 | V30: =O30-U30 | W30: =O30-(P30+R30) | X30: =O30-(P30+Q30+R30)
A31: EJ010223.TXT | B31: 001006 | C31: 000638 | D31: 44952 | E31: 16:05 | F31: 498.33 | J31: 99.67 | O31: 598 | Q31: 598 | S31: =F31*20% | T31: =J31-S31 | U31: =F31+J31 | V31: =O31-U31 | W31: =O31-(P31+R31) | X31: =O31-(P31+Q31+R31)
A32: EJ010223.TXT | B32: 001007 | C32: 000639 | D32: 44953 | E32: 13:19 | F32: 498.33 | J32: 99.67 | O32: 598 | P32: 598 | S32: =F32*20% | T32: =J32-S32 | U32: =F32+J32 | V32: =O32-U32 | W32: =O32-(P32+R32) | X32: =O32-(P32+Q32+R32)
A33: EJ010223.TXT | B33: 001008 | C33: 000640 | D33: 44953 | E33: 17:19 | F33: 498.33 | J33: 99.67 | O33: 598 | P33: 598 | S33: =F33*20% | T33: =J33-S33 | U33: =F33+J33 | V33: =O33-U33 | W33: =O33-(P33+R33) | X33: =O33-(P33+Q33+R33)
A34: EJ010323.TXT | B34: 001015 | C34: 000641 | D34: 44958 | E34: 15:26 | F34: 24.83 | J34: 4.97 | O34: 29.8 | Q34: 29.8 | S34: =F34*20% | T34: =J34-S34 | U34: =F34+J34 | V34: =O34-U34 | W34: =O34-(P34+R34) | X34: =O34-(P34+Q34+R34)
A35: EJ010323.TXT | B35: 001017 | C35: 000642 | D35: 44959 | E35: 12:55 | F35: 274.17 | J35: 54.83 | O35: 329 | P35: 329 | S35: =F35*20% | T35: =J35-S35 | U35: =F35+J35 | V35: =O35-U35 | W35: =O35-(P35+R35) | X35: =O35-(P35+Q35+R35)
A36: EJ010323.TXT | B36: 001020 | C36: 000643 | D36: 44959 | E36: 14:04 | F36: 274.17 | J36: 54.83 | O36: 329 | Q36: 329 | S36: =F36*20% | T36: =J36-S36 | U36: =F36+J36 | V36: =O36-U36 | W36: =O36-(P36+R36) | X36: =O36-(P36+Q36+R36)
A37: EJ010323.TXT | B37: 001021 | C37: 000644 | D37: 44961 | E37: 15:31 | F37: 548.33 | J37: 109.67 | O37: 658 | Q37: 658 | S37: =F37*20% | T37: =J37-S37 | U37: =F37+J37 | V37: =O37-U37 | W37: =O37-(P37+R37) | X37: =O37-(P37+Q37+R37)
A38: EJ010323.TXT | B38: 001022 | C38: 000645 | D38: 44961 | E38: 15:34 | F38: 548.33 | J38: 109.67 | O38: 658 | P38: 658 | S38: =F38*20% | T38: =J38-S38 | U38: =F38+J38 | V38: =O38-U38 | W38: =O38-(P38+R38) | X38: =O38-(P38+Q38+R38)
A39: EJ010323.TXT | B39: 001023 | C39: 000646 | D39: 44961 | E39: 16:26 | F39: 822.5 | J39: 164.5 | O39: 987 | Q39: 987 | S39: =F39*20% | T39: =J39-S39 | U39: =F39+J39 | V39: =O39-U39 | W39: =O39-(P39+R39) | X39: =O39-(P39+Q39+R39)
A40: EJ010323.TXT | B40: 001024 | C40: 000647 | D40: 44961 | E40: 16:35 | F40: 548.33 | J40: 109.67 | O40: 658 | P40: 658 | S40: =F40*20% | T40: =J40-S40 | U40: =F40+J40 | V40: =O40-U40 | W40: =O40-(P40+R40) | X40: =O40-(P40+Q40+R40)
...

Sheet Entetes_sequentialite
A1: nomfichier | B1: E_NUM_INTERNE | C1: E_NUM_TICKET | D1: E_DATE_TICKET | E1: E_HEURE_TICKET | F1: AJ_TROU_NUM_TICKET | G1: AJ_TROU_NUM_INTERNE | H1: OBSERVATION
A2: EJ010223.TXT | B2: 000977 | C2: 000609 | D2: 44930 | E2: 12:01 | F2: ="" | G2: ="" | H2: ="Premier enregistrement"
A3: EJ010223.TXT | B3: 000978 | C3: 000610 | D3: 44932 | E3: 11:30 | F3: =C3-C2 | G3: =B3-B2 | H3: =IF(AND(F3=1,G3=1),"OK","À JUSTIFIER")
A4: EJ010223.TXT | B4: 000979 | C4: 000611 | D4: 44932 | E4: 13:38 | F4: =C4-C3 | G4: =B4-B3 | H4: =IF(AND(F4=1,G4=1),"OK","À JUSTIFIER")
A5: EJ010223.TXT | B5: 000980 | C5: 000612 | D5: 44932 | E5: 13:38 | F5: =C5-C4 | G5: =B5-B4 | H5: =IF(AND(F5=1,G5=1),"OK","À JUSTIFIER")
A6: EJ010223.TXT | B6: 000981 | C6: 000613 | D6: 44932 | E6: 13:58 | F6: =C6-C5 | G6: =B6-B5 | H6: =IF(AND(F6=1,G6=1),"OK","À JUSTIFIER")
A7: EJ010223.TXT | B7: 000982 | C7: 000614 | D7: 44932 | E7: 13:59 | F7: =C7-C6 | G7: =B7-B6 | H7: =IF(AND(F7=1,G7=1),"OK","À JUSTIFIER")
A8: EJ010223.TXT | B8: 000983 | C8: 000615 | D8: 44937 | E8: 12:38 | F8: =C8-C7 | G8: =B8-B7 | H8: =IF(AND(F8=1,G8=1),"OK","À JUSTIFIER")
A9: EJ010223.TXT | B9: 000984 | C9: 000616 | D9: 44937 | E9: 14:46 | F9: =C9-C8 | G9: =B9-B8 | H9: =IF(AND(F9=1,G9=1),"OK","À JUSTIFIER")
A10: EJ010223.TXT | B10: 000985 | C10: 000617 | D10: 44939 | E10: 10:27 | F10: =C10-C9 | G10: =B10-B9 | H10: =IF(AND(F10=1,G10=1),"OK","À JUSTIFIER")
A11: EJ010223.TXT | B11: 000986 | C11: 000618 | D11: 44939 | E11: 10:48 | F11: =C11-C10 | G11: =B11-B10 | H11: =IF(AND(F11=1,G11=1),"OK","À JUSTIFIER")
A12: EJ010223.TXT | B12: 000987 | C12: 000619 | D12: 44939 | E12: 13:05 | F12: =C12-C11 | G12: =B12-B11 | H12: =IF(AND(F12=1,G12=1),"OK","À JUSTIFIER")
A13: EJ010223.TXT | B13: 000988 | C13: 000620 | D13: 44940 | E13: 16:39 | F13: =C13-C12 | G13: =B13-B12 | H13: =IF(AND(F13=1,G13=1),"OK","À JUSTIFIER")
A14: EJ010223.TXT | B14: 000989 | C14: 000621 | D14: 44940 | E14: 16:53 | F14: =C14-C13 | G14: =B14-B13 | H14: =IF(AND(F14=1,G14=1),"OK","À JUSTIFIER")
... A723: EJ010925.TXT | B723: 002113 | C723: 001330 | D723: 45898 | E723: 15:06 | F723: =C723-C722 | G723: =B723-B722 | H723: =IF(AND(F723=1,G723=1),"OK","À JUSTIFIER")

Sheet TD_OccurenceNumInterne
A1: E_NUM_INTERNE | B1: COMPTER_E_NUM_INTERNE
A2: 000977 | B2: =COUNTIF('Entetes_TriNumInterne'!$B$2:$B$723,A2)
A3: 000978 | B3: =COUNTIF('Entetes_TriNumInterne'!$B$2:$B$723,A3)
A4: 000979 | B4: =COUNTIF('Entetes_TriNumInterne'!$B$2:$B$723,A4)
A5: 000980 | B5: =COUNTIF('Entetes_TriNumInterne'!$B$2:$B$723,A5)
A6: 000981 | B6: =COUNTIF('Entetes_TriNumInterne'!$B$2:$B$723,A6)
A7: 000982 | B7: =COUNTIF('Entetes_TriNumInterne'!$B$2:$B$723,A7)
A8: 000983 | B8: =COUNTIF('Entetes_TriNumInterne'!$B$2:$B$723,A8)
A9: 000984 | B9: =COUNTIF('Entetes_TriNumInterne'!$B$2:$B$723,A9)
A10: 000985 | B10: =COUNTIF('Entetes_TriNumInterne'!$B$2:$B$723,A10)
A11: 000986 | B11: =COUNTIF('Entetes_TriNumInterne'!$B$2:$B$723,A11)
A12: 000987 | B12: =COUNTIF('Entetes_TriNumInterne'!$B$2:$B$723,A12)
A13: 000988 | B13: =COUNTIF('Entetes_TriNumInterne'!$B$2:$B$723,A13)
... A723: 002113 | B723: =COUNTIF('Entetes_TriNumInterne'!$B$2:$B$723,A723)

Sheet DoublonNumInterne
A1: E_NUM_INTERNE | B1: COMPTER_E_NUM_INTERNE
A2: AUCUN | B2: 0

Sheet TD_OccurenceNumTicket
A1: E_NUM_TICKET | B1: COMPTER_E_NUM_TICKET
A2: 000609 | B2: =COUNTIF('Entetes_TriNumInterne'!$C$2:$C$723,A2)
A3: 000610 | B3: =COUNTIF('Entetes_TriNumInterne'!$C$2:$C$723,A3)
A4: 000611 | B4: =COUNTIF('Entetes_TriNumInterne'!$C$2:$C$723,A4)
A5: 000612 | B5: =COUNTIF('Entetes_TriNumInterne'!$C$2:$C$723,A5)
A6: 000613 | B6: =COUNTIF('Entetes_TriNumInterne'!$C$2:$C$723,A6)
A7: 000614 | B7: =COUNTIF('Entetes_TriNumInterne'!$C$2:$C$723,A7)
A8: 000615 | B8: =COUNTIF('Entetes_TriNumInterne'!$C$2:$C$723,A8)
A9: 000616 | B9: =COUNTIF('Entetes_TriNumInterne'!$C$2:$C$723,A9)
A10: 000617 | B10: =COUNTIF('Entetes_TriNumInterne'!$C$2:$C$723,A10)
A11: 000618 | B11: =COUNTIF('Entetes_TriNumInterne'!$C$2:$C$723,A11)
A12: 000619 | B12: =COUNTIF('Entetes_TriNumInterne'!$C$2:$C$723,A12)
A13: 000620 | B13: =COUNTIF('Entetes_TriNumInterne'!$C$2:$C$723,A13)
... A723: 001330 | B723: =COUNTIF('Entetes_TriNumInterne'!$C$2:$C$723,A723)

Sheet DoublonNumTicket
A1: E_NUM_TICKET | B1: COMPTER_E_NUM_TICKET
A2: AUCUN | B2: 0

Sheet Entetes_CplteAnneeMois
A1: nomfichier | B1: E_NUM_INTERNE | C1: E_NUM_TICKET | D1: E_DATE_TICKET | E1: E_HEURE_TICKET | F1: E_HT1 | G1: E_HT2 | H1: E_HT3 | I1: E_HT4 | J1: E_TVA1 | K1: E_TVA2 | L1: E_TVA3 | M1: E_TVA4 | N1: E_HT_NON_TAXABLE | O1: E_TTC | P1: E_MDP_CB | Q1: E_MDP_ESPECES | R1: E_MDP_CHEQUES | S1: AJ_TOTAL_HT | T1: AJ_TOTAL_TVA_20 | U1: AJ_ANNEE | V1: AJ_MOIS
A2: EJ010223.TXT | B2: 000977 | C2: 000609 | D2: 44930 | E2: 12:01 | F2: 747.5 | J2: 149.5 | O2: 897 | Q2: 897 | S2: =SUM(F2:I2)+N2 | T2: =J2 | U2: =YEAR(D2) | V2: =TEXT(D2,"yyyy-mm")
A3: EJ010223.TXT | B3: 000978 | C3: 000610 | D3: 44932 | E3: 11:30 | F3: 498.33 | J3: 99.67 | O3: 598 | P3: 598 | S3: =SUM(F3:I3)+N3 | T3: =J3 | U3: =YEAR(D3) | V3: =TEXT(D3,"yyyy-mm")
A4: EJ010223.TXT | B4: 000979 | C4: 000611 | D4: 44932 | E4: 13:38 | F4: 483.33 | J4: 96.67 | O4: 580 | P4: 580 | S4: =SUM(F4:I4)+N4 | T4: =J4 | U4: =YEAR(D4) | V4: =TEXT(D4,"yyyy-mm")
A5: EJ010223.TXT | B5: 000980 | C5: 000612 | D5: 44932 | E5: 13:38 | F5: 1450 | J5: 290 | O5: 1740 | P5: 1740 | S5: =SUM(F5:I5)+N5 | T5: =J5 | U5: =YEAR(D5) | V5: =TEXT(D5,"yyyy-mm")
A6: EJ010223.TXT | B6: 000981 | C6: 000613 | D6: 44932 | E6: 13:58 | F6: 1450 | J6: 290 | O6: 1740 | P6: 1740 | S6: =SUM(F6:I6)+N6 | T6: =J6 | U6: =YEAR(D6) | V6: =TEXT(D6,"yyyy-mm")
A7: EJ010223.TXT | B7: 000982 | C7: 000614 | D7: 44932 | E7: 13:59 | F7: 2900 | J7: 580 | O7: 3480 | P7: 3480 | S7: =SUM(F7:I7)+N7 | T7: =J7 | U7: =YEAR(D7) | V7: =TEXT(D7,"yyyy-mm")
A8: EJ010223.TXT | B8: 000983 | C8: 000615 | D8: 44937 | E8: 12:38 | F8: 73.33 | J8: 14.67 | O8: 88 | P8: 88 | S8: =SUM(F8:I8)+N8 | T8: =J8 | U8: =YEAR(D8) | V8: =TEXT(D8,"yyyy-mm")
A9: EJ010223.TXT | B9: 000984 | C9: 000616 | D9: 44937 | E9: 14:46 | F9: 311.5 | J9: 62.3 | O9: 373.8 | P9: 373.8 | S9: =SUM(F9:I9)+N9 | T9: =J9 | U9: =YEAR(D9) | V9: =TEXT(D9,"yyyy-mm")
A10: EJ010223.TXT | B10: 000985 | C10: 000617 | D10: 44939 | E10: 10:27 | F10: 249.17 | J10: 49.83 | O10: 299 | P10: 299 | S10: =SUM(F10:I10)+N10 | T10: =J10 | U10: =YEAR(D10) | V10: =TEXT(D10,"yyyy-mm")
A11: EJ010223.TXT | B11: 000986 | C11: 000618 | D11: 44939 | E11: 10:48 | F11: 146.67 | J11: 29.33 | O11: 176 | P11: 176 | S11: =SUM(F11:I11)+N11 | T11: =J11 | U11: =YEAR(D11) | V11: =TEXT(D11,"yyyy-mm")
A12: EJ010223.TXT | B12: 000987 | C12: 000619 | D12: 44939 | E12: 13:05 | F12: 498.33 | J12: 99.67 | O12: 598 | P12: 598 | S12: =SUM(F12:I12)+N12 | T12: =J12 | U12: =YEAR(D12) | V12: =TEXT(D12,"yyyy-mm")
A13: EJ010223.TXT | B13: 000988 | C13: 000620 | D13: 44940 | E13: 16:39 | F13: 498.33 | J13: 99.67 | O13: 598 | P13: 598 | S13: =SUM(F13:I13)+N13 | T13: =J13 | U13: =YEAR(D13) | V13: =TEXT(D13,"yyyy-mm")
A14: EJ010223.TXT | B14: 000989 | C14: 000621 | D14: 44940 | E14: 16:53 | F14: 288.33 | J14: 57.67 | O14: 346 | P14: 346 | S14: =SUM(F14:I14)+N14 | T14: =J14 | U14: =YEAR(D14) | V14: =TEXT(D14,"yyyy-mm")
A15: EJ010223.TXT | B15: 000990 | C15: 000622 | D15: 44942 | E15: 17:36 | F15: 658.33 | J15: 131.67 | O15: 790 | Q15: 790 | S15: =SUM(F15:I15)+N15 | T15: =J15 | U15: =YEAR(D15) | V15: =TEXT(D15,"yyyy-mm")
A16: EJ010223.TXT | B16: 000991 | C16: 000623 | D16: 44942 | E16: 17:44 | F16: 241.67 | J16: 48.33 | O16: 290 | Q16: 290 | S16: =SUM(F16:I16)+N16 | T16: =J16 | U16: =YEAR(D16) | V16: =TEXT(D16,"yyyy-mm")
A17: EJ010223.TXT | B17: 000992 | C17: 000624 | D17: 44942 | E17: 17:44 | F17: 241.67 | J17: 48.33 | O17: 290 | Q17: 290 | S17: =SUM(F17:I17)+N17 | T17: =J17 | U17: =YEAR(D17) | V17: =TEXT(D17,"yyyy-mm")
A18: EJ010223.TXT | B18: 000993 | C18: 000625 | D18: 44942 | E18: 17:44 | F18: 241.67 | J18: 48.33 | O18: 290 | Q18: 290 | S18: =SUM(F18:I18)+N18 | T18: =J18 | U18: =YEAR(D18) | V18: =TEXT(D18,"yyyy-mm")
A19: EJ010223.TXT | B19: 000994 | C19: 000626 | D19: 44943 | E19: 10:05 | F19: 747.5 | J19: 149.5 | O19: 897 | P19: 897 | S19: =SUM(F19:I19)+N19 | T19: =J19 | U19: =YEAR(D19) | V19: =TEXT(D19,"yyyy-mm")
A20: EJ010223.TXT | B20: 000995 | C20: 000627 | D20: 44943 | E20: 11:17 | F20: 115.83 | J20: 23.17 | O20: 139 | P20: 139 | S20: =SUM(F20:I20)+N20 | T20: =J20 | U20: =YEAR(D20) | V20: =TEXT(D20,"yyyy-mm")
A21: EJ010223.TXT | B21: 000996 | C21: 000628 | D21: 44943 | E21: 11:23 | F21: 2900 | J21: 580 | O21: 3480 | P21: 3480 | S21: =SUM(F21:I21)+N21 | T21: =J21 | U21: =YEAR(D21) | V21: =TEXT(D21,"yyyy-mm")
A22: EJ010223.TXT | B22: 000997 | C22: 000629 | D22: 44943 | E22: 12:30 | F22: 144.17 | J22: 28.83 | O22: 173 | P22: 173 | S22: =SUM(F22:I22)+N22 | T22: =J22 | U22: =YEAR(D22) | V22: =TEXT(D22,"yyyy-mm")
A23: EJ010223.TXT | B23: 000998 | C23: 000630 | D23: 44943 | E23: 13:47 | F23: 498.33 | J23: 99.67 | O23: 598 | Q23: 598 | S23: =SUM(F23:I23)+N23 | T23: =J23 | U23: =YEAR(D23) | V23: =TEXT(D23,"yyyy-mm")
A24: EJ010223.TXT | B24: 000999 | C24: 000631 | D24: 44944 | E24: 12:59 | F24: 149 | J24: 29.8 | O24: 178.8 | P24: 178.8 | S24: =SUM(F24:I24)+N24 | T24: =J24 | U24: =YEAR(D24) | V24: =TEXT(D24,"yyyy-mm")
A25: EJ010223.TXT | B25: 001000 | C25: 000632 | D25: 44944 | E25: 17:24 | F25: 73.33 | J25: 14.67 | O25: 88 | P25: 88 | S25: =SUM(F25:I25)+N25 | T25: =J25 | U25: =YEAR(D25) | V25: =TEXT(D25,"yyyy-mm")
A26: EJ010223.TXT | B26: 001001 | C26: 000633 | D26: 44945 | E26: 12:34 | F26: 498.33 | J26: 99.67 | O26: 598 | Q26: 598 | S26: =SUM(F26:I26)+N26 | T26: =J26 | U26: =YEAR(D26) | V26: =TEXT(D26,"yyyy-mm")
A27: EJ010223.TXT | B27: 001002 | C27: 000634 | D27: 44947 | E27: 14:43 | F27: 498.33 | J27: 99.67 | O27: 598 | P27: 598 | S27: =SUM(F27:I27)+N27 | T27: =J27 | U27: =YEAR(D27) | V27: =TEXT(D27,"yyyy-mm")
A28: EJ010223.TXT | B28: 001003 | C28: 000635 | D28: 44951 | E28: 09:58 | F28: 249.17 | J28: 49.83 | O28: 299 | Q28: 299 | S28: =SUM(F28:I28)+N28 | T28: =J28 | U28: =YEAR(D28) | V28: =TEXT(D28,"yyyy-mm")
A29: EJ010223.TXT | B29: 001004 | C29: 000636 | D29: 44951 | E29: 16:08 | F29: 498.33 | J29: 99.67 | O29: 598 | P29: 598 | S29: =SUM(F29:I29)+N29 | T29: =J29 | U29: =YEAR(D29) | V29: =TEXT(D29,"yyyy-mm")
A30: EJ010223.TXT | B30: 001005 | C30: 000637 | D30: 44951 | E30: 16:46 | F30: 498.33 | J30: 99.67 | O30: 598 | Q30: 598 | S30: =SUM(F30:I30)+N30 | T30: =J30 | U30: =YEAR(D30) | V30: =TEXT(D30,"yyyy-mm")
A31: EJ010223.TXT | B31: 001006 | C31: 000638 | D31: 44952 | E31: 16:05 | F31: 498.33 | J31: 99.67 | O31: 598 | Q31: 598 | S31: =SUM(F31:I31)+N31 | T31: =J31 | U31: =YEAR(D31) | V31: =TEXT(D31,"yyyy-mm")
A32: EJ010223.TXT | B32: 001007 | C32: 000639 | D32: 44953 | E32: 13:19 | F32: 498.33 | J32: 99.67 | O32: 598 | P32: 598 | S32: =SUM(F32:I32)+N32 | T32: =J32 | U32: =YEAR(D32) | V32: =TEXT(D32,"yyyy-mm")
A33: EJ010223.TXT | B33: 001008 | C33: 000640 | D33: 44953 | E33: 17:19 | F33: 498.33 | J33: 99.67 | O33: 598 | P33: 598 | S33: =SUM(F33:I33)+N33 | T33: =J33 | U33: =YEAR(D33) | V33: =TEXT(D33,"yyyy-mm")
A34: EJ010323.TXT | B34: 001015 | C34: 000641 | D34: 44958 | E34: 15:26 | F34: 24.83 | J34: 4.97 | O34: 29.8 | Q34: 29.8 | S34: =SUM(F34:I34)+N34 | T34: =J34 | U34: =YEAR(D34) | V34: =TEXT(D34,"yyyy-mm")
A35: EJ010323.TXT | B35: 001017 | C35: 000642 | D35: 44959 | E35: 12:55 | F35: 274.17 | J35: 54.83 | O35: 329 | P35: 329 | S35: =SUM(F35:I35)+N35 | T35: =J35 | U35: =YEAR(D35) | V35: =TEXT(D35,"yyyy-mm")
A36: EJ010323.TXT | B36: 001020 | C36: 000643 | D36: 44959 | E36: 14:04 | F36: 274.17 | J36: 54.83 | O36: 329 | Q36: 329 | S36: =SUM(F36:I36)+N36 | T36: =J36 | U36: =YEAR(D36) | V36: =TEXT(D36,"yyyy-mm")
A37: EJ010323.TXT | B37: 001021 | C37: 000644 | D37: 44961 | E37: 15:31 | F37: 548.33 | J37: 109.67 | O37: 658 | Q37: 658 | S37: =SUM(F37:I37)+N37 | T37: =J37 | U37: =YEAR(D37) | V37: =TEXT(D37,"yyyy-mm")
A38: EJ010323.TXT | B38: 001022 | C38: 000645 | D38: 44961 | E38: 15:34 | F38: 548.33 | J38: 109.67 | O38: 658 | P38: 658 | S38: =SUM(F38:I38)+N38 | T38: =J38 | U38: =YEAR(D38) | V38: =TEXT(D38,"yyyy-mm")
A39: EJ010323.TXT | B39: 001023 | C39: 000646 | D39: 44961 | E39: 16:26 | F39: 822.5 | J39: 164.5 | O39: 987 | Q39: 987 | S39: =SUM(F39:I39)+N39 | T39: =J39 | U39: =YEAR(D39) | V39: =TEXT(D39,"yyyy-mm")
A40: EJ010323.TXT | B40: 001024 | C40: 000647 | D40: 44961 | E40: 16:35 | F40: 548.33 | J40: 109.67 | O40: 658 | P40: 658 | S40: =SUM(F40:I40)+N40 | T40: =J40 | U40: =YEAR(D40) | V40: =TEXT(D40,"yyyy-mm")
...

Sheet TD_TotalEnctTTC
A1: AJ_ANNEE | B1: AJ_MOIS | C1: SOMME_E_TTC | D1: SOMME_E_MDP_CB | E1: SOMME_E_MDP_CHEQUES | F1: SOMME_E_MDP_ESPECES
A2: 2023 | B2: 2023-01 | C2: =SUMIFS('Entetes_CplteAnneeMois'!$O$2:$O$723,'Entetes_CplteAnneeMois'!$V$2:$V$723,B2) | D2: =SUMIFS('Entetes_CplteAnneeMois'!$P$2:$P$723,'Entetes_CplteAnneeMois'!$V$2:$V$723,B2) | E2: =SUMIFS('Entetes_CplteAnneeMois'!$R$2:$R$723,'Entetes_CplteAnneeMois'!$V$2:$V$723,B2) | F2: =SUMIFS('Entetes_CplteAnneeMois'!$Q$2:$Q$723,'Entetes_CplteAnneeMois'!$V$2:$V$723,B2)
A3: 2023 | B3: 2023-02 | C3: =SUMIFS('Entetes_CplteAnneeMois'!$O$2:$O$723,'Entetes_CplteAnneeMois'!$V$2:$V$723,B3) | D3: =SUMIFS('Entetes_CplteAnneeMois'!$P$2:$P$723,'Entetes_CplteAnneeMois'!$V$2:$V$723,B3) | E3: =SUMIFS('Entetes_CplteAnneeMois'!$R$2:$R$723,'Entetes_CplteAnneeMois'!$V$2:$V$723,B3) | F3: =SUMIFS('Entetes_CplteAnneeMois'!$Q$2:$Q$723,'Entetes_CplteAnneeMois'!$V$2:$V$723,B3)
A4: 2023 | B4: 2023-03 | C4: =SUMIFS('Entetes_CplteAnneeMois'!$O$2:$O$723,'Entetes_CplteAnneeMois'!$V$2:$V$723,B4) | D4: =SUMIFS('Entetes_CplteAnneeMois'!$P$2:$P$723,'Entetes_CplteAnneeMois'!$V$2:$V$723,B4) | E4: =SUMIFS('Entetes_CplteAnneeMois'!$R$2:$R$723,'Entetes_CplteAnneeMois'!$V$2:$V$723,B4) | F4: =SUMIFS('Entetes_CplteAnneeMois'!$Q$2:$Q$723,'Entetes_CplteAnneeMois'!$V$2:$V$723,B4)
A5: 2023 | B5: 2023-04 | C5: =SUMIFS('Entetes_CplteAnneeMois'!$O$2:$O$723,'Entetes_CplteAnneeMois'!$V$2:$V$723,B5) | D5: =SUMIFS('Entetes_CplteAnneeMois'!$P$2:$P$723,'Entetes_CplteAnneeMois'!$V$2:$V$723,B5) | E5: =SUMIFS('Entetes_CplteAnneeMois'!$R$2:$R$723,'Entetes_CplteAnneeMois'!$V$2:$V$723,B5) | F5: =SUMIFS('Entetes_CplteAnneeMois'!$Q$2:$Q$723,'Entetes_CplteAnneeMois'!$V$2:$V$723,B5)
A6: 2023 | B6: 2023-05 | C6: =SUMIFS('Entetes_CplteAnneeMois'!$O$2:$O$723,'Entetes_CplteAnneeMois'!$V$2:$V$723,B6) | D6: =SUMIFS('Entetes_CplteAnneeMois'!$P$2:$P$723,'Entetes_CplteAnneeMois'!$V$2:$V$723,B6) | E6: =SUMIFS('Entetes_CplteAnneeMois'!$R$2:$R$723,'Entetes_CplteAnneeMois'!$V$2:$V$723,B6) | F6: =SUMIFS('Entetes_CplteAnneeMois'!$Q$2:$Q$723,'Entetes_CplteAnneeMois'!$V$2:$V$723,B6)
A7: 2023 | B7: 2023-06 | C7: =SUMIFS('Entetes_CplteAnneeMois'!$O$2:$O$723,'Entetes_CplteAnneeMois'!$V$2:$V$723,B7) | D7: =SUMIFS('Entetes_CplteAnneeMois'!$P$2:$P$723,'Entetes_CplteAnneeMois'!$V$2:$V$723,B7) | E7: =SUMIFS('Entetes_CplteAnneeMois'!$R$2:$R$723,'Entetes_CplteAnneeMois'!$V$2:$V$723,B7) | F7: =SUMIFS('Entetes_CplteAnneeMois'!$Q$2:$Q$723,'Entetes_CplteAnneeMois'!$V$2:$V$723,B7)
A8: 2023 | B8: 2023-07 | C8: =SUMIFS('Entetes_CplteAnneeMois'!$O$2:$O$723,'Entetes_CplteAnneeMois'!$V$2:$V$723,B8) | D8: =SUMIFS('Entetes_CplteAnneeMois'!$P$2:$P$723,'Entetes_CplteAnneeMois'!$V$2:$V$723,B8) | E8: =SUMIFS('Entetes_CplteAnneeMois'!$R$2:$R$723,'Entetes_CplteAnneeMois'!$V$2:$V$723,B8) | F8: =SUMIFS('Entetes_CplteAnneeMois'!$Q$2:$Q$723,'Entetes_CplteAnneeMois'!$V$2:$V$723,B8)
A9: 2023 | B9: 2023-08 | C9: =SUMIFS('Entetes_CplteAnneeMois'!$O$2:$O$723,'Entetes_CplteAnneeMois'!$V$2:$V$723,B9) | D9: =SUMIFS('Entetes_CplteAnneeMois'!$P$2:$P$723,'Entetes_CplteAnneeMois'!$V$2:$V$723,B9) | E9: =SUMIFS('Entetes_CplteAnneeMois'!$R$2:$R$723,'Entetes_CplteAnneeMois'!$V$2:$V$723,B9) | F9: =SUMIFS('Entetes_CplteAnneeMois'!$Q$2:$Q$723,'Entetes_CplteAnneeMois'!$V$2:$V$723,B9)
A10: 2023 | B10: 2023-09 | C10: =SUMIFS('Entetes_CplteAnneeMois'!$O$2:$O$723,'Entetes_CplteAnneeMois'!$V$2:$V$723,B10) | D10: =SUMIFS('Entetes_CplteAnneeMois'!$P$2:$P$723,'Entetes_CplteAnneeMois'!$V$2:$V$723,B10) | E10: =SUMIFS('Entetes_CplteAnneeMois'!$R$2:$R$723,'Entetes_CplteAnneeMois'!$V$2:$V$723,B10) | F10: =SUMIFS('Entetes_CplteAnneeMois'!$Q$2:$Q$723,'Entetes_CplteAnneeMois'!$V$2:$V$723,B10)
A11: 2023 | B11: 2023-10 | C11: =SUMIFS('Entetes_CplteAnneeMois'!$O$2:$O$723,'Entetes_CplteAnneeMois'!$V$2:$V$723,B11) | D11: =SUMIFS('Entetes_CplteAnneeMois'!$P$2:$P$723,'Entetes_CplteAnneeMois'!$V$2:$V$723,B11) | E11: =SUMIFS('Entetes_CplteAnneeMois'!$R$2:$R$723,'Entetes_CplteAnneeMois'!$V$2:$V$723,B11) | F11: =SUMIFS('Entetes_CplteAnneeMois'!$Q$2:$Q$723,'Entetes_CplteAnneeMois'!$V$2:$V$723,B11)
A12: 2023 | B12: 2023-11 | C12: =SUMIFS('Entetes_CplteAnneeMois'!$O$2:$O$723,'Entetes_CplteAnneeMois'!$V$2:$V$723,B12) | D12: =SUMIFS('Entetes_CplteAnneeMois'!$P$2:$P$723,'Entetes_CplteAnneeMois'!$V$2:$V$723,B12) | E12: =SUMIFS('Entetes_CplteAnneeMois'!$R$2:$R$723,'Entetes_CplteAnneeMois'!$V$2:$V$723,B12) | F12: =SUMIFS('Entetes_CplteAnneeMois'!$Q$2:$Q$723,'Entetes_CplteAnneeMois'!$V$2:$V$723,B12)
A13: 2023 | B13: 2023-12 | C13: =SUMIFS('Entetes_CplteAnneeMois'!$O$2:$O$723,'Entetes_CplteAnneeMois'!$V$2:$V$723,B13) | D13: =SUMIFS('Entetes_CplteAnneeMois'!$P$2:$P$723,'Entetes_CplteAnneeMois'!$V$2:$V$723,B13) | E13: =SUMIFS('Entetes_CplteAnneeMois'!$R$2:$R$723,'Entetes_CplteAnneeMois'!$V$2:$V$723,B13) | F13: =SUMIFS('Entetes_CplteAnneeMois'!$Q$2:$Q$723,'Entetes_CplteAnneeMois'!$V$2:$V$723,B13)
... A33: 2025 | B33: 2025-08 | C33: =SUMIFS('Entetes_CplteAnneeMois'!$O$2:$O$723,'Entetes_CplteAnneeMois'!$V$2:$V$723,B33) | D33: =SUMIFS('Entetes_CplteAnneeMois'!$P$2:$P$723,'Entetes_CplteAnneeMois'!$V$2:$V$723,B33) | E33: =SUMIFS('Entetes_CplteAnneeMois'!$R$2:$R$723,'Entetes_CplteAnneeMois'!$V$2:$V$723,B33) | F33: =SUMIFS('Entetes_CplteAnneeMois'!$Q$2:$Q$723,'Entetes_CplteAnneeMois'!$V$2:$V$723,B33)

Sheet enct_mensuels_MATURIN
A1: AJ_ANNEE | B1: AJ_MOIS | C1: SOMME_E_TTC | D1: SOMME_E_MDP_CB | E1: SOMME_E_MDP_CHEQUES | F1: SOMME_E_MDP_ESPECES
A2: ='TD_TotalEnctTTC'!A2 | B2: ='TD_TotalEnctTTC'!B2 | C2: ='TD_TotalEnctTTC'!C2 | D2: ='TD_TotalEnctTTC'!D2 | E2: ='TD_TotalEnctTTC'!E2 | F2: ='TD_TotalEnctTTC'!F2
A3: ='TD_TotalEnctTTC'!A3 | B3: ='TD_TotalEnctTTC'!B3 | C3: ='TD_TotalEnctTTC'!C3 | D3: ='TD_TotalEnctTTC'!D3 | E3: ='TD_TotalEnctTTC'!E3 | F3: ='TD_TotalEnctTTC'!F3
A4: ='TD_TotalEnctTTC'!A4 | B4: ='TD_TotalEnctTTC'!B4 | C4: ='TD_TotalEnctTTC'!C4 | D4: ='TD_TotalEnctTTC'!D4 | E4: ='TD_TotalEnctTTC'!E4 | F4: ='TD_TotalEnctTTC'!F4
A5: ='TD_TotalEnctTTC'!A5 | B5: ='TD_TotalEnctTTC'!B5 | C5: ='TD_TotalEnctTTC'!C5 | D5: ='TD_TotalEnctTTC'!D5 | E5: ='TD_TotalEnctTTC'!E5 | F5: ='TD_TotalEnctTTC'!F5
A6: ='TD_TotalEnctTTC'!A6 | B6: ='TD_TotalEnctTTC'!B6 | C6: ='TD_TotalEnctTTC'!C6 | D6: ='TD_TotalEnctTTC'!D6 | E6: ='TD_TotalEnctTTC'!E6 | F6: ='TD_TotalEnctTTC'!F6
A7: ='TD_TotalEnctTTC'!A7 | B7: ='TD_TotalEnctTTC'!B7 | C7: ='TD_TotalEnctTTC'!C7 | D7: ='TD_TotalEnctTTC'!D7 | E7: ='TD_TotalEnctTTC'!E7 | F7: ='TD_TotalEnctTTC'!F7
A8: ='TD_TotalEnctTTC'!A8 | B8: ='TD_TotalEnctTTC'!B8 | C8: ='TD_TotalEnctTTC'!C8 | D8: ='TD_TotalEnctTTC'!D8 | E8: ='TD_TotalEnctTTC'!E8 | F8: ='TD_TotalEnctTTC'!F8
A9: ='TD_TotalEnctTTC'!A9 | B9: ='TD_TotalEnctTTC'!B9 | C9: ='TD_TotalEnctTTC'!C9 | D9: ='TD_TotalEnctTTC'!D9 | E9: ='TD_TotalEnctTTC'!E9 | F9: ='TD_TotalEnctTTC'!F9
A10: ='TD_TotalEnctTTC'!A10 | B10: ='TD_TotalEnctTTC'!B10 | C10: ='TD_TotalEnctTTC'!C10 | D10: ='TD_TotalEnctTTC'!D10 | E10: ='TD_TotalEnctTTC'!E10 | F10: ='TD_TotalEnctTTC'!F10
A11: ='TD_TotalEnctTTC'!A11 | B11: ='TD_TotalEnctTTC'!B11 | C11: ='TD_TotalEnctTTC'!C11 | D11: ='TD_TotalEnctTTC'!D11 | E11: ='TD_TotalEnctTTC'!E11 | F11: ='TD_TotalEnctTTC'!F11
A12: ='TD_TotalEnctTTC'!A12 | B12: ='TD_TotalEnctTTC'!B12 | C12: ='TD_TotalEnctTTC'!C12 | D12: ='TD_TotalEnctTTC'!D12 | E12: ='TD_TotalEnctTTC'!E12 | F12: ='TD_TotalEnctTTC'!F12
A13: ='TD_TotalEnctTTC'!A13 | B13: ='TD_TotalEnctTTC'!B13 | C13: ='TD_TotalEnctTTC'!C13 | D13: ='TD_TotalEnctTTC'!D13 | E13: ='TD_TotalEnctTTC'!E13 | F13: ='TD_TotalEnctTTC'!F13
... A33: ='TD_TotalEnctTTC'!A33 | B33: ='TD_TotalEnctTTC'!B33 | C33: ='TD_TotalEnctTTC'!C33 | D33: ='TD_TotalEnctTTC'!D33 | E33: ='TD_TotalEnctTTC'!E33 | F33: ='TD_TotalEnctTTC'!F33

Sheet TD_TotalHtTvaTtc
A1: AJ_ANNEE | B1: AJ_MOIS | C1: SOMME_AJ_TOTAL_HT | D1: SOMME_AJ_TOTAL_TVA_20 | E1: SOMME_E_TTC
A2: 2023 | B2: 2023-01 | C2: =SUMIFS('Entetes_CplteAnneeMois'!$S$2:$S$723,'Entetes_CplteAnneeMois'!$V$2:$V$723,B2) | D2: =SUMIFS('Entetes_CplteAnneeMois'!$T$2:$T$723,'Entetes_CplteAnneeMois'!$V$2:$V$723,B2) | E2: =SUMIFS('Entetes_CplteAnneeMois'!$O$2:$O$723,'Entetes_CplteAnneeMois'!$V$2:$V$723,B2)
A3: 2023 | B3: 2023-02 | C3: =SUMIFS('Entetes_CplteAnneeMois'!$S$2:$S$723,'Entetes_CplteAnneeMois'!$V$2:$V$723,B3) | D3: =SUMIFS('Entetes_CplteAnneeMois'!$T$2:$T$723,'Entetes_CplteAnneeMois'!$V$2:$V$723,B3) | E3: =SUMIFS('Entetes_CplteAnneeMois'!$O$2:$O$723,'Entetes_CplteAnneeMois'!$V$2:$V$723,B3)
A4: 2023 | B4: 2023-03 | C4: =SUMIFS('Entetes_CplteAnneeMois'!$S$2:$S$723,'Entetes_CplteAnneeMois'!$V$2:$V$723,B4) | D4: =SUMIFS('Entetes_CplteAnneeMois'!$T$2:$T$723,'Entetes_CplteAnneeMois'!$V$2:$V$723,B4) | E4: =SUMIFS('Entetes_CplteAnneeMois'!$O$2:$O$723,'Entetes_CplteAnneeMois'!$V$2:$V$723,B4)
A5: 2023 | B5: 2023-04 | C5: =SUMIFS('Entetes_CplteAnneeMois'!$S$2:$S$723,'Entetes_CplteAnneeMois'!$V$2:$V$723,B5) | D5: =SUMIFS('Entetes_CplteAnneeMois'!$T$2:$T$723,'Entetes_CplteAnneeMois'!$V$2:$V$723,B5) | E5: =SUMIFS('Entetes_CplteAnneeMois'!$O$2:$O$723,'Entetes_CplteAnneeMois'!$V$2:$V$723,B5)
A6: 2023 | B6: 2023-05 | C6: =SUMIFS('Entetes_CplteAnneeMois'!$S$2:$S$723,'Entetes_CplteAnneeMois'!$V$2:$V$723,B6) | D6: =SUMIFS('Entetes_CplteAnneeMois'!$T$2:$T$723,'Entetes_CplteAnneeMois'!$V$2:$V$723,B6) | E6: =SUMIFS('Entetes_CplteAnneeMois'!$O$2:$O$723,'Entetes_CplteAnneeMois'!$V$2:$V$723,B6)
A7: 2023 | B7: 2023-06 | C7: =SUMIFS('Entetes_CplteAnneeMois'!$S$2:$S$723,'Entetes_CplteAnneeMois'!$V$2:$V$723,B7) | D7: =SUMIFS('Entetes_CplteAnneeMois'!$T$2:$T$723,'Entetes_CplteAnneeMois'!$V$2:$V$723,B7) | E7: =SUMIFS('Entetes_CplteAnneeMois'!$O$2:$O$723,'Entetes_CplteAnneeMois'!$V$2:$V$723,B7)
A8: 2023 | B8: 2023-07 | C8: =SUMIFS('Entetes_CplteAnneeMois'!$S$2:$S$723,'Entetes_CplteAnneeMois'!$V$2:$V$723,B8) | D8: =SUMIFS('Entetes_CplteAnneeMois'!$T$2:$T$723,'Entetes_CplteAnneeMois'!$V$2:$V$723,B8) | E8: =SUMIFS('Entetes_CplteAnneeMois'!$O$2:$O$723,'Entetes_CplteAnneeMois'!$V$2:$V$723,B8)
A9: 2023 | B9: 2023-08 | C9: =SUMIFS('Entetes_CplteAnneeMois'!$S$2:$S$723,'Entetes_CplteAnneeMois'!$V$2:$V$723,B9) | D9: =SUMIFS('Entetes_CplteAnneeMois'!$T$2:$T$723,'Entetes_CplteAnneeMois'!$V$2:$V$723,B9) | E9: =SUMIFS('Entetes_CplteAnneeMois'!$O$2:$O$723,'Entetes_CplteAnneeMois'!$V$2:$V$723,B9)
A10: 2023 | B10: 2023-09 | C10: =SUMIFS('Entetes_CplteAnneeMois'!$S$2:$S$723,'Entetes_CplteAnneeMois'!$V$2:$V$723,B10) | D10: =SUMIFS('Entetes_CplteAnneeMois'!$T$2:$T$723,'Entetes_CplteAnneeMois'!$V$2:$V$723,B10) | E10: =SUMIFS('Entetes_CplteAnneeMois'!$O$2:$O$723,'Entetes_CplteAnneeMois'!$V$2:$V$723,B10)
A11: 2023 | B11: 2023-10 | C11: =SUMIFS('Entetes_CplteAnneeMois'!$S$2:$S$723,'Entetes_CplteAnneeMois'!$V$2:$V$723,B11) | D11: =SUMIFS('Entetes_CplteAnneeMois'!$T$2:$T$723,'Entetes_CplteAnneeMois'!$V$2:$V$723,B11) | E11: =SUMIFS('Entetes_CplteAnneeMois'!$O$2:$O$723,'Entetes_CplteAnneeMois'!$V$2:$V$723,B11)
A12: 2023 | B12: 2023-11 | C12: =SUMIFS('Entetes_CplteAnneeMois'!$S$2:$S$723,'Entetes_CplteAnneeMois'!$V$2:$V$723,B12) | D12: =SUMIFS('Entetes_CplteAnneeMois'!$T$2:$T$723,'Entetes_CplteAnneeMois'!$V$2:$V$723,B12) | E12: =SUMIFS('Entetes_CplteAnneeMois'!$O$2:$O$723,'Entetes_CplteAnneeMois'!$V$2:$V$723,B12)
A13: 2023 | B13: 2023-12 | C13: =SUMIFS('Entetes_CplteAnneeMois'!$S$2:$S$723,'Entetes_CplteAnneeMois'!$V$2:$V$723,B13) | D13: =SUMIFS('Entetes_CplteAnneeMois'!$T$2:$T$723,'Entetes_CplteAnneeMois'!$V$2:$V$723,B13) | E13: =SUMIFS('Entetes_CplteAnneeMois'!$O$2:$O$723,'Entetes_CplteAnneeMois'!$V$2:$V$723,B13)
... A33: 2025 | B33: 2025-08 | C33: =SUMIFS('Entetes_CplteAnneeMois'!$S$2:$S$723,'Entetes_CplteAnneeMois'!$V$2:$V$723,B33) | D33: =SUMIFS('Entetes_CplteAnneeMois'!$T$2:$T$723,'Entetes_CplteAnneeMois'!$V$2:$V$723,B33) | E33: =SUMIFS('Entetes_CplteAnneeMois'!$O$2:$O$723,'Entetes_CplteAnneeMois'!$V$2:$V$723,B33)

Sheet recettes_mensuelles_MATURIN
A1: AJ_ANNEE | B1: AJ_MOIS | C1: SOMME_AJ_TOTAL_HT | D1: SOMME_AJ_TOTAL_TVA_20 | E1: SOMME_E_TTC
A2: ='TD_TotalHtTvaTtc'!A2 | B2: ='TD_TotalHtTvaTtc'!B2 | C2: ='TD_TotalHtTvaTtc'!C2 | D2: ='TD_TotalHtTvaTtc'!D2 | E2: ='TD_TotalHtTvaTtc'!E2
A3: ='TD_TotalHtTvaTtc'!A3 | B3: ='TD_TotalHtTvaTtc'!B3 | C3: ='TD_TotalHtTvaTtc'!C3 | D3: ='TD_TotalHtTvaTtc'!D3 | E3: ='TD_TotalHtTvaTtc'!E3
A4: ='TD_TotalHtTvaTtc'!A4 | B4: ='TD_TotalHtTvaTtc'!B4 | C4: ='TD_TotalHtTvaTtc'!C4 | D4: ='TD_TotalHtTvaTtc'!D4 | E4: ='TD_TotalHtTvaTtc'!E4
A5: ='TD_TotalHtTvaTtc'!A5 | B5: ='TD_TotalHtTvaTtc'!B5 | C5: ='TD_TotalHtTvaTtc'!C5 | D5: ='TD_TotalHtTvaTtc'!D5 | E5: ='TD_TotalHtTvaTtc'!E5
A6: ='TD_TotalHtTvaTtc'!A6 | B6: ='TD_TotalHtTvaTtc'!B6 | C6: ='TD_TotalHtTvaTtc'!C6 | D6: ='TD_TotalHtTvaTtc'!D6 | E6: ='TD_TotalHtTvaTtc'!E6
A7: ='TD_TotalHtTvaTtc'!A7 | B7: ='TD_TotalHtTvaTtc'!B7 | C7: ='TD_TotalHtTvaTtc'!C7 | D7: ='TD_TotalHtTvaTtc'!D7 | E7: ='TD_TotalHtTvaTtc'!E7
A8: ='TD_TotalHtTvaTtc'!A8 | B8: ='TD_TotalHtTvaTtc'!B8 | C8: ='TD_TotalHtTvaTtc'!C8 | D8: ='TD_TotalHtTvaTtc'!D8 | E8: ='TD_TotalHtTvaTtc'!E8
A9: ='TD_TotalHtTvaTtc'!A9 | B9: ='TD_TotalHtTvaTtc'!B9 | C9: ='TD_TotalHtTvaTtc'!C9 | D9: ='TD_TotalHtTvaTtc'!D9 | E9: ='TD_TotalHtTvaTtc'!E9
A10: ='TD_TotalHtTvaTtc'!A10 | B10: ='TD_TotalHtTvaTtc'!B10 | C10: ='TD_TotalHtTvaTtc'!C10 | D10: ='TD_TotalHtTvaTtc'!D10 | E10: ='TD_TotalHtTvaTtc'!E10
A11: ='TD_TotalHtTvaTtc'!A11 | B11: ='TD_TotalHtTvaTtc'!B11 | C11: ='TD_TotalHtTvaTtc'!C11 | D11: ='TD_TotalHtTvaTtc'!D11 | E11: ='TD_TotalHtTvaTtc'!E11
A12: ='TD_TotalHtTvaTtc'!A12 | B12: ='TD_TotalHtTvaTtc'!B12 | C12: ='TD_TotalHtTvaTtc'!C12 | D12: ='TD_TotalHtTvaTtc'!D12 | E12: ='TD_TotalHtTvaTtc'!E12
A13: ='TD_TotalHtTvaTtc'!A13 | B13: ='TD_TotalHtTvaTtc'!B13 | C13: ='TD_TotalHtTvaTtc'!C13 | D13: ='TD_TotalHtTvaTtc'!D13 | E13: ='TD_TotalHtTvaTtc'!E13
... A33: ='TD_TotalHtTvaTtc'!A33 | B33: ='TD_TotalHtTvaTtc'!B33 | C33: ='TD_TotalHtTvaTtc'!C33 | D33: ='TD_TotalHtTvaTtc'!D33 | E33: ='TD_TotalHtTvaTtc'!E33
