Workbook

Sheet Z2_2025_MASSENA_0
A1: nomfichier | B1: E_MODELE | C1: E_MACHINE | D1: E_RAPPORT | E1: E_FICHIER | F1: E_MODE | G1: E_COMPTEUR_Z | H1: E_DATE | I1: E_HEURE | J1: D_ENREGISTREMENT | K1: D_DESIGNATION | L1: D_QUANTITE | M1: D_MONTANT
A2: Z002_31B_072025_MASSENA.CSV | C2: MC#01 | D2: TRANSACTION | E2: FILE002 | F2: Z | G2: 0020 | H2: 45869 | I2: 18:40 | J2: 0001 | K2: ESPECES | L2: 402 | M2: 221991.1
A3: Z002_31B_072025_MASSENA.CSV | C3: MC#01 | D3: TRANSACTION | E3: FILE002 | F3: Z | G3: 0020 | H3: 45869 | I3: 18:40 | J3: 0002 | K3: SOUS-TOTAL | L3: 0 | M3: 0
A4: Z002_31B_072025_MASSENA.CSV | C4: MC#01 | D4: TRANSACTION | E4: FILE002 | F4: Z | G4: 0020 | H4: 45869 | I4: 18:40 | J4: 0003 | K4: CARTES | L4: 150 | M4: 108512.5
A5: Z002_31B_072025_MASSENA.CSV | C5: MC#01 | D5: TRANSACTION | E5: FILE002 | F5: Z | G5: 0020 | H5: 45869 | I5: 18:40 | J5: 0004 | K5: CHEQUES | L5: 0 | M5: 0
A6: Z002_31B_072025_MASSENA.CSV | C6: MC#01 | D6: TRANSACTION | E6: FILE002 | F6: Z | G6: 0020 | H6: 45869 | I6: 18:40 | J6: 0005 | K6: AIDE | L6: 0 | M6: 0
A7: Z002_31B_072025_MASSENA.CSV | C7: MC#01 | D7: TRANSACTION | E7: FILE002 | F7: Z | G7: 0020 | H7: 45869 | I7: 18:40 | J7: 0006 | K7: TAX PGM | L7: 0 | M7: 0
A8: Z002_31B_072025_MASSENA.CSV | C8: MC#01 | D8: TRANSACTION | E8: FILE002 | F8: Z | G8: 0020 | H8: 45869 | I8: 18:40 | J8: 0007 | K8: SORTIECAISSE | L8: 0 | M8: 0
A9: Z002_31B_072025_MASSENA.CSV | C9: MC#01 | D9: TRANSACTION | E9: FILE002 | F9: Z | G9: 0020 | H9: 45869 | I9: 18:40 | J9: 0008 | K9: REC&ACCOMPTE | L9: 0 | M9: 0
A10: Z002_31B_072025_MASSENA.CSV | C10: MC#01 | D10: TRANSACTION | E10: FILE002 | F10: Z | G10: 0020 | H10: 45869 | I10: 18:40 | J10: 0009 | K10: SIGN-OFF | L10: 0 | M10: 0
A11: Z002_31B_072025_MASSENA.CSV | C11: MC#01 | D11: TRANSACTION | E11: FILE002 | F11: Z | G11: 0020 | H11: 45869 | I11: 18:40 | J11: 0010 | K11: NUM CAISSIER | L11: 0 | M11: 0
A12: Z002_31B_072025_MASSENA.CSV | C12: MC#01 | D12: TRANSACTION | E12: FILE002 | F12: Z | G12: 0020 | H12: 45869 | I12: 18:40 | J12: 0011 | K12: SHIFT/No | L12: 0 | M12: 0
A13: Z002_31B_072025_MASSENA.CSV | C13: MC#01 | D13: TRANSACTION | E13: FILE002 | F13: Z | G13: 0020 | H13: 45869 | I13: 18:40 | J13: 0012 | K13: DWN | L13: 0 | M13: 0
... A33: Z002_31B_072025_MASSENA.CSV | C33: MC#01 | D33: TRANSACTION | E33: FILE002 | F33: Z | G33: 0020 | H33: 45869 | I33: 18:40 | J33: 0032 | K33: ANNULATION | L33: 0 | M33: 0
A34: Z002_31B_072025_MASSENA.CSV | C34: MC#01 | D34: TRANSACTION | E34: FILE002 | F34: Z | G34: 0020 | H34: 45869 | I34: 18:40 | J34: 0033 | L34: 0 | M34: 0
A35: Z002_31B_072025_MASSENA.CSV | C35: MC#01 | D35: TRANSACTION | E35: FILE002 | F35: Z | G35: 0020 | H35: 45869 | I35: 18:40 | J35: 0034 | L35: 0 | M35: 0
A36: Z002_31B_072025_MASSENA.CSV | C36: MC#01 | D36: TRANSACTION | E36: FILE002 | F36: Z | G36: 0020 | H36: 45869 | I36: 18:40 | J36: 0035 | L36: 0 | M36: 0
A37: Z002_31B_072025_MASSENA.CSV | C37: MC#01 | D37: TRANSACTION | E37: FILE002 | F37: Z | G37: 0020 | H37: 45869 | I37: 18:40 | J37: 0036 | L37: 0 | M37: 0
A38: Z002_31B_072025_MASSENA.CSV | C38: MC#01 | D38: TRANSACTION | E38: FILE002 | F38: Z | G38: 0020 | H38: 45869 | I38: 18:40 | J38: 0037 | L38: 0 | M38: 0
A39: Z002_31B_072025_MASSENA.CSV | C39: MC#01 | D39: TRANSACTION | E39: FILE002 | F39: Z | G39: 0020 | H39: 45869 | I39: 18:40 | J39: 0038 | L39: 0 | M39: 0
A40: Z002_31B_072025_MASSENA.CSV | C40: MC#01 | D40: TRANSACTION | E40: FILE002 | F40: Z | G40: 0020 | H40: 45869 | I40: 18:40 | J40: 0039 | L40: 0 | M40: 0
A41: Z002_31B_072025_MASSENA.CSV | C41: MC#01 | D41: TRANSACTION | E41: FILE002 | F41: Z | G41: 0020 | H41: 45869 | I41: 18:40 | J41: 0040 | L41: 0 | M41: 0
A42: Z002_31B_072025_MASSENA.CSV | C42: MC#01 | D42: TRANSACTION | E42: FILE002 | F42: Z | G42: 0020 | H42: 45869 | I42: 18:40 | J42: 0041 | L42: 0 | M42: 0
A43: Z002_31B_072025_MASSENA.CSV | C43: MC#01 | D43: TRANSACTION | E43: FILE002 | F43: Z | G43: 0020 | H43: 45869 | I43: 18:40 | J43: 0042 | L43: 0 | M43: 0
A44: Z002_31B_072025_MASSENA.CSV | C44: MC#01 | D44: TRANSACTION | E44: FILE002 | F44: Z | G44: 0020 | H44: 45869 | I44: 18:40 | J44: 0043 | L44: 0 | M44: 0
A45: Z002_31B_072025_MASSENA.CSV | C45: MC#01 | D45: TRANSACTION | E45: FILE002 | F45: Z | G45: 0020 | H45: 45869 | I45: 18:40 | J45: 0044 | L45: 0 | M45: 0
... A51: Z002_31B_072025_MASSENA.CSV | C51: MC#01 | D51: TRANSACTION | E51: FILE002 | F51: Z | G51: 0020 | H51: 45869 | I51: 18:40 | J51: 0050 | L51: 0 | M51: 0
A52: Z102_01_022025_MASSENA.CSV | C52: MC#01 | D52: TRANSACTION | E52: FILE102 | F52: ZZ1 | G52: 0086 | H52: 45717 | I52: 15:41 | J52: 0001 | K52: ESPECES | L52: 16 | M52: 10332.8
A53: Z102_01_022025_MASSENA.CSV | C53: MC#01 | D53: TRANSACTION | E53: FILE102 | F53: ZZ1 | G53: 0086 | H53: 45717 | I53: 15:41 | J53: 0002 | K53: SOUS-TOTAL | L53: 0 | M53: 0
A54: Z102_01_022025_MASSENA.CSV | C54: MC#01 | D54: TRANSACTION | E54: FILE102 | F54: ZZ1 | G54: 0086 | H54: 45717 | I54: 15:41 | J54: 0003 | K54: CARTES | L54: 7 | M54: 7497
A55: Z102_01_022025_MASSENA.CSV | C55: MC#01 | D55: TRANSACTION | E55: FILE102 | F55: ZZ1 | G55: 0086 | H55: 45717 | I55: 15:41 | J55: 0004 | K55: CHEQUES | L55: 0 | M55: 0
A56: Z102_01_022025_MASSENA.CSV | C56: MC#01 | D56: TRANSACTION | E56: FILE102 | F56: ZZ1 | G56: 0086 | H56: 45717 | I56: 15:41 | J56: 0005 | K56: AIDE | L56: 0 | M56: 0
A57: Z102_01_022025_MASSENA.CSV | C57: MC#01 | D57: TRANSACTION | E57: FILE102 | F57: ZZ1 | G57: 0086 | H57: 45717 | I57: 15:41 | J57: 0006 | K57: TAX PGM | L57: 0 | M57: 0
A58: Z102_01_022025_MASSENA.CSV | C58: MC#01 | D58: TRANSACTION | E58: FILE102 | F58: ZZ1 | G58: 0086 | H58: 45717 | I58: 15:41 | J58: 0007 | K58: SORTIECAISSE | L58: 0 | M58: 0
A59: Z102_01_022025_MASSENA.CSV | C59: MC#01 | D59: TRANSACTION | E59: FILE102 | F59: ZZ1 | G59: 0086 | H59: 45717 | I59: 15:41 | J59: 0008 | K59: REC&ACCOMPTE | L59: 0 | M59: 0
A60: Z102_01_022025_MASSENA.CSV | C60: MC#01 | D60: TRANSACTION | E60: FILE102 | F60: ZZ1 | G60: 0086 | H60: 45717 | I60: 15:41 | J60: 0009 | K60: SIGN-OFF | L60: 0 | M60: 0
A61: Z102_01_022025_MASSENA.CSV | C61: MC#01 | D61: TRANSACTION | E61: FILE102 | F61: ZZ1 | G61: 0086 | H61: 45717 | I61: 15:41 | J61: 0010 | K61: NUM CAISSIER | L61: 0 | M61: 0
A62: Z102_01_022025_MASSENA.CSV | C62: MC#01 | D62: TRANSACTION | E62: FILE102 | F62: ZZ1 | G62: 0086 | H62: 45717 | I62: 15:41 | J62: 0011 | K62: SHIFT/No | L62: 0 | M62: 0
A63: Z102_01_022025_MASSENA.CSV | C63: MC#01 | D63: TRANSACTION | E63: FILE102 | F63: ZZ1 | G63: 0086 | H63: 45717 | I63: 15:41 | J63: 0012 | K63: DWN | L63: 0 | M63: 0
... A83: Z102_01_022025_MASSENA.CSV | C83: MC#01 | D83: TRANSACTION | E83: FILE102 | F83: ZZ1 | G83: 0086 | H83: 45717 | I83: 15:41 | J83: 0032 | K83: ANNULATION | L83: 0 | M83: 0
...

Sheet Z2_CplteAnneeMois
A1: nomfichier | B1: E_MODELE | C1: E_MACHINE | D1: E_RAPPORT | E1: E_FICHIER | F1: E_MODE | G1: E_COMPTEUR_Z | H1: E_DATE | I1: E_HEURE | J1: D_ENREGISTREMENT | K1: D_DESIGNATION | L1: D_QUANTITE | M1: D_MONTANT | N1: AJ_ANNEE_Z | O1: AJ_MOIS_Z
A2: Z002_31B_072025_MASSENA.CSV | C2: MC#01 | D2: TRANSACTION | E2: FILE002 | F2: Z | G2: 0020 | H2: 45869 | I2: 18:40 | J2: 0001 | K2: ESPECES | L2: 402 | M2: 221991.1 | N2: 2025 | O2: 2025-07
A3: Z002_31B_072025_MASSENA.CSV | C3: MC#01 | D3: TRANSACTION | E3: FILE002 | F3: Z | G3: 0020 | H3: 45869 | I3: 18:40 | J3: 0002 | K3: SOUS-TOTAL | L3: 0 | M3: 0 | N3: 2025 | O3: 2025-07
A4: Z002_31B_072025_MASSENA.CSV | C4: MC#01 | D4: TRANSACTION | E4: FILE002 | F4: Z | G4: 0020 | H4: 45869 | I4: 18:40 | J4: 0003 | K4: CARTES | L4: 150 | M4: 108512.5 | N4: 2025 | O4: 2025-07
A5: Z002_31B_072025_MASSENA.CSV | C5: MC#01 | D5: TRANSACTION | E5: FILE002 | F5: Z | G5: 0020 | H5: 45869 | I5: 18:40 | J5: 0004 | K5: CHEQUES | L5: 0 | M5: 0 | N5: 2025 | O5: 2025-07
A6: Z002_31B_072025_MASSENA.CSV | C6: MC#01 | D6: TRANSACTION | E6: FILE002 | F6: Z | G6: 0020 | H6: 45869 | I6: 18:40 | J6: 0005 | K6: AIDE | L6: 0 | M6: 0 | N6: 2025 | O6: 2025-07
A7: Z002_31B_072025_MASSENA.CSV | C7: MC#01 | D7: TRANSACTION | E7: FILE002 | F7: Z | G7: 0020 | H7: 45869 | I7: 18:40 | J7: 0006 | K7: TAX PGM | L7: 0 | M7: 0 | N7: 2025 | O7: 2025-07
A8: Z002_31B_072025_MASSENA.CSV | C8: MC#01 | D8: TRANSACTION | E8: FILE002 | F8: Z | G8: 0020 | H8: 45869 | I8: 18:40 | J8: 0007 | K8: SORTIECAISSE | L8: 0 | M8: 0 | N8: 2025 | O8: 2025-07
A9: Z002_31B_072025_MASSENA.CSV | C9: MC#01 | D9: TRANSACTION | E9: FILE002 | F9: Z | G9: 0020 | H9: 45869 | I9: 18:40 | J9: 0008 | K9: REC&ACCOMPTE | L9: 0 | M9: 0 | N9: 2025 | O9: 2025-07
A10: Z002_31B_072025_MASSENA.CSV | C10: MC#01 | D10: TRANSACTION | E10: FILE002 | F10: Z | G10: 0020 | H10: 45869 | I10: 18:40 | J10: 0009 | K10: SIGN-OFF | L10: 0 | M10: 0 | N10: 2025 | O10: 2025-07
A11: Z002_31B_072025_MASSENA.CSV | C11: MC#01 | D11: TRANSACTION | E11: FILE002 | F11: Z | G11: 0020 | H11: 45869 | I11: 18:40 | J11: 0010 | K11: NUM CAISSIER | L11: 0 | M11: 0 | N11: 2025 | O11: 2025-07
A12: Z002_31B_072025_MASSENA.CSV | C12: MC#01 | D12: TRANSACTION | E12: FILE002 | F12: Z | G12: 0020 | H12: 45869 | I12: 18:40 | J12: 0011 | K12: SHIFT/No | L12: 0 | M12: 0 | N12: 2025 | O12: 2025-07
A13: Z002_31B_072025_MASSENA.CSV | C13: MC#01 | D13: TRANSACTION | E13: FILE002 | F13: Z | G13: 0020 | H13: 45869 | I13: 18:40 | J13: 0012 | K13: DWN | L13: 0 | M13: 0 | N13: 2025 | O13: 2025-07
... A33: Z002_31B_072025_MASSENA.CSV | C33: MC#01 | D33: TRANSACTION | E33: FILE002 | F33: Z | G33: 0020 | H33: 45869 | I33: 18:40 | J33: 0032 | K33: ANNULATION | L33: 0 | M33: 0 | N33: 2025 | O33: 2025-07
A34: Z002_31B_072025_MASSENA.CSV | C34: MC#01 | D34: TRANSACTION | E34: FILE002 | F34: Z | G34: 0020 | H34: 45869 | I34: 18:40 | J34: 0033 | L34: 0 | M34: 0 | N34: 2025 | O34: 2025-07
A35: Z002_31B_072025_MASSENA.CSV | C35: MC#01 | D35: TRANSACTION | E35: FILE002 | F35: Z | G35: 0020 | H35: 45869 | I35: 18:40 | J35: 0034 | L35: 0 | M35: 0 | N35: 2025 | O35: 2025-07
A36: Z002_31B_072025_MASSENA.CSV | C36: MC#01 | D36: TRANSACTION | E36: FILE002 | F36: Z | G36: 0020 | H36: 45869 | I36: 18:40 | J36: 0035 | L36: 0 | M36: 0 | N36: 2025 | O36: 2025-07
A37: Z002_31B_072025_MASSENA.CSV | C37: MC#01 | D37: TRANSACTION | E37: FILE002 | F37: Z | G37: 0020 | H37: 45869 | I37: 18:40 | J37: 0036 | L37: 0 | M37: 0 | N37: 2025 | O37: 2025-07
A38: Z002_31B_072025_MASSENA.CSV | C38: MC#01 | D38: TRANSACTION | E38: FILE002 | F38: Z | G38: 0020 | H38: 45869 | I38: 18:40 | J38: 0037 | L38: 0 | M38: 0 | N38: 2025 | O38: 2025-07
A39: Z002_31B_072025_MASSENA.CSV | C39: MC#01 | D39: TRANSACTION | E39: FILE002 | F39: Z | G39: 0020 | H39: 45869 | I39: 18:40 | J39: 0038 | L39: 0 | M39: 0 | N39: 2025 | O39: 2025-07
A40: Z002_31B_072025_MASSENA.CSV | C40: MC#01 | D40: TRANSACTION | E40: FILE002 | F40: Z | G40: 0020 | H40: 45869 | I40: 18:40 | J40: 0039 | L40: 0 | M40: 0 | N40: 2025 | O40: 2025-07
A41: Z002_31B_072025_MASSENA.CSV | C41: MC#01 | D41: TRANSACTION | E41: FILE002 | F41: Z | G41: 0020 | H41: 45869 | I41: 18:40 | J41: 0040 | L41: 0 | M41: 0 | N41: 2025 | O41: 2025-07
A42: Z002_31B_072025_MASSENA.CSV | C42: MC#01 | D42: TRANSACTION | E42: FILE002 | F42: Z | G42: 0020 | H42: 45869 | I42: 18:40 | J42: 0041 | L42: 0 | M42: 0 | N42: 2025 | O42: 2025-07
A43: Z002_31B_072025_MASSENA.CSV | C43: MC#01 | D43: TRANSACTION | E43: FILE002 | F43: Z | G43: 0020 | H43: 45869 | I43: 18:40 | J43: 0042 | L43: 0 | M43: 0 | N43: 2025 | O43: 2025-07
A44: Z002_31B_072025_MASSENA.CSV | C44: MC#01 | D44: TRANSACTION | E44: FILE002 | F44: Z | G44: 0020 | H44: 45869 | I44: 18:40 | J44: 0043 | L44: 0 | M44: 0 | N44: 2025 | O44: 2025-07
A45: Z002_31B_072025_MASSENA.CSV | C45: MC#01 | D45: TRANSACTION | E45: FILE002 | F45: Z | G45: 0020 | H45: 45869 | I45: 18:40 | J45: 0044 | L45: 0 | M45: 0 | N45: 2025 | O45: 2025-07
... A51: Z002_31B_072025_MASSENA.CSV | C51: MC#01 | D51: TRANSACTION | E51: FILE002 | F51: Z | G51: 0020 | H51: 45869 | I51: 18:40 | J51: 0050 | L51: 0 | M51: 0 | N51: 2025 | O51: 2025-07
A52: Z102_01_022025_MASSENA.CSV | C52: MC#01 | D52: TRANSACTION | E52: FILE102 | F52: ZZ1 | G52: 0086 | H52: 45717 | I52: 15:41 | J52: 0001 | K52: ESPECES | L52: 16 | M52: 10332.8 | N52: 2025 | O52: 2025-02
A53: Z102_01_022025_MASSENA.CSV | C53: MC#01 | D53: TRANSACTION | E53: FILE102 | F53: ZZ1 | G53: 0086 | H53: 45717 | I53: 15:41 | J53: 0002 | K53: SOUS-TOTAL | L53: 0 | M53: 0 | N53: 2025 | O53: 2025-02
A54: Z102_01_022025_MASSENA.CSV | C54: MC#01 | D54: TRANSACTION | E54: FILE102 | F54: ZZ1 | G54: 0086 | H54: 45717 | I54: 15:41 | J54: 0003 | K54: CARTES | L54: 7 | M54: 7497 | N54: 2025 | O54: 2025-02
A55: Z102_01_022025_MASSENA.CSV | C55: MC#01 | D55: TRANSACTION | E55: FILE102 | F55: ZZ1 | G55: 0086 | H55: 45717 | I55: 15:41 | J55: 0004 | K55: CHEQUES | L55: 0 | M55: 0 | N55: 2025 | O55: 2025-02
A56: Z102_01_022025_MASSENA.CSV | C56: MC#01 | D56: TRANSACTION | E56: FILE102 | F56: ZZ1 | G56: 0086 | H56: 45717 | I56: 15:41 | J56: 0005 | K56: AIDE | L56: 0 | M56: 0 | N56: 2025 | O56: 2025-02
A57: Z102_01_022025_MASSENA.CSV | C57: MC#01 | D57: TRANSACTION | E57: FILE102 | F57: ZZ1 | G57: 0086 | H57: 45717 | I57: 15:41 | J57: 0006 | K57: TAX PGM | L57: 0 | M57: 0 | N57: 2025 | O57: 2025-02
A58: Z102_01_022025_MASSENA.CSV | C58: MC#01 | D58: TRANSACTION | E58: FILE102 | F58: ZZ1 | G58: 0086 | H58: 45717 | I58: 15:41 | J58: 0007 | K58: SORTIECAISSE | L58: 0 | M58: 0 | N58: 2025 | O58: 2025-02
A59: Z102_01_022025_MASSENA.CSV | C59: MC#01 | D59: TRANSACTION | E59: FILE102 | F59: ZZ1 | G59: 0086 | H59: 45717 | I59: 15:41 | J59: 0008 | K59: REC&ACCOMPTE | L59: 0 | M59: 0 | N59: 2025 | O59: 2025-02
A60: Z102_01_022025_MASSENA.CSV | C60: MC#01 | D60: TRANSACTION | E60: FILE102 | F60: ZZ1 | G60: 0086 | H60: 45717 | I60: 15:41 | J60: 0009 | K60: SIGN-OFF | L60: 0 | M60: 0 | N60: 2025 | O60: 2025-02
A61: Z102_01_022025_MASSENA.CSV | C61: MC#01 | D61: TRANSACTION | E61: FILE102 | F61: ZZ1 | G61: 0086 | H61: 45717 | I61: 15:41 | J61: 0010 | K61: NUM CAISSIER | L61: 0 | M61: 0 | N61: 2025 | O61: 2025-02
A62: Z102_01_022025_MASSENA.CSV | C62: MC#01 | D62: TRANSACTION | E62: FILE102 | F62: ZZ1 | G62: 0086 | H62: 45717 | I62: 15:41 | J62: 0011 | K62: SHIFT/No | L62: 0 | M62: 0 | N62: 2025 | O62: 2025-02
A63: Z102_01_022025_MASSENA.CSV | C63: MC#01 | D63: TRANSACTION | E63: FILE102 | F63: ZZ1 | G63: 0086 | H63: 45717 | I63: 15:41 | J63: 0012 | K63: DWN | L63: 0 | M63: 0 | N63: 2025 | O63: 2025-02
... A83: Z102_01_022025_MASSENA.CSV | C83: MC#01 | D83: TRANSACTION | E83: FILE102 | F83: ZZ1 | G83: 0086 | H83: 45717 | I83: 15:41 | J83: 0032 | K83: ANNULATION | L83: 0 | M83: 0 | N83: 2025 | O83: 2025-02
...

Sheet TD_TotalNatureTransac
A1: AJ_ANNEE_Z | B1: AJ_MOIS_Z | C1: E_MODE | D1: D_DESIGNATION | E1: D_QUANTITE | F1: D_MONTANT
A2: 2025 | B2: 2025-01 | C2: Z | D2: CARTES | E2: =SUMIFS('Z2_CplteAnneeMois'!$L$2:$L$651,'Z2_CplteAnneeMois'!$O$2:$O$651,B2,'Z2_CplteAnneeMois'!$F$2:$F$651,C2,'Z2_CplteAnneeMois'!$K$2:$K$651,D2) | F2: =SUMIFS('Z2_CplteAnneeMois'!$M$2:$M$651,'Z2_CplteAnneeMois'!$O$2:$O$651,B2,'Z2_CplteAnneeMois'!$F$2:$F$651,C2,'Z2_CplteAnneeMois'!$K$2:$K$651,D2)
A3: 2025 | B3: 2025-01 | C3: Z | D3: CHEQUES | E3: =SUMIFS('Z2_CplteAnneeMois'!$L$2:$L$651,'Z2_CplteAnneeMois'!$O$2:$O$651,B3,'Z2_CplteAnneeMois'!$F$2:$F$651,C3,'Z2_CplteAnneeMois'!$K$2:$K$651,D3) | F3: =SUMIFS('Z2_CplteAnneeMois'!$M$2:$M$651,'Z2_CplteAnneeMois'!$O$2:$O$651,B3,'Z2_CplteAnneeMois'!$F$2:$F$651,C3,'Z2_CplteAnneeMois'!$K$2:$K$651,D3)
A4: 2025 | B4: 2025-01 | C4: Z | D4: CORRECTION | E4: =SUMIFS('Z2_CplteAnneeMois'!$L$2:$L$651,'Z2_CplteAnneeMois'!$O$2:$O$651,B4,'Z2_CplteAnneeMois'!$F$2:$F$651,C4,'Z2_CplteAnneeMois'!$K$2:$K$651,D4) | F4: =SUMIFS('Z2_CplteAnneeMois'!$M$2:$M$651,'Z2_CplteAnneeMois'!$O$2:$O$651,B4,'Z2_CplteAnneeMois'!$F$2:$F$651,C4,'Z2_CplteAnneeMois'!$K$2:$K$651,D4)
A5: 2025 | B5: 2025-01 | C5: Z | D5: ESPECES | E5: =SUMIFS('Z2_CplteAnneeMois'!$L$2:$L$651,'Z2_CplteAnneeMois'!$O$2:$O$651,B5,'Z2_CplteAnneeMois'!$F$2:$F$651,C5,'Z2_CplteAnneeMois'!$K$2:$K$651,D5) | F5: =SUMIFS('Z2_CplteAnneeMois'!$M$2:$M$651,'Z2_CplteAnneeMois'!$O$2:$O$651,B5,'Z2_CplteAnneeMois'!$F$2:$F$651,C5,'Z2_CplteAnneeMois'!$K$2:$K$651,D5)
A6: 2025 | B6: 2025-01 | C6: Z | D6: REF./TIROIR | E6: =SUMIFS('Z2_CplteAnneeMois'!$L$2:$L$651,'Z2_CplteAnneeMois'!$O$2:$O$651,B6,'Z2_CplteAnneeMois'!$F$2:$F$651,C6,'Z2_CplteAnneeMois'!$K$2:$K$651,D6) | F6: =SUMIFS('Z2_CplteAnneeMois'!$M$2:$M$651,'Z2_CplteAnneeMois'!$O$2:$O$651,B6,'Z2_CplteAnneeMois'!$F$2:$F$651,C6,'Z2_CplteAnneeMois'!$K$2:$K$651,D6)
A7: 2025 | B7: 2025-01 | C7: ZZ1 | D7: CARTES | E7: =SUMIFS('Z2_CplteAnneeMois'!$L$2:$L$651,'Z2_CplteAnneeMois'!$O$2:$O$651,B7,'Z2_CplteAnneeMois'!$F$2:$F$651,C7,'Z2_CplteAnneeMois'!$K$2:$K$651,D7) | F7: =SUMIFS('Z2_CplteAnneeMois'!$M$2:$M$651,'Z2_CplteAnneeMois'!$O$2:$O$651,B7,'Z2_CplteAnneeMois'!$F$2:$F$651,C7,'Z2_CplteAnneeMois'!$K$2:$K$651,D7)
A8: 2025 | B8: 2025-01 | C8: ZZ1 | D8: CHEQUES | E8: =SUMIFS('Z2_CplteAnneeMois'!$L$2:$L$651,'Z2_CplteAnneeMois'!$O$2:$O$651,B8,'Z2_CplteAnneeMois'!$F$2:$F$651,C8,'Z2_CplteAnneeMois'!$K$2:$K$651,D8) | F8: =SUMIFS('Z2_CplteAnneeMois'!$M$2:$M$651,'Z2_CplteAnneeMois'!$O$2:$O$651,B8,'Z2_CplteAnneeMois'!$F$2:$F$651,C8,'Z2_CplteAnneeMois'!$K$2:$K$651,D8)
A9: 2025 | B9: 2025-01 | C9: ZZ1 | D9: CORRECTION | E9: =SUMIFS('Z2_CplteAnneeMois'!$L$2:$L$651,'Z2_CplteAnneeMois'!$O$2:$O$651,B9,'Z2_CplteAnneeMois'!$F$2:$F$651,C9,'Z2_CplteAnneeMois'!$K$2:$K$651,D9) | F9: =SUMIFS('Z2_CplteAnneeMois'!$M$2:$M$651,'Z2_CplteAnneeMois'!$O$2:$O$651,B9,'Z2_CplteAnneeMois'!$F$2:$F$651,C9,'Z2_CplteAnneeMois'!$K$2:$K$651,D9)
A10: 2025 | B10: 2025-01 | C10: ZZ1 | D10: ESPECES | E10: =SUMIFS('Z2_CplteAnneeMois'!$L$2:$L$651,'Z2_CplteAnneeMois'!$O$2:$O$651,B10,'Z2_CplteAnneeMois'!$F$2:$F$651,C10,'Z2_CplteAnneeMois'!$K$2:$K$651,D10) | F10: =SUMIFS('Z2_CplteAnneeMois'!$M$2:$M$651,'Z2_CplteAnneeMois'!$O$2:$O$651,B10,'Z2_CplteAnneeMois'!$F$2:$F$651,C10,'Z2_CplteAnneeMois'!$K$2:$K$651,D10)
A11: 2025 | B11: 2025-01 | C11: ZZ1 | D11: REF./TIROIR | E11: =SUMIFS('Z2_CplteAnneeMois'!$L$2:$L$651,'Z2_CplteAnneeMois'!$O$2:$O$651,B11,'Z2_CplteAnneeMois'!$F$2:$F$651,C11,'Z2_CplteAnneeMois'!$K$2:$K$651,D11) | F11: =SUMIFS('Z2_CplteAnneeMois'!$M$2:$M$651,'Z2_CplteAnneeMois'!$O$2:$O$651,B11,'Z2_CplteAnneeMois'!$F$2:$F$651,C11,'Z2_CplteAnneeMois'!$K$2:$K$651,D11)
A12: 2025 | B12: 2025-01 | C12: ZZ2 | D12: CARTES | E12: =SUMIFS('Z2_CplteAnneeMois'!$L$2:$L$651,'Z2_CplteAnneeMois'!$O$2:$O$651,B12,'Z2_CplteAnneeMois'!$F$2:$F$651,C12,'Z2_CplteAnneeMois'!$K$2:$K$651,D12) | F12: =SUMIFS('Z2_CplteAnneeMois'!$M$2:$M$651,'Z2_CplteAnneeMois'!$O$2:$O$651,B12,'Z2_CplteAnneeMois'!$F$2:$F$651,C12,'Z2_CplteAnneeMois'!$K$2:$K$651,D12)
A13: 2025 | B13: 2025-01 | C13: ZZ2 | D13: CHEQUES | E13: =SUMIFS('Z2_CplteAnneeMois'!$L$2:$L$651,'Z2_CplteAnneeMois'!$O$2:$O$651,B13,'Z2_CplteAnneeMois'!$F$2:$F$651,C13,'Z2_CplteAnneeMois'!$K$2:$K$651,D13) | F13: =SUMIFS('Z2_CplteAnneeMois'!$M$2:$M$651,'Z2_CplteAnneeMois'!$O$2:$O$651,B13,'Z2_CplteAnneeMois'!$F$2:$F$651,C13,'Z2_CplteAnneeMois'!$K$2:$K$651,D13)
... A91: 2025 | B91: 2025-08 | C91: ZZ2 | D91: REF./TIROIR | E91: =SUMIFS('Z2_CplteAnneeMois'!$L$2:$L$651,'Z2_CplteAnneeMois'!$O$2:$O$651,B91,'Z2_CplteAnneeMois'!$F$2:$F$651,C91,'Z2_CplteAnneeMois'!$K$2:$K$651,D91) | F91: =SUMIFS('Z2_CplteAnneeMois'!$M$2:$M$651,'Z2_CplteAnneeMois'!$O$2:$O$651,B91,'Z2_CplteAnneeMois'!$F$2:$F$651,C91,'Z2_CplteAnneeMois'!$K$2:$K$651,D91)

Sheet Z2_Total_ModeZZ1
A1: AJ_ANNEE_Z | B1: AJ_MOIS_Z | C1: CARTES_D_QUANTITE | D1: CARTES_D_MONTANT | E1: CHEQUES_D_QUANTITE | F1: CHEQUES_D_MONTANT | G1: CORRECTION_D_QUANTITE | H1: CORRECTION_D_MONTANT | I1: ESPECES_D_QUANTITE | J1: ESPECES_D_MONTANT | K1: REF__TIROIR_D_QUANTITE | L1: REF__TIROIR_D_MONTANT
A2: 2025 | B2: 2025-01 | C2: =SUMIFS('TD_TotalNatureTransac'!$E$2:$E$91,'TD_TotalNatureTransac'!$B$2:$B$91,B2,'TD_TotalNatureTransac'!$C$2:$C$91,"ZZ1",'TD_TotalNatureTransac'!$D$2:$D$91,"CARTES") | D2: =SUMIFS('TD_TotalNatureTransac'!$F$2:$F$91,'TD_TotalNatureTransac'!$B$2:$B$91,B2,'TD_TotalNatureTransac'!$C$2:$C$91,"ZZ1",'TD_TotalNatureTransac'!$D$2:$D$91,"CARTES") | E2: =SUMIFS('TD_TotalNatureTransac'!$E$2:$E$91,'TD_TotalNatureTransac'!$B$2:$B$91,B2,'TD_TotalNatureTransac'!$C$2:$C$91,"ZZ1",'TD_TotalNatureTransac'!$D$2:$D$91,"CHEQUES") | F2: =SUMIFS('TD_TotalNatureTransac'!$F$2:$F$91,'TD_TotalNatureTransac'!$B$2:$B$91,B2,'TD_TotalNatureTransac'!$C$2:$C$91,"ZZ1",'TD_TotalNatureTransac'!$D$2:$D$91,"CHEQUES") | G2: =SUMIFS('TD_TotalNatureTransac'!$E$2:$E$91,'TD_TotalNatureTransac'!$B$2:$B$91,B2,'TD_TotalNatureTransac'!$C$2:$C$91,"ZZ1",'TD_TotalNatureTransac'!$D$2:$D$91,"CORRECTION") | H2: =SUMIFS('TD_TotalNatureTransac'!$F$2:$F$91,'TD_TotalNatureTransac'!$B$2:$B$91,B2,'TD_TotalNatureTransac'!$C$2:$C$91,"ZZ1",'TD_TotalNatureTransac'!$D$2:$D$91,"CORRECTION") | I2: =SUMIFS('TD_TotalNatureTransac'!$E$2:$E$91,'TD_TotalNatureTransac'!$B$2:$B$91,B2,'TD_TotalNatureTransac'!$C$2:$C$91,"ZZ1",'TD_TotalNatureTransac'!$D$2:$D$91,"ESPECES") | J2: =SUMIFS('TD_TotalNatureTransac'!$F$2:$F$91,'TD_TotalNatureTransac'!$B$2:$B$91,B2,'TD_TotalNatureTransac'!$C$2:$C$91,"ZZ1",'TD_TotalNatureTransac'!$D$2:$D$91,"ESPECES") | K2: =SUMIFS('TD_TotalNatureTransac'!$E$2:$E$91,'TD_TotalNatureTransac'!$B$2:$B$91,B2,'TD_TotalNatureTransac'!$C$2:$C$91,"ZZ1",'TD_TotalNatureTransac'!$D$2:$D$91,"REF./TIROIR") | L2: =SUMIFS('TD_TotalNatureTransac'!$F$2:$F$91,'TD_TotalNatureTransac'!$B$2:$B$91,B2,'TD_TotalNatureTransac'!$C$2:$C$91,"ZZ1",'TD_TotalNatureTransac'!$D$2:$D$91,"REF./TIROIR")
A3: 2025 | B3: 2025-02 | C3: =SUMIFS('TD_TotalNatureTransac'!$E$2:$E$91,'TD_TotalNatureTransac'!$B$2:$B$91,B3,'TD_TotalNatureTransac'!$C$2:$C$91,"ZZ1",'TD_TotalNatureTransac'!$D$2:$D$91,"CARTES") | D3: =SUMIFS('TD_TotalNatureTransac'!$F$2:$F$91,'TD_TotalNatureTransac'!$B$2:$B$91,B3,'TD_TotalNatureTransac'!$C$2:$C$91,"ZZ1",'TD_TotalNatureTransac'!$D$2:$D$91,"CARTES") | E3: =SUMIFS('TD_TotalNatureTransac'!$E$2:$E$91,'TD_TotalNatureTransac'!$B$2:$B$91,B3,'TD_TotalNatureTransac'!$C$2:$C$91,"ZZ1",'TD_TotalNatureTransac'!$D$2:$D$91,"CHEQUES") | F3: =SUMIFS('TD_TotalNatureTransac'!$F$2:$F$91,'TD_TotalNatureTransac'!$B$2:$B$91,B3,'TD_TotalNatureTransac'!$C$2:$C$91,"ZZ1",'TD_TotalNatureTransac'!$D$2:$D$91,"CHEQUES") | G3: =SUMIFS('TD_TotalNatureTransac'!$E$2:$E$91,'TD_TotalNatureTransac'!$B$2:$B$91,B3,'TD_TotalNatureTransac'!$C$2:$C$91,"ZZ1",'TD_TotalNatureTransac'!$D$2:$D$91,"CORRECTION") | H3: =SUMIFS('TD_TotalNatureTransac'!$F$2:$F$91,'TD_TotalNatureTransac'!$B$2:$B$91,B3,'TD_TotalNatureTransac'!$C$2:$C$91,"ZZ1",'TD_TotalNatureTransac'!$D$2:$D$91,"CORRECTION") | I3: =SUMIFS('TD_TotalNatureTransac'!$E$2:$E$91,'TD_TotalNatureTransac'!$B$2:$B$91,B3,'TD_TotalNatureTransac'!$C$2:$C$91,"ZZ1",'TD_TotalNatureTransac'!$D$2:$D$91,"ESPECES") | J3: =SUMIFS('TD_TotalNatureTransac'!$F$2:$F$91,'TD_TotalNatureTransac'!$B$2:$B$91,B3,'TD_TotalNatureTransac'!$C$2:$C$91,"ZZ1",'TD_TotalNatureTransac'!$D$2:$D$91,"ESPECES") | K3: =SUMIFS('TD_TotalNatureTransac'!$E$2:$E$91,'TD_TotalNatureTransac'!$B$2:$B$91,B3,'TD_TotalNatureTransac'!$C$2:$C$91,"ZZ1",'TD_TotalNatureTransac'!$D$2:$D$91,"REF./TIROIR") | L3: =SUMIFS('TD_TotalNatureTransac'!$F$2:$F$91,'TD_TotalNatureTransac'!$B$2:$B$91,B3,'TD_TotalNatureTransac'!$C$2:$C$91,"ZZ1",'TD_TotalNatureTransac'!$D$2:$D$91,"REF./TIROIR")
A4: 2025 | B4: 2025-03 | C4: =SUMIFS('TD_TotalNatureTransac'!$E$2:$E$91,'TD_TotalNatureTransac'!$B$2:$B$91,B4,'TD_TotalNatureTransac'!$C$2:$C$91,"ZZ1",'TD_TotalNatureTransac'!$D$2:$D$91,"CARTES") | D4: =SUMIFS('TD_TotalNatureTransac'!$F$2:$F$91,'TD_TotalNatureTransac'!$B$2:$B$91,B4,'TD_TotalNatureTransac'!$C$2:$C$91,"ZZ1",'TD_TotalNatureTransac'!$D$2:$D$91,"CARTES") | E4: =SUMIFS('TD_TotalNatureTransac'!$E$2:$E$91,'TD_TotalNatureTransac'!$B$2:$B$91,B4,'TD_TotalNatureTransac'!$C$2:$C$91,"ZZ1",'TD_TotalNatureTransac'!$D$2:$D$91,"CHEQUES") | F4: =SUMIFS('TD_TotalNatureTransac'!$F$2:$F$91,'TD_TotalNatureTransac'!$B$2:$B$91,B4,'TD_TotalNatureTransac'!$C$2:$C$91,"ZZ1",'TD_TotalNatureTransac'!$D$2:$D$91,"CHEQUES") | G4: =SUMIFS('TD_TotalNatureTransac'!$E$2:$E$91,'TD_TotalNatureTransac'!$B$2:$B$91,B4,'TD_TotalNatureTransac'!$C$2:$C$91,"ZZ1",'TD_TotalNatureTransac'!$D$2:$D$91,"CORRECTION") | H4: =SUMIFS('TD_TotalNatureTransac'!$F$2:$F$91,'TD_TotalNatureTransac'!$B$2:$B$91,B4,'TD_TotalNatureTransac'!$C$2:$C$91,"ZZ1",'TD_TotalNatureTransac'!$D$2:$D$91,"CORRECTION") | I4: =SUMIFS('TD_TotalNatureTransac'!$E$2:$E$91,'TD_TotalNatureTransac'!$B$2:$B$91,B4,'TD_TotalNatureTransac'!$C$2:$C$91,"ZZ1",'TD_TotalNatureTransac'!$D$2:$D$91,"ESPECES") | J4: =SUMIFS('TD_TotalNatureTransac'!$F$2:$F$91,'TD_TotalNatureTransac'!$B$2:$B$91,B4,'TD_TotalNatureTransac'!$C$2:$C$91,"ZZ1",'TD_TotalNatureTransac'!$D$2:$D$91,"ESPECES") | K4: =SUMIFS('TD_TotalNatureTransac'!$E$2:$E$91,'TD_TotalNatureTransac'!$B$2:$B$91,B4,'TD_TotalNatureTransac'!$C$2:$C$91,"ZZ1",'TD_TotalNatureTransac'!$D$2:$D$91,"REF./TIROIR") | L4: =SUMIFS('TD_TotalNatureTransac'!$F$2:$F$91,'TD_TotalNatureTransac'!$B$2:$B$91,B4,'TD_TotalNatureTransac'!$C$2:$C$91,"ZZ1",'TD_TotalNatureTransac'!$D$2:$D$91,"REF./TIROIR")
A5: 2025 | B5: 2025-04|2025-05|2025-06 | C5: =SUMIFS('TD_TotalNatureTransac'!$E$2:$E$91,'TD_TotalNatureTransac'!$B$2:$B$91,B5,'TD_TotalNatureTransac'!$C$2:$C$91,"ZZ1",'TD_TotalNatureTransac'!$D$2:$D$91,"CARTES") | D5: =SUMIFS('TD_TotalNatureTransac'!$F$2:$F$91,'TD_TotalNatureTransac'!$B$2:$B$91,B5,'TD_TotalNatureTransac'!$C$2:$C$91,"ZZ1",'TD_TotalNatureTransac'!$D$2:$D$91,"CARTES") | E5: =SUMIFS('TD_TotalNatureTransac'!$E$2:$E$91,'TD_TotalNatureTransac'!$B$2:$B$91,B5,'TD_TotalNatureTransac'!$C$2:$C$91,"ZZ1",'TD_TotalNatureTransac'!$D$2:$D$91,"CHEQUES") | F5: =SUMIFS('TD_TotalNatureTransac'!$F$2:$F$91,'TD_TotalNatureTransac'!$B$2:$B$91,B5,'TD_TotalNatureTransac'!$C$2:$C$91,"ZZ1",'TD_TotalNatureTransac'!$D$2:$D$91,"CHEQUES") | G5: =SUMIFS('TD_TotalNatureTransac'!$E$2:$E$91,'TD_TotalNatureTransac'!$B$2:$B$91,B5,'TD_TotalNatureTransac'!$C$2:$C$91,"ZZ1",'TD_TotalNatureTransac'!$D$2:$D$91,"CORRECTION") | H5: =SUMIFS('TD_TotalNatureTransac'!$F$2:$F$91,'TD_TotalNatureTransac'!$B$2:$B$91,B5,'TD_TotalNatureTransac'!$C$2:$C$91,"ZZ1",'TD_TotalNatureTransac'!$D$2:$D$91,"CORRECTION") | I5: =SUMIFS('TD_TotalNatureTransac'!$E$2:$E$91,'TD_TotalNatureTransac'!$B$2:$B$91,B5,'TD_TotalNatureTransac'!$C$2:$C$91,"ZZ1",'TD_TotalNatureTransac'!$D$2:$D$91,"ESPECES") | J5: =SUMIFS('TD_TotalNatureTransac'!$F$2:$F$91,'TD_TotalNatureTransac'!$B$2:$B$91,B5,'TD_TotalNatureTransac'!$C$2:$C$91,"ZZ1",'TD_TotalNatureTransac'!$D$2:$D$91,"ESPECES") | K5: =SUMIFS('TD_TotalNatureTransac'!$E$2:$E$91,'TD_TotalNatureTransac'!$B$2:$B$91,B5,'TD_TotalNatureTransac'!$C$2:$C$91,"ZZ1",'TD_TotalNatureTransac'!$D$2:$D$91,"REF./TIROIR") | L5: =SUMIFS('TD_TotalNatureTransac'!$F$2:$F$91,'TD_TotalNatureTransac'!$B$2:$B$91,B5,'TD_TotalNatureTransac'!$C$2:$C$91,"ZZ1",'TD_TotalNatureTransac'!$D$2:$D$91,"REF./TIROIR")
A6: 2025 | B6: 2025-07 | C6: =SUMIFS('TD_TotalNatureTransac'!$E$2:$E$91,'TD_TotalNatureTransac'!$B$2:$B$91,B6,'TD_TotalNatureTransac'!$C$2:$C$91,"ZZ1",'TD_TotalNatureTransac'!$D$2:$D$91,"CARTES") | D6: =SUMIFS('TD_TotalNatureTransac'!$F$2:$F$91,'TD_TotalNatureTransac'!$B$2:$B$91,B6,'TD_TotalNatureTransac'!$C$2:$C$91,"ZZ1",'TD_TotalNatureTransac'!$D$2:$D$91,"CARTES") | E6: =SUMIFS('TD_TotalNatureTransac'!$E$2:$E$91,'TD_TotalNatureTransac'!$B$2:$B$91,B6,'TD_TotalNatureTransac'!$C$2:$C$91,"ZZ1",'TD_TotalNatureTransac'!$D$2:$D$91,"CHEQUES") | F6: =SUMIFS('TD_TotalNatureTransac'!$F$2:$F$91,'TD_TotalNatureTransac'!$B$2:$B$91,B6,'TD_TotalNatureTransac'!$C$2:$C$91,"ZZ1",'TD_TotalNatureTransac'!$D$2:$D$91,"CHEQUES") | G6: =SUMIFS('TD_TotalNatureTransac'!$E$2:$E$91,'TD_TotalNatureTransac'!$B$2:$B$91,B6,'TD_TotalNatureTransac'!$C$2:$C$91,"ZZ1",'TD_TotalNatureTransac'!$D$2:$D$91,"CORRECTION") | H6: =SUMIFS('TD_TotalNatureTransac'!$F$2:$F$91,'TD_TotalNatureTransac'!$B$2:$B$91,B6,'TD_TotalNatureTransac'!$C$2:$C$91,"ZZ1",'TD_TotalNatureTransac'!$D$2:$D$91,"CORRECTION") | I6: =SUMIFS('TD_TotalNatureTransac'!$E$2:$E$91,'TD_TotalNatureTransac'!$B$2:$B$91,B6,'TD_TotalNatureTransac'!$C$2:$C$91,"ZZ1",'TD_TotalNatureTransac'!$D$2:$D$91,"ESPECES") | J6: =SUMIFS('TD_TotalNatureTransac'!$F$2:$F$91,'TD_TotalNatureTransac'!$B$2:$B$91,B6,'TD_TotalNatureTransac'!$C$2:$C$91,"ZZ1",'TD_TotalNatureTransac'!$D$2:$D$91,"ESPECES") | K6: =SUMIFS('TD_TotalNatureTransac'!$E$2:$E$91,'TD_TotalNatureTransac'!$B$2:$B$91,B6,'TD_TotalNatureTransac'!$C$2:$C$91,"ZZ1",'TD_TotalNatureTransac'!$D$2:$D$91,"REF./TIROIR") | L6: =SUMIFS('TD_TotalNatureTransac'!$F$2:$F$91,'TD_TotalNatureTransac'!$B$2:$B$91,B6,'TD_TotalNatureTransac'!$C$2:$C$91,"ZZ1",'TD_TotalNatureTransac'!$D$2:$D$91,"REF./TIROIR")
A7: 2025 | B7: 2025-08 | C7: =SUMIFS('TD_TotalNatureTransac'!$E$2:$E$91,'TD_TotalNatureTransac'!$B$2:$B$91,B7,'TD_TotalNatureTransac'!$C$2:$C$91,"ZZ1",'TD_TotalNatureTransac'!$D$2:$D$91,"CARTES") | D7: =SUMIFS('TD_TotalNatureTransac'!$F$2:$F$91,'TD_TotalNatureTransac'!$B$2:$B$91,B7,'TD_TotalNatureTransac'!$C$2:$C$91,"ZZ1",'TD_TotalNatureTransac'!$D$2:$D$91,"CARTES") | E7: =SUMIFS('TD_TotalNatureTransac'!$E$2:$E$91,'TD_TotalNatureTransac'!$B$2:$B$91,B7,'TD_TotalNatureTransac'!$C$2:$C$91,"ZZ1",'TD_TotalNatureTransac'!$D$2:$D$91,"CHEQUES") | F7: =SUMIFS('TD_TotalNatureTransac'!$F$2:$F$91,'TD_TotalNatureTransac'!$B$2:$B$91,B7,'TD_TotalNatureTransac'!$C$2:$C$91,"ZZ1",'TD_TotalNatureTransac'!$D$2:$D$91,"CHEQUES") | G7: =SUMIFS('TD_TotalNatureTransac'!$E$2:$E$91,'TD_TotalNatureTransac'!$B$2:$B$91,B7,'TD_TotalNatureTransac'!$C$2:$C$91,"ZZ1",'TD_TotalNatureTransac'!$D$2:$D$91,"CORRECTION") | H7: =SUMIFS('TD_TotalNatureTransac'!$F$2:$F$91,'TD_TotalNatureTransac'!$B$2:$B$91,B7,'TD_TotalNatureTransac'!$C$2:$C$91,"ZZ1",'TD_TotalNatureTransac'!$D$2:$D$91,"CORRECTION") | I7: =SUMIFS('TD_TotalNatureTransac'!$E$2:$E$91,'TD_TotalNatureTransac'!$B$2:$B$91,B7,'TD_TotalNatureTransac'!$C$2:$C$91,"ZZ1",'TD_TotalNatureTransac'!$D$2:$D$91,"ESPECES") | J7: =SUMIFS('TD_TotalNatureTransac'!$F$2:$F$91,'TD_TotalNatureTransac'!$B$2:$B$91,B7,'TD_TotalNatureTransac'!$C$2:$C$91,"ZZ1",'TD_TotalNatureTransac'!$D$2:$D$91,"ESPECES") | K7: =SUMIFS('TD_TotalNatureTransac'!$E$2:$E$91,'TD_TotalNatureTransac'!$B$2:$B$91,B7,'TD_TotalNatureTransac'!$C$2:$C$91,"ZZ1",'TD_TotalNatureTransac'!$D$2:$D$91,"REF./TIROIR") | L7: =SUMIFS('TD_TotalNatureTransac'!$F$2:$F$91,'TD_TotalNatureTransac'!$B$2:$B$91,B7,'TD_TotalNatureTransac'!$C$2:$C$91,"ZZ1",'TD_TotalNatureTransac'!$D$2:$D$91,"REF./TIROIR")

Sheet Z2_Total_ModeZZ2
A1: AJ_ANNEE_Z | B1: AJ_MOIS_Z | C1: CARTES_D_QUANTITE | D1: CARTES_D_MONTANT | E1: CHEQUES_D_QUANTITE | F1: CHEQUES_D_MONTANT | G1: CORRECTION_D_QUANTITE | H1: CORRECTION_D_MONTANT | I1: ESPECES_D_QUANTITE | J1: ESPECES_D_MONTANT | K1: REF__TIROIR_D_QUANTITE | L1: REF__TIROIR_D_MONTANT
A2: 2025 | B2: 2025-01 | C2: =SUMIFS('TD_TotalNatureTransac'!$E$2:$E$91,'TD_TotalNatureTransac'!$B$2:$B$91,B2,'TD_TotalNatureTransac'!$C$2:$C$91,"ZZ2",'TD_TotalNatureTransac'!$D$2:$D$91,"CARTES") | D2: =SUMIFS('TD_TotalNatureTransac'!$F$2:$F$91,'TD_TotalNatureTransac'!$B$2:$B$91,B2,'TD_TotalNatureTransac'!$C$2:$C$91,"ZZ2",'TD_TotalNatureTransac'!$D$2:$D$91,"CARTES") | E2: =SUMIFS('TD_TotalNatureTransac'!$E$2:$E$91,'TD_TotalNatureTransac'!$B$2:$B$91,B2,'TD_TotalNatureTransac'!$C$2:$C$91,"ZZ2",'TD_TotalNatureTransac'!$D$2:$D$91,"CHEQUES") | F2: =SUMIFS('TD_TotalNatureTransac'!$F$2:$F$91,'TD_TotalNatureTransac'!$B$2:$B$91,B2,'TD_TotalNatureTransac'!$C$2:$C$91,"ZZ2",'TD_TotalNatureTransac'!$D$2:$D$91,"CHEQUES") | G2: =SUMIFS('TD_TotalNatureTransac'!$E$2:$E$91,'TD_TotalNatureTransac'!$B$2:$B$91,B2,'TD_TotalNatureTransac'!$C$2:$C$91,"ZZ2",'TD_TotalNatureTransac'!$D$2:$D$91,"CORRECTION") | H2: =SUMIFS('TD_TotalNatureTransac'!$F$2:$F$91,'TD_TotalNatureTransac'!$B$2:$B$91,B2,'TD_TotalNatureTransac'!$C$2:$C$91,"ZZ2",'TD_TotalNatureTransac'!$D$2:$D$91,"CORRECTION") | I2: =SUMIFS('TD_TotalNatureTransac'!$E$2:$E$91,'TD_TotalNatureTransac'!$B$2:$B$91,B2,'TD_TotalNatureTransac'!$C$2:$C$91,"ZZ2",'TD_TotalNatureTransac'!$D$2:$D$91,"ESPECES") | J2: =SUMIFS('TD_TotalNatureTransac'!$F$2:$F$91,'TD_TotalNatureTransac'!$B$2:$B$91,B2,'TD_TotalNatureTransac'!$C$2:$C$91,"ZZ2",'TD_TotalNatureTransac'!$D$2:$D$91,"ESPECES") | K2: =SUMIFS('TD_TotalNatureTransac'!$E$2:$E$91,'TD_TotalNatureTransac'!$B$2:$B$91,B2,'TD_TotalNatureTransac'!$C$2:$C$91,"ZZ2",'TD_TotalNatureTransac'!$D$2:$D$91,"REF./TIROIR") | L2: =SUMIFS('TD_TotalNatureTransac'!$F$2:$F$91,'TD_TotalNatureTransac'!$B$2:$B$91,B2,'TD_TotalNatureTransac'!$C$2:$C$91,"ZZ2",'TD_TotalNatureTransac'!$D$2:$D$91,"REF./TIROIR")
A3: 2025 | B3: 2025-02 | C3: =SUMIFS('TD_TotalNatureTransac'!$E$2:$E$91,'TD_TotalNatureTransac'!$B$2:$B$91,B3,'TD_TotalNatureTransac'!$C$2:$C$91,"ZZ2",'TD_TotalNatureTransac'!$D$2:$D$91,"CARTES") | D3: =SUMIFS('TD_TotalNatureTransac'!$F$2:$F$91,'TD_TotalNatureTransac'!$B$2:$B$91,B3,'TD_TotalNatureTransac'!$C$2:$C$91,"ZZ2",'TD_TotalNatureTransac'!$D$2:$D$91,"CARTES") | E3: =SUMIFS('TD_TotalNatureTransac'!$E$2:$E$91,'TD_TotalNatureTransac'!$B$2:$B$91,B3,'TD_TotalNatureTransac'!$C$2:$C$91,"ZZ2",'TD_TotalNatureTransac'!$D$2:$D$91,"CHEQUES") | F3: =SUMIFS('TD_TotalNatureTransac'!$F$2:$F$91,'TD_TotalNatureTransac'!$B$2:$B$91,B3,'TD_TotalNatureTransac'!$C$2:$C$91,"ZZ2",'TD_TotalNatureTransac'!$D$2:$D$91,"CHEQUES") | G3: =SUMIFS('TD_TotalNatureTransac'!$E$2:$E$91,'TD_TotalNatureTransac'!$B$2:$B$91,B3,'TD_TotalNatureTransac'!$C$2:$C$91,"ZZ2",'TD_TotalNatureTransac'!$D$2:$D$91,"CORRECTION") | H3: =SUMIFS('TD_TotalNatureTransac'!$F$2:$F$91,'TD_TotalNatureTransac'!$B$2:$B$91,B3,'TD_TotalNatureTransac'!$C$2:$C$91,"ZZ2",'TD_TotalNatureTransac'!$D$2:$D$91,"CORRECTION") | I3: =SUMIFS('TD_TotalNatureTransac'!$E$2:$E$91,'TD_TotalNatureTransac'!$B$2:$B$91,B3,'TD_TotalNatureTransac'!$C$2:$C$91,"ZZ2",'TD_TotalNatureTransac'!$D$2:$D$91,"ESPECES") | J3: =SUMIFS('TD_TotalNatureTransac'!$F$2:$F$91,'TD_TotalNatureTransac'!$B$2:$B$91,B3,'TD_TotalNatureTransac'!$C$2:$C$91,"ZZ2",'TD_TotalNatureTransac'!$D$2:$D$91,"ESPECES") | K3: =SUMIFS('TD_TotalNatureTransac'!$E$2:$E$91,'TD_TotalNatureTransac'!$B$2:$B$91,B3,'TD_TotalNatureTransac'!$C$2:$C$91,"ZZ2",'TD_TotalNatureTransac'!$D$2:$D$91,"REF./TIROIR") | L3: =SUMIFS('TD_TotalNatureTransac'!$F$2:$F$91,'TD_TotalNatureTransac'!$B$2:$B$91,B3,'TD_TotalNatureTransac'!$C$2:$C$91,"ZZ2",'TD_TotalNatureTransac'!$D$2:$D$91,"REF./TIROIR")
A4: 2025 | B4: 2025-03 | C4: =SUMIFS('TD_TotalNatureTransac'!$E$2:$E$91,'TD_TotalNatureTransac'!$B$2:$B$91,B4,'TD_TotalNatureTransac'!$C$2:$C$91,"ZZ2",'TD_TotalNatureTransac'!$D$2:$D$91,"CARTES") | D4: =SUMIFS('TD_TotalNatureTransac'!$F$2:$F$91,'TD_TotalNatureTransac'!$B$2:$B$91,B4,'TD_TotalNatureTransac'!$C$2:$C$91,"ZZ2",'TD_TotalNatureTransac'!$D$2:$D$91,"CARTES") | E4: =SUMIFS('TD_TotalNatureTransac'!$E$2:$E$91,'TD_TotalNatureTransac'!$B$2:$B$91,B4,'TD_TotalNatureTransac'!$C$2:$C$91,"ZZ2",'TD_TotalNatureTransac'!$D$2:$D$91,"CHEQUES") | F4: =SUMIFS('TD_TotalNatureTransac'!$F$2:$F$91,'TD_TotalNatureTransac'!$B$2:$B$91,B4,'TD_TotalNatureTransac'!$C$2:$C$91,"ZZ2",'TD_TotalNatureTransac'!$D$2:$D$91,"CHEQUES") | G4: =SUMIFS('TD_TotalNatureTransac'!$E$2:$E$91,'TD_TotalNatureTransac'!$B$2:$B$91,B4,'TD_TotalNatureTransac'!$C$2:$C$91,"ZZ2",'TD_TotalNatureTransac'!$D$2:$D$91,"CORRECTION") | H4: =SUMIFS('TD_TotalNatureTransac'!$F$2:$F$91,'TD_TotalNatureTransac'!$B$2:$B$91,B4,'TD_TotalNatureTransac'!$C$2:$C$91,"ZZ2",'TD_TotalNatureTransac'!$D$2:$D$91,"CORRECTION") | I4: =SUMIFS('TD_TotalNatureTransac'!$E$2:$E$91,'TD_TotalNatureTransac'!$B$2:$B$91,B4,'TD_TotalNatureTransac'!$C$2:$C$91,"ZZ2",'TD_TotalNatureTransac'!$D$2:$D$91,"ESPECES") | J4: =SUMIFS('TD_TotalNatureTransac'!$F$2:$F$91,'TD_TotalNatureTransac'!$B$2:$B$91,B4,'TD_TotalNatureTransac'!$C$2:$C$91,"ZZ2",'TD_TotalNatureTransac'!$D$2:$D$91,"ESPECES") | K4: =SUMIFS('TD_TotalNatureTransac'!$E$2:$E$91,'TD_TotalNatureTransac'!$B$2:$B$91,B4,'TD_TotalNatureTransac'!$C$2:$C$91,"ZZ2",'TD_TotalNatureTransac'!$D$2:$D$91,"REF./TIROIR") | L4: =SUMIFS('TD_TotalNatureTransac'!$F$2:$F$91,'TD_TotalNatureTransac'!$B$2:$B$91,B4,'TD_TotalNatureTransac'!$C$2:$C$91,"ZZ2",'TD_TotalNatureTransac'!$D$2:$D$91,"REF./TIROIR")
A5: 2025 | B5: 2025-04|2025-05|2025-06 | C5: =SUMIFS('TD_TotalNatureTransac'!$E$2:$E$91,'TD_TotalNatureTransac'!$B$2:$B$91,B5,'TD_TotalNatureTransac'!$C$2:$C$91,"ZZ2",'TD_TotalNatureTransac'!$D$2:$D$91,"CARTES") | D5: =SUMIFS('TD_TotalNatureTransac'!$F$2:$F$91,'TD_TotalNatureTransac'!$B$2:$B$91,B5,'TD_TotalNatureTransac'!$C$2:$C$91,"ZZ2",'TD_TotalNatureTransac'!$D$2:$D$91,"CARTES") | E5: =SUMIFS('TD_TotalNatureTransac'!$E$2:$E$91,'TD_TotalNatureTransac'!$B$2:$B$91,B5,'TD_TotalNatureTransac'!$C$2:$C$91,"ZZ2",'TD_TotalNatureTransac'!$D$2:$D$91,"CHEQUES") | F5: =SUMIFS('TD_TotalNatureTransac'!$F$2:$F$91,'TD_TotalNatureTransac'!$B$2:$B$91,B5,'TD_TotalNatureTransac'!$C$2:$C$91,"ZZ2",'TD_TotalNatureTransac'!$D$2:$D$91,"CHEQUES") | G5: =SUMIFS('TD_TotalNatureTransac'!$E$2:$E$91,'TD_TotalNatureTransac'!$B$2:$B$91,B5,'TD_TotalNatureTransac'!$C$2:$C$91,"ZZ2",'TD_TotalNatureTransac'!$D$2:$D$91,"CORRECTION") | H5: =SUMIFS('TD_TotalNatureTransac'!$F$2:$F$91,'TD_TotalNatureTransac'!$B$2:$B$91,B5,'TD_TotalNatureTransac'!$C$2:$C$91,"ZZ2",'TD_TotalNatureTransac'!$D$2:$D$91,"CORRECTION") | I5: =SUMIFS('TD_TotalNatureTransac'!$E$2:$E$91,'TD_TotalNatureTransac'!$B$2:$B$91,B5,'TD_TotalNatureTransac'!$C$2:$C$91,"ZZ2",'TD_TotalNatureTransac'!$D$2:$D$91,"ESPECES") | J5: =SUMIFS('TD_TotalNatureTransac'!$F$2:$F$91,'TD_TotalNatureTransac'!$B$2:$B$91,B5,'TD_TotalNatureTransac'!$C$2:$C$91,"ZZ2",'TD_TotalNatureTransac'!$D$2:$D$91,"ESPECES") | K5: =SUMIFS('TD_TotalNatureTransac'!$E$2:$E$91,'TD_TotalNatureTransac'!$B$2:$B$91,B5,'TD_TotalNatureTransac'!$C$2:$C$91,"ZZ2",'TD_TotalNatureTransac'!$D$2:$D$91,"REF./TIROIR") | L5: =SUMIFS('TD_TotalNatureTransac'!$F$2:$F$91,'TD_TotalNatureTransac'!$B$2:$B$91,B5,'TD_TotalNatureTransac'!$C$2:$C$91,"ZZ2",'TD_TotalNatureTransac'!$D$2:$D$91,"REF./TIROIR")
A6: 2025 | B6: 2025-07 | C6: =SUMIFS('TD_TotalNatureTransac'!$E$2:$E$91,'TD_TotalNatureTransac'!$B$2:$B$91,B6,'TD_TotalNatureTransac'!$C$2:$C$91,"ZZ2",'TD_TotalNatureTransac'!$D$2:$D$91,"CARTES") | D6: =SUMIFS('TD_TotalNatureTransac'!$F$2:$F$91,'TD_TotalNatureTransac'!$B$2:$B$91,B6,'TD_TotalNatureTransac'!$C$2:$C$91,"ZZ2",'TD_TotalNatureTransac'!$D$2:$D$91,"CARTES") | E6: =SUMIFS('TD_TotalNatureTransac'!$E$2:$E$91,'TD_TotalNatureTransac'!$B$2:$B$91,B6,'TD_TotalNatureTransac'!$C$2:$C$91,"ZZ2",'TD_TotalNatureTransac'!$D$2:$D$91,"CHEQUES") | F6: =SUMIFS('TD_TotalNatureTransac'!$F$2:$F$91,'TD_TotalNatureTransac'!$B$2:$B$91,B6,'TD_TotalNatureTransac'!$C$2:$C$91,"ZZ2",'TD_TotalNatureTransac'!$D$2:$D$91,"CHEQUES") | G6: =SUMIFS('TD_TotalNatureTransac'!$E$2:$E$91,'TD_TotalNatureTransac'!$B$2:$B$91,B6,'TD_TotalNatureTransac'!$C$2:$C$91,"ZZ2",'TD_TotalNatureTransac'!$D$2:$D$91,"CORRECTION") | H6: =SUMIFS('TD_TotalNatureTransac'!$F$2:$F$91,'TD_TotalNatureTransac'!$B$2:$B$91,B6,'TD_TotalNatureTransac'!$C$2:$C$91,"ZZ2",'TD_TotalNatureTransac'!$D$2:$D$91,"CORRECTION") | I6: =SUMIFS('TD_TotalNatureTransac'!$E$2:$E$91,'TD_TotalNatureTransac'!$B$2:$B$91,B6,'TD_TotalNatureTransac'!$C$2:$C$91,"ZZ2",'TD_TotalNatureTransac'!$D$2:$D$91,"ESPECES") | J6: =SUMIFS('TD_TotalNatureTransac'!$F$2:$F$91,'TD_TotalNatureTransac'!$B$2:$B$91,B6,'TD_TotalNatureTransac'!$C$2:$C$91,"ZZ2",'TD_TotalNatureTransac'!$D$2:$D$91,"ESPECES") | K6: =SUMIFS('TD_TotalNatureTransac'!$E$2:$E$91,'TD_TotalNatureTransac'!$B$2:$B$91,B6,'TD_TotalNatureTransac'!$C$2:$C$91,"ZZ2",'TD_TotalNatureTransac'!$D$2:$D$91,"REF./TIROIR") | L6: =SUMIFS('TD_TotalNatureTransac'!$F$2:$F$91,'TD_TotalNatureTransac'!$B$2:$B$91,B6,'TD_TotalNatureTransac'!$C$2:$C$91,"ZZ2",'TD_TotalNatureTransac'!$D$2:$D$91,"REF./TIROIR")
A7: 2025 | B7: 2025-08 | C7: =SUMIFS('TD_TotalNatureTransac'!$E$2:$E$91,'TD_TotalNatureTransac'!$B$2:$B$91,B7,'TD_TotalNatureTransac'!$C$2:$C$91,"ZZ2",'TD_TotalNatureTransac'!$D$2:$D$91,"CARTES") | D7: =SUMIFS('TD_TotalNatureTransac'!$F$2:$F$91,'TD_TotalNatureTransac'!$B$2:$B$91,B7,'TD_TotalNatureTransac'!$C$2:$C$91,"ZZ2",'TD_TotalNatureTransac'!$D$2:$D$91,"CARTES") | E7: =SUMIFS('TD_TotalNatureTransac'!$E$2:$E$91,'TD_TotalNatureTransac'!$B$2:$B$91,B7,'TD_TotalNatureTransac'!$C$2:$C$91,"ZZ2",'TD_TotalNatureTransac'!$D$2:$D$91,"CHEQUES") | F7: =SUMIFS('TD_TotalNatureTransac'!$F$2:$F$91,'TD_TotalNatureTransac'!$B$2:$B$91,B7,'TD_TotalNatureTransac'!$C$2:$C$91,"ZZ2",'TD_TotalNatureTransac'!$D$2:$D$91,"CHEQUES") | G7: =SUMIFS('TD_TotalNatureTransac'!$E$2:$E$91,'TD_TotalNatureTransac'!$B$2:$B$91,B7,'TD_TotalNatureTransac'!$C$2:$C$91,"ZZ2",'TD_TotalNatureTransac'!$D$2:$D$91,"CORRECTION") | H7: =SUMIFS('TD_TotalNatureTransac'!$F$2:$F$91,'TD_TotalNatureTransac'!$B$2:$B$91,B7,'TD_TotalNatureTransac'!$C$2:$C$91,"ZZ2",'TD_TotalNatureTransac'!$D$2:$D$91,"CORRECTION") | I7: =SUMIFS('TD_TotalNatureTransac'!$E$2:$E$91,'TD_TotalNatureTransac'!$B$2:$B$91,B7,'TD_TotalNatureTransac'!$C$2:$C$91,"ZZ2",'TD_TotalNatureTransac'!$D$2:$D$91,"ESPECES") | J7: =SUMIFS('TD_TotalNatureTransac'!$F$2:$F$91,'TD_TotalNatureTransac'!$B$2:$B$91,B7,'TD_TotalNatureTransac'!$C$2:$C$91,"ZZ2",'TD_TotalNatureTransac'!$D$2:$D$91,"ESPECES") | K7: =SUMIFS('TD_TotalNatureTransac'!$E$2:$E$91,'TD_TotalNatureTransac'!$B$2:$B$91,B7,'TD_TotalNatureTransac'!$C$2:$C$91,"ZZ2",'TD_TotalNatureTransac'!$D$2:$D$91,"REF./TIROIR") | L7: =SUMIFS('TD_TotalNatureTransac'!$F$2:$F$91,'TD_TotalNatureTransac'!$B$2:$B$91,B7,'TD_TotalNatureTransac'!$C$2:$C$91,"ZZ2",'TD_TotalNatureTransac'!$D$2:$D$91,"REF./TIROIR")

Sheet Z2_Total_ModeZ
A1: AJ_ANNEE_Z | B1: AJ_MOIS_Z | C1: CARTES_D_QUANTITE | D1: CARTES_D_MONTANT | E1: CHEQUES_D_QUANTITE | F1: CHEQUES_D_MONTANT | G1: CORRECTION_D_QUANTITE | H1: CORRECTION_D_MONTANT | I1: ESPECES_D_QUANTITE | J1: ESPECES_D_MONTANT | K1: REF__TIROIR_D_QUANTITE | L1: REF__TIROIR_D_MONTANT
A2: 2025 | B2: 2025-01 | C2: =SUMIFS('TD_TotalNatureTransac'!$E$2:$E$91,'TD_TotalNatureTransac'!$B$2:$B$91,B2,'TD_TotalNatureTransac'!$C$2:$C$91,"Z",'TD_TotalNatureTransac'!$D$2:$D$91,"CARTES") | D2: =SUMIFS('TD_TotalNatureTransac'!$F$2:$F$91,'TD_TotalNatureTransac'!$B$2:$B$91,B2,'TD_TotalNatureTransac'!$C$2:$C$91,"Z",'TD_TotalNatureTransac'!$D$2:$D$91,"CARTES") | E2: =SUMIFS('TD_TotalNatureTransac'!$E$2:$E$91,'TD_TotalNatureTransac'!$B$2:$B$91,B2,'TD_TotalNatureTransac'!$C$2:$C$91,"Z",'TD_TotalNatureTransac'!$D$2:$D$91,"CHEQUES") | F2: =SUMIFS('TD_TotalNatureTransac'!$F$2:$F$91,'TD_TotalNatureTransac'!$B$2:$B$91,B2,'TD_TotalNatureTransac'!$C$2:$C$91,"Z",'TD_TotalNatureTransac'!$D$2:$D$91,"CHEQUES") | G2: =SUMIFS('TD_TotalNatureTransac'!$E$2:$E$91,'TD_TotalNatureTransac'!$B$2:$B$91,B2,'TD_TotalNatureTransac'!$C$2:$C$91,"Z",'TD_TotalNatureTransac'!$D$2:$D$91,"CORRECTION") | H2: =SUMIFS('TD_TotalNatureTransac'!$F$2:$F$91,'TD_TotalNatureTransac'!$B$2:$B$91,B2,'TD_TotalNatureTransac'!$C$2:$C$91,"Z",'TD_TotalNatureTransac'!$D$2:$D$91,"CORRECTION") | I2: =SUMIFS('TD_TotalNatureTransac'!$E$2:$E$91,'TD_TotalNatureTransac'!$B$2:$B$91,B2,'TD_TotalNatureTransac'!$C$2:$C$91,"Z",'TD_TotalNatureTransac'!$D$2:$D$91,"ESPECES") | J2: =SUMIFS('TD_TotalNatureTransac'!$F$2:$F$91,'TD_TotalNatureTransac'!$B$2:$B$91,B2,'TD_TotalNatureTransac'!$C$2:$C$91,"Z",'TD_TotalNatureTransac'!$D$2:$D$91,"ESPECES") | K2: =SUMIFS('TD_TotalNatureTransac'!$E$2:$E$91,'TD_TotalNatureTransac'!$B$2:$B$91,B2,'TD_TotalNatureTransac'!$C$2:$C$91,"Z",'TD_TotalNatureTransac'!$D$2:$D$91,"REF./TIROIR") | L2: =SUMIFS('TD_TotalNatureTransac'!$F$2:$F$91,'TD_TotalNatureTransac'!$B$2:$B$91,B2,'TD_TotalNatureTransac'!$C$2:$C$91,"Z",'TD_TotalNatureTransac'!$D$2:$D$91,"REF./TIROIR")
A3: 2025 | B3: 2025-02 | C3: =SUMIFS('TD_TotalNatureTransac'!$E$2:$E$91,'TD_TotalNatureTransac'!$B$2:$B$91,B3,'TD_TotalNatureTransac'!$C$2:$C$91,"Z",'TD_TotalNatureTransac'!$D$2:$D$91,"CARTES") | D3: =SUMIFS('TD_TotalNatureTransac'!$F$2:$F$91,'TD_TotalNatureTransac'!$B$2:$B$91,B3,'TD_TotalNatureTransac'!$C$2:$C$91,"Z",'TD_TotalNatureTransac'!$D$2:$D$91,"CARTES") | E3: =SUMIFS('TD_TotalNatureTransac'!$E$2:$E$91,'TD_TotalNatureTransac'!$B$2:$B$91,B3,'TD_TotalNatureTransac'!$C$2:$C$91,"Z",'TD_TotalNatureTransac'!$D$2:$D$91,"CHEQUES") | F3: =SUMIFS('TD_TotalNatureTransac'!$F$2:$F$91,'TD_TotalNatureTransac'!$B$2:$B$91,B3,'TD_TotalNatureTransac'!$C$2:$C$91,"Z",'TD_TotalNatureTransac'!$D$2:$D$91,"CHEQUES") | G3: =SUMIFS('TD_TotalNatureTransac'!$E$2:$E$91,'TD_TotalNatureTransac'!$B$2:$B$91,B3,'TD_TotalNatureTransac'!$C$2:$C$91,"Z",'TD_TotalNatureTransac'!$D$2:$D$91,"CORRECTION") | H3: =SUMIFS('TD_TotalNatureTransac'!$F$2:$F$91,'TD_TotalNatureTransac'!$B$2:$B$91,B3,'TD_TotalNatureTransac'!$C$2:$C$91,"Z",'TD_TotalNatureTransac'!$D$2:$D$91,"CORRECTION") | I3: =SUMIFS('TD_TotalNatureTransac'!$E$2:$E$91,'TD_TotalNatureTransac'!$B$2:$B$91,B3,'TD_TotalNatureTransac'!$C$2:$C$91,"Z",'TD_TotalNatureTransac'!$D$2:$D$91,"ESPECES") | J3: =SUMIFS('TD_TotalNatureTransac'!$F$2:$F$91,'TD_TotalNatureTransac'!$B$2:$B$91,B3,'TD_TotalNatureTransac'!$C$2:$C$91,"Z",'TD_TotalNatureTransac'!$D$2:$D$91,"ESPECES") | K3: =SUMIFS('TD_TotalNatureTransac'!$E$2:$E$91,'TD_TotalNatureTransac'!$B$2:$B$91,B3,'TD_TotalNatureTransac'!$C$2:$C$91,"Z",'TD_TotalNatureTransac'!$D$2:$D$91,"REF./TIROIR") | L3: =SUMIFS('TD_TotalNatureTransac'!$F$2:$F$91,'TD_TotalNatureTransac'!$B$2:$B$91,B3,'TD_TotalNatureTransac'!$C$2:$C$91,"Z",'TD_TotalNatureTransac'!$D$2:$D$91,"REF./TIROIR")
A4: 2025 | B4: 2025-03 | C4: =SUMIFS('TD_TotalNatureTransac'!$E$2:$E$91,'TD_TotalNatureTransac'!$B$2:$B$91,B4,'TD_TotalNatureTransac'!$C$2:$C$91,"Z",'TD_TotalNatureTransac'!$D$2:$D$91,"CARTES") | D4: =SUMIFS('TD_TotalNatureTransac'!$F$2:$F$91,'TD_TotalNatureTransac'!$B$2:$B$91,B4,'TD_TotalNatureTransac'!$C$2:$C$91,"Z",'TD_TotalNatureTransac'!$D$2:$D$91,"CARTES") | E4: =SUMIFS('TD_TotalNatureTransac'!$E$2:$E$91,'TD_TotalNatureTransac'!$B$2:$B$91,B4,'TD_TotalNatureTransac'!$C$2:$C$91,"Z",'TD_TotalNatureTransac'!$D$2:$D$91,"CHEQUES") | F4: =SUMIFS('TD_TotalNatureTransac'!$F$2:$F$91,'TD_TotalNatureTransac'!$B$2:$B$91,B4,'TD_TotalNatureTransac'!$C$2:$C$91,"Z",'TD_TotalNatureTransac'!$D$2:$D$91,"CHEQUES") | G4: =SUMIFS('TD_TotalNatureTransac'!$E$2:$E$91,'TD_TotalNatureTransac'!$B$2:$B$91,B4,'TD_TotalNatureTransac'!$C$2:$C$91,"Z",'TD_TotalNatureTransac'!$D$2:$D$91,"CORRECTION") | H4: =SUMIFS('TD_TotalNatureTransac'!$F$2:$F$91,'TD_TotalNatureTransac'!$B$2:$B$91,B4,'TD_TotalNatureTransac'!$C$2:$C$91,"Z",'TD_TotalNatureTransac'!$D$2:$D$91,"CORRECTION") | I4: =SUMIFS('TD_TotalNatureTransac'!$E$2:$E$91,'TD_TotalNatureTransac'!$B$2:$B$91,B4,'TD_TotalNatureTransac'!$C$2:$C$91,"Z",'TD_TotalNatureTransac'!$D$2:$D$91,"ESPECES") | J4: =SUMIFS('TD_TotalNatureTransac'!$F$2:$F$91,'TD_TotalNatureTransac'!$B$2:$B$91,B4,'TD_TotalNatureTransac'!$C$2:$C$91,"Z",'TD_TotalNatureTransac'!$D$2:$D$91,"ESPECES") | K4: =SUMIFS('TD_TotalNatureTransac'!$E$2:$E$91,'TD_TotalNatureTransac'!$B$2:$B$91,B4,'TD_TotalNatureTransac'!$C$2:$C$91,"Z",'TD_TotalNatureTransac'!$D$2:$D$91,"REF./TIROIR") | L4: =SUMIFS('TD_TotalNatureTransac'!$F$2:$F$91,'TD_TotalNatureTransac'!$B$2:$B$91,B4,'TD_TotalNatureTransac'!$C$2:$C$91,"Z",'TD_TotalNatureTransac'!$D$2:$D$91,"REF./TIROIR")
A5: 2025 | B5: 2025-04|2025-05|2025-06 | C5: =SUMIFS('TD_TotalNatureTransac'!$E$2:$E$91,'TD_TotalNatureTransac'!$B$2:$B$91,B5,'TD_TotalNatureTransac'!$C$2:$C$91,"Z",'TD_TotalNatureTransac'!$D$2:$D$91,"CARTES") | D5: =SUMIFS('TD_TotalNatureTransac'!$F$2:$F$91,'TD_TotalNatureTransac'!$B$2:$B$91,B5,'TD_TotalNatureTransac'!$C$2:$C$91,"Z",'TD_TotalNatureTransac'!$D$2:$D$91,"CARTES") | E5: =SUMIFS('TD_TotalNatureTransac'!$E$2:$E$91,'TD_TotalNatureTransac'!$B$2:$B$91,B5,'TD_TotalNatureTransac'!$C$2:$C$91,"Z",'TD_TotalNatureTransac'!$D$2:$D$91,"CHEQUES") | F5: =SUMIFS('TD_TotalNatureTransac'!$F$2:$F$91,'TD_TotalNatureTransac'!$B$2:$B$91,B5,'TD_TotalNatureTransac'!$C$2:$C$91,"Z",'TD_TotalNatureTransac'!$D$2:$D$91,"CHEQUES") | G5: =SUMIFS('TD_TotalNatureTransac'!$E$2:$E$91,'TD_TotalNatureTransac'!$B$2:$B$91,B5,'TD_TotalNatureTransac'!$C$2:$C$91,"Z",'TD_TotalNatureTransac'!$D$2:$D$91,"CORRECTION") | H5: =SUMIFS('TD_TotalNatureTransac'!$F$2:$F$91,'TD_TotalNatureTransac'!$B$2:$B$91,B5,'TD_TotalNatureTransac'!$C$2:$C$91,"Z",'TD_TotalNatureTransac'!$D$2:$D$91,"CORRECTION") | I5: =SUMIFS('TD_TotalNatureTransac'!$E$2:$E$91,'TD_TotalNatureTransac'!$B$2:$B$91,B5,'TD_TotalNatureTransac'!$C$2:$C$91,"Z",'TD_TotalNatureTransac'!$D$2:$D$91,"ESPECES") | J5: =SUMIFS('TD_TotalNatureTransac'!$F$2:$F$91,'TD_TotalNatureTransac'!$B$2:$B$91,B5,'TD_TotalNatureTransac'!$C$2:$C$91,"Z",'TD_TotalNatureTransac'!$D$2:$D$91,"ESPECES") | K5: =SUMIFS('TD_TotalNatureTransac'!$E$2:$E$91,'TD_TotalNatureTransac'!$B$2:$B$91,B5,'TD_TotalNatureTransac'!$C$2:$C$91,"Z",'TD_TotalNatureTransac'!$D$2:$D$91,"REF./TIROIR") | L5: =SUMIFS('TD_TotalNatureTransac'!$F$2:$F$91,'TD_TotalNatureTransac'!$B$2:$B$91,B5,'TD_TotalNatureTransac'!$C$2:$C$91,"Z",'TD_TotalNatureTransac'!$D$2:$D$91,"REF./TIROIR")
A6: 2025 | B6: 2025-07 | C6: =SUMIFS('TD_TotalNatureTransac'!$E$2:$E$91,'TD_TotalNatureTransac'!$B$2:$B$91,B6,'TD_TotalNatureTransac'!$C$2:$C$91,"Z",'TD_TotalNatureTransac'!$D$2:$D$91,"CARTES") | D6: =SUMIFS('TD_TotalNatureTransac'!$F$2:$F$91,'TD_TotalNatureTransac'!$B$2:$B$91,B6,'TD_TotalNatureTransac'!$C$2:$C$91,"Z",'TD_TotalNatureTransac'!$D$2:$D$91,"CARTES") | E6: =SUMIFS('TD_TotalNatureTransac'!$E$2:$E$91,'TD_TotalNatureTransac'!$B$2:$B$91,B6,'TD_TotalNatureTransac'!$C$2:$C$91,"Z",'TD_TotalNatureTransac'!$D$2:$D$91,"CHEQUES") | F6: =SUMIFS('TD_TotalNatureTransac'!$F$2:$F$91,'TD_TotalNatureTransac'!$B$2:$B$91,B6,'TD_TotalNatureTransac'!$C$2:$C$91,"Z",'TD_TotalNatureTransac'!$D$2:$D$91,"CHEQUES") | G6: =SUMIFS('TD_TotalNatureTransac'!$E$2:$E$91,'TD_TotalNatureTransac'!$B$2:$B$91,B6,'TD_TotalNatureTransac'!$C$2:$C$91,"Z",'TD_TotalNatureTransac'!$D$2:$D$91,"CORRECTION") | H6: =SUMIFS('TD_TotalNatureTransac'!$F$2:$F$91,'TD_TotalNatureTransac'!$B$2:$B$91,B6,'TD_TotalNatureTransac'!$C$2:$C$91,"Z",'TD_TotalNatureTransac'!$D$2:$D$91,"CORRECTION") | I6: =SUMIFS('TD_TotalNatureTransac'!$E$2:$E$91,'TD_TotalNatureTransac'!$B$2:$B$91,B6,'TD_TotalNatureTransac'!$C$2:$C$91,"Z",'TD_TotalNatureTransac'!$D$2:$D$91,"ESPECES") | J6: =SUMIFS('TD_TotalNatureTransac'!$F$2:$F$91,'TD_TotalNatureTransac'!$B$2:$B$91,B6,'TD_TotalNatureTransac'!$C$2:$C$91,"Z",'TD_TotalNatureTransac'!$D$2:$D$91,"ESPECES") | K6: =SUMIFS('TD_TotalNatureTransac'!$E$2:$E$91,'TD_TotalNatureTransac'!$B$2:$B$91,B6,'TD_TotalNatureTransac'!$C$2:$C$91,"Z",'TD_TotalNatureTransac'!$D$2:$D$91,"REF./TIROIR") | L6: =SUMIFS('TD_TotalNatureTransac'!$F$2:$F$91,'TD_TotalNatureTransac'!$B$2:$B$91,B6,'TD_TotalNatureTransac'!$C$2:$C$91,"Z",'TD_TotalNatureTransac'!$D$2:$D$91,"REF./TIROIR")
A7: 2025 | B7: 2025-08 | C7: =SUMIFS('TD_TotalNatureTransac'!$E$2:$E$91,'TD_TotalNatureTransac'!$B$2:$B$91,B7,'TD_TotalNatureTransac'!$C$2:$C$91,"Z",'TD_TotalNatureTransac'!$D$2:$D$91,"CARTES") | D7: =SUMIFS('TD_TotalNatureTransac'!$F$2:$F$91,'TD_TotalNatureTransac'!$B$2:$B$91,B7,'TD_TotalNatureTransac'!$C$2:$C$91,"Z",'TD_TotalNatureTransac'!$D$2:$D$91,"CARTES") | E7: =SUMIFS('TD_TotalNatureTransac'!$E$2:$E$91,'TD_TotalNatureTransac'!$B$2:$B$91,B7,'TD_TotalNatureTransac'!$C$2:$C$91,"Z",'TD_TotalNatureTransac'!$D$2:$D$91,"CHEQUES") | F7: =SUMIFS('TD_TotalNatureTransac'!$F$2:$F$91,'TD_TotalNatureTransac'!$B$2:$B$91,B7,'TD_TotalNatureTransac'!$C$2:$C$91,"Z",'TD_TotalNatureTransac'!$D$2:$D$91,"CHEQUES") | G7: =SUMIFS('TD_TotalNatureTransac'!$E$2:$E$91,'TD_TotalNatureTransac'!$B$2:$B$91,B7,'TD_TotalNatureTransac'!$C$2:$C$91,"Z",'TD_TotalNatureTransac'!$D$2:$D$91,"CORRECTION") | H7: =SUMIFS('TD_TotalNatureTransac'!$F$2:$F$91,'TD_TotalNatureTransac'!$B$2:$B$91,B7,'TD_TotalNatureTransac'!$C$2:$C$91,"Z",'TD_TotalNatureTransac'!$D$2:$D$91,"CORRECTION") | I7: =SUMIFS('TD_TotalNatureTransac'!$E$2:$E$91,'TD_TotalNatureTransac'!$B$2:$B$91,B7,'TD_TotalNatureTransac'!$C$2:$C$91,"Z",'TD_TotalNatureTransac'!$D$2:$D$91,"ESPECES") | J7: =SUMIFS('TD_TotalNatureTransac'!$F$2:$F$91,'TD_TotalNatureTransac'!$B$2:$B$91,B7,'TD_TotalNatureTransac'!$C$2:$C$91,"Z",'TD_TotalNatureTransac'!$D$2:$D$91,"ESPECES") | K7: =SUMIFS('TD_TotalNatureTransac'!$E$2:$E$91,'TD_TotalNatureTransac'!$B$2:$B$91,B7,'TD_TotalNatureTransac'!$C$2:$C$91,"Z",'TD_TotalNatureTransac'!$D$2:$D$91,"REF./TIROIR") | L7: =SUMIFS('TD_TotalNatureTransac'!$F$2:$F$91,'TD_TotalNatureTransac'!$B$2:$B$91,B7,'TD_TotalNatureTransac'!$C$2:$C$91,"Z",'TD_TotalNatureTransac'!$D$2:$D$91,"REF./TIROIR")

Sheet Compare_ZZ1_vs_ZZ2
A1: AJ_ANNEE_Z | B1: AJ_MOIS_Z | C1: CARTES_AJ_ECART_QTE | D1: CARTES_AJ_ECART_MONTANT | E1: CHEQUES_AJ_ECART_QTE | F1: CHEQUES_AJ_ECART_MONTANT | G1: CORRECTION_AJ_ECART_QTE | H1: CORRECTION_AJ_ECART_MONTANT | I1: ESPECES_AJ_ECART_QTE | J1: ESPECES_AJ_ECART_MONTANT | K1: REF__TIROIR_AJ_ECART_QTE | L1: REF__TIROIR_AJ_ECART_MONTANT
A2: 2025 | B2: 2025-01 | C2: ='Z2_Total_ModeZZ1'!C2-'Z2_Total_ModeZZ2'!C2 | D2: ='Z2_Total_ModeZZ1'!D2-'Z2_Total_ModeZZ2'!D2 | E2: ='Z2_Total_ModeZZ1'!E2-'Z2_Total_ModeZZ2'!E2 | F2: ='Z2_Total_ModeZZ1'!F2-'Z2_Total_ModeZZ2'!F2 | G2: ='Z2_Total_ModeZZ1'!G2-'Z2_Total_ModeZZ2'!G2 | H2: ='Z2_Total_ModeZZ1'!H2-'Z2_Total_ModeZZ2'!H2 | I2: ='Z2_Total_ModeZZ1'!I2-'Z2_Total_ModeZZ2'!I2 | J2: ='Z2_Total_ModeZZ1'!J2-'Z2_Total_ModeZZ2'!J2 | ... L2: ='Z2_Total_ModeZZ1'!L2-'Z2_Total_ModeZZ2'!L2
A3: 2025 | B3: 2025-02 | C3: ='Z2_Total_ModeZZ1'!C3-'Z2_Total_ModeZZ2'!C3 | D3: ='Z2_Total_ModeZZ1'!D3-'Z2_Total_ModeZZ2'!D3 | E3: ='Z2_Total_ModeZZ1'!E3-'Z2_Total_ModeZZ2'!E3 | F3: ='Z2_Total_ModeZZ1'!F3-'Z2_Total_ModeZZ2'!F3 | G3: ='Z2_Total_ModeZZ1'!G3-'Z2_Total_ModeZZ2'!G3 | H3: ='Z2_Total_ModeZZ1'!H3-'Z2_Total_ModeZZ2'!H3 | I3: ='Z2_Total_ModeZZ1'!I3-'Z2_Total_ModeZZ2'!I3 | J3: ='Z2_Total_ModeZZ1'!J3-'Z2_Total_ModeZZ2'!J3 | ... L3: ='Z2_Total_ModeZZ1'!L3-'Z2_Total_ModeZZ2'!L3
A4: 2025 | B4: 2025-03 | C4: ='Z2_Total_ModeZZ1'!C4-'Z2_Total_ModeZZ2'!C4 | D4: ='Z2_Total_ModeZZ1'!D4-'Z2_Total_ModeZZ2'!D4 | E4: ='Z2_Total_ModeZZ1'!E4-'Z2_Total_ModeZZ2'!E4 | F4: ='Z2_Total_ModeZZ1'!F4-'Z2_Total_ModeZZ2'!F4 | G4: ='Z2_Total_ModeZZ1'!G4-'Z2_Total_ModeZZ2'!G4 | H4: ='Z2_Total_ModeZZ1'!H4-'Z2_Total_ModeZZ2'!H4 | I4: ='Z2_Total_ModeZZ1'!I4-'Z2_Total_ModeZZ2'!I4 | J4: ='Z2_Total_ModeZZ1'!J4-'Z2_Total_ModeZZ2'!J4 | ... L4: ='Z2_Total_ModeZZ1'!L4-'Z2_Total_ModeZZ2'!L4
A5: 2025 | B5: 2025-04|2025-05|2025-06 | C5: ='Z2_Total_ModeZZ1'!C5-'Z2_Total_ModeZZ2'!C5 | D5: ='Z2_Total_ModeZZ1'!D5-'Z2_Total_ModeZZ2'!D5 | E5: ='Z2_Total_ModeZZ1'!E5-'Z2_Total_ModeZZ2'!E5 | F5: ='Z2_Total_ModeZZ1'!F5-'Z2_Total_ModeZZ2'!F5 | G5: ='Z2_Total_ModeZZ1'!G5-'Z2_Total_ModeZZ2'!G5 | H5: ='Z2_Total_ModeZZ1'!H5-'Z2_Total_ModeZZ2'!H5 | I5: ='Z2_Total_ModeZZ1'!I5-'Z2_Total_ModeZZ2'!I5 | J5: ='Z2_Total_ModeZZ1'!J5-'Z2_Total_ModeZZ2'!J5 | ... L5: ='Z2_Total_ModeZZ1'!L5-'Z2_Total_ModeZZ2'!L5
A6: 2025 | B6: 2025-07 | C6: ='Z2_Total_ModeZZ1'!C6-'Z2_Total_ModeZZ2'!C6 | D6: ='Z2_Total_ModeZZ1'!D6-'Z2_Total_ModeZZ2'!D6 | E6: ='Z2_Total_ModeZZ1'!E6-'Z2_Total_ModeZZ2'!E6 | F6: ='Z2_Total_ModeZZ1'!F6-'Z2_Total_ModeZZ2'!F6 | G6: ='Z2_Total_ModeZZ1'!G6-'Z2_Total_ModeZZ2'!G6 | H6: ='Z2_Total_ModeZZ1'!H6-'Z2_Total_ModeZZ2'!H6 | I6: ='Z2_Total_ModeZZ1'!I6-'Z2_Total_ModeZZ2'!I6 | J6: ='Z2_Total_ModeZZ1'!J6-'Z2_Total_ModeZZ2'!J6 | ... L6: ='Z2_Total_ModeZZ1'!L6-'Z2_Total_ModeZZ2'!L6
A7: 2025 | B7: 2025-08 | C7: ='Z2_Total_ModeZZ1'!C7-'Z2_Total_ModeZZ2'!C7 | D7: ='Z2_Total_ModeZZ1'!D7-'Z2_Total_ModeZZ2'!D7 | E7: ='Z2_Total_ModeZZ1'!E7-'Z2_Total_ModeZZ2'!E7 | F7: ='Z2_Total_ModeZZ1'!F7-'Z2_Total_ModeZZ2'!F7 | G7: ='Z2_Total_ModeZZ1'!G7-'Z2_Total_ModeZZ2'!G7 | H7: ='Z2_Total_ModeZZ1'!H7-'Z2_Total_ModeZZ2'!H7 | I7: ='Z2_Total_ModeZZ1'!I7-'Z2_Total_ModeZZ2'!I7 | J7: ='Z2_Total_ModeZZ1'!J7-'Z2_Total_ModeZZ2'!J7 | ... L7: ='Z2_Total_ModeZZ1'!L7-'Z2_Total_ModeZZ2'!L7

Sheet Compare_ZZ1_vs_EJ
A1: AJ_ANNEE_Z | B1: AJ_MOIS_Z | C1: CARTES_Z2 | D1: CARTES_EJ | E1: AJ_ECART_CARTES | F1: CHEQUES_Z2 | G1: CHEQUES_EJ | H1: AJ_ECART_CHEQUES | I1: ESPECES_Z2 | J1: ESPECES_EJ | K1: AJ_ECART_ESPECES
A2: 2025 | B2: 2025-01 | C2: ='Z2_Total_ModeZZ1'!D2 | D2: 3089.5 | E2: =C2-D2 | F2: ='Z2_Total_ModeZZ1'!F2 | G2: 0 | H2: =F2-G2 | I2: ='Z2_Total_ModeZZ1'!J2 | J2: 6334.7 | K2: =I2-J2
A3: 2025 | B3: 2025-02 | C3: ='Z2_Total_ModeZZ1'!D3 | D3: 7497 | E3: =C3-D3 | F3: ='Z2_Total_ModeZZ1'!F3 | G3: 0 | H3: =F3-G3 | I3: ='Z2_Total_ModeZZ1'!J3 | J3: 10332.8 | K3: =I3-J3
A4: 2025 | B4: 2025-03 | C4: ='Z2_Total_ModeZZ1'!D4 | D4: 9581 | E4: =C4-D4 | F4: ='Z2_Total_ModeZZ1'!F4 | G4: 0 | H4: =F4-G4 | I4: ='Z2_Total_ModeZZ1'!J4 | J4: 11051.7 | K4: =I4-J4
A5: 2025 | B5: 2025-04|2025-05|2025-06 | C5: ='Z2_Total_ModeZZ1'!D5 | D5: 5642.4 | E5: =C5-D5 | F5: ='Z2_Total_ModeZZ1'!F5 | G5: 0 | H5: =F5-G5 | I5: ='Z2_Total_ModeZZ1'!J5 | J5: 6815.7 | K5: =I5-J5
A6: 2025 | B6: 2025-07 | C6: ='Z2_Total_ModeZZ1'!D6 | D6: 2581 | E6: =C6-D6 | F6: ='Z2_Total_ModeZZ1'!F6 | G6: 0 | H6: =F6-G6 | I6: ='Z2_Total_ModeZZ1'!J6 | J6: 17603.9 | K6: =I6-J6
A7: 2025 | B7: 2025-08 | C7: ='Z2_Total_ModeZZ1'!D7 | D7: 2072 | E7: =C7-D7 | F7: ='Z2_Total_ModeZZ1'!F7 | G7: 0 | H7: =F7-G7 | I7: ='Z2_Total_ModeZZ1'!J7 | J7: 1914 | K7: =I7-J7
