Workbook

Sheet Z1_2025_MATURIN_0
A1: nomfichier | B1: E_MODELE | C1: E_MACHINE | D1: E_RAPPORT | E1: E_FICHIER | F1: E_MODE | G1: E_COMPTEUR_Z | H1: E_DATE | I1: E_HEURE | J1: D_ENREGISTREMENT | K1: D_DESIGNATION | L1: D_QUANTITE | M1: D_MONTANT
A2: Z001_01_012025_MATURIN.CSV | C2: MC#01 | D2: FONC FIXES | E2: FILE001 | F2: Z | G2: 0041 | H2: 45689 | I2: 15:53 | J2: 0001 | K2: CA BRUT | L2: 31 | M2: 11680.3
A3: Z001_01_012025_MATURIN.CSV | C3: MC#01 | D3: FONC FIXES | E3: FILE001 | F3: Z | G3: 0041 | H3: 45689 | I3: 15:53 | J3: 0002 | K3: CA NET | L3: 19 | M3: 11680.3
A4: Z001_01_012025_MATURIN.CSV | C4: MC#01 | D4: FONC FIXES | E4: FILE001 | F4: Z | G4: 0041 | H4: 45689 | I4: 15:53 | J4: 0003 | K4: ESP.TIROIR | L4: 0 | M4: 2731.5
A5: Z001_01_012025_MATURIN.CSV | C5: MC#01 | D5: FONC FIXES | E5: FILE001 | F5: Z | G5: 0041 | H5: 45689 | I5: 15:53 | J5: 0004 | K5: CB.TIROIR | L5: 0 | M5: 8948.8
A6: Z001_01_012025_MATURIN.CSV | C6: MC#01 | D6: FONC FIXES | E6: FILE001 | F6: Z | G6: 0041 | H6: 45689 | I6: 15:53 | J6: 0005 | K6: CHQ.TIROIR | L6: 0 | M6: 0
A7: Z001_01_012025_MATURIN.CSV | C7: MC#01 | D7: FONC FIXES | E7: FILE001 | F7: Z | G7: 0041 | H7: 45689 | I7: 15:53 | J7: 0006 | K7: CR.TIROIR(1) | L7: 0 | M7: 0
A8: Z001_01_012025_MATURIN.CSV | C8: MC#01 | D8: FONC FIXES | E8: FILE001 | F8: Z | G8: 0041 | H8: 45689 | I8: 15:53 | J8: 0007 | K8: CR.TIROIR(2) | L8: 0 | M8: 0
A9: Z001_01_012025_MATURIN.CSV | C9: MC#01 | D9: FONC FIXES | E9: FILE001 | F9: Z | G9: 0041 | H9: 45689 | I9: 15:53 | J9: 0008 | K9: CR.TIROIR(3) | L9: 0 | M9: 0
A10: Z001_01_012025_MATURIN.CSV | C10: MC#01 | D10: FONC FIXES | E10: FILE001 | F10: Z | G10: 0041 | H10: 45689 | I10: 15:53 | J10: 0009 | K10: CR.TIROIR(4) | L10: 0 | M10: 0
A11: Z001_01_012025_MATURIN.CSV | C11: MC#01 | D11: FONC FIXES | E11: FILE001 | F11: Z | G11: 0041 | H11: 45689 | I11: 15:53 | J11: 0010 | K11: ESP.TIROIR2 | L11: 0 | M11: 0
A12: Z001_01_012025_MATURIN.CSV | C12: MC#01 | D12: FONC FIXES | E12: FILE001 | F12: Z | G12: 0041 | H12: 45689 | I12: 15:53 | J12: 0011 | K12: CB.TIROIR2 | L12: 0 | M12: 0
A13: Z001_01_012025_MATURIN.CSV | C13: MC#01 | D13: FONC FIXES | E13: FILE001 | F13: Z | G13: 0041 | H13: 45689 | I13: 15:53 | J13: 0012 | K13: CHQ.TIROIR2 | L13: 0 | M13: 0
... A27: Z001_01_012025_MATURIN.CSV | C27: MC#01 | D27: FONC FIXES | E27: FILE001 | F27: Z | G27: 0041 | H27: 45689 | I27: 15:53 | J27: 0026 | K27: TOTAL REMISE | L27: 0 | M27: 0
A28: Z001_01_012025_MATURIN.CSV | C28: MC#01 | D28: FONC FIXES | E28: FILE001 | F28: Z | G28: 0041 | H28: 45689 | I28: 15:53 | J28: 0027 | L28: 0 | M28: 0
A29: Z001_01_012025_MATURIN.CSV | C29: MC#01 | D29: FONC FIXES | E29: FILE001 | F29: Z | G29: 0041 | H29: 45689 | I29: 15:53 | J29: 0028 | K29: RETOUR+ANNUL | L29: 0 | M29: 0
A30: Z001_01_012025_MATURIN.CSV | C30: MC#01 | D30: FONC FIXES | E30: FILE001 | F30: Z | G30: 0041 | H30: 45689 | I30: 15:53 | J30: 0029 | K30: TL ARRONDI | L30: 0 | M30: 0
A31: Z001_01_012025_MATURIN.CSV | C31: MC#01 | D31: FONC FIXES | E31: FILE001 | F31: Z | G31: 0041 | H31: 45689 | I31: 15:53 | J31: 0030 | K31: TL ARRONDI | L31: 0 | M31: 0
A32: Z001_01_012025_MATURIN.CSV | C32: MC#01 | D32: FONC FIXES | E32: FILE001 | F32: Z | G32: 0041 | H32: 45689 | I32: 15:53 | J32: 0031 | K32: NUL TICKET | L32: 0 | M32: 0
A33: Z001_01_012025_MATURIN.CSV | C33: MC#01 | D33: FONC FIXES | E33: FILE001 | F33: Z | G33: 0041 | H33: 45689 | I33: 15:53 | J33: 0032 | L33: 0 | M33: 0
A34: Z001_01_012025_MATURIN.CSV | C34: MC#01 | D34: FONC FIXES | E34: FILE001 | F34: Z | G34: 0041 | H34: 45689 | I34: 15:53 | J34: 0033 | K34: HORS TAXE 1 | L34: 0 | M34: 9733.59
A35: Z001_01_012025_MATURIN.CSV | C35: MC#01 | D35: FONC FIXES | E35: FILE001 | F35: Z | G35: 0041 | H35: 45689 | I35: 15:53 | J35: 0034 | K35: TVA 1 | L35: 0 | M35: 1946.71
A36: Z001_01_012025_MATURIN.CSV | C36: MC#01 | D36: FONC FIXES | E36: FILE001 | F36: Z | G36: 0041 | H36: 45689 | I36: 15:53 | J36: 0035 | K36: HORS TAXE 2 | L36: 0 | M36: 0
A37: Z001_01_012025_MATURIN.CSV | C37: MC#01 | D37: FONC FIXES | E37: FILE001 | F37: Z | G37: 0041 | H37: 45689 | I37: 15:53 | J37: 0036 | K37: TVA 2 | L37: 0 | M37: 0
A38: Z001_01_012025_MATURIN.CSV | C38: MC#01 | D38: FONC FIXES | E38: FILE001 | F38: Z | G38: 0041 | H38: 45689 | I38: 15:53 | J38: 0037 | K38: HORS TAXE 3 | L38: 0 | M38: 0
A39: Z001_01_012025_MATURIN.CSV | C39: MC#01 | D39: FONC FIXES | E39: FILE001 | F39: Z | G39: 0041 | H39: 45689 | I39: 15:53 | J39: 0038 | K39: TVA 3 | L39: 0 | M39: 0
A40: Z001_01_012025_MATURIN.CSV | C40: MC#01 | D40: FONC FIXES | E40: FILE001 | F40: Z | G40: 0041 | H40: 45689 | I40: 15:53 | J40: 0039 | K40: HORS TAXE 4 | L40: 0 | M40: 0
A41: Z001_01_012025_MATURIN.CSV | C41: MC#01 | D41: FONC FIXES | E41: FILE001 | F41: Z | G41: 0041 | H41: 45689 | I41: 15:53 | J41: 0040 | K41: TVA 4 | L41: 0 | M41: 0
A42: Z001_01_012025_MATURIN.CSV | C42: MC#01 | D42: FONC FIXES | E42: FILE001 | F42: Z | G42: 0041 | H42: 45689 | I42: 15:53 | J42: 0041 | K42: NON TAXABLE | L42: 0 | M42: 0
A43: Z001_01_022025_MATURIN.CSV | C43: MC#01 | D43: FONC FIXES | E43: FILE001 | F43: Z | G43: 0042 | H43: 45717 | I43: 13:36 | J43: 0001 | K43: CA BRUT | L43: 16 | M43: 4578.8
A44: Z001_01_022025_MATURIN.CSV | C44: MC#01 | D44: FONC FIXES | E44: FILE001 | F44: Z | G44: 0042 | H44: 45717 | I44: 13:36 | J44: 0002 | K44: CA NET | L44: 13 | M44: 4578.8
A45: Z001_01_022025_MATURIN.CSV | C45: MC#01 | D45: FONC FIXES | E45: FILE001 | F45: Z | G45: 0042 | H45: 45717 | I45: 13:36 | J45: 0003 | K45: ESP.TIROIR | L45: 0 | M45: 2530
... A68: Z001_01_022025_MATURIN.CSV | C68: MC#01 | D68: FONC FIXES | E68: FILE001 | F68: Z | G68: 0042 | H68: 45717 | I68: 13:36 | J68: 0026 | K68: TOTAL REMISE | L68: 0 | M68: 0
A69: Z001_01_022025_MATURIN.CSV | C69: MC#01 | D69: FONC FIXES | E69: FILE001 | F69: Z | G69: 0042 | H69: 45717 | I69: 13:36 | J69: 0027 | L69: 0 | M69: 0
A70: Z001_01_022025_MATURIN.CSV | C70: MC#01 | D70: FONC FIXES | E70: FILE001 | F70: Z | G70: 0042 | H70: 45717 | I70: 13:36 | J70: 0028 | K70: RETOUR+ANNUL | L70: 0 | M70: 0
A71: Z001_01_022025_MATURIN.CSV | C71: MC#01 | D71: FONC FIXES | E71: FILE001 | F71: Z | G71: 0042 | H71: 45717 | I71: 13:36 | J71: 0029 | K71: TL ARRONDI | L71: 0 | M71: 0
A72: Z001_01_022025_MATURIN.CSV | C72: MC#01 | D72: FONC FIXES | E72: FILE001 | F72: Z | G72: 0042 | H72: 45717 | I72: 13:36 | J72: 0030 | K72: TL ARRONDI | L72: 0 | M72: 0
A73: Z001_01_022025_MATURIN.CSV | C73: MC#01 | D73: FONC FIXES | E73: FILE001 | F73: Z | G73: 0042 | H73: 45717 | I73: 13:36 | J73: 0031 | K73: NUL TICKET | L73: 0 | M73: 0
A74: Z001_01_022025_MATURIN.CSV | C74: MC#01 | D74: FONC FIXES | E74: FILE001 | F74: Z | G74: 0042 | H74: 45717 | I74: 13:36 | J74: 0032 | L74: 0 | M74: 0
A75: Z001_01_022025_MATURIN.CSV | C75: MC#01 | D75: FONC FIXES | E75: FILE001 | F75: Z | G75: 0042 | H75: 45717 | I75: 13:36 | J75: 0033 | K75: HORS TAXE 1 | L75: 0 | M75: 3815.68
...

Sheet Z1_CplteAnneeMois
A1: nomfichier | B1: E_MODELE | C1: E_MACHINE | D1: E_RAPPORT | E1: E_FICHIER | F1: E_MODE | G1: E_COMPTEUR_Z | H1: E_DATE | I1: E_HEURE | J1: D_ENREGISTREMENT | K1: D_DESIGNATION | L1: D_QUANTITE | M1: D_MONTANT | N1: AJ_ANNEE_Z | O1: AJ_MOIS_Z
A2: Z001_01_012025_MATURIN.CSV | C2: MC#01 | D2: FONC FIXES | E2: FILE001 | F2: Z | G2: 0041 | H2: 45689 | I2: 15:53 | J2: 0001 | K2: CA BRUT | L2: 31 | M2: 11680.3 | N2: 2025 | O2: 2025-01
A3: Z001_01_012025_MATURIN.CSV | C3: MC#01 | D3: FONC FIXES | E3: FILE001 | F3: Z | G3: 0041 | H3: 45689 | I3: 15:53 | J3: 0002 | K3: CA NET | L3: 19 | M3: 11680.3 | N3: 2025 | O3: 2025-01
A4: Z001_01_012025_MATURIN.CSV | C4: MC#01 | D4: FONC FIXES | E4: FILE001 | F4: Z | G4: 0041 | H4: 45689 | I4: 15:53 | J4: 0003 | K4: ESP.TIROIR | L4: 0 | M4: 2731.5 | N4: 2025 | O4: 2025-01
A5: Z001_01_012025_MATURIN.CSV | C5: MC#01 | D5: FONC FIXES | E5: FILE001 | F5: Z | G5: 0041 | H5: 45689 | I5: 15:53 | J5: 0004 | K5: CB.TIROIR | L5: 0 | M5: 8948.8 | N5: 2025 | O5: 2025-01
A6: Z001_01_012025_MATURIN.CSV | C6: MC#01 | D6: FONC FIXES | E6: FILE001 | F6: Z | G6: 0041 | H6: 45689 | I6: 15:53 | J6: 0005 | K6: CHQ.TIROIR | L6: 0 | M6: 0 | N6: 2025 | O6: 2025-01
A7: Z001_01_012025_MATURIN.CSV | C7: MC#01 | D7: FONC FIXES | E7: FILE001 | F7: Z | G7: 0041 | H7: 45689 | I7: 15:53 | J7: 0006 | K7: CR.TIROIR(1) | L7: 0 | M7: 0 | N7: 2025 | O7: 2025-01
A8: Z001_01_012025_MATURIN.CSV | C8: MC#01 | D8: FONC FIXES | E8: FILE001 | F8: Z | G8: 0041 | H8: 45689 | I8: 15:53 | J8: 0007 | K8: CR.TIROIR(2) | L8: 0 | M8: 0 | N8: 2025 | O8: 2025-01
A9: Z001_01_012025_MATURIN.CSV | C9: MC#01 | D9: FONC FIXES | E9: FILE001 | F9: Z | G9: 0041 | H9: 45689 | I9: 15:53 | J9: 0008 | K9: CR.TIROIR(3) | L9: 0 | M9: 0 | N9: 2025 | O9: 2025-01
A10: Z001_01_012025_MATURIN.CSV | C10: MC#01 | D10: FONC FIXES | E10: FILE001 | F10: Z | G10: 0041 | H10: 45689 | I10: 15:53 | J10: 0009 | K10: CR.TIROIR(4) | L10: 0 | M10: 0 | N10: 2025 | O10: 2025-01
A11: Z001_01_012025_MATURIN.CSV | C11: MC#01 | D11: FONC FIXES | E11: FILE001 | F11: Z | G11: 0041 | H11: 45689 | I11: 15:53 | J11: 0010 | K11: ESP.TIROIR2 | L11: 0 | M11: 0 | N11: 2025 | O11: 2025-01
A12: Z001_01_012025_MATURIN.CSV | C12: MC#01 | D12: FONC FIXES | E12: FILE001 | F12: Z | G12: 0041 | H12: 45689 | I12: 15:53 | J12: 0011 | K12: CB.TIROIR2 | L12: 0 | M12: 0 | N12: 2025 | O12: 2025-01
A13: Z001_01_012025_MATURIN.CSV | C13: MC#01 | D13: FONC FIXES | E13: FILE001 | F13: Z | G13: 0041 | H13: 45689 | I13: 15:53 | J13: 0012 | K13: CHQ.TIROIR2 | L13: 0 | M13: 0 | N13: 2025 | O13: 2025-01
... A27: Z001_01_012025_MATURIN.CSV | C27: MC#01 | D27: FONC FIXES | E27: FILE001 | F27: Z | G27: 0041 | H27: 45689 | I27: 15:53 | J27: 0026 | K27: TOTAL REMISE | L27: 0 | M27: 0 | N27: 2025 | O27: 2025-01
A28: Z001_01_012025_MATURIN.CSV | C28: MC#01 | D28: FONC FIXES | E28: FILE001 | F28: Z | G28: 0041 | H28: 45689 | I28: 15:53 | J28: 0027 | L28: 0 | M28: 0 | N28: 2025 | O28: 2025-01
A29: Z001_01_012025_MATURIN.CSV | C29: MC#01 | D29: FONC FIXES | E29: FILE001 | F29: Z | G29: 0041 | H29: 45689 | I29: 15:53 | J29: 0028 | K29: RETOUR+ANNUL | L29: 0 | M29: 0 | N29: 2025 | O29: 2025-01
A30: Z001_01_012025_MATURIN.CSV | C30: MC#01 | D30: FONC FIXES | E30: FILE001 | F30: Z | G30: 0041 | H30: 45689 | I30: 15:53 | J30: 0029 | K30: TL ARRONDI | L30: 0 | M30: 0 | N30: 2025 | O30: 2025-01
A31: Z001_01_012025_MATURIN.CSV | C31: MC#01 | D31: FONC FIXES | E31: FILE001 | F31: Z | G31: 0041 | H31: 45689 | I31: 15:53 | J31: 0030 | K31: TL ARRONDI | L31: 0 | M31: 0 | N31: 2025 | O31: 2025-01
A32: Z001_01_012025_MATURIN.CSV | C32: MC#01 | D32: FONC FIXES | E32: FILE001 | F32: Z | G32: 0041 | H32: 45689 | I32: 15:53 | J32: 0031 | K32: NUL TICKET | L32: 0 | M32: 0 | N32: 2025 | O32: 2025-01
A33: Z001_01_012025_MATURIN.CSV | C33: MC#01 | D33: FONC FIXES | E33: FILE001 | F33: Z | G33: 0041 | H33: 45689 | I33: 15:53 | J33: 0032 | L33: 0 | M33: 0 | N33: 2025 | O33: 2025-01
A34: Z001_01_012025_MATURIN.CSV | C34: MC#01 | D34: FONC FIXES | E34: FILE001 | F34: Z | G34: 0041 | H34: 45689 | I34: 15:53 | J34: 0033 | K34: HORS TAXE 1 | L34: 0 | M34: 9733.59 | N34: 2025 | O34: 2025-01
A35: Z001_01_012025_MATURIN.CSV | C35: MC#01 | D35: FONC FIXES | E35: FILE001 | F35: Z | G35: 0041 | H35: 45689 | I35: 15:53 | J35: 0034 | K35: TVA 1 | L35: 0 | M35: 1946.71 | N35: 2025 | O35: 2025-01
A36: Z001_01_012025_MATURIN.CSV | C36: MC#01 | D36: FONC FIXES | E36: FILE001 | F36: Z | G36: 0041 | H36: 45689 | I36: 15:53 | J36: 0035 | K36: HORS TAXE 2 | L36: 0 | M36: 0 | N36: 2025 | O36: 2025-01
A37: Z001_01_012025_MATURIN.CSV | C37: MC#01 | D37: FONC FIXES | E37: FILE001 | F37: Z | G37: 0041 | H37: 45689 | I37: 15:53 | J37: 0036 | K37: TVA 2 | L37: 0 | M37: 0 | N37: 2025 | O37: 2025-01
A38: Z001_01_012025_MATURIN.CSV | C38: MC#01 | D38: FONC FIXES | E38: FILE001 | F38: Z | G38: 0041 | H38: 45689 | I38: 15:53 | J38: 0037 | K38: HORS TAXE 3 | L38: 0 | M38: 0 | N38: 2025 | O38: 2025-01
A39: Z001_01_012025_MATURIN.CSV | C39: MC#01 | D39: FONC FIXES | E39: FILE001 | F39: Z | G39: 0041 | H39: 45689 | I39: 15:53 | J39: 0038 | K39: TVA 3 | L39: 0 | M39: 0 | N39: 2025 | O39: 2025-01
A40: Z001_01_012025_MATURIN.CSV | C40: MC#01 | D40: FONC FIXES | E40: FILE001 | F40: Z | G40: 0041 | H40: 45689 | I40: 15:53 | J40: 0039 | K40: HORS TAXE 4 | L40: 0 | M40: 0 | N40: 2025 | O40: 2025-01
A41: Z001_01_012025_MATURIN.CSV | C41: MC#01 | D41: FONC FIXES | E41: FILE001 | F41: Z | G41: 0041 | H41: 45689 | I41: 15:53 | J41: 0040 | K41: TVA 4 | L41: 0 | M41: 0 | N41: 2025 | O41: 2025-01
A42: Z001_01_012025_MATURIN.CSV | C42: MC#01 | D42: FONC FIXES | E42: FILE001 | F42: Z | G42: 0041 | H42: 45689 | I42: 15:53 | J42: 0041 | K42: NON TAXABLE | L42: 0 | M42: 0 | N42: 2025 | O42: 2025-01
A43: Z001_01_022025_MATURIN.CSV | C43: MC#01 | D43: FONC FIXES | E43: FILE001 | F43: Z | G43: 0042 | H43: 45717 | I43: 13:36 | J43: 0001 | K43: CA BRUT | L43: 16 | M43: 4578.8 | N43: 2025 | O43: 2025-02
A44: Z001_01_022025_MATURIN.CSV | C44: MC#01 | D44: FONC FIXES | E44: FILE001 | F44: Z | G44: 0042 | H44: 45717 | I44: 13:36 | J44: 0002 | K44: CA NET | L44: 13 | M44: 4578.8 | N44: 2025 | O44: 2025-02
A45: Z001_01_022025_MATURIN.CSV | C45: MC#01 | D45: FONC FIXES | E45: FILE001 | F45: Z | G45: 0042 | H45: 45717 | I45: 13:36 | J45: 0003 | K45: ESP.TIROIR | L45: 0 | M45: 2530 | N45: 2025 | O45: 2025-02
... A68: Z001_01_022025_MATURIN.CSV | C68: MC#01 | D68: FONC FIXES | E68: FILE001 | F68: Z | G68: 0042 | H68: 45717 | I68: 13:36 | J68: 0026 | K68: TOTAL REMISE | L68: 0 | M68: 0 | N68: 2025 | O68: 2025-02
A69: Z001_01_022025_MATURIN.CSV | C69: MC#01 | D69: FONC FIXES | E69: FILE001 | F69: Z | G69: 0042 | H69: 45717 | I69: 13:36 | J69: 0027 | L69: 0 | M69: 0 | N69: 2025 | O69: 2025-02
A70: Z001_01_022025_MATURIN.CSV | C70: MC#01 | D70: FONC FIXES | E70: FILE001 | F70: Z | G70: 0042 | H70: 45717 | I70: 13:36 | J70: 0028 | K70: RETOUR+ANNUL | L70: 0 | M70: 0 | N70: 2025 | O70: 2025-02
A71: Z001_01_022025_MATURIN.CSV | C71: MC#01 | D71: FONC FIXES | E71: FILE001 | F71: Z | G71: 0042 | H71: 45717 | I71: 13:36 | J71: 0029 | K71: TL ARRONDI | L71: 0 | M71: 0 | N71: 2025 | O71: 2025-02
A72: Z001_01_022025_MATURIN.CSV | C72: MC#01 | D72: FONC FIXES | E72: FILE001 | F72: Z | G72: 0042 | H72: 45717 | I72: 13:36 | J72: 0030 | K72: TL ARRONDI | L72: 0 | M72: 0 | N72: 2025 | O72: 2025-02
A73: Z001_01_022025_MATURIN.CSV | C73: MC#01 | D73: FONC FIXES | E73: FILE001 | F73: Z | G73: 0042 | H73: 45717 | I73: 13:36 | J73: 0031 | K73: NUL TICKET | L73: 0 | M73: 0 | N73: 2025 | O73: 2025-02
A74: Z001_01_022025_MATURIN.CSV | C74: MC#01 | D74: FONC FIXES | E74: FILE001 | F74: Z | G74: 0042 | H74: 45717 | I74: 13:36 | J74: 0032 | L74: 0 | M74: 0 | N74: 2025 | O74: 2025-02
A75: Z001_01_022025_MATURIN.CSV | C75: MC#01 | D75: FONC FIXES | E75: FILE001 | F75: Z | G75: 0042 | H75: 45717 | I75: 13:36 | J75: 0033 | K75: HORS TAXE 1 | L75: 0 | M75: 3815.68 | N75: 2025 | O75: 2025-02
...

Sheet TD_OccurenceFichMode
A1: AJ_ANNEE_Z | B1: AJ_MOIS_Z | C1: E_DATE | D1: E_FICHIER | E1: E_MODE | F1: OCCURRENCES
A2: 2025 | B2: 2025-01 | C2: 45689 | D2: FILE001 | E2: Z | F2: =COUNTIFS('Z1_CplteAnneeMois'!$O$2:$O$288,B2,'Z1_CplteAnneeMois'!$H$2:$H$288,C2,'Z1_CplteAnneeMois'!$E$2:$E$288,D2,'Z1_CplteAnneeMois'!$F$2:$F$288,E2)
A3: 2025 | B3: 2025-02 | C3: 45717 | D3: FILE001 | E3: Z | F3: =COUNTIFS('Z1_CplteAnneeMois'!$O$2:$O$288,B3,'Z1_CplteAnneeMois'!$H$2:$H$288,C3,'Z1_CplteAnneeMois'!$E$2:$E$288,D3,'Z1_CplteAnneeMois'!$F$2:$F$288,E3)
A4: 2025 | B4: 2025-03 | C4: 45748 | D4: FILE001 | E4: Z | F4: =COUNTIFS('Z1_CplteAnneeMois'!$O$2:$O$288,B4,'Z1_CplteAnneeMois'!$H$2:$H$288,C4,'Z1_CplteAnneeMois'!$E$2:$E$288,D4,'Z1_CplteAnneeMois'!$F$2:$F$288,E4)
A5: 2025 | B5: 2025-05 | C5: 45810 | D5: FILE101 | E5: ZZ1 | F5: =COUNTIFS('Z1_CplteAnneeMois'!$O$2:$O$288,B5,'Z1_CplteAnneeMois'!$H$2:$H$288,C5,'Z1_CplteAnneeMois'!$E$2:$E$288,D5,'Z1_CplteAnneeMois'!$F$2:$F$288,E5)
A6: 2025 | B6: 2025-05 | C6: 45810 | D6: FILE201 | E6: ZZ2 | F6: =COUNTIFS('Z1_CplteAnneeMois'!$O$2:$O$288,B6,'Z1_CplteAnneeMois'!$H$2:$H$288,C6,'Z1_CplteAnneeMois'!$E$2:$E$288,D6,'Z1_CplteAnneeMois'!$F$2:$F$288,E6)
A7: 2025 | B7: 2025-06|2025-07 | C7: 45870 | D7: FILE001 | E7: Z | F7: =COUNTIFS('Z1_CplteAnneeMois'!$O$2:$O$288,B7,'Z1_CplteAnneeMois'!$H$2:$H$288,C7,'Z1_CplteAnneeMois'!$E$2:$E$288,D7,'Z1_CplteAnneeMois'!$F$2:$F$288,E7)
A8: 2025 | B8: 2025-08 | C8: 45901 | D8: FILE001 | E8: Z | F8: =COUNTIFS('Z1_CplteAnneeMois'!$O$2:$O$288,B8,'Z1_CplteAnneeMois'!$H$2:$H$288,C8,'Z1_CplteAnneeMois'!$E$2:$E$288,D8,'Z1_CplteAnneeMois'!$F$2:$F$288,E8)

Sheet TD_Z1_TotalMontant
A1: AJ_ANNEE_Z | B1: AJ_MOIS_Z | C1: E_MODE | D1: D_DESIGNATION | E1: D_MONTANT
A2: 2025 | B2: 2025-01 | C2: Z | D2: CA BRUT | E2: =SUMIFS('Z1_CplteAnneeMois'!$M$2:$M$288,'Z1_CplteAnneeMois'!$O$2:$O$288,B2,'Z1_CplteAnneeMois'!$F$2:$F$288,C2,'Z1_CplteAnneeMois'!$K$2:$K$288,D2)
A3: 2025 | B3: 2025-01 | C3: Z | D3: CA NET | E3: =SUMIFS('Z1_CplteAnneeMois'!$M$2:$M$288,'Z1_CplteAnneeMois'!$O$2:$O$288,B3,'Z1_CplteAnneeMois'!$F$2:$F$288,C3,'Z1_CplteAnneeMois'!$K$2:$K$288,D3)
A4: 2025 | B4: 2025-01 | C4: Z | D4: CB.TIROIR | E4: =SUMIFS('Z1_CplteAnneeMois'!$M$2:$M$288,'Z1_CplteAnneeMois'!$O$2:$O$288,B4,'Z1_CplteAnneeMois'!$F$2:$F$288,C4,'Z1_CplteAnneeMois'!$K$2:$K$288,D4)
A5: 2025 | B5: 2025-01 | C5: Z | D5: CHQ.TIROIR | E5: =SUMIFS('Z1_CplteAnneeMois'!$M$2:$M$288,'Z1_CplteAnneeMois'!$O$2:$O$288,B5,'Z1_CplteAnneeMois'!$F$2:$F$288,C5,'Z1_CplteAnneeMois'!$K$2:$K$288,D5)
A6: 2025 | B6: 2025-01 | C6: Z | D6: ESP.TIROIR | E6: =SUMIFS('Z1_CplteAnneeMois'!$M$2:$M$288,'Z1_CplteAnneeMois'!$O$2:$O$288,B6,'Z1_CplteAnneeMois'!$F$2:$F$288,C6,'Z1_CplteAnneeMois'!$K$2:$K$288,D6)
A7: 2025 | B7: 2025-01 | C7: Z | D7: HORS TAXE 1 | E7: =SUMIFS('Z1_CplteAnneeMois'!$M$2:$M$288,'Z1_CplteAnneeMois'!$O$2:$O$288,B7,'Z1_CplteAnneeMois'!$F$2:$F$288,C7,'Z1_CplteAnneeMois'!$K$2:$K$288,D7)
A8: 2025 | B8: 2025-01 | C8: Z | D8: TVA 1 | E8: =SUMIFS('Z1_CplteAnneeMois'!$M$2:$M$288,'Z1_CplteAnneeMois'!$O$2:$O$288,B8,'Z1_CplteAnneeMois'!$F$2:$F$288,C8,'Z1_CplteAnneeMois'!$K$2:$K$288,D8)
A9: 2025 | B9: 2025-01 | C9: ZZ1 | D9: CA BRUT | E9: =SUMIFS('Z1_CplteAnneeMois'!$M$2:$M$288,'Z1_CplteAnneeMois'!$O$2:$O$288,B9,'Z1_CplteAnneeMois'!$F$2:$F$288,C9,'Z1_CplteAnneeMois'!$K$2:$K$288,D9)
A10: 2025 | B10: 2025-01 | C10: ZZ1 | D10: CA NET | E10: =SUMIFS('Z1_CplteAnneeMois'!$M$2:$M$288,'Z1_CplteAnneeMois'!$O$2:$O$288,B10,'Z1_CplteAnneeMois'!$F$2:$F$288,C10,'Z1_CplteAnneeMois'!$K$2:$K$288,D10)
A11: 2025 | B11: 2025-01 | C11: ZZ1 | D11: CB.TIROIR | E11: =SUMIFS('Z1_CplteAnneeMois'!$M$2:$M$288,'Z1_CplteAnneeMois'!$O$2:$O$288,B11,'Z1_CplteAnneeMois'!$F$2:$F$288,C11,'Z1_CplteAnneeMois'!$K$2:$K$288,D11)
A12: 2025 | B12: 2025-01 | C12: ZZ1 | D12: CHQ.TIROIR | E12: =SUMIFS('Z1_CplteAnneeMois'!$M$2:$M$288,'Z1_CplteAnneeMois'!$O$2:$O$288,B12,'Z1_CplteAnneeMois'!$F$2:$F$288,C12,'Z1_CplteAnneeMois'!$K$2:$K$288,D12)
A13: 2025 | B13: 2025-01 | C13: ZZ1 | D13: ESP.TIROIR | E13: =SUMIFS('Z1_CplteAnneeMois'!$M$2:$M$288,'Z1_CplteAnneeMois'!$O$2:$O$288,B13,'Z1_CplteAnneeMois'!$F$2:$F$288,C13,'Z1_CplteAnneeMois'!$K$2:$K$288,D13)
... A148: 2025 | B148: 2025-08 | C148: ZZ2 | D148: TVA 1 | E148: =SUMIFS('Z1_CplteAnneeMois'!$M$2:$M$288,'Z1_CplteAnneeMois'!$O$2:$O$288,B148,'Z1_CplteAnneeMois'!$F$2:$F$288,C148,'Z1_CplteAnneeMois'!$K$2:$K$288,D148)

Sheet Z1_Total_ModeZZ1
A1: AJ_ANNEE_Z | B1: AJ_MOIS_Z | C1: CA_BRUT_D_MONTANT | D1: CA_NET_D_MONTANT | E1: CB_TIROIR_D_MONTANT | F1: CHQ_TIROIR_D_MONTANT | G1: ESP_TIROIR_D_MONTANT | H1: HORS_TAXE_1_D_MONTANT | I1: TVA_1_D_MONTANT
A2: 2025 | B2: 2025-01 | C2: =SUMIFS('TD_Z1_TotalMontant'!$E$2:$E$148,'TD_Z1_TotalMontant'!$B$2:$B$148,B2,'TD_Z1_TotalMontant'!$C$2:$C$148,"ZZ1",'TD_Z1_TotalMontant'!$D$2:$D$148,"CA BRUT") | D2: =SUMIFS('TD_Z1_TotalMontant'!$E$2:$E$148,'TD_Z1_TotalMontant'!$B$2:$B$148,B2,'TD_Z1_TotalMontant'!$C$2:$C$148,"ZZ1",'TD_Z1_TotalMontant'!$D$2:$D$148,"CA NET") | E2: =SUMIFS('TD_Z1_TotalMontant'!$E$2:$E$148,'TD_Z1_TotalMontant'!$B$2:$B$148,B2,'TD_Z1_TotalMontant'!$C$2:$C$148,"ZZ1",'TD_Z1_TotalMontant'!$D$2:$D$148,"CB.TIROIR") | F2: =SUMIFS('TD_Z1_TotalMontant'!$E$2:$E$148,'TD_Z1_TotalMontant'!$B$2:$B$148,B2,'TD_Z1_TotalMontant'!$C$2:$C$148,"ZZ1",'TD_Z1_TotalMontant'!$D$2:$D$148,"CHQ.TIROIR") | G2: =SUMIFS('TD_Z1_TotalMontant'!$E$2:$E$148,'TD_Z1_TotalMontant'!$B$2:$B$148,B2,'TD_Z1_TotalMontant'!$C$2:$C$148,"ZZ1",'TD_Z1_TotalMontant'!$D$2:$D$148,"ESP.TIROIR") | H2: =SUMIFS('TD_Z1_TotalMontant'!$E$2:$E$148,'TD_Z1_TotalMontant'!$B$2:$B$148,B2,'TD_Z1_TotalMontant'!$C$2:$C$148,"ZZ1",'TD_Z1_TotalMontant'!$D$2:$D$148,"HORS TAXE 1") | I2: =SUMIFS('TD_Z1_TotalMontant'!$E$2:$E$148,'TD_Z1_TotalMontant'!$B$2:$B$148,B2,'TD_Z1_TotalMontant'!$C$2:$C$148,"ZZ1",'TD_Z1_TotalMontant'!$D$2:$D$148,"TVA 1")
A3: 2025 | B3: 2025-02 | C3: =SUMIFS('TD_Z1_TotalMontant'!$E$2:$E$148,'TD_Z1_TotalMontant'!$B$2:$B$148,B3,'TD_Z1_TotalMontant'!$C$2:$C$148,"ZZ1",'TD_Z1_TotalMontant'!$D$2:$D$148,"CA BRUT") | D3: =SUMIFS('TD_Z1_TotalMontant'!$E$2:$E$148,'TD_Z1_TotalMontant'!$B$2:$B$148,B3,'TD_Z1_TotalMontant'!$C$2:$C$148,"ZZ1",'TD_Z1_TotalMontant'!$D$2:$D$148,"CA NET") | E3: =SUMIFS('TD_Z1_TotalMontant'!$E$2:$E$148,'TD_Z1_TotalMontant'!$B$2:$B$148,B3,'TD_Z1_TotalMontant'!$C$2:$C$148,"ZZ1",'TD_Z1_TotalMontant'!$D$2:$D$148,"CB.TIROIR") | F3: =SUMIFS('TD_Z1_TotalMontant'!$E$2:$E$148,'TD_Z1_TotalMontant'!$B$2:$B$148,B3,'TD_Z1_TotalMontant'!$C$2:$C$148,"ZZ1",'TD_Z1_TotalMontant'!$D$2:$D$148,"CHQ.TIROIR") | G3: =SUMIFS('TD_Z1_TotalMontant'!$E$2:$E$148,'TD_Z1_TotalMontant'!$B$2:$B$148,B3,'TD_Z1_TotalMontant'!$C$2:$C$148,"ZZ1",'TD_Z1_TotalMontant'!$D$2:$D$148,"ESP.TIROIR") | H3: =SUMIFS('TD_Z1_TotalMontant'!$E$2:$E$148,'TD_Z1_TotalMontant'!$B$2:$B$148,B3,'TD_Z1_TotalMontant'!$C$2:$C$148,"ZZ1",'TD_Z1_TotalMontant'!$D$2:$D$148,"HORS TAXE 1") | I3: =SUMIFS('TD_Z1_TotalMontant'!$E$2:$E$148,'TD_Z1_TotalMontant'!$B$2:$B$148,B3,'TD_Z1_TotalMontant'!$C$2:$C$148,"ZZ1",'TD_Z1_TotalMontant'!$D$2:$D$148,"TVA 1")
A4: 2025 | B4: 2025-03 | C4: =SUMIFS('TD_Z1_TotalMontant'!$E$2:$E$148,'TD_Z1_TotalMontant'!$B$2:$B$148,B4,'TD_Z1_TotalMontant'!$C$2:$C$148,"ZZ1",'TD_Z1_TotalMontant'!$D$2:$D$148,"CA BRUT") | D4: =SUMIFS('TD_Z1_TotalMontant'!$E$2:$E$148,'TD_Z1_TotalMontant'!$B$2:$B$148,B4,'TD_Z1_TotalMontant'!$C$2:$C$148,"ZZ1",'TD_Z1_TotalMontant'!$D$2:$D$148,"CA NET") | E4: =SUMIFS('TD_Z1_TotalMontant'!$E$2:$E$148,'TD_Z1_TotalMontant'!$B$2:$B$148,B4,'TD_Z1_TotalMontant'!$C$2:$C$148,"ZZ1",'TD_Z1_TotalMontant'!$D$2:$D$148,"CB.TIROIR") | F4: =SUMIFS('TD_Z1_TotalMontant'!$E$2:$E$148,'TD_Z1_TotalMontant'!$B$2:$B$148,B4,'TD_Z1_TotalMontant'!$C$2:$C$148,"ZZ1",'TD_Z1_TotalMontant'!$D$2:$D$148,"CHQ.TIROIR") | G4: =SUMIFS('TD_Z1_TotalMontant'!$E$2:$E$148,'TD_Z1_TotalMontant'!$B$2:$B$148,B4,'TD_Z1_TotalMontant'!$C$2:$C$148,"ZZ1",'TD_Z1_TotalMontant'!$D$2:$D$148,"ESP.TIROIR") | H4: =SUMIFS('TD_Z1_TotalMontant'!$E$2:$E$148,'TD_Z1_TotalMontant'!$B$2:$B$148,B4,'TD_Z1_TotalMontant'!$C$2:$C$148,"ZZ1",'TD_Z1_TotalMontant'!$D$2:$D$148,"HORS TAXE 1") | I4: =SUMIFS('TD_Z1_TotalMontant'!$E$2:$E$148,'TD_Z1_TotalMontant'!$B$2:$B$148,B4,'TD_Z1_TotalMontant'!$C$2:$C$148,"ZZ1",'TD_Z1_TotalMontant'!$D$2:$D$148,"TVA 1")
A5: 2025 | B5: 2025-04 | C5: =SUMIFS('TD_Z1_TotalMontant'!$E$2:$E$148,'TD_Z1_TotalMontant'!$B$2:$B$148,B5,'TD_Z1_TotalMontant'!$C$2:$C$148,"ZZ1",'TD_Z1_TotalMontant'!$D$2:$D$148,"CA BRUT") | D5: =SUMIFS('TD_Z1_TotalMontant'!$E$2:$E$148,'TD_Z1_TotalMontant'!$B$2:$B$148,B5,'TD_Z1_TotalMontant'!$C$2:$C$148,"ZZ1",'TD_Z1_TotalMontant'!$D$2:$D$148,"CA NET") | E5: =SUMIFS('TD_Z1_TotalMontant'!$E$2:$E$148,'TD_Z1_TotalMontant'!$B$2:$B$148,B5,'TD_Z1_TotalMontant'!$C$2:$C$148,"ZZ1",'TD_Z1_TotalMontant'!$D$2:$D$148,"CB.TIROIR") | F5: =SUMIFS('TD_Z1_TotalMontant'!$E$2:$E$148,'TD_Z1_TotalMontant'!$B$2:$B$148,B5,'TD_Z1_TotalMontant'!$C$2:$C$148,"ZZ1",'TD_Z1_TotalMontant'!$D$2:$D$148,"CHQ.TIROIR") | G5: =SUMIFS('TD_Z1_TotalMontant'!$E$2:$E$148,'TD_Z1_TotalMontant'!$B$2:$B$148,B5,'TD_Z1_TotalMontant'!$C$2:$C$148,"ZZ1",'TD_Z1_TotalMontant'!$D$2:$D$148,"ESP.TIROIR") | H5: =SUMIFS('TD_Z1_TotalMontant'!$E$2:$E$148,'TD_Z1_TotalMontant'!$B$2:$B$148,B5,'TD_Z1_TotalMontant'!$C$2:$C$148,"ZZ1",'TD_Z1_TotalMontant'!$D$2:$D$148,"HORS TAXE 1") | I5: =SUMIFS('TD_Z1_TotalMontant'!$E$2:$E$148,'TD_Z1_TotalMontant'!$B$2:$B$148,B5,'TD_Z1_TotalMontant'!$C$2:$C$148,"ZZ1",'TD_Z1_TotalMontant'!$D$2:$D$148,"TVA 1")
A6: 2025 | B6: 2025-05 | C6: =SUMIFS('TD_Z1_TotalMontant'!$E$2:$E$148,'TD_Z1_TotalMontant'!$B$2:$B$148,B6,'TD_Z1_TotalMontant'!$C$2:$C$148,"ZZ1",'TD_Z1_TotalMontant'!$D$2:$D$148,"CA BRUT") | D6: =SUMIFS('TD_Z1_TotalMontant'!$E$2:$E$148,'TD_Z1_TotalMontant'!$B$2:$B$148,B6,'TD_Z1_TotalMontant'!$C$2:$C$148,"ZZ1",'TD_Z1_TotalMontant'!$D$2:$D$148,"CA NET") | E6: =SUMIFS('TD_Z1_TotalMontant'!$E$2:$E$148,'TD_Z1_TotalMontant'!$B$2:$B$148,B6,'TD_Z1_TotalMontant'!$C$2:$C$148,"ZZ1",'TD_Z1_TotalMontant'!$D$2:$D$148,"CB.TIROIR") | F6: =SUMIFS('TD_Z1_TotalMontant'!$E$2:$E$148,'TD_Z1_TotalMontant'!$B$2:$B$148,B6,'TD_Z1_TotalMontant'!$C$2:$C$148,"ZZ1",'TD_Z1_TotalMontant'!$D$2:$D$148,"CHQ.TIROIR") | G6: =SUMIFS('TD_Z1_TotalMontant'!$E$2:$E$148,'TD_Z1_TotalMontant'!$B$2:$B$148,B6,'TD_Z1_TotalMontant'!$C$2:$C$148,"ZZ1",'TD_Z1_TotalMontant'!$D$2:$D$148,"ESP.TIROIR") | H6: =SUMIFS('TD_Z1_TotalMontant'!$E$2:$E$148,'TD_Z1_TotalMontant'!$B$2:$B$148,B6,'TD_Z1_TotalMontant'!$C$2:$C$148,"ZZ1",'TD_Z1_TotalMontant'!$D$2:$D$148,"HORS TAXE 1") | I6: =SUMIFS('TD_Z1_TotalMontant'!$E$2:$E$148,'TD_Z1_TotalMontant'!$B$2:$B$148,B6,'TD_Z1_TotalMontant'!$C$2:$C$148,"ZZ1",'TD_Z1_TotalMontant'!$D$2:$D$148,"TVA 1")
A7: 2025 | B7: 2025-06|2025-07 | C7: =SUMIFS('TD_Z1_TotalMontant'!$E$2:$E$148,'TD_Z1_TotalMontant'!$B$2:$B$148,B7,'TD_Z1_TotalMontant'!$C$2:$C$148,"ZZ1",'TD_Z1_TotalMontant'!$D$2:$D$148,"CA BRUT") | D7: =SUMIFS('TD_Z1_TotalMontant'!$E$2:$E$148,'TD_Z1_TotalMontant'!$B$2:$B$148,B7,'TD_Z1_TotalMontant'!$C$2:$C$148,"ZZ1",'TD_Z1_TotalMontant'!$D$2:$D$148,"CA NET") | E7: =SUMIFS('TD_Z1_TotalMontant'!$E$2:$E$148,'TD_Z1_TotalMontant'!$B$2:$B$148,B7,'TD_Z1_TotalMontant'!$C$2:$C$148,"ZZ1",'TD_Z1_TotalMontant'!$D$2:$D$148,"CB.TIROIR") | F7: =SUMIFS('TD_Z1_TotalMontant'!$E$2:$E$148,'TD_Z1_TotalMontant'!$B$2:$B$148,B7,'TD_Z1_TotalMontant'!$C$2:$C$148,"ZZ1",'TD_Z1_TotalMontant'!$D$2:$D$148,"CHQ.TIROIR") | G7: =SUMIFS('TD_Z1_TotalMontant'!$E$2:$E$148,'TD_Z1_TotalMontant'!$B$2:$B$148,B7,'TD_Z1_TotalMontant'!$C$2:$C$148,"ZZ1",'TD_Z1_TotalMontant'!$D$2:$D$148,"ESP.TIROIR") | H7: =SUMIFS('TD_Z1_TotalMontant'!$E$2:$E$148,'TD_Z1_TotalMontant'!$B$2:$B$148,B7,'TD_Z1_TotalMontant'!$C$2:$C$148,"ZZ1",'TD_Z1_TotalMontant'!$D$2:$D$148,"HORS TAXE 1") | I7: =SUMIFS('TD_Z1_TotalMontant'!$E$2:$E$148,'TD_Z1_TotalMontant'!$B$2:$B$148,B7,'TD_Z1_TotalMontant'!$C$2:$C$148,"ZZ1",'TD_Z1_TotalMontant'!$D$2:$D$148,"TVA 1")
A8: 2025 | B8: 2025-08 | C8: =SUMIFS('TD_Z1_TotalMontant'!$E$2:$E$148,'TD_Z1_TotalMontant'!$B$2:$B$148,B8,'TD_Z1_TotalMontant'!$C$2:$C$148,"ZZ1",'TD_Z1_TotalMontant'!$D$2:$D$148,"CA BRUT") | D8: =SUMIFS('TD_Z1_TotalMontant'!$E$2:$E$148,'TD_Z1_TotalMontant'!$B$2:$B$148,B8,'TD_Z1_TotalMontant'!$C$2:$C$148,"ZZ1",'TD_Z1_TotalMontant'!$D$2:$D$148,"CA NET") | E8: =SUMIFS('TD_Z1_TotalMontant'!$E$2:$E$148,'TD_Z1_TotalMontant'!$B$2:$B$148,B8,'TD_Z1_TotalMontant'!$C$2:$C$148,"ZZ1",'TD_Z1_TotalMontant'!$D$2:$D$148,"CB.TIROIR") | F8: =SUMIFS('TD_Z1_TotalMontant'!$E$2:$E$148,'TD_Z1_TotalMontant'!$B$2:$B$148,B8,'TD_Z1_TotalMontant'!$C$2:$C$148,"ZZ1",'TD_Z1_TotalMontant'!$D$2:$D$148,"CHQ.TIROIR") | G8: =SUMIFS('TD_Z1_TotalMontant'!$E$2:$E$148,'TD_Z1_TotalMontant'!$B$2:$B$148,B8,'TD_Z1_TotalMontant'!$C$2:$C$148,"ZZ1",'TD_Z1_TotalMontant'!$D$2:$D$148,"ESP.TIROIR") | H8: =SUMIFS('TD_Z1_TotalMontant'!$E$2:$E$148,'TD_Z1_TotalMontant'!$B$2:$B$148,B8,'TD_Z1_TotalMontant'!$C$2:$C$148,"ZZ1",'TD_Z1_TotalMontant'!$D$2:$D$148,"HORS TAXE 1") | I8: =SUMIFS('TD_Z1_TotalMontant'!$E$2:$E$148,'TD_Z1_TotalMontant'!$B$2:$B$148,B8,'TD_Z1_TotalMontant'!$C$2:$C$148,"ZZ1",'TD_Z1_TotalMontant'!$D$2:$D$148,"TVA 1")

Sheet Z1_Total_ModeZZ2
A1: AJ_ANNEE_Z | B1: AJ_MOIS_Z | C1: CA_BRUT_D_MONTANT | D1: CA_NET_D_MONTANT | E1: CB_TIROIR_D_MONTANT | F1: CHQ_TIROIR_D_MONTANT | G1: ESP_TIROIR_D_MONTANT | H1: HORS_TAXE_1_D_MONTANT | I1: TVA_1_D_MONTANT
A2: 2025 | B2: 2025-01 | C2: =SUMIFS('TD_Z1_TotalMontant'!$E$2:$E$148,'TD_Z1_TotalMontant'!$B$2:$B$148,B2,'TD_Z1_TotalMontant'!$C$2:$C$148,"ZZ2",'TD_Z1_TotalMontant'!$D$2:$D$148,"CA BRUT") | D2: =SUMIFS('TD_Z1_TotalMontant'!$E$2:$E$148,'TD_Z1_TotalMontant'!$B$2:$B$148,B2,'TD_Z1_TotalMontant'!$C$2:$C$148,"ZZ2",'TD_Z1_TotalMontant'!$D$2:$D$148,"CA NET") | E2: =SUMIFS('TD_Z1_TotalMontant'!$E$2:$E$148,'TD_Z1_TotalMontant'!$B$2:$B$148,B2,'TD_Z1_TotalMontant'!$C$2:$C$148,"ZZ2",'TD_Z1_TotalMontant'!$D$2:$D$148,"CB.TIROIR") | F2: =SUMIFS('TD_Z1_TotalMontant'!$E$2:$E$148,'TD_Z1_TotalMontant'!$B$2:$B$148,B2,'TD_Z1_TotalMontant'!$C$2:$C$148,"ZZ2",'TD_Z1_TotalMontant'!$D$2:$D$148,"CHQ.TIROIR") | G2: =SUMIFS('TD_Z1_TotalMontant'!$E$2:$E$148,'TD_Z1_TotalMontant'!$B$2:$B$148,B2,'TD_Z1_TotalMontant'!$C$2:$C$148,"ZZ2",'TD_Z1_TotalMontant'!$D$2:$D$148,"ESP.TIROIR") | H2: =SUMIFS('TD_Z1_TotalMontant'!$E$2:$E$148,'TD_Z1_TotalMontant'!$B$2:$B$148,B2,'TD_Z1_TotalMontant'!$C$2:$C$148,"ZZ2",'TD_Z1_TotalMontant'!$D$2:$D$148,"HORS TAXE 1") | I2: =SUMIFS('TD_Z1_TotalMontant'!$E$2:$E$148,'TD_Z1_TotalMontant'!$B$2:$B$148,B2,'TD_Z1_TotalMontant'!$C$2:$C$148,"ZZ2",'TD_Z1_TotalMontant'!$D$2:$D$148,"TVA 1")
A3: 2025 | B3: 2025-02 | C3: =SUMIFS('TD_Z1_TotalMontant'!$E$2:$E$148,'TD_Z1_TotalMontant'!$B$2:$B$148,B3,'TD_Z1_TotalMontant'!$C$2:$C$148,"ZZ2",'TD_Z1_TotalMontant'!$D$2:$D$148,"CA BRUT") | D3: =SUMIFS('TD_Z1_TotalMontant'!$E$2:$E$148,'TD_Z1_TotalMontant'!$B$2:$B$148,B3,'TD_Z1_TotalMontant'!$C$2:$C$148,"ZZ2",'TD_Z1_TotalMontant'!$D$2:$D$148,"CA NET") | E3: =SUMIFS('TD_Z1_TotalMontant'!$E$2:$E$148,'TD_Z1_TotalMontant'!$B$2:$B$148,B3,'TD_Z1_TotalMontant'!$C$2:$C$148,"ZZ2",'TD_Z1_TotalMontant'!$D$2:$D$148,"CB.TIROIR") | F3: =SUMIFS('TD_Z1_TotalMontant'!$E$2:$E$148,'TD_Z1_TotalMontant'!$B$2:$B$148,B3,'TD_Z1_TotalMontant'!$C$2:$C$148,"ZZ2",'TD_Z1_TotalMontant'!$D$2:$D$148,"CHQ.TIROIR") | G3: =SUMIFS('TD_Z1_TotalMontant'!$E$2:$E$148,'TD_Z1_TotalMontant'!$B$2:$B$148,B3,'TD_Z1_TotalMontant'!$C$2:$C$148,"ZZ2",'TD_Z1_TotalMontant'!$D$2:$D$148,"ESP.TIROIR") | H3: =SUMIFS('TD_Z1_TotalMontant'!$E$2:$E$148,'TD_Z1_TotalMontant'!$B$2:$B$148,B3,'TD_Z1_TotalMontant'!$C$2:$C$148,"ZZ2",'TD_Z1_TotalMontant'!$D$2:$D$148,"HORS TAXE 1") | I3: =SUMIFS('TD_Z1_TotalMontant'!$E$2:$E$148,'TD_Z1_TotalMontant'!$B$2:$B$148,B3,'TD_Z1_TotalMontant'!$C$2:$C$148,"ZZ2",'TD_Z1_TotalMontant'!$D$2:$D$148,"TVA 1")
A4: 2025 | B4: 2025-03 | C4: =SUMIFS('TD_Z1_TotalMontant'!$E$2:$E$148,'TD_Z1_TotalMontant'!$B$2:$B$148,B4,'TD_Z1_TotalMontant'!$C$2:$C$148,"ZZ2",'TD_Z1_TotalMontant'!$D$2:$D$148,"CA BRUT") | D4: =SUMIFS('TD_Z1_TotalMontant'!$E$2:$E$148,'TD_Z1_TotalMontant'!$B$2:$B$148,B4,'TD_Z1_TotalMontant'!$C$2:$C$148,"ZZ2",'TD_Z1_TotalMontant'!$D$2:$D$148,"CA NET") | E4: =SUMIFS('TD_Z1_TotalMontant'!$E$2:$E$148,'TD_Z1_TotalMontant'!$B$2:$B$148,B4,'TD_Z1_TotalMontant'!$C$2:$C$148,"ZZ2",'TD_Z1_TotalMontant'!$D$2:$D$148,"CB.TIROIR") | F4: =SUMIFS('TD_Z1_TotalMontant'!$E$2:$E$148,'TD_Z1_TotalMontant'!$B$2:$B$148,B4,'TD_Z1_TotalMontant'!$C$2:$C$148,"ZZ2",'TD_Z1_TotalMontant'!$D$2:$D$148,"CHQ.TIROIR") | G4: =SUMIFS('TD_Z1_TotalMontant'!$E$2:$E$148,'TD_Z1_TotalMontant'!$B$2:$B$148,B4,'TD_Z1_TotalMontant'!$C$2:$C$148,"ZZ2",'TD_Z1_TotalMontant'!$D$2:$D$148,"ESP.TIROIR") | H4: =SUMIFS('TD_Z1_TotalMontant'!$E$2:$E$148,'TD_Z1_TotalMontant'!$B$2:$B$148,B4,'TD_Z1_TotalMontant'!$C$2:$C$148,"ZZ2",'TD_Z1_TotalMontant'!$D$2:$D$148,"HORS TAXE 1") | I4: =SUMIFS('TD_Z1_TotalMontant'!$E$2:$E$148,'TD_Z1_TotalMontant'!$B$2:$B$148,B4,'TD_Z1_TotalMontant'!$C$2:$C$148,"ZZ2",'TD_Z1_TotalMontant'!$D$2:$D$148,"TVA 1")
A5: 2025 | B5: 2025-04 | C5: =SUMIFS('TD_Z1_TotalMontant'!$E$2:$E$148,'TD_Z1_TotalMontant'!$B$2:$B$148,B5,'TD_Z1_TotalMontant'!$C$2:$C$148,"ZZ2",'TD_Z1_TotalMontant'!$D$2:$D$148,"CA BRUT") | D5: =SUMIFS('TD_Z1_TotalMontant'!$E$2:$E$148,'TD_Z1_TotalMontant'!$B$2:$B$148,B5,'TD_Z1_TotalMontant'!$C$2:$C$148,"ZZ2",'TD_Z1_TotalMontant'!$D$2:$D$148,"CA NET") | E5: =SUMIFS('TD_Z1_TotalMontant'!$E$2:$E$148,'TD_Z1_TotalMontant'!$B$2:$B$148,B5,'TD_Z1_TotalMontant'!$C$2:$C$148,"ZZ2",'TD_Z1_TotalMontant'!$D$2:$D$148,"CB.TIROIR") | F5: =SUMIFS('TD_Z1_TotalMontant'!$E$2:$E$148,'TD_Z1_TotalMontant'!$B$2:$B$148,B5,'TD_Z1_TotalMontant'!$C$2:$C$148,"ZZ2",'TD_Z1_TotalMontant'!$D$2:$D$148,"CHQ.TIROIR") | G5: =SUMIFS('TD_Z1_TotalMontant'!$E$2:$E$148,'TD_Z1_TotalMontant'!$B$2:$B$148,B5,'TD_Z1_TotalMontant'!$C$2:$C$148,"ZZ2",'TD_Z1_TotalMontant'!$D$2:$D$148,"ESP.TIROIR") | H5: =SUMIFS('TD_Z1_TotalMontant'!$E$2:$E$148,'TD_Z1_TotalMontant'!$B$2:$B$148,B5,'TD_Z1_TotalMontant'!$C$2:$C$148,"ZZ2",'TD_Z1_TotalMontant'!$D$2:$D$148,"HORS TAXE 1") | I5: =SUMIFS('TD_Z1_TotalMontant'!$E$2:$E$148,'TD_Z1_TotalMontant'!$B$2:$B$148,B5,'TD_Z1_TotalMontant'!$C$2:$C$148,"ZZ2",'TD_Z1_TotalMontant'!$D$2:$D$148,"TVA 1")
A6: 2025 | B6: 2025-05 | C6: =SUMIFS('TD_Z1_TotalMontant'!$E$2:$E$148,'TD_Z1_TotalMontant'!$B$2:$B$148,B6,'TD_Z1_TotalMontant'!$C$2:$C$148,"ZZ2",'TD_Z1_TotalMontant'!$D$2:$D$148,"CA BRUT") | D6: =SUMIFS('TD_Z1_TotalMontant'!$E$2:$E$148,'TD_Z1_TotalMontant'!$B$2:$B$148,B6,'TD_Z1_TotalMontant'!$C$2:$C$148,"ZZ2",'TD_Z1_TotalMontant'!$D$2:$D$148,"CA NET") | E6: =SUMIFS('TD_Z1_TotalMontant'!$E$2:$E$148,'TD_Z1_TotalMontant'!$B$2:$B$148,B6,'TD_Z1_TotalMontant'!$C$2:$C$148,"ZZ2",'TD_Z1_TotalMontant'!$D$2:$D$148,"CB.TIROIR") | F6: =SUMIFS('TD_Z1_TotalMontant'!$E$2:$E$148,'TD_Z1_TotalMontant'!$B$2:$B$148,B6,'TD_Z1_TotalMontant'!$C$2:$C$148,"ZZ2",'TD_Z1_TotalMontant'!$D$2:$D$148,"CHQ.TIROIR") | G6: =SUMIFS('TD_Z1_TotalMontant'!$E$2:$E$148,'TD_Z1_TotalMontant'!$B$2:$B$148,B6,'TD_Z1_TotalMontant'!$C$2:$C$148,"ZZ2",'TD_Z1_TotalMontant'!$D$2:$D$148,"ESP.TIROIR") | H6: =SUMIFS('TD_Z1_TotalMontant'!$E$2:$E$148,'TD_Z1_TotalMontant'!$B$2:$B$148,B6,'TD_Z1_TotalMontant'!$C$2:$C$148,"ZZ2",'TD_Z1_TotalMontant'!$D$2:$D$148,"HORS TAXE 1") | I6: =SUMIFS('TD_Z1_TotalMontant'!$E$2:$E$148,'TD_Z1_TotalMontant'!$B$2:$B$148,B6,'TD_Z1_TotalMontant'!$C$2:$C$148,"ZZ2",'TD_Z1_TotalMontant'!$D$2:$D$148,"TVA 1")
A7: 2025 | B7: 2025-06|2025-07 | C7: =SUMIFS('TD_Z1_TotalMontant'!$E$2:$E$148,'TD_Z1_TotalMontant'!$B$2:$B$148,B7,'TD_Z1_TotalMontant'!$C$2:$C$148,"ZZ2",'TD_Z1_TotalMontant'!$D$2:$D$148,"CA BRUT") | D7: =SUMIFS('TD_Z1_TotalMontant'!$E$2:$E$148,'TD_Z1_TotalMontant'!$B$2:$B$148,B7,'TD_Z1_TotalMontant'!$C$2:$C$148,"ZZ2",'TD_Z1_TotalMontant'!$D$2:$D$148,"CA NET") | E7: =SUMIFS('TD_Z1_TotalMontant'!$E$2:$E$148,'TD_Z1_TotalMontant'!$B$2:$B$148,B7,'TD_Z1_TotalMontant'!$C$2:$C$148,"ZZ2",'TD_Z1_TotalMontant'!$D$2:$D$148,"CB.TIROIR") | F7: =SUMIFS('TD_Z1_TotalMontant'!$E$2:$E$148,'TD_Z1_TotalMontant'!$B$2:$B$148,B7,'TD_Z1_TotalMontant'!$C$2:$C$148,"ZZ2",'TD_Z1_TotalMontant'!$D$2:$D$148,"CHQ.TIROIR") | G7: =SUMIFS('TD_Z1_TotalMontant'!$E$2:$E$148,'TD_Z1_TotalMontant'!$B$2:$B$148,B7,'TD_Z1_TotalMontant'!$C$2:$C$148,"ZZ2",'TD_Z1_TotalMontant'!$D$2:$D$148,"ESP.TIROIR") | H7: =SUMIFS('TD_Z1_TotalMontant'!$E$2:$E$148,'TD_Z1_TotalMontant'!$B$2:$B$148,B7,'TD_Z1_TotalMontant'!$C$2:$C$148,"ZZ2",'TD_Z1_TotalMontant'!$D$2:$D$148,"HORS TAXE 1") | I7: =SUMIFS('TD_Z1_TotalMontant'!$E$2:$E$148,'TD_Z1_TotalMontant'!$B$2:$B$148,B7,'TD_Z1_TotalMontant'!$C$2:$C$148,"ZZ2",'TD_Z1_TotalMontant'!$D$2:$D$148,"TVA 1")
A8: 2025 | B8: 2025-08 | C8: =SUMIFS('TD_Z1_TotalMontant'!$E$2:$E$148,'TD_Z1_TotalMontant'!$B$2:$B$148,B8,'TD_Z1_TotalMontant'!$C$2:$C$148,"ZZ2",'TD_Z1_TotalMontant'!$D$2:$D$148,"CA BRUT") | D8: =SUMIFS('TD_Z1_TotalMontant'!$E$2:$E$148,'TD_Z1_TotalMontant'!$B$2:$B$148,B8,'TD_Z1_TotalMontant'!$C$2:$C$148,"ZZ2",'TD_Z1_TotalMontant'!$D$2:$D$148,"CA NET") | E8: =SUMIFS('TD_Z1_TotalMontant'!$E$2:$E$148,'TD_Z1_TotalMontant'!$B$2:$B$148,B8,'TD_Z1_TotalMontant'!$C$2:$C$148,"ZZ2",'TD_Z1_TotalMontant'!$D$2:$D$148,"CB.TIROIR") | F8: =SUMIFS('TD_Z1_TotalMontant'!$E$2:$E$148,'TD_Z1_TotalMontant'!$B$2:$B$148,B8,'TD_Z1_TotalMontant'!$C$2:$C$148,"ZZ2",'TD_Z1_TotalMontant'!$D$2:$D$148,"CHQ.TIROIR") | G8: =SUMIFS('TD_Z1_TotalMontant'!$E$2:$E$148,'TD_Z1_TotalMontant'!$B$2:$B$148,B8,'TD_Z1_TotalMontant'!$C$2:$C$148,"ZZ2",'TD_Z1_TotalMontant'!$D$2:$D$148,"ESP.TIROIR") | H8: =SUMIFS('TD_Z1_TotalMontant'!$E$2:$E$148,'TD_Z1_TotalMontant'!$B$2:$B$148,B8,'TD_Z1_TotalMontant'!$C$2:$C$148,"ZZ2",'TD_Z1_TotalMontant'!$D$2:$D$148,"HORS TAXE 1") | I8: =SUMIFS('TD_Z1_TotalMontant'!$E$2:$E$148,'TD_Z1_TotalMontant'!$B$2:$B$148,B8,'TD_Z1_TotalMontant'!$C$2:$C$148,"ZZ2",'TD_Z1_TotalMontant'!$D$2:$D$148,"TVA 1")

Sheet Z1_Total_ModeZ
A1: AJ_ANNEE_Z | B1: AJ_MOIS_Z | C1: CA_BRUT_D_MONTANT | D1: CA_NET_D_MONTANT | E1: CB_TIROIR_D_MONTANT | F1: CHQ_TIROIR_D_MONTANT | G1: ESP_TIROIR_D_MONTANT | H1: HORS_TAXE_1_D_MONTANT | I1: TVA_1_D_MONTANT
A2: 2025 | B2: 2025-01 | C2: =SUMIFS('TD_Z1_TotalMontant'!$E$2:$E$148,'TD_Z1_TotalMontant'!$B$2:$B$148,B2,'TD_Z1_TotalMontant'!$C$2:$C$148,"Z",'TD_Z1_TotalMontant'!$D$2:$D$148,"CA BRUT") | D2: =SUMIFS('TD_Z1_TotalMontant'!$E$2:$E$148,'TD_Z1_TotalMontant'!$B$2:$B$148,B2,'TD_Z1_TotalMontant'!$C$2:$C$148,"Z",'TD_Z1_TotalMontant'!$D$2:$D$148,"CA NET") | E2: =SUMIFS('TD_Z1_TotalMontant'!$E$2:$E$148,'TD_Z1_TotalMontant'!$B$2:$B$148,B2,'TD_Z1_TotalMontant'!$C$2:$C$148,"Z",'TD_Z1_TotalMontant'!$D$2:$D$148,"CB.TIROIR") | F2: =SUMIFS('TD_Z1_TotalMontant'!$E$2:$E$148,'TD_Z1_TotalMontant'!$B$2:$B$148,B2,'TD_Z1_TotalMontant'!$C$2:$C$148,"Z",'TD_Z1_TotalMontant'!$D$2:$D$148,"CHQ.TIROIR") | G2: =SUMIFS('TD_Z1_TotalMontant'!$E$2:$E$148,'TD_Z1_TotalMontant'!$B$2:$B$148,B2,'TD_Z1_TotalMontant'!$C$2:$C$148,"Z",'TD_Z1_TotalMontant'!$D$2:$D$148,"ESP.TIROIR") | H2: =SUMIFS('TD_Z1_TotalMontant'!$E$2:$E$148,'TD_Z1_TotalMontant'!$B$2:$B$148,B2,'TD_Z1_TotalMontant'!$C$2:$C$148,"Z",'TD_Z1_TotalMontant'!$D$2:$D$148,"HORS TAXE 1") | I2: =SUMIFS('TD_Z1_TotalMontant'!$E$2:$E$148,'TD_Z1_TotalMontant'!$B$2:$B$148,B2,'TD_Z1_TotalMontant'!$C$2:$C$148,"Z",'TD_Z1_TotalMontant'!$D$2:$D$148,"TVA 1")
A3: 2025 | B3: 2025-02 | C3: =SUMIFS('TD_Z1_TotalMontant'!$E$2:$E$148,'TD_Z1_TotalMontant'!$B$2:$B$148,B3,'TD_Z1_TotalMontant'!$C$2:$C$148,"Z",'TD_Z1_TotalMontant'!$D$2:$D$148,"CA BRUT") | D3: =SUMIFS('TD_Z1_TotalMontant'!$E$2:$E$148,'TD_Z1_TotalMontant'!$B$2:$B$148,B3,'TD_Z1_TotalMontant'!$C$2:$C$148,"Z",'TD_Z1_TotalMontant'!$D$2:$D$148,"CA NET") | E3: =SUMIFS('TD_Z1_TotalMontant'!$E$2:$E$148,'TD_Z1_TotalMontant'!$B$2:$B$148,B3,'TD_Z1_TotalMontant'!$C$2:$C$148,"Z",'TD_Z1_TotalMontant'!$D$2:$D$148,"CB.TIROIR") | F3: =SUMIFS('TD_Z1_TotalMontant'!$E$2:$E$148,'TD_Z1_TotalMontant'!$B$2:$B$148,B3,'TD_Z1_TotalMontant'!$C$2:$C$148,"Z",'TD_Z1_TotalMontant'!$D$2:$D$148,"CHQ.TIROIR") | G3: =SUMIFS('TD_Z1_TotalMontant'!$E$2:$E$148,'TD_Z1_TotalMontant'!$B$2:$B$148,B3,'TD_Z1_TotalMontant'!$C$2:$C$148,"Z",'TD_Z1_TotalMontant'!$D$2:$D$148,"ESP.TIROIR") | H3: =SUMIFS('TD_Z1_TotalMontant'!$E$2:$E$148,'TD_Z1_TotalMontant'!$B$2:$B$148,B3,'TD_Z1_TotalMontant'!$C$2:$C$148,"Z",'TD_Z1_TotalMontant'!$D$2:$D$148,"HORS TAXE 1") | I3: =SUMIFS('TD_Z1_TotalMontant'!$E$2:$E$148,'TD_Z1_TotalMontant'!$B$2:$B$148,B3,'TD_Z1_TotalMontant'!$C$2:$C$148,"Z",'TD_Z1_TotalMontant'!$D$2:$D$148,"TVA 1")
A4: 2025 | B4: 2025-03 | C4: =SUMIFS('TD_Z1_TotalMontant'!$E$2:$E$148,'TD_Z1_TotalMontant'!$B$2:$B$148,B4,'TD_Z1_TotalMontant'!$C$2:$C$148,"Z",'TD_Z1_TotalMontant'!$D$2:$D$148,"CA BRUT") | D4: =SUMIFS('TD_Z1_TotalMontant'!$E$2:$E$148,'TD_Z1_TotalMontant'!$B$2:$B$148,B4,'TD_Z1_TotalMontant'!$C$2:$C$148,"Z",'TD_Z1_TotalMontant'!$D$2:$D$148,"CA NET") | E4: =SUMIFS('TD_Z1_TotalMontant'!$E$2:$E$148,'TD_Z1_TotalMontant'!$B$2:$B$148,B4,'TD_Z1_TotalMontant'!$C$2:$C$148,"Z",'TD_Z1_TotalMontant'!$D$2:$D$148,"CB.TIROIR") | F4: =SUMIFS('TD_Z1_TotalMontant'!$E$2:$E$148,'TD_Z1_TotalMontant'!$B$2:$B$148,B4,'TD_Z1_TotalMontant'!$C$2:$C$148,"Z",'TD_Z1_TotalMontant'!$D$2:$D$148,"CHQ.TIROIR") | G4: =SUMIFS('TD_Z1_TotalMontant'!$E$2:$E$148,'TD_Z1_TotalMontant'!$B$2:$B$148,B4,'TD_Z1_TotalMontant'!$C$2:$C$148,"Z",'TD_Z1_TotalMontant'!$D$2:$D$148,"ESP.TIROIR") | H4: =SUMIFS('TD_Z1_TotalMontant'!$E$2:$E$148,'TD_Z1_TotalMontant'!$B$2:$B$148,B4,'TD_Z1_TotalMontant'!$C$2:$C$148,"Z",'TD_Z1_TotalMontant'!$D$2:$D$148,"HORS TAXE 1") | I4: =SUMIFS('TD_Z1_TotalMontant'!$E$2:$E$148,'TD_Z1_TotalMontant'!$B$2:$B$148,B4,'TD_Z1_TotalMontant'!$C$2:$C$148,"Z",'TD_Z1_TotalMontant'!$D$2:$D$148,"TVA 1")
A5: 2025 | B5: 2025-04 | C5: =SUMIFS('TD_Z1_TotalMontant'!$E$2:$E$148,'TD_Z1_TotalMontant'!$B$2:$B$148,B5,'TD_Z1_TotalMontant'!$C$2:$C$148,"Z",'TD_Z1_TotalMontant'!$D$2:$D$148,"CA BRUT") | D5: =SUMIFS('TD_Z1_TotalMontant'!$E$2:$E$148,'TD_Z1_TotalMontant'!$B$2:$B$148,B5,'TD_Z1_TotalMontant'!$C$2:$C$148,"Z",'TD_Z1_TotalMontant'!$D$2:$D$148,"CA NET") | E5: =SUMIFS('TD_Z1_TotalMontant'!$E$2:$E$148,'TD_Z1_TotalMontant'!$B$2:$B$148,B5,'TD_Z1_TotalMontant'!$C$2:$C$148,"Z",'TD_Z1_TotalMontant'!$D$2:$D$148,"CB.TIROIR") | F5: =SUMIFS('TD_Z1_TotalMontant'!$E$2:$E$148,'TD_Z1_TotalMontant'!$B$2:$B$148,B5,'TD_Z1_TotalMontant'!$C$2:$C$148,"Z",'TD_Z1_TotalMontant'!$D$2:$D$148,"CHQ.TIROIR") | G5: =SUMIFS('TD_Z1_TotalMontant'!$E$2:$E$148,'TD_Z1_TotalMontant'!$B$2:$B$148,B5,'TD_Z1_TotalMontant'!$C$2:$C$148,"Z",'TD_Z1_TotalMontant'!$D$2:$D$148,"ESP.TIROIR") | H5: =SUMIFS('TD_Z1_TotalMontant'!$E$2:$E$148,'TD_Z1_TotalMontant'!$B$2:$B$148,B5,'TD_Z1_TotalMontant'!$C$2:$C$148,"Z",'TD_Z1_TotalMontant'!$D$2:$D$148,"HORS TAXE 1") | I5: =SUMIFS('TD_Z1_TotalMontant'!$E$2:$E$148,'TD_Z1_TotalMontant'!$B$2:$B$148,B5,'TD_Z1_TotalMontant'!$C$2:$C$148,"Z",'TD_Z1_TotalMontant'!$D$2:$D$148,"TVA 1")
A6: 2025 | B6: 2025-05 | C6: =SUMIFS('TD_Z1_TotalMontant'!$E$2:$E$148,'TD_Z1_TotalMontant'!$B$2:$B$148,B6,'TD_Z1_TotalMontant'!$C$2:$C$148,"Z",'TD_Z1_TotalMontant'!$D$2:$D$148,"CA BRUT") | D6: =SUMIFS('TD_Z1_TotalMontant'!$E$2:$E$148,'TD_Z1_TotalMontant'!$B$2:$B$148,B6,'TD_Z1_TotalMontant'!$C$2:$C$148,"Z",'TD_Z1_TotalMontant'!$D$2:$D$148,"CA NET") | E6: =SUMIFS('TD_Z1_TotalMontant'!$E$2:$E$148,'TD_Z1_TotalMontant'!$B$2:$B$148,B6,'TD_Z1_TotalMontant'!$C$2:$C$148,"Z",'TD_Z1_TotalMontant'!$D$2:$D$148,"CB.TIROIR") | F6: =SUMIFS('TD_Z1_TotalMontant'!$E$2:$E$148,'TD_Z1_TotalMontant'!$B$2:$B$148,B6,'TD_Z1_TotalMontant'!$C$2:$C$148,"Z",'TD_Z1_TotalMontant'!$D$2:$D$148,"CHQ.TIROIR") | G6: =SUMIFS('TD_Z1_TotalMontant'!$E$2:$E$148,'TD_Z1_TotalMontant'!$B$2:$B$148,B6,'TD_Z1_TotalMontant'!$C$2:$C$148,"Z",'TD_Z1_TotalMontant'!$D$2:$D$148,"ESP.TIROIR") | H6: =SUMIFS('TD_Z1_TotalMontant'!$E$2:$E$148,'TD_Z1_TotalMontant'!$B$2:$B$148,B6,'TD_Z1_TotalMontant'!$C$2:$C$148,"Z",'TD_Z1_TotalMontant'!$D$2:$D$148,"HORS TAXE 1") | I6: =SUMIFS('TD_Z1_TotalMontant'!$E$2:$E$148,'TD_Z1_TotalMontant'!$B$2:$B$148,B6,'TD_Z1_TotalMontant'!$C$2:$C$148,"Z",'TD_Z1_TotalMontant'!$D$2:$D$148,"TVA 1")
A7: 2025 | B7: 2025-06|2025-07 | C7: =SUMIFS('TD_Z1_TotalMontant'!$E$2:$E$148,'TD_Z1_TotalMontant'!$B$2:$B$148,B7,'TD_Z1_TotalMontant'!$C$2:$C$148,"Z",'TD_Z1_TotalMontant'!$D$2:$D$148,"CA BRUT") | D7: =SUMIFS('TD_Z1_TotalMontant'!$E$2:$E$148,'TD_Z1_TotalMontant'!$B$2:$B$148,B7,'TD_Z1_TotalMontant'!$C$2:$C$148,"Z",'TD_Z1_TotalMontant'!$D$2:$D$148,"CA NET") | E7: =SUMIFS('TD_Z1_TotalMontant'!$E$2:$E$148,'TD_Z1_TotalMontant'!$B$2:$B$148,B7,'TD_Z1_TotalMontant'!$C$2:$C$148,"Z",'TD_Z1_TotalMontant'!$D$2:$D$148,"CB.TIROIR") | F7: =SUMIFS('TD_Z1_TotalMontant'!$E$2:$E$148,'TD_Z1_TotalMontant'!$B$2:$B$148,B7,'TD_Z1_TotalMontant'!$C$2:$C$148,"Z",'TD_Z1_TotalMontant'!$D$2:$D$148,"CHQ.TIROIR") | G7: =SUMIFS('TD_Z1_TotalMontant'!$E$2:$E$148,'TD_Z1_TotalMontant'!$B$2:$B$148,B7,'TD_Z1_TotalMontant'!$C$2:$C$148,"Z",'TD_Z1_TotalMontant'!$D$2:$D$148,"ESP.TIROIR") | H7: =SUMIFS('TD_Z1_TotalMontant'!$E$2:$E$148,'TD_Z1_TotalMontant'!$B$2:$B$148,B7,'TD_Z1_TotalMontant'!$C$2:$C$148,"Z",'TD_Z1_TotalMontant'!$D$2:$D$148,"HORS TAXE 1") | I7: =SUMIFS('TD_Z1_TotalMontant'!$E$2:$E$148,'TD_Z1_TotalMontant'!$B$2:$B$148,B7,'TD_Z1_TotalMontant'!$C$2:$C$148,"Z",'TD_Z1_TotalMontant'!$D$2:$D$148,"TVA 1")
A8: 2025 | B8: 2025-08 | C8: =SUMIFS('TD_Z1_TotalMontant'!$E$2:$E$148,'TD_Z1_TotalMontant'!$B$2:$B$148,B8,'TD_Z1_TotalMontant'!$C$2:$C$148,"Z",'TD_Z1_TotalMontant'!$D$2:$D$148,"CA BRUT") | D8: =SUMIFS('TD_Z1_TotalMontant'!$E$2:$E$148,'TD_Z1_TotalMontant'!$B$2:$B$148,B8,'TD_Z1_TotalMontant'!$C$2:$C$148,"Z",'TD_Z1_TotalMontant'!$D$2:$D$148,"CA NET") | E8: =SUMIFS('TD_Z1_TotalMontant'!$E$2:$E$148,'TD_Z1_TotalMontant'!$B$2:$B$148,B8,'TD_Z1_TotalMontant'!$C$2:$C$148,"Z",'TD_Z1_TotalMontant'!$D$2:$D$148,"CB.TIROIR") | F8: =SUMIFS('TD_Z1_TotalMontant'!$E$2:$E$148,'TD_Z1_TotalMontant'!$B$2:$B$148,B8,'TD_Z1_TotalMontant'!$C$2:$C$148,"Z",'TD_Z1_TotalMontant'!$D$2:$D$148,"CHQ.TIROIR") | G8: =SUMIFS('TD_Z1_TotalMontant'!$E$2:$E$148,'TD_Z1_TotalMontant'!$B$2:$B$148,B8,'TD_Z1_TotalMontant'!$C$2:$C$148,"Z",'TD_Z1_TotalMontant'!$D$2:$D$148,"ESP.TIROIR") | H8: =SUMIFS('TD_Z1_TotalMontant'!$E$2:$E$148,'TD_Z1_TotalMontant'!$B$2:$B$148,B8,'TD_Z1_TotalMontant'!$C$2:$C$148,"Z",'TD_Z1_TotalMontant'!$D$2:$D$148,"HORS TAXE 1") | I8: =SUMIFS('TD_Z1_TotalMontant'!$E$2:$E$148,'TD_Z1_TotalMontant'!$B$2:$B$148,B8,'TD_Z1_TotalMontant'!$C$2:$C$148,"Z",'TD_Z1_TotalMontant'!$D$2:$D$148,"TVA 1")

Sheet Compare_Z_vs_EJ
A1: AJ_ANNEE_Z | B1: AJ_MOIS_Z | C1: CA_TTC_Z1 | D1: CA_TTC_EJ | E1: AJ_ECART_CA_TTC | F1: HORS_TAXE_1_Z1 | G1: HORS_TAXE_1_EJ | H1: AJ_ECART_HORS_TAXE_1 | I1: TVA1_Z1 | J1: TVA1_EJ | K1: AJ_ECART_TVA1
A2: 2025 | B2: 2025-01 | C2: ='Z1_Total_ModeZ'!C2 | D2: 11680.3 | E2: =C2-D2 | F2: ='Z1_Total_ModeZ'!H2 | G2: 9733.59 | H2: =F2-G2 | I2: ='Z1_Total_ModeZ'!I2 | J2: 1946.71 | K2: =I2-J2
A3: 2025 | B3: 2025-02 | C3: ='Z1_Total_ModeZ'!C3 | D3: 4578.8 | E3: =C3-D3 | F3: ='Z1_Total_ModeZ'!H3 | G3: 3815.68 | H3: =F3-G3 | I3: ='Z1_Total_ModeZ'!I3 | J3: 763.12 | K3: =I3-J3
A4: 2025 | B4: 2025-03 | C4: ='Z1_Total_ModeZ'!C4 | D4: 3853.7 | E4: =C4-D4 | F4: ='Z1_Total_ModeZ'!H4 | G4: 3211.42 | H4: =F4-G4 | I4: ='Z1_Total_ModeZ'!I4 | J4: 642.28 | K4: =I4-J4
A5: 2025 | B5: 2025-04 | C5: ='Z1_Total_ModeZ'!C5 | D5: 0 | E5: =C5-D5 | F5: ='Z1_Total_ModeZ'!H5 | G5: 0 | H5: =F5-G5 | I5: ='Z1_Total_ModeZ'!I5 | J5: 0 | K5: =I5-J5
A6: 2025 | B6: 2025-05 | C6: ='Z1_Total_ModeZ'!C6 | D6: 0 | E6: =C6-D6 | F6: ='Z1_Total_ModeZ'!H6 | G6: 0 | H6: =F6-G6 | I6: ='Z1_Total_ModeZ'!I6 | J6: 0 | K6: =I6-J6
A7: 2025 | B7: 2025-06|2025-07 | C7: ='Z1_Total_ModeZ'!C7 | D7: 27074.6 | E7: =C7-D7 | F7: ='Z1_Total_ModeZ'!H7 | G7: 22562.17 | H7: =F7-G7 | I7: ='Z1_Total_ModeZ'!I7 | J7: 4512.43 | K7: =I7-J7
A8: 2025 | B8: 2025-08 | C8: ='Z1_Total_ModeZ'!C8 | D8: 2176 | E8: =C8-D8 | F8: ='Z1_Total_ModeZ'!H8 | G8: 1813.33 | H8: =F8-G8 | I8: ='Z1_Total_ModeZ'!I8 | J8: 362.67 | K8: =I8-J8
