Workbook

Sheet Z1_2024_MATURIN_0
A1: nomfichier | B1: E_MODELE | C1: E_MACHINE | D1: E_RAPPORT | E1: E_FICHIER | F1: E_MODE | G1: E_COMPTEUR_Z | H1: E_DATE | I1: E_HEURE | J1: D_ENREGISTREMENT | K1: D_DESIGNATION | L1: D_QUANTITE | M1: D_MONTANT
A2: Z001_01_012024_MATURIN.CSV | C2: MC#01 | D2: FONC FIXES | E2: FILE001 | F2: Z | G2: 0029 | H2: 45323 | I2: 10:29 | J2: 0001 | K2: CA BRUT | L2: 63 | M2: 26282.65
A3: Z001_01_012024_MATURIN.CSV | C3: MC#01 | D3: FONC FIXES | E3: FILE001 | F3: Z | G3: 0029 | H3: 45323 | I3: 10:29 | J3: 0002 | K3: CA NET | L3: 94 | M3: 26282.65
A4: Z001_01_012024_MATURIN.CSV | C4: MC#01 | D4: FONC FIXES | E4: FILE001 | F4: Z | G4: 0029 | H4: 45323 | I4: 10:29 | J4: 0003 | K4: ESP.TIROIR | L4: 0 | M4: 2027.95
A5: Z001_01_012024_MATURIN.CSV | C5: MC#01 | D5: FONC FIXES | E5: FILE001 | F5: Z | G5: 0029 | H5: 45323 | I5: 10:29 | J5: 0004 | K5: CB.TIROIR | L5: 0 | M5: 24254.7
A6: Z001_01_012024_MATURIN.CSV | C6: MC#01 | D6: FONC FIXES | E6: FILE001 | F6: Z | G6: 0029 | H6: 45323 | I6: 10:29 | J6: 0005 | K6: CHQ.TIROIR | L6: 0 | M6: 0
A7: Z001_01_012024_MATURIN.CSV | C7: MC#01 | D7: FONC FIXES | E7: FILE001 | F7: Z | G7: 0029 | H7: 45323 | I7: 10:29 | J7: 0006 | K7: CR.TIROIR(1) | L7: 0 | M7: 0
A8: Z001_01_012024_MATURIN.CSV | C8: MC#01 | D8: FONC FIXES | E8: FILE001 | F8: Z | G8: 0029 | H8: 45323 | I8: 10:29 | J8: 0007 | K8: CR.TIROIR(2) | L8: 0 | M8: 0
A9: Z001_01_012024_MATURIN.CSV | C9: MC#01 | D9: FONC FIXES | E9: FILE001 | F9: Z | G9: 0029 | H9: 45323 | I9: 10:29 | J9: 0008 | K9: CR.TIROIR(3) | L9: 0 | M9: 0
A10: Z001_01_012024_MATURIN.CSV | C10: MC#01 | D10: FONC FIXES | E10: FILE001 | F10: Z | G10: 0029 | H10: 45323 | I10: 10:29 | J10: 0009 | K10: CR.TIROIR(4) | L10: 0 | M10: 0
A11: Z001_01_012024_MATURIN.CSV | C11: MC#01 | D11: FONC FIXES | E11: FILE001 | F11: Z | G11: 0029 | H11: 45323 | I11: 10:29 | J11: 0010 | K11: ESP.TIROIR2 | L11: 0 | M11: 0
A12: Z001_01_012024_MATURIN.CSV | C12: MC#01 | D12: FONC FIXES | E12: FILE001 | F12: Z | G12: 0029 | H12: 45323 | I12: 10:29 | J12: 0011 | K12: CB.TIROIR2 | L12: 0 | M12: 0
A13: Z001_01_012024_MATURIN.CSV | C13: MC#01 | D13: FONC FIXES | E13: FILE001 | F13: Z | G13: 0029 | H13: 45323 | I13: 10:29 | J13: 0012 | K13: CHQ.TIROIR2 | L13: 0 | M13: 0
... A27: Z001_01_012024_MATURIN.CSV | C27: MC#01 | D27: FONC FIXES | E27: FILE001 | F27: Z | G27: 0029 | H27: 45323 | I27: 10:29 | J27: 0026 | K27: TOTAL REMISE | L27: 0 | M27: 0
A28: Z001_01_012024_MATURIN.CSV | C28: MC#01 | D28: FONC FIXES | E28: FILE001 | F28: Z | G28: 0029 | H28: 45323 | I28: 10:29 | J28: 0027 | L28: 0 | M28: 0
A29: Z001_01_012024_MATURIN.CSV | C29: MC#01 | D29: FONC FIXES | E29: FILE001 | F29: Z | G29: 0029 | H29: 45323 | I29: 10:29 | J29: 0028 | K29: RETOUR+ANNUL | L29: 0 | M29: 0
A30: Z001_01_012024_MATURIN.CSV | C30: MC#01 | D30: FONC FIXES | E30: FILE001 | F30: Z | G30: 0029 | H30: 45323 | I30: 10:29 | J30: 0029 | K30: TL ARRONDI | L30: 0 | M30: 0
A31: Z001_01_012024_MATURIN.CSV | C31: MC#01 | D31: FONC FIXES | E31: FILE001 | F31: Z | G31: 0029 | H31: 45323 | I31: 10:29 | J31: 0030 | K31: TL ARRONDI | L31: 0 | M31: 0
A32: Z001_01_012024_MATURIN.CSV | C32: MC#01 | D32: FONC FIXES | E32: FILE001 | F32: Z | G32: 0029 | H32: 45323 | I32: 10:29 | J32: 0031 | K32: NUL TICKET | L32: 0 | M32: 0
A33: Z001_01_012024_MATURIN.CSV | C33: MC#01 | D33: FONC FIXES | E33: FILE001 | F33: Z | G33: 0029 | H33: 45323 | I33: 10:29 | J33: 0032 | L33: 0 | M33: 0
A34: Z001_01_012024_MATURIN.CSV | C34: MC#01 | D34: FONC FIXES | E34: FILE001 | F34: Z | G34: 0029 | H34: 45323 | I34: 10:29 | J34: 0033 | K34: HORS TAXE 1 | L34: 0 | M34: 21902.19
A35: Z001_01_012024_MATURIN.CSV | C35: MC#01 | D35: FONC FIXES | E35: FILE001 | F35: Z | G35: 0029 | H35: 45323 | I35: 10:29 | J35: 0034 | K35: TVA 1 | L35: 0 | M35: 4380.46
A36: Z001_01_012024_MATURIN.CSV | C36: MC#01 | D36: FONC FIXES | E36: FILE001 | F36: Z | G36: 0029 | H36: 45323 | I36: 10:29 | J36: 0035 | K36: HORS TAXE 2 | L36: 0 | M36: 0
A37: Z001_01_012024_MATURIN.CSV | C37: MC#01 | D37: FONC FIXES | E37: FILE001 | F37: Z | G37: 0029 | H37: 45323 | I37: 10:29 | J37: 0036 | K37: TVA 2 | L37: 0 | M37: 0
A38: Z001_01_012024_MATURIN.CSV | C38: MC#01 | D38: FONC FIXES | E38: FILE001 | F38: Z | G38: 0029 | H38: 45323 | I38: 10:29 | J38: 0037 | K38: HORS TAXE 3 | L38: 0 | M38: 0
A39: Z001_01_012024_MATURIN.CSV | C39: MC#01 | D39: FONC FIXES | E39: FILE001 | F39: Z | G39: 0029 | H39: 45323 | I39: 10:29 | J39: 0038 | K39: TVA 3 | L39: 0 | M39: 0
A40: Z001_01_012024_MATURIN.CSV | C40: MC#01 | D40: FONC FIXES | E40: FILE001 | F40: Z | G40: 0029 | H40: 45323 | I40: 10:29 | J40: 0039 | K40: HORS TAXE 4 | L40: 0 | M40: 0
A41: Z001_01_012024_MATURIN.CSV | C41: MC#01 | D41: FONC FIXES | E41: FILE001 | F41: Z | G41: 0029 | H41: 45323 | I41: 10:29 | J41: 0040 | K41: TVA 4 | L41: 0 | M41: 0
A42: Z001_01_012024_MATURIN.CSV | C42: MC#01 | D42: FONC FIXES | E42: FILE001 | F42: Z | G42: 0029 | H42: 45323 | I42: 10:29 | J42: 0041 | K42: NON TAXABLE | L42: 0 | M42: 0
A43: Z001_01_022024_MATURIN.CSV | C43: MC#01 | D43: FONC FIXES | E43: FILE001 | F43: Z | G43: 0030 | H43: 45352 | I43: 09:35 | J43: 0001 | K43: CA BRUT | L43: 107 | M43: 30494.5
A44: Z001_01_022024_MATURIN.CSV | C44: MC#01 | D44: FONC FIXES | E44: FILE001 | F44: Z | G44: 0030 | H44: 45352 | I44: 09:35 | J44: 0002 | K44: CA NET | L44: 40 | M44: 30494.5
A45: Z001_01_022024_MATURIN.CSV | C45: MC#01 | D45: FONC FIXES | E45: FILE001 | F45: Z | G45: 0030 | H45: 45352 | I45: 09:35 | J45: 0003 | K45: ESP.TIROIR | L45: 0 | M45: 3786.8
... A68: Z001_01_022024_MATURIN.CSV | C68: MC#01 | D68: FONC FIXES | E68: FILE001 | F68: Z | G68: 0030 | H68: 45352 | I68: 09:35 | J68: 0026 | K68: TOTAL REMISE | L68: 0 | M68: 0
A69: Z001_01_022024_MATURIN.CSV | C69: MC#01 | D69: FONC FIXES | E69: FILE001 | F69: Z | G69: 0030 | H69: 45352 | I69: 09:35 | J69: 0027 | L69: 0 | M69: 0
A70: Z001_01_022024_MATURIN.CSV | C70: MC#01 | D70: FONC FIXES | E70: FILE001 | F70: Z | G70: 0030 | H70: 45352 | I70: 09:35 | J70: 0028 | K70: RETOUR+ANNUL | L70: 0 | M70: 0
A71: Z001_01_022024_MATURIN.CSV | C71: MC#01 | D71: FONC FIXES | E71: FILE001 | F71: Z | G71: 0030 | H71: 45352 | I71: 09:35 | J71: 0029 | K71: TL ARRONDI | L71: 0 | M71: 0
A72: Z001_01_022024_MATURIN.CSV | C72: MC#01 | D72: FONC FIXES | E72: FILE001 | F72: Z | G72: 0030 | H72: 45352 | I72: 09:35 | J72: 0030 | K72: TL ARRONDI | L72: 0 | M72: 0
A73: Z001_01_022024_MATURIN.CSV | C73: MC#01 | D73: FONC FIXES | E73: FILE001 | F73: Z | G73: 0030 | H73: 45352 | I73: 09:35 | J73: 0031 | K73: NUL TICKET | L73: 0 | M73: 0
A74: Z001_01_022024_MATURIN.CSV | C74: MC#01 | D74: FONC FIXES | E74: FILE001 | F74: Z | G74: 0030 | H74: 45352 | I74: 09:35 | J74: 0032 | L74: 0 | M74: 0
A75: Z001_01_022024_MATURIN.CSV | C75: MC#01 | D75: FONC FIXES | E75: FILE001 | F75: Z | G75: 0030 | H75: 45352 | I75: 09:35 | J75: 0033 | K75: HORS TAXE 1 | L75: 0 | M75: 25412.08
...

Sheet Z1_CplteAnneeMois
A1: nomfichier | B1: E_MODELE | C1: E_MACHINE | D1: E_RAPPORT | E1: E_FICHIER | F1: E_MODE | G1: E_COMPTEUR_Z | H1: E_DATE | I1: E_HEURE | J1: D_ENREGISTREMENT | K1: D_DESIGNATION | L1: D_QUANTITE | M1: D_MONTANT | N1: AJ_ANNEE_Z | O1: AJ_MOIS_Z
A2: Z001_01_012024_MATURIN.CSV | C2: MC#01 | D2: FONC FIXES | E2: FILE001 | F2: Z | G2: 0029 | H2: 45323 | I2: 10:29 | J2: 0001 | K2: CA BRUT | L2: 63 | M2: 26282.65 | N2: 2024 | O2: 2024-01
A3: Z001_01_012024_MATURIN.CSV | C3: MC#01 | D3: FONC FIXES | E3: FILE001 | F3: Z | G3: 0029 | H3: 45323 | I3: 10:29 | J3: 0002 | K3: CA NET | L3: 94 | M3: 26282.65 | N3: 2024 | O3: 2024-01
A4: Z001_01_012024_MATURIN.CSV | C4: MC#01 | D4: FONC FIXES | E4: FILE001 | F4: Z | G4: 0029 | H4: 45323 | I4: 10:29 | J4: 0003 | K4: ESP.TIROIR | L4: 0 | M4: 2027.95 | N4: 2024 | O4: 2024-01
A5: Z001_01_012024_MATURIN.CSV | C5: MC#01 | D5: FONC FIXES | E5: FILE001 | F5: Z | G5: 0029 | H5: 45323 | I5: 10:29 | J5: 0004 | K5: CB.TIROIR | L5: 0 | M5: 24254.7 | N5: 2024 | O5: 2024-01
A6: Z001_01_012024_MATURIN.CSV | C6: MC#01 | D6: FONC FIXES | E6: FILE001 | F6: Z | G6: 0029 | H6: 45323 | I6: 10:29 | J6: 0005 | K6: CHQ.TIROIR | L6: 0 | M6: 0 | N6: 2024 | O6: 2024-01
A7: Z001_01_012024_MATURIN.CSV | C7: MC#01 | D7: FONC FIXES | E7: FILE001 | F7: Z | G7: 0029 | H7: 45323 | I7: 10:29 | J7: 0006 | K7: CR.TIROIR(1) | L7: 0 | M7: 0 | N7: 2024 | O7: 2024-01
A8: Z001_01_012024_MATURIN.CSV | C8: MC#01 | D8: FONC FIXES | E8: FILE001 | F8: Z | G8: 0029 | H8: 45323 | I8: 10:29 | J8: 0007 | K8: CR.TIROIR(2) | L8: 0 | M8: 0 | N8: 2024 | O8: 2024-01
A9: Z001_01_012024_MATURIN.CSV | C9: MC#01 | D9: FONC FIXES | E9: FILE001 | F9: Z | G9: 0029 | H9: 45323 | I9: 10:29 | J9: 0008 | K9: CR.TIROIR(3) | L9: 0 | M9: 0 | N9: 2024 | O9: 2024-01
A10: Z001_01_012024_MATURIN.CSV | C10: MC#01 | D10: FONC FIXES | E10: FILE001 | F10: Z | G10: 0029 | H10: 45323 | I10: 10:29 | J10: 0009 | K10: CR.TIROIR(4) | L10: 0 | M10: 0 | N10: 2024 | O10: 2024-01
A11: Z001_01_012024_MATURIN.CSV | C11: MC#01 | D11: FONC FIXES | E11: FILE001 | F11: Z | G11: 0029 | H11: 45323 | I11: 10:29 | J11: 0010 | K11: ESP.TIROIR2 | L11: 0 | M11: 0 | N11: 2024 | O11: 2024-01
A12: Z001_01_012024_MATURIN.CSV | C12: MC#01 | D12: FONC FIXES | E12: FILE001 | F12: Z | G12: 0029 | H12: 45323 | I12: 10:29 | J12: 0011 | K12: CB.TIROIR2 | L12: 0 | M12: 0 | N12: 2024 | O12: 2024-01
A13: Z001_01_012024_MATURIN.CSV | C13: MC#01 | D13: FONC FIXES | E13: FILE001 | F13: Z | G13: 0029 | H13: 45323 | I13: 10:29 | J13: 0012 | K13: CHQ.TIROIR2 | L13: 0 | M13: 0 | N13: 2024 | O13: 2024-01
... A27: Z001_01_012024_MATURIN.CSV | C27: MC#01 | D27: FONC FIXES | E27: FILE001 | F27: Z | G27: 0029 | H27: 45323 | I27: 10:29 | J27: 0026 | K27: TOTAL REMISE | L27: 0 | M27: 0 | N27: 2024 | O27: 2024-01
A28: Z001_01_012024_MATURIN.CSV | C28: MC#01 | D28: FONC FIXES | E28: FILE001 | F28: Z | G28: 0029 | H28: 45323 | I28: 10:29 | J28: 0027 | L28: 0 | M28: 0 | N28: 2024 | O28: 2024-01
A29: Z001_01_012024_MATURIN.CSV | C29: MC#01 | D29: FONC FIXES | E29: FILE001 | F29: Z | G29: 0029 | H29: 45323 | I29: 10:29 | J29: 0028 | K29: RETOUR+ANNUL | L29: 0 | M29: 0 | N29: 2024 | O29: 2024-01
A30: Z001_01_012024_MATURIN.CSV | C30: MC#01 | D30: FONC FIXES | E30: FILE001 | F30: Z | G30: 0029 | H30: 45323 | I30: 10:29 | J30: 0029 | K30: TL ARRONDI | L30: 0 | M30: 0 | N30: 2024 | O30: 2024-01
A31: Z001_01_012024_MATURIN.CSV | C31: MC#01 | D31: FONC FIXES | E31: FILE001 | F31: Z | G31: 0029 | H31: 45323 | I31: 10:29 | J31: 0030 | K31: TL ARRONDI | L31: 0 | M31: 0 | N31: 2024 | O31: 2024-01
A32: Z001_01_012024_MATURIN.CSV | C32: MC#01 | D32: FONC FIXES | E32: FILE001 | F32: Z | G32: 0029 | H32: 45323 | I32: 10:29 | J32: 0031 | K32: NUL TICKET | L32: 0 | M32: 0 | N32: 2024 | O32: 2024-01
A33: Z001_01_012024_MATURIN.CSV | C33: MC#01 | D33: FONC FIXES | E33: FILE001 | F33: Z | G33: 0029 | H33: 45323 | I33: 10:29 | J33: 0032 | L33: 0 | M33: 0 | N33: 2024 | O33: 2024-01
A34: Z001_01_012024_MATURIN.CSV | C34: MC#01 | D34: FONC FIXES | E34: FILE001 | F34: Z | G34: 0029 | H34: 45323 | I34: 10:29 | J34: 0033 | K34: HORS TAXE 1 | L34: 0 | M34: 21902.19 | N34: 2024 | O34: 2024-01
A35: Z001_01_012024_MATURIN.CSV | C35: MC#01 | D35: FONC FIXES | E35: FILE001 | F35: Z | G35: 0029 | H35: 45323 | I35: 10:29 | J35: 0034 | K35: TVA 1 | L35: 0 | M35: 4380.46 | N35: 2024 | O35: 2024-01
A36: Z001_01_012024_MATURIN.CSV | C36: MC#01 | D36: FONC FIXES | E36: FILE001 | F36: Z | G36: 0029 | H36: 45323 | I36: 10:29 | J36: 0035 | K36: HORS TAXE 2 | L36: 0 | M36: 0 | N36: 2024 | O36: 2024-01
A37: Z001_01_012024_MATURIN.CSV | C37: MC#01 | D37: FONC FIXES | E37: FILE001 | F37: Z | G37: 0029 | H37: 45323 | I37: 10:29 | J37: 0036 | K37: TVA 2 | L37: 0 | M37: 0 | N37: 2024 | O37: 2024-01
A38: Z001_01_012024_MATURIN.CSV | C38: MC#01 | D38: FONC FIXES | E38: FILE001 | F38: Z | G38: 0029 | H38: 45323 | I38: 10:29 | J38: 0037 | K38: HORS TAXE 3 | L38: 0 | M38: 0 | N38: 2024 | O38: 2024-01
A39: Z001_01_012024_MATURIN.CSV | C39: MC#01 | D39: FONC FIXES | E39: FILE001 | F39: Z | G39: 0029 | H39: 45323 | I39: 10:29 | J39: 0038 | K39: TVA 3 | L39: 0 | M39: 0 | N39: 2024 | O39: 2024-01
A40: Z001_01_012024_MATURIN.CSV | C40: MC#01 | D40: FONC FIXES | E40: FILE001 | F40: Z | G40: 0029 | H40: 45323 | I40: 10:29 | J40: 0039 | K40: HORS TAXE 4 | L40: 0 | M40: 0 | N40: 2024 | O40: 2024-01
A41: Z001_01_012024_MATURIN.CSV | C41: MC#01 | D41: FONC FIXES | E41: FILE001 | F41: Z | G41: 0029 | H41: 45323 | I41: 10:29 | J41: 0040 | K41: TVA 4 | L41: 0 | M41: 0 | N41: 2024 | O41: 2024-01
A42: Z001_01_012024_MATURIN.CSV | C42: MC#01 | D42: FONC FIXES | E42: FILE001 | F42: Z | G42: 0029 | H42: 45323 | I42: 10:29 | J42: 0041 | K42: NON TAXABLE | L42: 0 | M42: 0 | N42: 2024 | O42: 2024-01
A43: Z001_01_022024_MATURIN.CSV | C43: MC#01 | D43: FONC FIXES | E43: FILE001 | F43: Z | G43: 0030 | H43: 45352 | I43: 09:35 | J43: 0001 | K43: CA BRUT | L43: 107 | M43: 30494.5 | N43: 2024 | O43: 2024-02
A44: Z001_01_022024_MATURIN.CSV | C44: MC#01 | D44: FONC FIXES | E44: FILE001 | F44: Z | G44: 0030 | H44: 45352 | I44: 09:35 | J44: 0002 | K44: CA NET | L44: 40 | M44: 30494.5 | N44: 2024 | O44: 2024-02
A45: Z001_01_022024_MATURIN.CSV | C45: MC#01 | D45: FONC FIXES | E45: FILE001 | F45: Z | G45: 0030 | H45: 45352 | I45: 09:35 | J45: 0003 | K45: ESP.TIROIR | L45: 0 | M45: 3786.8 | N45: 2024 | O45: 2024-02
... A68: Z001_01_022024_MATURIN.CSV | C68: MC#01 | D68: FONC FIXES | E68: FILE001 | F68: Z | G68: 0030 | H68: 45352 | I68: 09:35 | J68: 0026 | K68: TOTAL REMISE | L68: 0 | M68: 0 | N68: 2024 | O68: 2024-02
A69: Z001_01_022024_MATURIN.CSV | C69: MC#01 | D69: FONC FIXES | E69: FILE001 | F69: Z | G69: 0030 | H69: 45352 | I69: 09:35 | J69: 0027 | L69: 0 | M69: 0 | N69: 2024 | O69: 2024-02
A70: Z001_01_022024_MATURIN.CSV | C70: MC#01 | D70: FONC FIXES | E70: FILE001 | F70: Z | G70: 0030 | H70: 45352 | I70: 09:35 | J70: 0028 | K70: RETOUR+ANNUL | L70: 0 | M70: 0 | N70: 2024 | O70: 2024-02
A71: Z001_01_022024_MATURIN.CSV | C71: MC#01 | D71: FONC FIXES | E71: FILE001 | F71: Z | G71: 0030 | H71: 45352 | I71: 09:35 | J71: 0029 | K71: TL ARRONDI | L71: 0 | M71: 0 | N71: 2024 | O71: 2024-02
A72: Z001_01_022024_MATURIN.CSV | C72: MC#01 | D72: FONC FIXES | E72: FILE001 | F72: Z | G72: 0030 | H72: 45352 | I72: 09:35 | J72: 0030 | K72: TL ARRONDI | L72: 0 | M72: 0 | N72: 2024 | O72: 2024-02
A73: Z001_01_022024_MATURIN.CSV | C73: MC#01 | D73: FONC FIXES | E73: FILE001 | F73: Z | G73: 0030 | H73: 45352 | I73: 09:35 | J73: 0031 | K73: NUL TICKET | L73: 0 | M73: 0 | N73: 2024 | O73: 2024-02
A74: Z001_01_022024_MATURIN.CSV | C74: MC#01 | D74: FONC FIXES | E74: FILE001 | F74: Z | G74: 0030 | H74: 45352 | I74: 09:35 | J74: 0032 | L74: 0 | M74: 0 | N74: 2024 | O74: 2024-02
A75: Z001_01_022024_MATURIN.CSV | C75: MC#01 | D75: FONC FIXES | E75: FILE001 | F75: Z | G75: 0030 | H75: 45352 | I75: 09:35 | J75: 0033 | K75: HORS TAXE 1 | L75: 0 | M75: 25412.08 | N75: 2024 | O75: 2024-02
...

Sheet TD_OccurenceFichMode
A1: AJ_ANNEE_Z | B1: AJ_MOIS_Z | C1: E_DATE | D1: E_FICHIER | E1: E_MODE | F1: OCCURRENCES
A2: 2024 | B2: 2024-01 | C2: 45323 | D2: FILE001 | E2: Z | F2: =COUNTIFS('Z1_CplteAnneeMois'!$O$2:$O$493,B2,'Z1_CplteAnneeMois'!$H$2:$H$493,C2,'Z1_CplteAnneeMois'!$E$2:$E$493,D2,'Z1_CplteAnneeMois'!$F$2:$F$493,E2)
A3: 2024 | B3: 2024-02 | C3: 45352 | D3: FILE001 | E3: Z | F3: =COUNTIFS('Z1_CplteAnneeMois'!$O$2:$O$493,B3,'Z1_CplteAnneeMois'!$H$2:$H$493,C3,'Z1_CplteAnneeMois'!$E$2:$E$493,D3,'Z1_CplteAnneeMois'!$F$2:$F$493,E3)
A4: 2024 | B4: 2024-03 | C4: 45384 | D4: FILE001 | E4: Z | F4: =COUNTIFS('Z1_CplteAnneeMois'!$O$2:$O$493,B4,'Z1_CplteAnneeMois'!$H$2:$H$493,C4,'Z1_CplteAnneeMois'!$E$2:$E$493,D4,'Z1_CplteAnneeMois'!$F$2:$F$493,E4)
A5: 2024 | B5: 2024-04 | C5: 45414 | D5: FILE001 | E5: Z | F5: =COUNTIFS('Z1_CplteAnneeMois'!$O$2:$O$493,B5,'Z1_CplteAnneeMois'!$H$2:$H$493,C5,'Z1_CplteAnneeMois'!$E$2:$E$493,D5,'Z1_CplteAnneeMois'!$F$2:$F$493,E5)
A6: 2024 | B6: 2024-05 | C6: 45444 | D6: FILE001 | E6: Z | F6: =COUNTIFS('Z1_CplteAnneeMois'!$O$2:$O$493,B6,'Z1_CplteAnneeMois'!$H$2:$H$493,C6,'Z1_CplteAnneeMois'!$E$2:$E$493,D6,'Z1_CplteAnneeMois'!$F$2:$F$493,E6)
A7: 2024 | B7: 2024-06 | C7: 45474 | D7: FILE001 | E7: Z | F7: =COUNTIFS('Z1_CplteAnneeMois'!$O$2:$O$493,B7,'Z1_CplteAnneeMois'!$H$2:$H$493,C7,'Z1_CplteAnneeMois'!$E$2:$E$493,D7,'Z1_CplteAnneeMois'!$F$2:$F$493,E7)
A8: 2024 | B8: 2024-07 | C8: 45505 | D8: FILE001 | E8: Z | F8: =COUNTIFS('Z1_CplteAnneeMois'!$O$2:$O$493,B8,'Z1_CplteAnneeMois'!$H$2:$H$493,C8,'Z1_CplteAnneeMois'!$E$2:$E$493,D8,'Z1_CplteAnneeMois'!$F$2:$F$493,E8)
A9: 2024 | B9: 2024-08 | C9: 45534 | D9: FILE001 | E9: Z | F9: =COUNTIFS('Z1_CplteAnneeMois'!$O$2:$O$493,B9,'Z1_CplteAnneeMois'!$H$2:$H$493,C9,'Z1_CplteAnneeMois'!$E$2:$E$493,D9,'Z1_CplteAnneeMois'!$F$2:$F$493,E9)
A10: 2024 | B10: 2024-09 | C10: 45565 | D10: FILE001 | E10: Z | F10: =COUNTIFS('Z1_CplteAnneeMois'!$O$2:$O$493,B10,'Z1_CplteAnneeMois'!$H$2:$H$493,C10,'Z1_CplteAnneeMois'!$E$2:$E$493,D10,'Z1_CplteAnneeMois'!$F$2:$F$493,E10)
A11: 2024 | B11: 2024-10 | C11: 45598 | D11: FILE001 | E11: Z | F11: =COUNTIFS('Z1_CplteAnneeMois'!$O$2:$O$493,B11,'Z1_CplteAnneeMois'!$H$2:$H$493,C11,'Z1_CplteAnneeMois'!$E$2:$E$493,D11,'Z1_CplteAnneeMois'!$F$2:$F$493,E11)
A12: 2024 | B12: 2024-11 | C12: 45628 | D12: FILE001 | E12: Z | F12: =COUNTIFS('Z1_CplteAnneeMois'!$O$2:$O$493,B12,'Z1_CplteAnneeMois'!$H$2:$H$493,C12,'Z1_CplteAnneeMois'!$E$2:$E$493,D12,'Z1_CplteAnneeMois'!$F$2:$F$493,E12)
A13: 2024 | B13: 2024-12 | C13: 45657 | D13: FILE001 | E13: Z | F13: =COUNTIFS('Z1_CplteAnneeMois'!$O$2:$O$493,B13,'Z1_CplteAnneeMois'!$H$2:$H$493,C13,'Z1_CplteAnneeMois'!$E$2:$E$493,D13,'Z1_CplteAnneeMois'!$F$2:$F$493,E13)

Sheet TD_Z1_TotalMontant
A1: AJ_ANNEE_Z | B1: AJ_MOIS_Z | C1: E_MODE | D1: D_DESIGNATION | E1: D_MONTANT
A2: 2024 | B2: 2024-01 | C2: Z | D2: CA BRUT | E2: =SUMIFS('Z1_CplteAnneeMois'!$M$2:$M$493,'Z1_CplteAnneeMois'!$O$2:$O$493,B2,'Z1_CplteAnneeMois'!$F$2:$F$493,C2,'Z1_CplteAnneeMois'!$K$2:$K$493,D2)
A3: 2024 | B3: 2024-01 | C3: Z | D3: CA NET | E3: =SUMIFS('Z1_CplteAnneeMois'!$M$2:$M$493,'Z1_CplteAnneeMois'!$O$2:$O$493,B3,'Z1_CplteAnneeMois'!$F$2:$F$493,C3,'Z1_CplteAnneeMois'!$K$2:$K$493,D3)
A4: 2024 | B4: 2024-01 | C4: Z | D4: CB.TIROIR | E4: =SUMIFS('Z1_CplteAnneeMois'!$M$2:$M$493,'Z1_CplteAnneeMois'!$O$2:$O$493,B4,'Z1_CplteAnneeMois'!$F$2:$F$493,C4,'Z1_CplteAnneeMois'!$K$2:$K$493,D4)
A5: 2024 | B5: 2024-01 | C5: Z | D5: CHQ.TIROIR | E5: =SUMIFS('Z1_CplteAnneeMois'!$M$2:$M$493,'Z1_CplteAnneeMois'!$O$2:$O$493,B5,'Z1_CplteAnneeMois'!$F$2:$F$493,C5,'Z1_CplteAnneeMois'!$K$2:$K$493,D5)
A6: 2024 | B6: 2024-01 | C6: Z | D6: ESP.TIROIR | E6: =SUMIFS('Z1_CplteAnneeMois'!$M$2:$M$493,'Z1_CplteAnneeMois'!$O$2:$O$493,B6,'Z1_CplteAnneeMois'!$F$2:$F$493,C6,'Z1_CplteAnneeMois'!$K$2:$K$493,D6)
A7: 2024 | B7: 2024-01 | C7: Z | D7: HORS TAXE 1 | E7: =SUMIFS('Z1_CplteAnneeMois'!$M$2:$M$493,'Z1_CplteAnneeMois'!$O$2:$O$493,B7,'Z1_CplteAnneeMois'!$F$2:$F$493,C7,'Z1_CplteAnneeMois'!$K$2:$K$493,D7)
A8: 2024 | B8: 2024-01 | C8: Z | D8: TVA 1 | E8: =SUMIFS('Z1_CplteAnneeMois'!$M$2:$M$493,'Z1_CplteAnneeMois'!$O$2:$O$493,B8,'Z1_CplteAnneeMois'!$F$2:$F$493,C8,'Z1_CplteAnneeMois'!$K$2:$K$493,D8)
A9: 2024 | B9: 2024-01 | C9: ZZ1 | D9: CA BRUT | E9: =SUMIFS('Z1_CplteAnneeMois'!$M$2:$M$493,'Z1_CplteAnneeMois'!$O$2:$O$493,B9,'Z1_CplteAnneeMois'!$F$2:$F$493,C9,'Z1_CplteAnneeMois'!$K$2:$K$493,D9)
A10: 2024 | B10: 2024-01 | C10: ZZ1 | D10: CA NET | E10: =SUMIFS('Z1_CplteAnneeMois'!$M$2:$M$493,'Z1_CplteAnneeMois'!$O$2:$O$493,B10,'Z1_CplteAnneeMois'!$F$2:$F$493,C10,'Z1_CplteAnneeMois'!$K$2:$K$493,D10)
A11: 2024 | B11: 2024-01 | C11: ZZ1 | D11: CB.TIROIR | E11: =SUMIFS('Z1_CplteAnneeMois'!$M$2:$M$493,'Z1_CplteAnneeMois'!$O$2:$O$493,B11,'Z1_CplteAnneeMois'!$F$2:$F$493,C11,'Z1_CplteAnneeMois'!$K$2:$K$493,D11)
A12: 2024 | B12: 2024-01 | C12: ZZ1 | D12: CHQ.TIROIR | E12: =SUMIFS('Z1_CplteAnneeMois'!$M$2:$M$493,'Z1_CplteAnneeMois'!$O$2:$O$493,B12,'Z1_CplteAnneeMois'!$F$2:$F$493,C12,'Z1_CplteAnneeMois'!$K$2:$K$493,D12)
A13: 2024 | B13: 2024-01 | C13: ZZ1 | D13: ESP.TIROIR | E13: =SUMIFS('Z1_CplteAnneeMois'!$M$2:$M$493,'Z1_CplteAnneeMois'!$O$2:$O$493,B13,'Z1_CplteAnneeMois'!$F$2:$F$493,C13,'Z1_CplteAnneeMois'!$K$2:$K$493,D13)
... A253: 2024 | B253: 2024-12 | C253: ZZ2 | D253: TVA 1 | E253: =SUMIFS('Z1_CplteAnneeMois'!$M$2:$M$493,'Z1_CplteAnneeMois'!$O$2:$O$493,B253,'Z1_CplteAnneeMois'!$F$2:$F$493,C253,'Z1_CplteAnneeMois'!$K$2:$K$493,D253)

Sheet Z1_Total_ModeZZ1
A1: AJ_ANNEE_Z | B1: AJ_MOIS_Z | C1: CA_BRUT_D_MONTANT | D1: CA_NET_D_MONTANT | E1: CB_TIROIR_D_MONTANT | F1: CHQ_TIROIR_D_MONTANT | G1: ESP_TIROIR_D_MONTANT | H1: HORS_TAXE_1_D_MONTANT | I1: TVA_1_D_MONTANT
A2: 2024 | B2: 2024-01 | C2: =SUMIFS('TD_Z1_TotalMontant'!$E$2:$E$253,'TD_Z1_TotalMontant'!$B$2:$B$253,B2,'TD_Z1_TotalMontant'!$C$2:$C$253,"ZZ1",'TD_Z1_TotalMontant'!$D$2:$D$253,"CA BRUT") | D2: =SUMIFS('TD_Z1_TotalMontant'!$E$2:$E$253,'TD_Z1_TotalMontant'!$B$2:$B$253,B2,'TD_Z1_TotalMontant'!$C$2:$C$253,"ZZ1",'TD_Z1_TotalMontant'!$D$2:$D$253,"CA NET") | E2: =SUMIFS('TD_Z1_TotalMontant'!$E$2:$E$253,'TD_Z1_TotalMontant'!$B$2:$B$253,B2,'TD_Z1_TotalMontant'!$C$2:$C$253,"ZZ1",'TD_Z1_TotalMontant'!$D$2:$D$253,"CB.TIROIR") | F2: =SUMIFS('TD_Z1_TotalMontant'!$E$2:$E$253,'TD_Z1_TotalMontant'!$B$2:$B$253,B2,'TD_Z1_TotalMontant'!$C$2:$C$253,"ZZ1",'TD_Z1_TotalMontant'!$D$2:$D$253,"CHQ.TIROIR") | G2: =SUMIFS('TD_Z1_TotalMontant'!$E$2:$E$253,'TD_Z1_TotalMontant'!$B$2:$B$253,B2,'TD_Z1_TotalMontant'!$C$2:$C$253,"ZZ1",'TD_Z1_TotalMontant'!$D$2:$D$253,"ESP.TIROIR") | H2: =SUMIFS('TD_Z1_TotalMontant'!$E$2:$E$253,'TD_Z1_TotalMontant'!$B$2:$B$253,B2,'TD_Z1_TotalMontant'!$C$2:$C$253,"ZZ1",'TD_Z1_TotalMontant'!$D$2:$D$253,"HORS TAXE 1") | I2: =SUMIFS('TD_Z1_TotalMontant'!$E$2:$E$253,'TD_Z1_TotalMontant'!$B$2:$B$253,B2,'TD_Z1_TotalMontant'!$C$2:$C$253,"ZZ1",'TD_Z1_TotalMontant'!$D$2:$D$253,"TVA 1")
A3: 2024 | B3: 2024-02 | C3: =SUMIFS('TD_Z1_TotalMontant'!$E$2:$E$253,'TD_Z1_TotalMontant'!$B$2:$B$253,B3,'TD_Z1_TotalMontant'!$C$2:$C$253,"ZZ1",'TD_Z1_TotalMontant'!$D$2:$D$253,"CA BRUT") | D3: =SUMIFS('TD_Z1_TotalMontant'!$E$2:$E$253,'TD_Z1_TotalMontant'!$B$2:$B$253,B3,'TD_Z1_TotalMontant'!$C$2:$C$253,"ZZ1",'TD_Z1_TotalMontant'!$D$2:$D$253,"CA NET") | E3: =SUMIFS('TD_Z1_TotalMontant'!$E$2:$E$253,'TD_Z1_TotalMontant'!$B$2:$B$253,B3,'TD_Z1_TotalMontant'!$C$2:$C$253,"ZZ1",'TD_Z1_TotalMontant'!$D$2:$D$253,"CB.TIROIR") | F3: =SUMIFS('TD_Z1_TotalMontant'!$E$2:$E$253,'TD_Z1_TotalMontant'!$B$2:$B$253,B3,'TD_Z1_TotalMontant'!$C$2:$C$253,"ZZ1",'TD_Z1_TotalMontant'!$D$2:$D$253,"CHQ.TIROIR") | G3: =SUMIFS('TD_Z1_TotalMontant'!$E$2:$E$253,'TD_Z1_TotalMontant'!$B$2:$B$253,B3,'TD_Z1_TotalMontant'!$C$2:$C$253,"ZZ1",'TD_Z1_TotalMontant'!$D$2:$D$253,"ESP.TIROIR") | H3: =SUMIFS('TD_Z1_TotalMontant'!$E$2:$E$253,'TD_Z1_TotalMontant'!$B$2:$B$253,B3,'TD_Z1_TotalMontant'!$C$2:$C$253,"ZZ1",'TD_Z1_TotalMontant'!$D$2:$D$253,"HORS TAXE 1") | I3: =SUMIFS('TD_Z1_TotalMontant'!$E$2:$E$253,'TD_Z1_TotalMontant'!$B$2:$B$253,B3,'TD_Z1_TotalMontant'!$C$2:$C$253,"ZZ1",'TD_Z1_TotalMontant'!$D$2:$D$253,"TVA 1")
A4: 2024 | B4: 2024-03 | C4: =SUMIFS('TD_Z1_TotalMontant'!$E$2:$E$253,'TD_Z1_TotalMontant'!$B$2:$B$253,B4,'TD_Z1_TotalMontant'!$C$2:$C$253,"ZZ1",'TD_Z1_TotalMontant'!$D$2:$D$253,"CA BRUT") | D4: =SUMIFS('TD_Z1_TotalMontant'!$E$2:$E$253,'TD_Z1_TotalMontant'!$B$2:$B$253,B4,'TD_Z1_TotalMontant'!$C$2:$C$253,"ZZ1",'TD_Z1_TotalMontant'!$D$2:$D$253,"CA NET") | E4: =SUMIFS('TD_Z1_TotalMontant'!$E$2:$E$253,'TD_Z1_TotalMontant'!$B$2:$B$253,B4,'TD_Z1_TotalMontant'!$C$2:$C$253,"ZZ1",'TD_Z1_TotalMontant'!$D$2:$D$253,"CB.TIROIR") | F4: =SUMIFS('TD_Z1_TotalMontant'!$E$2:$E$253,'TD_Z1_TotalMontant'!$B$2:$B$253,B4,'TD_Z1_TotalMontant'!$C$2:$C$253,"ZZ1",'TD_Z1_TotalMontant'!$D$2:$D$253,"CHQ.TIROIR") | G4: =SUMIFS('TD_Z1_TotalMontant'!$E$2:$E$253,'TD_Z1_TotalMontant'!$B$2:$B$253,B4,'TD_Z1_TotalMontant'!$C$2:$C$253,"ZZ1",'TD_Z1_TotalMontant'!$D$2:$D$253,"ESP.TIROIR") | H4: =SUMIFS('TD_Z1_TotalMontant'!$E$2:$E$253,'TD_Z1_TotalMontant'!$B$2:$B$253,B4,'TD_Z1_TotalMontant'!$C$2:$C$253,"ZZ1",'TD_Z1_TotalMontant'!$D$2:$D$253,"HORS TAXE 1") | I4: =SUMIFS('TD_Z1_TotalMontant'!$E$2:$E$253,'TD_Z1_TotalMontant'!$B$2:$B$253,B4,'TD_Z1_TotalMontant'!$C$2:$C$253,"ZZ1",'TD_Z1_TotalMontant'!$D$2:$D$253,"TVA 1")
A5: 2024 | B5: 2024-04 | C5: =SUMIFS('TD_Z1_TotalMontant'!$E$2:$E$253,'TD_Z1_TotalMontant'!$B$2:$B$253,B5,'TD_Z1_TotalMontant'!$C$2:$C$253,"ZZ1",'TD_Z1_TotalMontant'!$D$2:$D$253,"CA BRUT") | D5: =SUMIFS('TD_Z1_TotalMontant'!$E$2:$E$253,'TD_Z1_TotalMontant'!$B$2:$B$253,B5,'TD_Z1_TotalMontant'!$C$2:$C$253,"ZZ1",'TD_Z1_TotalMontant'!$D$2:$D$253,"CA NET") | E5: =SUMIFS('TD_Z1_TotalMontant'!$E$2:$E$253,'TD_Z1_TotalMontant'!$B$2:$B$253,B5,'TD_Z1_TotalMontant'!$C$2:$C$253,"ZZ1",'TD_Z1_TotalMontant'!$D$2:$D$253,"CB.TIROIR") | F5: =SUMIFS('TD_Z1_TotalMontant'!$E$2:$E$253,'TD_Z1_TotalMontant'!$B$2:$B$253,B5,'TD_Z1_TotalMontant'!$C$2:$C$253,"ZZ1",'TD_Z1_TotalMontant'!$D$2:$D$253,"CHQ.TIROIR") | G5: =SUMIFS('TD_Z1_TotalMontant'!$E$2:$E$253,'TD_Z1_TotalMontant'!$B$2:$B$253,B5,'TD_Z1_TotalMontant'!$C$2:$C$253,"ZZ1",'TD_Z1_TotalMontant'!$D$2:$D$253,"ESP.TIROIR") | H5: =SUMIFS('TD_Z1_TotalMontant'!$E$2:$E$253,'TD_Z1_TotalMontant'!$B$2:$B$253,B5,'TD_Z1_TotalMontant'!$C$2:$C$253,"ZZ1",'TD_Z1_TotalMontant'!$D$2:$D$253,"HORS TAXE 1") | I5: =SUMIFS('TD_Z1_TotalMontant'!$E$2:$E$253,'TD_Z1_TotalMontant'!$B$2:$B$253,B5,'TD_Z1_TotalMontant'!$C$2:$C$253,"ZZ1",'TD_Z1_TotalMontant'!$D$2:$D$253,"TVA 1")
A6: 2024 | B6: 2024-05 | C6: =SUMIFS('TD_Z1_TotalMontant'!$E$2:$E$253,'TD_Z1_TotalMontant'!$B$2:$B$253,B6,'TD_Z1_TotalMontant'!$C$2:$C$253,"ZZ1",'TD_Z1_TotalMontant'!$D$2:$D$253,"CA BRUT") | D6: =SUMIFS('TD_Z1_TotalMontant'!$E$2:$E$253,'TD_Z1_TotalMontant'!$B$2:$B$253,B6,'TD_Z1_TotalMontant'!$C$2:$C$253,"ZZ1",'TD_Z1_TotalMontant'!$D$2:$D$253,"CA NET") | E6: =SUMIFS('TD_Z1_TotalMontant'!$E$2:$E$253,'TD_Z1_TotalMontant'!$B$2:$B$253,B6,'TD_Z1_TotalMontant'!$C$2:$C$253,"ZZ1",'TD_Z1_TotalMontant'!$D$2:$D$253,"CB.TIROIR") | F6: =SUMIFS('TD_Z1_TotalMontant'!$E$2:$E$253,'TD_Z1_TotalMontant'!$B$2:$B$253,B6,'TD_Z1_TotalMontant'!$C$2:$C$253,"ZZ1",'TD_Z1_TotalMontant'!$D$2:$D$253,"CHQ.TIROIR") | G6: =SUMIFS('TD_Z1_TotalMontant'!$E$2:$E$253,'TD_Z1_TotalMontant'!$B$2:$B$253,B6,'TD_Z1_TotalMontant'!$C$2:$C$253,"ZZ1",'TD_Z1_TotalMontant'!$D$2:$D$253,"ESP.TIROIR") | H6: =SUMIFS('TD_Z1_TotalMontant'!$E$2:$E$253,'TD_Z1_TotalMontant'!$B$2:$B$253,B6,'TD_Z1_TotalMontant'!$C$2:$C$253,"ZZ1",'TD_Z1_TotalMontant'!$D$2:$D$253,"HORS TAXE 1") | I6: =SUMIFS('TD_Z1_TotalMontant'!$E$2:$E$253,'TD_Z1_TotalMontant'!$B$2:$B$253,B6,'TD_Z1_TotalMontant'!$C$2:$C$253,"ZZ1",'TD_Z1_TotalMontant'!$D$2:$D$253,"TVA 1")
A7: 2024 | B7: 2024-06 | C7: =SUMIFS('TD_Z1_TotalMontant'!$E$2:$E$253,'TD_Z1_TotalMontant'!$B$2:$B$253,B7,'TD_Z1_TotalMontant'!$C$2:$C$253,"ZZ1",'TD_Z1_TotalMontant'!$D$2:$D$253,"CA BRUT") | D7: =SUMIFS('TD_Z1_TotalMontant'!$E$2:$E$253,'TD_Z1_TotalMontant'!$B$2:$B$253,B7,'TD_Z1_TotalMontant'!$C$2:$C$253,"ZZ1",'TD_Z1_TotalMontant'!$D$2:$D$253,"CA NET") | E7: =SUMIFS('TD_Z1_TotalMontant'!$E$2:$E$253,'TD_Z1_TotalMontant'!$B$2:$B$253,B7,'TD_Z1_TotalMontant'!$C$2:$C$253,"ZZ1",'TD_Z1_TotalMontant'!$D$2:$D$253,"CB.TIROIR") | F7: =SUMIFS('TD_Z1_TotalMontant'!$E$2:$E$253,'TD_Z1_TotalMontant'!$B$2:$B$253,B7,'TD_Z1_TotalMontant'!$C$2:$C$253,"ZZ1",'TD_Z1_TotalMontant'!$D$2:$D$253,"CHQ.TIROIR") | G7: =SUMIFS('TD_Z1_TotalMontant'!$E$2:$E$253,'TD_Z1_TotalMontant'!$B$2:$B$253,B7,'TD_Z1_TotalMontant'!$C$2:$C$253,"ZZ1",'TD_Z1_TotalMontant'!$D$2:$D$253,"ESP.TIROIR") | H7: =SUMIFS('TD_Z1_TotalMontant'!$E$2:$E$253,'TD_Z1_TotalMontant'!$B$2:$B$253,B7,'TD_Z1_TotalMontant'!$C$2:$C$253,"ZZ1",'TD_Z1_TotalMontant'!$D$2:$D$253,"HORS TAXE 1") | I7: =SUMIFS('TD_Z1_TotalMontant'!$E$2:$E$253,'TD_Z1_TotalMontant'!$B$2:$B$253,B7,'TD_Z1_TotalMontant'!$C$2:$C$253,"ZZ1",'TD_Z1_TotalMontant'!$D$2:$D$253,"TVA 1")
A8: 2024 | B8: 2024-07 | C8: =SUMIFS('TD_Z1_TotalMontant'!$E$2:$E$253,'TD_Z1_TotalMontant'!$B$2:$B$253,B8,'TD_Z1_TotalMontant'!$C$2:$C$253,"ZZ1",'TD_Z1_TotalMontant'!$D$2:$D$253,"CA BRUT") | D8: =SUMIFS('TD_Z1_TotalMontant'!$E$2:$E$253,'TD_Z1_TotalMontant'!$B$2:$B$253,B8,'TD_Z1_TotalMontant'!$C$2:$C$253,"ZZ1",'TD_Z1_TotalMontant'!$D$2:$D$253,"CA NET") | E8: =SUMIFS('TD_Z1_TotalMontant'!$E$2:$E$253,'TD_Z1_TotalMontant'!$B$2:$B$253,B8,'TD_Z1_TotalMontant'!$C$2:$C$253,"ZZ1",'TD_Z1_TotalMontant'!$D$2:$D$253,"CB.TIROIR") | F8: =SUMIFS('TD_Z1_TotalMontant'!$E$2:$E$253,'TD_Z1_TotalMontant'!$B$2:$B$253,B8,'TD_Z1_TotalMontant'!$C$2:$C$253,"ZZ1",'TD_Z1_TotalMontant'!$D$2:$D$253,"CHQ.TIROIR") | G8: =SUMIFS('TD_Z1_TotalMontant'!$E$2:$E$253,'TD_Z1_TotalMontant'!$B$2:$B$253,B8,'TD_Z1_TotalMontant'!$C$2:$C$253,"ZZ1",'TD_Z1_TotalMontant'!$D$2:$D$253,"ESP.TIROIR") | H8: =SUMIFS('TD_Z1_TotalMontant'!$E$2:$E$253,'TD_Z1_TotalMontant'!$B$2:$B$253,B8,'TD_Z1_TotalMontant'!$C$2:$C$253,"ZZ1",'TD_Z1_TotalMontant'!$D$2:$D$253,"HORS TAXE 1") | I8: =SUMIFS('TD_Z1_TotalMontant'!$E$2:$E$253,'TD_Z1_TotalMontant'!$B$2:$B$253,B8,'TD_Z1_TotalMontant'!$C$2:$C$253,"ZZ1",'TD_Z1_TotalMontant'!$D$2:$D$253,"TVA 1")
A9: 2024 | B9: 2024-08 | C9: =SUMIFS('TD_Z1_TotalMontant'!$E$2:$E$253,'TD_Z1_TotalMontant'!$B$2:$B$253,B9,'TD_Z1_TotalMontant'!$C$2:$C$253,"ZZ1",'TD_Z1_TotalMontant'!$D$2:$D$253,"CA BRUT") | D9: =SUMIFS('TD_Z1_TotalMontant'!$E$2:$E$253,'TD_Z1_TotalMontant'!$B$2:$B$253,B9,'TD_Z1_TotalMontant'!$C$2:$C$253,"ZZ1",'TD_Z1_TotalMontant'!$D$2:$D$253,"CA NET") | E9: =SUMIFS('TD_Z1_TotalMontant'!$E$2:$E$253,'TD_Z1_TotalMontant'!$B$2:$B$253,B9,'TD_Z1_TotalMontant'!$C$2:$C$253,"ZZ1",'TD_Z1_TotalMontant'!$D$2:$D$253,"CB.TIROIR") | F9: =SUMIFS('TD_Z1_TotalMontant'!$E$2:$E$253,'TD_Z1_TotalMontant'!$B$2:$B$253,B9,'TD_Z1_TotalMontant'!$C$2:$C$253,"ZZ1",'TD_Z1_TotalMontant'!$D$2:$D$253,"CHQ.TIROIR") | G9: =SUMIFS('TD_Z1_TotalMontant'!$E$2:$E$253,'TD_Z1_TotalMontant'!$B$2:$B$253,B9,'TD_Z1_TotalMontant'!$C$2:$C$253,"ZZ1",'TD_Z1_TotalMontant'!$D$2:$D$253,"ESP.TIROIR") | H9: =SUMIFS('TD_Z1_TotalMontant'!$E$2:$E$253,'TD_Z1_TotalMontant'!$B$2:$B$253,B9,'TD_Z1_TotalMontant'!$C$2:$C$253,"ZZ1",'TD_Z1_TotalMontant'!$D$2:$D$253,"HORS TAXE 1") | I9: =SUMIFS('TD_Z1_TotalMontant'!$E$2:$E$253,'TD_Z1_TotalMontant'!$B$2:$B$253,B9,'TD_Z1_TotalMontant'!$C$2:$C$253,"ZZ1",'TD_Z1_TotalMontant'!$D$2:$D$253,"TVA 1")
A10: 2024 | B10: 2024-09 | C10: =SUMIFS('TD_Z1_TotalMontant'!$E$2:$E$253,'TD_Z1_TotalMontant'!$B$2:$B$253,B10,'TD_Z1_TotalMontant'!$C$2:$C$253,"ZZ1",'TD_Z1_TotalMontant'!$D$2:$D$253,"CA BRUT") | D10: =SUMIFS('TD_Z1_TotalMontant'!$E$2:$E$253,'TD_Z1_TotalMontant'!$B$2:$B$253,B10,'TD_Z1_TotalMontant'!$C$2:$C$253,"ZZ1",'TD_Z1_TotalMontant'!$D$2:$D$253,"CA NET") | E10: =SUMIFS('TD_Z1_TotalMontant'!$E$2:$E$253,'TD_Z1_TotalMontant'!$B$2:$B$253,B10,'TD_Z1_TotalMontant'!$C$2:$C$253,"ZZ1",'TD_Z1_TotalMontant'!$D$2:$D$253,"CB.TIROIR") | F10: =SUMIFS('TD_Z1_TotalMontant'!$E$2:$E$253,'TD_Z1_TotalMontant'!$B$2:$B$253,B10,'TD_Z1_TotalMontant'!$C$2:$C$253,"ZZ1",'TD_Z1_TotalMontant'!$D$2:$D$253,"CHQ.TIROIR") | G10: =SUMIFS('TD_Z1_TotalMontant'!$E$2:$E$253,'TD_Z1_TotalMontant'!$B$2:$B$253,B10,'TD_Z1_TotalMontant'!$C$2:$C$253,"ZZ1",'TD_Z1_TotalMontant'!$D$2:$D$253,"ESP.TIROIR") | H10: =SUMIFS('TD_Z1_TotalMontant'!$E$2:$E$253,'TD_Z1_TotalMontant'!$B$2:$B$253,B10,'TD_Z1_TotalMontant'!$C$2:$C$253,"ZZ1",'TD_Z1_TotalMontant'!$D$2:$D$253,"HORS TAXE 1") | I10: =SUMIFS('TD_Z1_TotalMontant'!$E$2:$E$253,'TD_Z1_TotalMontant'!$B$2:$B$253,B10,'TD_Z1_TotalMontant'!$C$2:$C$253,"ZZ1",'TD_Z1_TotalMontant'!$D$2:$D$253,"TVA 1")
A11: 2024 | B11: 2024-10 | C11: =SUMIFS('TD_Z1_TotalMontant'!$E$2:$E$253,'TD_Z1_TotalMontant'!$B$2:$B$253,B11,'TD_Z1_TotalMontant'!$C$2:$C$253,"ZZ1",'TD_Z1_TotalMontant'!$D$2:$D$253,"CA BRUT") | D11: =SUMIFS('TD_Z1_TotalMontant'!$E$2:$E$253,'TD_Z1_TotalMontant'!$B$2:$B$253,B11,'TD_Z1_TotalMontant'!$C$2:$C$253,"ZZ1",'TD_Z1_TotalMontant'!$D$2:$D$253,"CA NET") | E11: =SUMIFS('TD_Z1_TotalMontant'!$E$2:$E$253,'TD_Z1_TotalMontant'!$B$2:$B$253,B11,'TD_Z1_TotalMontant'!$C$2:$C$253,"ZZ1",'TD_Z1_TotalMontant'!$D$2:$D$253,"CB.TIROIR") | F11: =SUMIFS('TD_Z1_TotalMontant'!$E$2:$E$253,'TD_Z1_TotalMontant'!$B$2:$B$253,B11,'TD_Z1_TotalMontant'!$C$2:$C$253,"ZZ1",'TD_Z1_TotalMontant'!$D$2:$D$253,"CHQ.TIROIR") | G11: =SUMIFS('TD_Z1_TotalMontant'!$E$2:$E$253,'TD_Z1_TotalMontant'!$B$2:$B$253,B11,'TD_Z1_TotalMontant'!$C$2:$C$253,"ZZ1",'TD_Z1_TotalMontant'!$D$2:$D$253,"ESP.TIROIR") | H11: =SUMIFS('TD_Z1_TotalMontant'!$E$2:$E$253,'TD_Z1_TotalMontant'!$B$2:$B$253,B11,'TD_Z1_TotalMontant'!$C$2:$C$253,"ZZ1",'TD_Z1_TotalMontant'!$D$2:$D$253,"HORS TAXE 1") | I11: =SUMIFS('TD_Z1_TotalMontant'!$E$2:$E$253,'TD_Z1_TotalMontant'!$B$2:$B$253,B11,'TD_Z1_TotalMontant'!$C$2:$C$253,"ZZ1",'TD_Z1_TotalMontant'!$D$2:$D$253,"TVA 1")
A12: 2024 | B12: 2024-11 | C12: =SUMIFS('TD_Z1_TotalMontant'!$E$2:$E$253,'TD_Z1_TotalMontant'!$B$2:$B$253,B12,'TD_Z1_TotalMontant'!$C$2:$C$253,"ZZ1",'TD_Z1_TotalMontant'!$D$2:$D$253,"CA BRUT") | D12: =SUMIFS('TD_Z1_TotalMontant'!$E$2:$E$253,'TD_Z1_TotalMontant'!$B$2:$B$253,B12,'TD_Z1_TotalMontant'!$C$2:$C$253,"ZZ1",'TD_Z1_TotalMontant'!$D$2:$D$253,"CA NET") | E12: =SUMIFS('TD_Z1_TotalMontant'!$E$2:$E$253,'TD_Z1_TotalMontant'!$B$2:$B$253,B12,'TD_Z1_TotalMontant'!$C$2:$C$253,"ZZ1",'TD_Z1_TotalMontant'!$D$2:$D$253,"CB.TIROIR") | F12: =SUMIFS('TD_Z1_TotalMontant'!$E$2:$E$253,'TD_Z1_TotalMontant'!$B$2:$B$253,B12,'TD_Z1_TotalMontant'!$C$2:$C$253,"ZZ1",'TD_Z1_TotalMontant'!$D$2:$D$253,"CHQ.TIROIR") | G12: =SUMIFS('TD_Z1_TotalMontant'!$E$2:$E$253,'TD_Z1_TotalMontant'!$B$2:$B$253,B12,'TD_Z1_TotalMontant'!$C$2:$C$253,"ZZ1",'TD_Z1_TotalMontant'!$D$2:$D$253,"ESP.TIROIR") | H12: =SUMIFS('TD_Z1_TotalMontant'!$E$2:$E$253,'TD_Z1_TotalMontant'!$B$2:$B$253,B12,'TD_Z1_TotalMontant'!$C$2:$C$253,"ZZ1",'TD_Z1_TotalMontant'!$D$2:$D$253,"HORS TAXE 1") | I12: =SUMIFS('TD_Z1_TotalMontant'!$E$2:$E$253,'TD_Z1_TotalMontant'!$B$2:$B$253,B12,'TD_Z1_TotalMontant'!$C$2:$C$253,"ZZ1",'TD_Z1_TotalMontant'!$D$2:$D$253,"TVA 1")
A13: 2024 | B13: 2024-12 | C13: =SUMIFS('TD_Z1_TotalMontant'!$E$2:$E$253,'TD_Z1_TotalMontant'!$B$2:$B$253,B13,'TD_Z1_TotalMontant'!$C$2:$C$253,"ZZ1",'TD_Z1_TotalMontant'!$D$2:$D$253,"CA BRUT") | D13: =SUMIFS('TD_Z1_TotalMontant'!$E$2:$E$253,'TD_Z1_TotalMontant'!$B$2:$B$253,B13,'TD_Z1_TotalMontant'!$C$2:$C$253,"ZZ1",'TD_Z1_TotalMontant'!$D$2:$D$253,"CA NET") | E13: =SUMIFS('TD_Z1_TotalMontant'!$E$2:$E$253,'TD_Z1_TotalMontant'!$B$2:$B$253,B13,'TD_Z1_TotalMontant'!$C$2:$C$253,"ZZ1",'TD_Z1_TotalMontant'!$D$2:$D$253,"CB.TIROIR") | F13: =SUMIFS('TD_Z1_TotalMontant'!$E$2:$E$253,'TD_Z1_TotalMontant'!$B$2:$B$253,B13,'TD_Z1_TotalMontant'!$C$2:$C$253,"ZZ1",'TD_Z1_TotalMontant'!$D$2:$D$253,"CHQ.TIROIR") | G13: =SUMIFS('TD_Z1_TotalMontant'!$E$2:$E$253,'TD_Z1_TotalMontant'!$B$2:$B$253,B13,'TD_Z1_TotalMontant'!$C$2:$C$253,"ZZ1",'TD_Z1_TotalMontant'!$D$2:$D$253,"ESP.TIROIR") | H13: =SUMIFS('TD_Z1_TotalMontant'!$E$2:$E$253,'TD_Z1_TotalMontant'!$B$2:$B$253,B13,'TD_Z1_TotalMontant'!$C$2:$C$253,"ZZ1",'TD_Z1_TotalMontant'!$D$2:$D$253,"HORS TAXE 1") | I13: =SUMIFS('TD_Z1_TotalMontant'!$E$2:$E$253,'TD_Z1_TotalMontant'!$B$2:$B$253,B13,'TD_Z1_TotalMontant'!$C$2:$C$253,"ZZ1",'TD_Z1_TotalMontant'!$D$2:$D$253,"TVA 1")

Sheet Z1_Total_ModeZZ2
A1: AJ_ANNEE_Z | B1: AJ_MOIS_Z | C1: CA_BRUT_D_MONTANT | D1: CA_NET_D_MONTANT | E1: CB_TIROIR_D_MONTANT | F1: CHQ_TIROIR_D_MONTANT | G1: ESP_TIROIR_D_MONTANT | H1: HORS_TAXE_1_D_MONTANT | I1: TVA_1_D_MONTANT
A2: 2024 | B2: 2024-01 | C2: =SUMIFS('TD_Z1_TotalMontant'!$E$2:$E$253,'TD_Z1_TotalMontant'!$B$2:$B$253,B2,'TD_Z1_TotalMontant'!$C$2:$C$253,"ZZ2",'TD_Z1_TotalMontant'!$D$2:$D$253,"CA BRUT") | D2: =SUMIFS('TD_Z1_TotalMontant'!$E$2:$E$253,'TD_Z1_TotalMontant'!$B$2:$B$253,B2,'TD_Z1_TotalMontant'!$C$2:$C$253,"ZZ2",'TD_Z1_TotalMontant'!$D$2:$D$253,"CA NET") | E2: =SUMIFS('TD_Z1_TotalMontant'!$E$2:$E$253,'TD_Z1_TotalMontant'!$B$2:$B$253,B2,'TD_Z1_TotalMontant'!$C$2:$C$253,"ZZ2",'TD_Z1_TotalMontant'!$D$2:$D$253,"CB.TIROIR") | F2: =SUMIFS('TD_Z1_TotalMontant'!$E$2:$E$253,'TD_Z1_TotalMontant'!$B$2:$B$253,B2,'TD_Z1_TotalMontant'!$C$2:$C$253,"ZZ2",'TD_Z1_TotalMontant'!$D$2:$D$253,"CHQ.TIROIR") | G2: =SUMIFS('TD_Z1_TotalMontant'!$E$2:$E$253,'TD_Z1_TotalMontant'!$B$2:$B$253,B2,'TD_Z1_TotalMontant'!$C$2:$C$253,"ZZ2",'TD_Z1_TotalMontant'!$D$2:$D$253,"ESP.TIROIR") | H2: =SUMIFS('TD_Z1_TotalMontant'!$E$2:$E$253,'TD_Z1_TotalMontant'!$B$2:$B$253,B2,'TD_Z1_TotalMontant'!$C$2:$C$253,"ZZ2",'TD_Z1_TotalMontant'!$D$2:$D$253,"HORS TAXE 1") | I2: =SUMIFS('TD_Z1_TotalMontant'!$E$2:$E$253,'TD_Z1_TotalMontant'!$B$2:$B$253,B2,'TD_Z1_TotalMontant'!$C$2:$C$253,"ZZ2",'TD_Z1_TotalMontant'!$D$2:$D$253,"TVA 1")
A3: 2024 | B3: 2024-02 | C3: =SUMIFS('TD_Z1_TotalMontant'!$E$2:$E$253,'TD_Z1_TotalMontant'!$B$2:$B$253,B3,'TD_Z1_TotalMontant'!$C$2:$C$253,"ZZ2",'TD_Z1_TotalMontant'!$D$2:$D$253,"CA BRUT") | D3: =SUMIFS('TD_Z1_TotalMontant'!$E$2:$E$253,'TD_Z1_TotalMontant'!$B$2:$B$253,B3,'TD_Z1_TotalMontant'!$C$2:$C$253,"ZZ2",'TD_Z1_TotalMontant'!$D$2:$D$253,"CA NET") | E3: =SUMIFS('TD_Z1_TotalMontant'!$E$2:$E$253,'TD_Z1_TotalMontant'!$B$2:$B$253,B3,'TD_Z1_TotalMontant'!$C$2:$C$253,"ZZ2",'TD_Z1_TotalMontant'!$D$2:$D$253,"CB.TIROIR") | F3: =SUMIFS('TD_Z1_TotalMontant'!$E$2:$E$253,'TD_Z1_TotalMontant'!$B$2:$B$253,B3,'TD_Z1_TotalMontant'!$C$2:$C$253,"ZZ2",'TD_Z1_TotalMontant'!$D$2:$D$253,"CHQ.TIROIR") | G3: =SUMIFS('TD_Z1_TotalMontant'!$E$2:$E$253,'TD_Z1_TotalMontant'!$B$2:$B$253,B3,'TD_Z1_TotalMontant'!$C$2:$C$253,"ZZ2",'TD_Z1_TotalMontant'!$D$2:$D$253,"ESP.TIROIR") | H3: =SUMIFS('TD_Z1_TotalMontant'!$E$2:$E$253,'TD_Z1_TotalMontant'!$B$2:$B$253,B3,'TD_Z1_TotalMontant'!$C$2:$C$253,"ZZ2",'TD_Z1_TotalMontant'!$D$2:$D$253,"HORS TAXE 1") | I3: =SUMIFS('TD_Z1_TotalMontant'!$E$2:$E$253,'TD_Z1_TotalMontant'!$B$2:$B$253,B3,'TD_Z1_TotalMontant'!$C$2:$C$253,"ZZ2",'TD_Z1_TotalMontant'!$D$2:$D$253,"TVA 1")
A4: 2024 | B4: 2024-03 | C4: =SUMIFS('TD_Z1_TotalMontant'!$E$2:$E$253,'TD_Z1_TotalMontant'!$B$2:$B$253,B4,'TD_Z1_TotalMontant'!$C$2:$C$253,"ZZ2",'TD_Z1_TotalMontant'!$D$2:$D$253,"CA BRUT") | D4: =SUMIFS('TD_Z1_TotalMontant'!$E$2:$E$253,'TD_Z1_TotalMontant'!$B$2:$B$253,B4,'TD_Z1_TotalMontant'!$C$2:$C$253,"ZZ2",'TD_Z1_TotalMontant'!$D$2:$D$253,"CA NET") | E4: =SUMIFS('TD_Z1_TotalMontant'!$E$2:$E$253,'TD_Z1_TotalMontant'!$B$2:$B$253,B4,'TD_Z1_TotalMontant'!$C$2:$C$253,"ZZ2",'TD_Z1_TotalMontant'!$D$2:$D$253,"CB.TIROIR") | F4: =SUMIFS('TD_Z1_TotalMontant'!$E$2:$E$253,'TD_Z1_TotalMontant'!$B$2:$B$253,B4,'TD_Z1_TotalMontant'!$C$2:$C$253,"ZZ2",'TD_Z1_TotalMontant'!$D$2:$D$253,"CHQ.TIROIR") | G4: =SUMIFS('TD_Z1_TotalMontant'!$E$2:$E$253,'TD_Z1_TotalMontant'!$B$2:$B$253,B4,'TD_Z1_TotalMontant'!$C$2:$C$253,"ZZ2",'TD_Z1_TotalMontant'!$D$2:$D$253,"ESP.TIROIR") | H4: =SUMIFS('TD_Z1_TotalMontant'!$E$2:$E$253,'TD_Z1_TotalMontant'!$B$2:$B$253,B4,'TD_Z1_TotalMontant'!$C$2:$C$253,"ZZ2",'TD_Z1_TotalMontant'!$D$2:$D$253,"HORS TAXE 1") | I4: =SUMIFS('TD_Z1_TotalMontant'!$E$2:$E$253,'TD_Z1_TotalMontant'!$B$2:$B$253,B4,'TD_Z1_TotalMontant'!$C$2:$C$253,"ZZ2",'TD_Z1_TotalMontant'!$D$2:$D$253,"TVA 1")
A5: 2024 | B5: 2024-04 | C5: =SUMIFS('TD_Z1_TotalMontant'!$E$2:$E$253,'TD_Z1_TotalMontant'!$B$2:$B$253,B5,'TD_Z1_TotalMontant'!$C$2:$C$253,"ZZ2",'TD_Z1_TotalMontant'!$D$2:$D$253,"CA BRUT") | D5: =SUMIFS('TD_Z1_TotalMontant'!$E$2:$E$253,'TD_Z1_TotalMontant'!$B$2:$B$253,B5,'TD_Z1_TotalMontant'!$C$2:$C$253,"ZZ2",'TD_Z1_TotalMontant'!$D$2:$D$253,"CA NET") | E5: =SUMIFS('TD_Z1_TotalMontant'!$E$2:$E$253,'TD_Z1_TotalMontant'!$B$2:$B$253,B5,'TD_Z1_TotalMontant'!$C$2:$C$253,"ZZ2",'TD_Z1_TotalMontant'!$D$2:$D$253,"CB.TIROIR") | F5: =SUMIFS('TD_Z1_TotalMontant'!$E$2:$E$253,'TD_Z1_TotalMontant'!$B$2:$B$253,B5,'TD_Z1_TotalMontant'!$C$2:$C$253,"ZZ2",'TD_Z1_TotalMontant'!$D$2:$D$253,"CHQ.TIROIR") | G5: =SUMIFS('TD_Z1_TotalMontant'!$E$2:$E$253,'TD_Z1_TotalMontant'!$B$2:$B$253,B5,'TD_Z1_TotalMontant'!$C$2:$C$253,"ZZ2",'TD_Z1_TotalMontant'!$D$2:$D$253,"ESP.TIROIR") | H5: =SUMIFS('TD_Z1_TotalMontant'!$E$2:$E$253,'TD_Z1_TotalMontant'!$B$2:$B$253,B5,'TD_Z1_TotalMontant'!$C$2:$C$253,"ZZ2",'TD_Z1_TotalMontant'!$D$2:$D$253,"HORS TAXE 1") | I5: =SUMIFS('TD_Z1_TotalMontant'!$E$2:$E$253,'TD_Z1_TotalMontant'!$B$2:$B$253,B5,'TD_Z1_TotalMontant'!$C$2:$C$253,"ZZ2",'TD_Z1_TotalMontant'!$D$2:$D$253,"TVA 1")
A6: 2024 | B6: 2024-05 | C6: =SUMIFS('TD_Z1_TotalMontant'!$E$2:$E$253,'TD_Z1_TotalMontant'!$B$2:$B$253,B6,'TD_Z1_TotalMontant'!$C$2:$C$253,"ZZ2",'TD_Z1_TotalMontant'!$D$2:$D$253,"CA BRUT") | D6: =SUMIFS('TD_Z1_TotalMontant'!$E$2:$E$253,'TD_Z1_TotalMontant'!$B$2:$B$253,B6,'TD_Z1_TotalMontant'!$C$2:$C$253,"ZZ2",'TD_Z1_TotalMontant'!$D$2:$D$253,"CA NET") | E6: =SUMIFS('TD_Z1_TotalMontant'!$E$2:$E$253,'TD_Z1_TotalMontant'!$B$2:$B$253,B6,'TD_Z1_TotalMontant'!$C$2:$C$253,"ZZ2",'TD_Z1_TotalMontant'!$D$2:$D$253,"CB.TIROIR") | F6: =SUMIFS('TD_Z1_TotalMontant'!$E$2:$E$253,'TD_Z1_TotalMontant'!$B$2:$B$253,B6,'TD_Z1_TotalMontant'!$C$2:$C$253,"ZZ2",'TD_Z1_TotalMontant'!$D$2:$D$253,"CHQ.TIROIR") | G6: =SUMIFS('TD_Z1_TotalMontant'!$E$2:$E$253,'TD_Z1_TotalMontant'!$B$2:$B$253,B6,'TD_Z1_TotalMontant'!$C$2:$C$253,"ZZ2",'TD_Z1_TotalMontant'!$D$2:$D$253,"ESP.TIROIR") | H6: =SUMIFS('TD_Z1_TotalMontant'!$E$2:$E$253,'TD_Z1_TotalMontant'!$B$2:$B$253,B6,'TD_Z1_TotalMontant'!$C$2:$C$253,"ZZ2",'TD_Z1_TotalMontant'!$D$2:$D$253,"HORS TAXE 1") | I6: =SUMIFS('TD_Z1_TotalMontant'!$E$2:$E$253,'TD_Z1_TotalMontant'!$B$2:$B$253,B6,'TD_Z1_TotalMontant'!$C$2:$C$253,"ZZ2",'TD_Z1_TotalMontant'!$D$2:$D$253,"TVA 1")
A7: 2024 | B7: 2024-06 | C7: =SUMIFS('TD_Z1_TotalMontant'!$E$2:$E$253,'TD_Z1_TotalMontant'!$B$2:$B$253,B7,'TD_Z1_TotalMontant'!$C$2:$C$253,"ZZ2",'TD_Z1_TotalMontant'!$D$2:$D$253,"CA BRUT") | D7: =SUMIFS('TD_Z1_TotalMontant'!$E$2:$E$253,'TD_Z1_TotalMontant'!$B$2:$B$253,B7,'TD_Z1_TotalMontant'!$C$2:$C$253,"ZZ2",'TD_Z1_TotalMontant'!$D$2:$D$253,"CA NET") | E7: =SUMIFS('TD_Z1_TotalMontant'!$E$2:$E$253,'TD_Z1_TotalMontant'!$B$2:$B$253,B7,'TD_Z1_TotalMontant'!$C$2:$C$253,"ZZ2",'TD_Z1_TotalMontant'!$D$2:$D$253,"CB.TIROIR") | F7: =SUMIFS('TD_Z1_TotalMontant'!$E$2:$E$253,'TD_Z1_TotalMontant'!$B$2:$B$253,B7,'TD_Z1_TotalMontant'!$C$2:$C$253,"ZZ2",'TD_Z1_TotalMontant'!$D$2:$D$253,"CHQ.TIROIR") | G7: =SUMIFS('TD_Z1_TotalMontant'!$E$2:$E$253,'TD_Z1_TotalMontant'!$B$2:$B$253,B7,'TD_Z1_TotalMontant'!$C$2:$C$253,"ZZ2",'TD_Z1_TotalMontant'!$D$2:$D$253,"ESP.TIROIR") | H7: =SUMIFS('TD_Z1_TotalMontant'!$E$2:$E$253,'TD_Z1_TotalMontant'!$B$2:$B$253,B7,'TD_Z1_TotalMontant'!$C$2:$C$253,"ZZ2",'TD_Z1_TotalMontant'!$D$2:$D$253,"HORS TAXE 1") | I7: =SUMIFS('TD_Z1_TotalMontant'!$E$2:$E$253,'TD_Z1_TotalMontant'!$B$2:$B$253,B7,'TD_Z1_TotalMontant'!$C$2:$C$253,"ZZ2",'TD_Z1_TotalMontant'!$D$2:$D$253,"TVA 1")
A8: 2024 | B8: 2024-07 | C8: =SUMIFS('TD_Z1_TotalMontant'!$E$2:$E$253,'TD_Z1_TotalMontant'!$B$2:$B$253,B8,'TD_Z1_TotalMontant'!$C$2:$C$253,"ZZ2",'TD_Z1_TotalMontant'!$D$2:$D$253,"CA BRUT") | D8: =SUMIFS('TD_Z1_TotalMontant'!$E$2:$E$253,'TD_Z1_TotalMontant'!$B$2:$B$253,B8,'TD_Z1_TotalMontant'!$C$2:$C$253,"ZZ2",'TD_Z1_TotalMontant'!$D$2:$D$253,"CA NET") | E8: =SUMIFS('TD_Z1_TotalMontant'!$E$2:$E$253,'TD_Z1_TotalMontant'!$B$2:$B$253,B8,'TD_Z1_TotalMontant'!$C$2:$C$253,"ZZ2",'TD_Z1_TotalMontant'!$D$2:$D$253,"CB.TIROIR") | F8: =SUMIFS('TD_Z1_TotalMontant'!$E$2:$E$253,'TD_Z1_TotalMontant'!$B$2:$B$253,B8,'TD_Z1_TotalMontant'!$C$2:$C$253,"ZZ2",'TD_Z1_TotalMontant'!$D$2:$D$253,"CHQ.TIROIR") | G8: =SUMIFS('TD_Z1_TotalMontant'!$E$2:$E$253,'TD_Z1_TotalMontant'!$B$2:$B$253,B8,'TD_Z1_TotalMontant'!$C$2:$C$253,"ZZ2",'TD_Z1_TotalMontant'!$D$2:$D$253,"ESP.TIROIR") | H8: =SUMIFS('TD_Z1_TotalMontant'!$E$2:$E$253,'TD_Z1_TotalMontant'!$B$2:$B$253,B8,'TD_Z1_TotalMontant'!$C$2:$C$253,"ZZ2",'TD_Z1_TotalMontant'!$D$2:$D$253,"HORS TAXE 1") | I8: =SUMIFS('TD_Z1_TotalMontant'!$E$2:$E$253,'TD_Z1_TotalMontant'!$B$2:$B$253,B8,'TD_Z1_TotalMontant'!$C$2:$C$253,"ZZ2",'TD_Z1_TotalMontant'!$D$2:$D$253,"TVA 1")
A9: 2024 | B9: 2024-08 | C9: =SUMIFS('TD_Z1_TotalMontant'!$E$2:$E$253,'TD_Z1_TotalMontant'!$B$2:$B$253,B9,'TD_Z1_TotalMontant'!$C$2:$C$253,"ZZ2",'TD_Z1_TotalMontant'!$D$2:$D$253,"CA BRUT") | D9: =SUMIFS('TD_Z1_TotalMontant'!$E$2:$E$253,'TD_Z1_TotalMontant'!$B$2:$B$253,B9,'TD_Z1_TotalMontant'!$C$2:$C$253,"ZZ2",'TD_Z1_TotalMontant'!$D$2:$D$253,"CA NET") | E9: =SUMIFS('TD_Z1_TotalMontant'!$E$2:$E$253,'TD_Z1_TotalMontant'!$B$2:$B$253,B9,'TD_Z1_TotalMontant'!$C$2:$C$253,"ZZ2",'TD_Z1_TotalMontant'!$D$2:$D$253,"CB.TIROIR") | F9: =SUMIFS('TD_Z1_TotalMontant'!$E$2:$E$253,'TD_Z1_TotalMontant'!$B$2:$B$253,B9,'TD_Z1_TotalMontant'!$C$2:$C$253,"ZZ2",'TD_Z1_TotalMontant'!$D$2:$D$253,"CHQ.TIROIR") | G9: =SUMIFS('TD_Z1_TotalMontant'!$E$2:$E$253,'TD_Z1_TotalMontant'!$B$2:$B$253,B9,'TD_Z1_TotalMontant'!$C$2:$C$253,"ZZ2",'TD_Z1_TotalMontant'!$D$2:$D$253,"ESP.TIROIR") | H9: =SUMIFS('TD_Z1_TotalMontant'!$E$2:$E$253,'TD_Z1_TotalMontant'!$B$2:$B$253,B9,'TD_Z1_TotalMontant'!$C$2:$C$253,"ZZ2",'TD_Z1_TotalMontant'!$D$2:$D$253,"HORS TAXE 1") | I9: =SUMIFS('TD_Z1_TotalMontant'!$E$2:$E$253,'TD_Z1_TotalMontant'!$B$2:$B$253,B9,'TD_Z1_TotalMontant'!$C$2:$C$253,"ZZ2",'TD_Z1_TotalMontant'!$D$2:$D$253,"TVA 1")
A10: 2024 | B10: 2024-09 | C10: =SUMIFS('TD_Z1_TotalMontant'!$E$2:$E$253,'TD_Z1_TotalMontant'!$B$2:$B$253,B10,'TD_Z1_TotalMontant'!$C$2:$C$253,"ZZ2",'TD_Z1_TotalMontant'!$D$2:$D$253,"CA BRUT") | D10: =SUMIFS('TD_Z1_TotalMontant'!$E$2:$E$253,'TD_Z1_TotalMontant'!$B$2:$B$253,B10,'TD_Z1_TotalMontant'!$C$2:$C$253,"ZZ2",'TD_Z1_TotalMontant'!$D$2:$D$253,"CA NET") | E10: =SUMIFS('TD_Z1_TotalMontant'!$E$2:$E$253,'TD_Z1_TotalMontant'!$B$2:$B$253,B10,'TD_Z1_TotalMontant'!$C$2:$C$253,"ZZ2",'TD_Z1_TotalMontant'!$D$2:$D$253,"CB.TIROIR") | F10: =SUMIFS('TD_Z1_TotalMontant'!$E$2:$E$253,'TD_Z1_TotalMontant'!$B$2:$B$253,B10,'TD_Z1_TotalMontant'!$C$2:$C$253,"ZZ2",'TD_Z1_TotalMontant'!$D$2:$D$253,"CHQ.TIROIR") | G10: =SUMIFS('TD_Z1_TotalMontant'!$E$2:$E$253,'TD_Z1_TotalMontant'!$B$2:$B$253,B10,'TD_Z1_TotalMontant'!$C$2:$C$253,"ZZ2",'TD_Z1_TotalMontant'!$D$2:$D$253,"ESP.TIROIR") | H10: =SUMIFS('TD_Z1_TotalMontant'!$E$2:$E$253,'TD_Z1_TotalMontant'!$B$2:$B$253,B10,'TD_Z1_TotalMontant'!$C$2:$C$253,"ZZ2",'TD_Z1_TotalMontant'!$D$2:$D$253,"HORS TAXE 1") | I10: =SUMIFS('TD_Z1_TotalMontant'!$E$2:$E$253,'TD_Z1_TotalMontant'!$B$2:$B$253,B10,'TD_Z1_TotalMontant'!$C$2:$C$253,"ZZ2",'TD_Z1_TotalMontant'!$D$2:$D$253,"TVA 1")
A11: 2024 | B11: 2024-10 | C11: =SUMIFS('TD_Z1_TotalMontant'!$E$2:$E$253,'TD_Z1_TotalMontant'!$B$2:$B$253,B11,'TD_Z1_TotalMontant'!$C$2:$C$253,"ZZ2",'TD_Z1_TotalMontant'!$D$2:$D$253,"CA BRUT") | D11: =SUMIFS('TD_Z1_TotalMontant'!$E$2:$E$253,'TD_Z1_TotalMontant'!$B$2:$B$253,B11,'TD_Z1_TotalMontant'!$C$2:$C$253,"ZZ2",'TD_Z1_TotalMontant'!$D$2:$D$253,"CA NET") | E11: =SUMIFS('TD_Z1_TotalMontant'!$E$2:$E$253,'TD_Z1_TotalMontant'!$B$2:$B$253,B11,'TD_Z1_TotalMontant'!$C$2:$C$253,"ZZ2",'TD_Z1_TotalMontant'!$D$2:$D$253,"CB.TIROIR") | F11: =SUMIFS('TD_Z1_TotalMontant'!$E$2:$E$253,'TD_Z1_TotalMontant'!$B$2:$B$253,B11,'TD_Z1_TotalMontant'!$C$2:$C$253,"ZZ2",'TD_Z1_TotalMontant'!$D$2:$D$253,"CHQ.TIROIR") | G11: =SUMIFS('TD_Z1_TotalMontant'!$E$2:$E$253,'TD_Z1_TotalMontant'!$B$2:$B$253,B11,'TD_Z1_TotalMontant'!$C$2:$C$253,"ZZ2",'TD_Z1_TotalMontant'!$D$2:$D$253,"ESP.TIROIR") | H11: =SUMIFS('TD_Z1_TotalMontant'!$E$2:$E$253,'TD_Z1_TotalMontant'!$B$2:$B$253,B11,'TD_Z1_TotalMontant'!$C$2:$C$253,"ZZ2",'TD_Z1_TotalMontant'!$D$2:$D$253,"HORS TAXE 1") | I11: =SUMIFS('TD_Z1_TotalMontant'!$E$2:$E$253,'TD_Z1_TotalMontant'!$B$2:$B$253,B11,'TD_Z1_TotalMontant'!$C$2:$C$253,"ZZ2",'TD_Z1_TotalMontant'!$D$2:$D$253,"TVA 1")
A12: 2024 | B12: 2024-11 | C12: =SUMIFS('TD_Z1_TotalMontant'!$E$2:$E$253,'TD_Z1_TotalMontant'!$B$2:$B$253,B12,'TD_Z1_TotalMontant'!$C$2:$C$253,"ZZ2",'TD_Z1_TotalMontant'!$D$2:$D$253,"CA BRUT") | D12: =SUMIFS('TD_Z1_TotalMontant'!$E$2:$E$253,'TD_Z1_TotalMontant'!$B$2:$B$253,B12,'TD_Z1_TotalMontant'!$C$2:$C$253,"ZZ2",'TD_Z1_TotalMontant'!$D$2:$D$253,"CA NET") | E12: =SUMIFS('TD_Z1_TotalMontant'!$E$2:$E$253,'TD_Z1_TotalMontant'!$B$2:$B$253,B12,'TD_Z1_TotalMontant'!$C$2:$C$253,"ZZ2",'TD_Z1_TotalMontant'!$D$2:$D$253,"CB.TIROIR") | F12: =SUMIFS('TD_Z1_TotalMontant'!$E$2:$E$253,'TD_Z1_TotalMontant'!$B$2:$B$253,B12,'TD_Z1_TotalMontant'!$C$2:$C$253,"ZZ2",'TD_Z1_TotalMontant'!$D$2:$D$253,"CHQ.TIROIR") | G12: =SUMIFS('TD_Z1_TotalMontant'!$E$2:$E$253,'TD_Z1_TotalMontant'!$B$2:$B$253,B12,'TD_Z1_TotalMontant'!$C$2:$C$253,"ZZ2",'TD_Z1_TotalMontant'!$D$2:$D$253,"ESP.TIROIR") | H12: =SUMIFS('TD_Z1_TotalMontant'!$E$2:$E$253,'TD_Z1_TotalMontant'!$B$2:$B$253,B12,'TD_Z1_TotalMontant'!$C$2:$C$253,"ZZ2",'TD_Z1_TotalMontant'!$D$2:$D$253,"HORS TAXE 1") | I12: =SUMIFS('TD_Z1_TotalMontant'!$E$2:$E$253,'TD_Z1_TotalMontant'!$B$2:$B$253,B12,'TD_Z1_TotalMontant'!$C$2:$C$253,"ZZ2",'TD_Z1_TotalMontant'!$D$2:$D$253,"TVA 1")
A13: 2024 | B13: 2024-12 | C13: =SUMIFS('TD_Z1_TotalMontant'!$E$2:$E$253,'TD_Z1_TotalMontant'!$B$2:$B$253,B13,'TD_Z1_TotalMontant'!$C$2:$C$253,"ZZ2",'TD_Z1_TotalMontant'!$D$2:$D$253,"CA BRUT") | D13: =SUMIFS('TD_Z1_TotalMontant'!$E$2:$E$253,'TD_Z1_TotalMontant'!$B$2:$B$253,B13,'TD_Z1_TotalMontant'!$C$2:$C$253,"ZZ2",'TD_Z1_TotalMontant'!$D$2:$D$253,"CA NET") | E13: =SUMIFS('TD_Z1_TotalMontant'!$E$2:$E$253,'TD_Z1_TotalMontant'!$B$2:$B$253,B13,'TD_Z1_TotalMontant'!$C$2:$C$253,"ZZ2",'TD_Z1_TotalMontant'!$D$2:$D$253,"CB.TIROIR") | F13: =SUMIFS('TD_Z1_TotalMontant'!$E$2:$E$253,'TD_Z1_TotalMontant'!$B$2:$B$253,B13,'TD_Z1_TotalMontant'!$C$2:$C$253,"ZZ2",'TD_Z1_TotalMontant'!$D$2:$D$253,"CHQ.TIROIR") | G13: =SUMIFS('TD_Z1_TotalMontant'!$E$2:$E$253,'TD_Z1_TotalMontant'!$B$2:$B$253,B13,'TD_Z1_TotalMontant'!$C$2:$C$253,"ZZ2",'TD_Z1_TotalMontant'!$D$2:$D$253,"ESP.TIROIR") | H13: =SUMIFS('TD_Z1_TotalMontant'!$E$2:$E$253,'TD_Z1_TotalMontant'!$B$2:$B$253,B13,'TD_Z1_TotalMontant'!$C$2:$C$253,"ZZ2",'TD_Z1_TotalMontant'!$D$2:$D$253,"HORS TAXE 1") | I13: =SUMIFS('TD_Z1_TotalMontant'!$E$2:$E$253,'TD_Z1_TotalMontant'!$B$2:$B$253,B13,'TD_Z1_TotalMontant'!$C$2:$C$253,"ZZ2",'TD_Z1_TotalMontant'!$D$2:$D$253,"TVA 1")

Sheet Z1_Total_ModeZ
A1: AJ_ANNEE_Z | B1: AJ_MOIS_Z | C1: CA_BRUT_D_MONTANT | D1: CA_NET_D_MONTANT | E1: CB_TIROIR_D_MONTANT | F1: CHQ_TIROIR_D_MONTANT | G1: ESP_TIROIR_D_MONTANT | H1: HORS_TAXE_1_D_MONTANT | I1: TVA_1_D_MONTANT
A2: 2024 | B2: 2024-01 | C2: =SUMIFS('TD_Z1_TotalMontant'!$E$2:$E$253,'TD_Z1_TotalMontant'!$B$2:$B$253,B2,'TD_Z1_TotalMontant'!$C$2:$C$253,"Z",'TD_Z1_TotalMontant'!$D$2:$D$253,"CA BRUT") | D2: =SUMIFS('TD_Z1_TotalMontant'!$E$2:$E$253,'TD_Z1_TotalMontant'!$B$2:$B$253,B2,'TD_Z1_TotalMontant'!$C$2:$C$253,"Z",'TD_Z1_TotalMontant'!$D$2:$D$253,"CA NET") | E2: =SUMIFS('TD_Z1_TotalMontant'!$E$2:$E$253,'TD_Z1_TotalMontant'!$B$2:$B$253,B2,'TD_Z1_TotalMontant'!$C$2:$C$253,"Z",'TD_Z1_TotalMontant'!$D$2:$D$253,"CB.TIROIR") | F2: =SUMIFS('TD_Z1_TotalMontant'!$E$2:$E$253,'TD_Z1_TotalMontant'!$B$2:$B$253,B2,'TD_Z1_TotalMontant'!$C$2:$C$253,"Z",'TD_Z1_TotalMontant'!$D$2:$D$253,"CHQ.TIROIR") | G2: =SUMIFS('TD_Z1_TotalMontant'!$E$2:$E$253,'TD_Z1_TotalMontant'!$B$2:$B$253,B2,'TD_Z1_TotalMontant'!$C$2:$C$253,"Z",'TD_Z1_TotalMontant'!$D$2:$D$253,"ESP.TIROIR") | H2: =SUMIFS('TD_Z1_TotalMontant'!$E$2:$E$253,'TD_Z1_TotalMontant'!$B$2:$B$253,B2,'TD_Z1_TotalMontant'!$C$2:$C$253,"Z",'TD_Z1_TotalMontant'!$D$2:$D$253,"HORS TAXE 1") | I2: =SUMIFS('TD_Z1_TotalMontant'!$E$2:$E$253,'TD_Z1_TotalMontant'!$B$2:$B$253,B2,'TD_Z1_TotalMontant'!$C$2:$C$253,"Z",'TD_Z1_TotalMontant'!$D$2:$D$253,"TVA 1")
A3: 2024 | B3: 2024-02 | C3: =SUMIFS('TD_Z1_TotalMontant'!$E$2:$E$253,'TD_Z1_TotalMontant'!$B$2:$B$253,B3,'TD_Z1_TotalMontant'!$C$2:$C$253,"Z",'TD_Z1_TotalMontant'!$D$2:$D$253,"CA BRUT") | D3: =SUMIFS('TD_Z1_TotalMontant'!$E$2:$E$253,'TD_Z1_TotalMontant'!$B$2:$B$253,B3,'TD_Z1_TotalMontant'!$C$2:$C$253,"Z",'TD_Z1_TotalMontant'!$D$2:$D$253,"CA NET") | E3: =SUMIFS('TD_Z1_TotalMontant'!$E$2:$E$253,'TD_Z1_TotalMontant'!$B$2:$B$253,B3,'TD_Z1_TotalMontant'!$C$2:$C$253,"Z",'TD_Z1_TotalMontant'!$D$2:$D$253,"CB.TIROIR") | F3: =SUMIFS('TD_Z1_TotalMontant'!$E$2:$E$253,'TD_Z1_TotalMontant'!$B$2:$B$253,B3,'TD_Z1_TotalMontant'!$C$2:$C$253,"Z",'TD_Z1_TotalMontant'!$D$2:$D$253,"CHQ.TIROIR") | G3: =SUMIFS('TD_Z1_TotalMontant'!$E$2:$E$253,'TD_Z1_TotalMontant'!$B$2:$B$253,B3,'TD_Z1_TotalMontant'!$C$2:$C$253,"Z",'TD_Z1_TotalMontant'!$D$2:$D$253,"ESP.TIROIR") | H3: =SUMIFS('TD_Z1_TotalMontant'!$E$2:$E$253,'TD_Z1_TotalMontant'!$B$2:$B$253,B3,'TD_Z1_TotalMontant'!$C$2:$C$253,"Z",'TD_Z1_TotalMontant'!$D$2:$D$253,"HORS TAXE 1") | I3: =SUMIFS('TD_Z1_TotalMontant'!$E$2:$E$253,'TD_Z1_TotalMontant'!$B$2:$B$253,B3,'TD_Z1_TotalMontant'!$C$2:$C$253,"Z",'TD_Z1_TotalMontant'!$D$2:$D$253,"TVA 1")
A4: 2024 | B4: 2024-03 | C4: =SUMIFS('TD_Z1_TotalMontant'!$E$2:$E$253,'TD_Z1_TotalMontant'!$B$2:$B$253,B4,'TD_Z1_TotalMontant'!$C$2:$C$253,"Z",'TD_Z1_TotalMontant'!$D$2:$D$253,"CA BRUT") | D4: =SUMIFS('TD_Z1_TotalMontant'!$E$2:$E$253,'TD_Z1_TotalMontant'!$B$2:$B$253,B4,'TD_Z1_TotalMontant'!$C$2:$C$253,"Z",'TD_Z1_TotalMontant'!$D$2:$D$253,"CA NET") | E4: =SUMIFS('TD_Z1_TotalMontant'!$E$2:$E$253,'TD_Z1_TotalMontant'!$B$2:$B$253,B4,'TD_Z1_TotalMontant'!$C$2:$C$253,"Z",'TD_Z1_TotalMontant'!$D$2:$D$253,"CB.TIROIR") | F4: =SUMIFS('TD_Z1_TotalMontant'!$E$2:$E$253,'TD_Z1_TotalMontant'!$B$2:$B$253,B4,'TD_Z1_TotalMontant'!$C$2:$C$253,"Z",'TD_Z1_TotalMontant'!$D$2:$D$253,"CHQ.TIROIR") | G4: =SUMIFS('TD_Z1_TotalMontant'!$E$2:$E$253,'TD_Z1_TotalMontant'!$B$2:$B$253,B4,'TD_Z1_TotalMontant'!$C$2:$C$253,"Z",'TD_Z1_TotalMontant'!$D$2:$D$253,"ESP.TIROIR") | H4: =SUMIFS('TD_Z1_TotalMontant'!$E$2:$E$253,'TD_Z1_TotalMontant'!$B$2:$B$253,B4,'TD_Z1_TotalMontant'!$C$2:$C$253,"Z",'TD_Z1_TotalMontant'!$D$2:$D$253,"HORS TAXE 1") | I4: =SUMIFS('TD_Z1_TotalMontant'!$E$2:$E$253,'TD_Z1_TotalMontant'!$B$2:$B$253,B4,'TD_Z1_TotalMontant'!$C$2:$C$253,"Z",'TD_Z1_TotalMontant'!$D$2:$D$253,"TVA 1")
A5: 2024 | B5: 2024-04 | C5: =SUMIFS('TD_Z1_TotalMontant'!$E$2:$E$253,'TD_Z1_TotalMontant'!$B$2:$B$253,B5,'TD_Z1_TotalMontant'!$C$2:$C$253,"Z",'TD_Z1_TotalMontant'!$D$2:$D$253,"CA BRUT") | D5: =SUMIFS('TD_Z1_TotalMontant'!$E$2:$E$253,'TD_Z1_TotalMontant'!$B$2:$B$253,B5,'TD_Z1_TotalMontant'!$C$2:$C$253,"Z",'TD_Z1_TotalMontant'!$D$2:$D$253,"CA NET") | E5: =SUMIFS('TD_Z1_TotalMontant'!$E$2:$E$253,'TD_Z1_TotalMontant'!$B$2:$B$253,B5,'TD_Z1_TotalMontant'!$C$2:$C$253,"Z",'TD_Z1_TotalMontant'!$D$2:$D$253,"CB.TIROIR") | F5: =SUMIFS('TD_Z1_TotalMontant'!$E$2:$E$253,'TD_Z1_TotalMontant'!$B$2:$B$253,B5,'TD_Z1_TotalMontant'!$C$2:$C$253,"Z",'TD_Z1_TotalMontant'!$D$2:$D$253,"CHQ.TIROIR") | G5: =SUMIFS('TD_Z1_TotalMontant'!$E$2:$E$253,'TD_Z1_TotalMontant'!$B$2:$B$253,B5,'TD_Z1_TotalMontant'!$C$2:$C$253,"Z",'TD_Z1_TotalMontant'!$D$2:$D$253,"ESP.TIROIR") | H5: =SUMIFS('TD_Z1_TotalMontant'!$E$2:$E$253,'TD_Z1_TotalMontant'!$B$2:$B$253,B5,'TD_Z1_TotalMontant'!$C$2:$C$253,"Z",'TD_Z1_TotalMontant'!$D$2:$D$253,"HORS TAXE 1") | I5: =SUMIFS('TD_Z1_TotalMontant'!$E$2:$E$253,'TD_Z1_TotalMontant'!$B$2:$B$253,B5,'TD_Z1_TotalMontant'!$C$2:$C$253,"Z",'TD_Z1_TotalMontant'!$D$2:$D$253,"TVA 1")
A6: 2024 | B6: 2024-05 | C6: =SUMIFS('TD_Z1_TotalMontant'!$E$2:$E$253,'TD_Z1_TotalMontant'!$B$2:$B$253,B6,'TD_Z1_TotalMontant'!$C$2:$C$253,"Z",'TD_Z1_TotalMontant'!$D$2:$D$253,"CA BRUT") | D6: =SUMIFS('TD_Z1_TotalMontant'!$E$2:$E$253,'TD_Z1_TotalMontant'!$B$2:$B$253,B6,'TD_Z1_TotalMontant'!$C$2:$C$253,"Z",'TD_Z1_TotalMontant'!$D$2:$D$253,"CA NET") | E6: =SUMIFS('TD_Z1_TotalMontant'!$E$2:$E$253,'TD_Z1_TotalMontant'!$B$2:$B$253,B6,'TD_Z1_TotalMontant'!$C$2:$C$253,"Z",'TD_Z1_TotalMontant'!$D$2:$D$253,"CB.TIROIR") | F6: =SUMIFS('TD_Z1_TotalMontant'!$E$2:$E$253,'TD_Z1_TotalMontant'!$B$2:$B$253,B6,'TD_Z1_TotalMontant'!$C$2:$C$253,"Z",'TD_Z1_TotalMontant'!$D$2:$D$253,"CHQ.TIROIR") | G6: =SUMIFS('TD_Z1_TotalMontant'!$E$2:$E$253,'TD_Z1_TotalMontant'!$B$2:$B$253,B6,'TD_Z1_TotalMontant'!$C$2:$C$253,"Z",'TD_Z1_TotalMontant'!$D$2:$D$253,"ESP.TIROIR") | H6: =SUMIFS('TD_Z1_TotalMontant'!$E$2:$E$253,'TD_Z1_TotalMontant'!$B$2:$B$253,B6,'TD_Z1_TotalMontant'!$C$2:$C$253,"Z",'TD_Z1_TotalMontant'!$D$2:$D$253,"HORS TAXE 1") | I6: =SUMIFS('TD_Z1_TotalMontant'!$E$2:$E$253,'TD_Z1_TotalMontant'!$B$2:$B$253,B6,'TD_Z1_TotalMontant'!$C$2:$C$253,"Z",'TD_Z1_TotalMontant'!$D$2:$D$253,"TVA 1")
A7: 2024 | B7: 2024-06 | C7: =SUMIFS('TD_Z1_TotalMontant'!$E$2:$E$253,'TD_Z1_TotalMontant'!$B$2:$B$253,B7,'TD_Z1_TotalMontant'!$C$2:$C$253,"Z",'TD_Z1_TotalMontant'!$D$2:$D$253,"CA BRUT") | D7: =SUMIFS('TD_Z1_TotalMontant'!$E$2:$E$253,'TD_Z1_TotalMontant'!$B$2:$B$253,B7,'TD_Z1_TotalMontant'!$C$2:$C$253,"Z",'TD_Z1_TotalMontant'!$D$2:$D$253,"CA NET") | E7: =SUMIFS('TD_Z1_TotalMontant'!$E$2:$E$253,'TD_Z1_TotalMontant'!$B$2:$B$253,B7,'TD_Z1_TotalMontant'!$C$2:$C$253,"Z",'TD_Z1_TotalMontant'!$D$2:$D$253,"CB.TIROIR") | F7: =SUMIFS('TD_Z1_TotalMontant'!$E$2:$E$253,'TD_Z1_TotalMontant'!$B$2:$B$253,B7,'TD_Z1_TotalMontant'!$C$2:$C$253,"Z",'TD_Z1_TotalMontant'!$D$2:$D$253,"CHQ.TIROIR") | G7: =SUMIFS('TD_Z1_TotalMontant'!$E$2:$E$253,'TD_Z1_TotalMontant'!$B$2:$B$253,B7,'TD_Z1_TotalMontant'!$C$2:$C$253,"Z",'TD_Z1_TotalMontant'!$D$2:$D$253,"ESP.TIROIR") | H7: =SUMIFS('TD_Z1_TotalMontant'!$E$2:$E$253,'TD_Z1_TotalMontant'!$B$2:$B$253,B7,'TD_Z1_TotalMontant'!$C$2:$C$253,"Z",'TD_Z1_TotalMontant'!$D$2:$D$253,"HORS TAXE 1") | I7: =SUMIFS('TD_Z1_TotalMontant'!$E$2:$E$253,'TD_Z1_TotalMontant'!$B$2:$B$253,B7,'TD_Z1_TotalMontant'!$C$2:$C$253,"Z",'TD_Z1_TotalMontant'!$D$2:$D$253,"TVA 1")
A8: 2024 | B8: 2024-07 | C8: =SUMIFS('TD_Z1_TotalMontant'!$E$2:$E$253,'TD_Z1_TotalMontant'!$B$2:$B$253,B8,'TD_Z1_TotalMontant'!$C$2:$C$253,"Z",'TD_Z1_TotalMontant'!$D$2:$D$253,"CA BRUT") | D8: =SUMIFS('TD_Z1_TotalMontant'!$E$2:$E$253,'TD_Z1_TotalMontant'!$B$2:$B$253,B8,'TD_Z1_TotalMontant'!$C$2:$C$253,"Z",'TD_Z1_TotalMontant'!$D$2:$D$253,"CA NET") | E8: =SUMIFS('TD_Z1_TotalMontant'!$E$2:$E$253,'TD_Z1_TotalMontant'!$B$2:$B$253,B8,'TD_Z1_TotalMontant'!$C$2:$C$253,"Z",'TD_Z1_TotalMontant'!$D$2:$D$253,"CB.TIROIR") | F8: =SUMIFS('TD_Z1_TotalMontant'!$E$2:$E$253,'TD_Z1_TotalMontant'!$B$2:$B$253,B8,'TD_Z1_TotalMontant'!$C$2:$C$253,"Z",'TD_Z1_TotalMontant'!$D$2:$D$253,"CHQ.TIROIR") | G8: =SUMIFS('TD_Z1_TotalMontant'!$E$2:$E$253,'TD_Z1_TotalMontant'!$B$2:$B$253,B8,'TD_Z1_TotalMontant'!$C$2:$C$253,"Z",'TD_Z1_TotalMontant'!$D$2:$D$253,"ESP.TIROIR") | H8: =SUMIFS('TD_Z1_TotalMontant'!$E$2:$E$253,'TD_Z1_TotalMontant'!$B$2:$B$253,B8,'TD_Z1_TotalMontant'!$C$2:$C$253,"Z",'TD_Z1_TotalMontant'!$D$2:$D$253,"HORS TAXE 1") | I8: =SUMIFS('TD_Z1_TotalMontant'!$E$2:$E$253,'TD_Z1_TotalMontant'!$B$2:$B$253,B8,'TD_Z1_TotalMontant'!$C$2:$C$253,"Z",'TD_Z1_TotalMontant'!$D$2:$D$253,"TVA 1")
A9: 2024 | B9: 2024-08 | C9: =SUMIFS('TD_Z1_TotalMontant'!$E$2:$E$253,'TD_Z1_TotalMontant'!$B$2:$B$253,B9,'TD_Z1_TotalMontant'!$C$2:$C$253,"Z",'TD_Z1_TotalMontant'!$D$2:$D$253,"CA BRUT") | D9: =SUMIFS('TD_Z1_TotalMontant'!$E$2:$E$253,'TD_Z1_TotalMontant'!$B$2:$B$253,B9,'TD_Z1_TotalMontant'!$C$2:$C$253,"Z",'TD_Z1_TotalMontant'!$D$2:$D$253,"CA NET") | E9: =SUMIFS('TD_Z1_TotalMontant'!$E$2:$E$253,'TD_Z1_TotalMontant'!$B$2:$B$253,B9,'TD_Z1_TotalMontant'!$C$2:$C$253,"Z",'TD_Z1_TotalMontant'!$D$2:$D$253,"CB.TIROIR") | F9: =SUMIFS('TD_Z1_TotalMontant'!$E$2:$E$253,'TD_Z1_TotalMontant'!$B$2:$B$253,B9,'TD_Z1_TotalMontant'!$C$2:$C$253,"Z",'TD_Z1_TotalMontant'!$D$2:$D$253,"CHQ.TIROIR") | G9: =SUMIFS('TD_Z1_TotalMontant'!$E$2:$E$253,'TD_Z1_TotalMontant'!$B$2:$B$253,B9,'TD_Z1_TotalMontant'!$C$2:$C$253,"Z",'TD_Z1_TotalMontant'!$D$2:$D$253,"ESP.TIROIR") | H9: =SUMIFS('TD_Z1_TotalMontant'!$E$2:$E$253,'TD_Z1_TotalMontant'!$B$2:$B$253,B9,'TD_Z1_TotalMontant'!$C$2:$C$253,"Z",'TD_Z1_TotalMontant'!$D$2:$D$253,"HORS TAXE 1") | I9: =SUMIFS('TD_Z1_TotalMontant'!$E$2:$E$253,'TD_Z1_TotalMontant'!$B$2:$B$253,B9,'TD_Z1_TotalMontant'!$C$2:$C$253,"Z",'TD_Z1_TotalMontant'!$D$2:$D$253,"TVA 1")
